Workbook

Sheet Stock Item
A1: Name | B1: Group Name | C1: Units | D1: Name of BOM | E1: Unit of manufacture | F1: BOM Component - Item Name | G1: BOM Component - Quantity | H1: BOM Component - Godown | I1: BOM Component - Type of Item | K1: BOM Component - Rate (%) | L1: BOM Component - Location | M1: Unit Price | N1: Cost | O1: USD | P1: INS&FRED | Q1: BCD | R1: Total Cost
A2: =D2 -> NRRR08F30 | B2: Down Light Series | C2: Nos. | D2: NRRR08F30 | E2: 1 | F2: ='Backend data'!C6 -> Trim-O-68 I-51 H-63mm White NRRR8-18W | G2: 1 | H2: Mechanical Store | I2: Component | M2: =R2*87 -> 55.9845 | N2: =M2*G2 -> 55.9845 | O2: 0.429 | P2: 0.5 | R2: =O2+(O2*(P2+Q2)) -> 0.6435
F3: HS 50X24.5mm 8W DR-NR-SR | G3: 1 | H3: Mechanical Store | I3: Component | M3: =R3*87 -> 57.2895 | N3: =M3*G3 -> 57.2895 | O3: 0.439 | P3: 0.5 | R3: =O3+(O3*(P3+Q3)) -> 0.6585
F4: Refl. 50014-W OD-50 LES ID -20.5 H-13.4mm 8-18W | G4: 1 | H4: Mechanical Store | I4: Component | M4: =R4*87 -> 7.4385 | N4: =M4*G4 -> 7.4385 | O4: 0.057 | P4: 0.5 | R4: =O4+(O4*(P4+Q4)) -> 0.0855
F5: Diff. 50014-W D-49.5 T-1.2mm Frosted - 8-18W | G5: 1 | H5: Mechanical Store | I5: Component
F6: COB Holder 50014-W OD-35 ID-17 H-3.5mm 8-18W | G6: 1 | H6: Mechanical Store | I6: Component
F7: Locking Spring L-57 W-10mm T-0.2mm DR/NR-5/18W | G7: 2 | H7: Mechanical Store | I7: Component | M7: =R7*87 -> 2.2185 | N7: =M7*G7 -> 4.437 | O7: 0.017 | P7: 0.5 | R7: =O7+(O7*(P7+Q7)) -> 0.0255
F8: PBX-COB 8-15W | G8: 1 | H8: Mechanical Store | I8: Component | M8: 8.5 | N8: =M8*G8 -> 8.5 | O8: 0 | P8: 0.5 | R8: =O8+(O8*(P8+Q8)) -> 0
F9: SBX-COB 8-18W (12Nos) | G9: 0.08 | H9: Mechanical Store | I9: Component | M9: 27 | N9: =M9*G9 -> 2.16 | O9: 0 | P9: 0.5 | R9: =O9+(O9*(P9+Q9)) -> 0
F10: Conn. 2Pin Ass. Wire Black Male (Small) | G10: 1 | H10: Mechanical Store | I10: Component | M10: =R10*87 -> 3.915 | N10: =M10*G10 -> 3.915 | O10: =0.06/2 -> 0.03 | P10: 0.5 | R10: =O10+(O10*(P10+Q10)) -> 0.045
F11: Sleeve M4mm Fiber Glass White | G11: 0.12 | H11: Mechanical Store | I11: Component | J11: L-120mm | M11: =5.7/1000*120 -> 0.684 | N11: =M11*G11 -> 0.08208 | O11: 0 | P11: 0.5 | R11: =O11+(O11*(P11+Q11)) -> 0
F12: Wire Clip-M3-MS | G12: 1 | H12: Mechanical Store | I12: Component | M12: 0.6 | N12: =M12*G12 -> 0.6 | O12: 0 | P12: 0.5 | R12: =O12+(O12*(P12+Q12)) -> 0
F13: Screw No. 4X6.5mm Self Pan Combi. PH - SS | G13: 1 | H13: Mechanical Store | I13: Component | J13: Screw- M3X7mm use for Wire Clip | M13: 0.21 | N13: =M13*G13 -> 0.21 | O13: 0 | P13: 0.5 | R13: =O13+(O13*(P13+Q13)) -> 0
F14: Screw M3X6mm CSK PH - SS | G14: 2 | H14: Mechanical Store | I14: Component | J14: Screw-M3X6mm use for COB Holder | M14: 0.48 | N14: =M14*G14 -> 0.96 | O14: 0 | P14: 0.5 | R14: =O14+(O14*(P14+Q14)) -> 0
F15: Rivet 1/8" x 1/4" MS (Big) | G15: 4 | H15: Mechanical Store | I15: Component | J15: Ravit - 3.2X6mm | M15: 0.26 | N15: =M15*G15 -> 1.04 | O15: 0 | P15: 0.5 | R15: =O15+(O15*(P15+Q15)) -> 0
F17: ='Backend data'!G6 -> COB 30-36W 3000K 12LED 34-38V 890mA 19x19mm CRI-90 | G17: 1 | H17: Electronics Store | I17: Component | M17: =R17*87 -> 84.825 | N17: =M17*G17 -> 84.825 | O17: 0.65 | P17: 0.5 | R17: =O17+(O17*(P17+Q17)) -> 0.975
F18: ='Backend data'!H6 -> PS 8W 200MA 36V LPF (PCB MT43-8-12W-V2 LPF) | G18: 1 | H18: Mechanical Store | I18: Component | M18: =R18*87 -> 0 | N18: =M18*G18 -> 0 | O18: PS Rate Mention with Total Amt
N19: =SUM(N2:N18) -> 227.44158
L21: NRRR08-CC | N21: =N19+42 -> 269.44158
L22: NRRR08 Track Dimming | N22: =N19+275 -> 502.44158 | S22: Rate
L23: NRRR08 Dali Single Color | N23: =((N19)+(R23*87)) -> 885.16158 | O23: 5.04 | P23: 0.5 | R23: =O23+(O23*(P23+Q23)) -> 7.56 | S23: =R23*87 -> 657.72
L24: NRRR08 BT Single Color | N24: =N19+330 -> 557.44158
L25: NRRR08 Dali Dual Color | N25: =((N19)+(R25*87)) -> 941.92908 | O25: 5.475 | P25: 0.5 | R25: =O25+(O25*(P25+Q25)) -> 8.2125 | S25: =R25*87 -> 714.4875
L26: NRRR08 BT Dual Color | N26: =N19+330 -> 557.44158

Sheet Stock Item (Read Me)
A1: List of Fields | B1: Applicable Countries | C1: Applicable Values
A2: General Details
A3: Name | B3: All | E3: Read the following, before you start using the sample file:
A4: Group Name | B4: All | E4: Stock Item worksheet:
A5: B | B5: All | E5: - Use the worksheet without making any changes to the column headers to enter your business data. - The column headers represent field names in TallyPrime. Mandatory fields are marked in bold for easy reference. - Add new columns, if needed. Ensure to enter Column Headers exactly as mentioned under the List of Fields of the Read Me worksheet. - Delete unwanted columns. However, do not delete columns that represent mandatory fields for masters.
A6: Part No. | B6: All
A7: Alias - Part No. | B7: All
A8: Description | B8: All
A9: Notes | B9: All
A10: Category | B10: All
A11: Units | B11: All | E11: Stock Item (Read Me)
A12: Conversion | B12: All | E12: - The Read Me worksheet is only for your reference. It lists all the fields, with related details, applicable for Stock Item.
A13: Denominator | B13: All
A14: Alternate Units | B14: All | E14: For more information on using Sample Excel File for importing data, refer to | M14: TallyHelp
A15: GST Applicability | B15: All | C15: Applicable, Not Applicable
A16: Opening Balance - Quantity | B16: All
A17: Opening Balance - Rate | B17: All
A18: Opening Balance - Rate Per | B18: All
A19: Opening Balance - Value | B19: All
A20: Language for Name (Except English) | B20: All
A21: Is TCS Applicable | B21: All
A22: Item Allocations Details
A23: Item Allocations - Godown | B23: (When Accounting Terminology is set to "India/SAARC")
A24: Item Allocations - Batch | B24: All
A25: Item Allocations - Quantity | B25: All
A26: Item Allocations - Rate | B26: All
A27: Item Allocations - Rate per | B27: All
A28: Item Allocations - Amount | B28: All
A29: Item Allocations - Mfg. Date | B29: All
A30: Item Allocations - Expiry Date | B30: All
A31: Item Allocations - Location | B31: (When Accounting Terminology is set to "International")
A32: Additional Details
A33: Maintain in Batches | B33: All
A34: Track date of manufacturing | B34: All
A35: Use expiry dates | B35: All
A36: Enable Cost Tracking | B36: All
A37: Costing Method | B37: All | C37: At Zero Cost, Avg. Cost, FIFO, FIFO Perpetual, Last Purchase Cost, LIFO Annual, LIFO Perpetual, Monthly Avg. Cost, Std. Cost
A38: Market Valuation Method | B38: All | C38: At Zero Price, Avg. Price, Last Sale Price, Std. Price
A39: Behaviour
A40: Ignore difference due to physical counting | B40: All
...

Sheet Backend data
C2: TRIM | D2: HOUSING/HS | E2: REFLECTOR | F2: BEAM ANGLE | G2: COLOR TEMP | H2: DRIVING SYSTEM | I2: EXTRA
C3: =MID('Stock Item'!$D$2,4,1) -> R | D3: =MID('Stock Item'!$D$2,3,1) -> R | E3: =MID('Stock Item'!$D$2,5,2) -> 08 | F3: =MID('Stock Item'!$D$2,8,1) -> 3 | G3: =MID('Stock Item'!$D$2,8,2) -> 30 | H3: =MID('Stock Item'!$D$2,10,3) | I3: =MID('Stock Item'!$D$2,2,1) -> R
D4: =CONCATENATE('Backend data'!$D$3,'Backend data'!$E$3) -> R08 | G4: =CONCATENATE($G$3,H3,H5) -> 30- | H4: =CONCATENATE($E$3,$H$3,"-") -> 08-
H5: =CONCATENATE(("-")) -> -
B6: Formulae | C6: =VLOOKUP($C$3,$B$23:$E$72,2,0) -> Trim-O-68 I-51 H-63mm White NRRR8-18W | D6: =VLOOKUP($D$4,G23:$J$100,2,0) -> HS 50X24.5mm 8W DR-NR-SR | E6: =VLOOKUP($E$3,$L$23:$O$72,2,0) -> #N/A | F6: =VLOOKUP($F$3,$Q$23:$T$72,2,0) -> #N/A | G6: =VLOOKUP($G$4,$V$23:$Y$72,2,0) -> COB 30-36W 3000K 12LED 34-38V 890mA 19x19mm CRI-90 | H6: =VLOOKUP($H$4,$AA$23:$AD$72,2,0) -> PS 8W 200MA 36V LPF (PCB MT43-8-12W-V2 LPF) | I6: =VLOOKUP($I$3,AF23:$AI$100,2,0) -> #N/A
B7: Formulae for COST | C7: =VLOOKUP($C$3,$B$23:$E$72,4,0) -> 0 | D7: =VLOOKUP($D$4,G23:$J$100,4,0) -> 0 | E7: =VLOOKUP($E$3,$L$23:$O$72,4,0) -> #N/A | F7: =VLOOKUP($F$3,$Q$23:$T$72,4,0) -> #N/A | G7: =VLOOKUP($G$4,$V$23:$Y$72,4,0) -> 0 | H7: =VLOOKUP($H$4,$AA$23:$AD$72,4,0) -> 0 | I7: =VLOOKUP($I$3,$AF$23:$AI$100,4,0) -> #N/A
B8: Formulae for Quantity | C8: =VLOOKUP($C$3,$B$23:$E$72,3,0) -> 0 | D8: =VLOOKUP($D$4,G23:$J$100,3,0) -> 0 | E8: =VLOOKUP($E$3,$L$23:$O$72,3,0) -> #N/A | F8: =VLOOKUP($F$3,$Q$23:$T$72,3,0) -> #N/A | G8: =VLOOKUP($G$4,$V$23:$Y$72,3,0) -> 0 | H8: =VLOOKUP($H$4,$AA$23:$AD$72,3,0) -> 0 | I8: =VLOOKUP($I$3,$AF$23:$AI$100,3,0) -> #N/A
B21: TRIM | G21: HOUSING/HS | L21: REFLECTOR | Q21: BEAM ANGLE | V21: COLOR TEMPERATURE | AA21: DRIVING SYSTEM | AF21: EXTRA
B22: Code | C22: Item Name | D22: Quantity | E22: Cost | G22: Code | H22: Item Name | I22: Quantity | J22: Cost | L22: Code | M22: Item Name | N22: Quantity | O22: Cost | Q22: Code | R22: Item Name | S22: Quantity | T22: Cost | V22: Code | W22: Item Name | X22: Quantity | Y22: Cost | AA22: Code | AB22: Item Name | AC22: Quantity | AD22: Cost | AF22: Code | AG22: Item Name | AH22: Quantity | AI22: Cost
B23: R | C23: Trim-O-68 I-51 H-63mm White NRRR8-18W | G23: R08 | H23: HS 50X24.5mm 8W DR-NR-SR | Q23: F | R23: Refl. 50014-W OD-50 LES ID -20.5 H-13.4mm 8-18W | V23: 27- | W23: COB 30W 2700K 12LED 34-38V 890mA 19x19mm CRI-90 | AA23: 08- | AB23: PS 8W 200MA 36V LPF (PCB MT43-8-12W-V2 LPF)
B24: B | C24: Trim-O-68 I-51 H-63mm Black NRRR8-18W | G24: R12 | H24: HS 50x34.5mm (SR-DR-NR-12W) | V24: 30- | W24: COB 30-36W 3000K 12LED 34-38V 890mA 19x19mm CRI-90 | AA24: 08T- | AB24: PS 8W 200MA 36V Triac Dimming
B25: T | C25: Trim-O-68 I-51 H-63mm Inner Black NRRR8-18W | G25: R15 | H25: HS-50X40.5mm (SR-DR-NR-15W) | V25: 40- | W25: COB 30-36W 4000K 12LED 34-38V 890mA 19x19mm CRI-90 | AA25: 08I- | AB25: Dali Driver SC-10W PE19DA4240 (AI-Dimming)-25-40V
G26: R18 | H26: HS-50X50.5mm (SR-DR-NR-12W) | V26: 50- | W26: COB 30-36W 5000K 12LED 34-38V 890mA 19x19mm CRI-90 | AA26: 08BT- | AB26: PS CCT 8W 170MA 36V BT-SC (PCB LT 7-20W-CCT-V 1.1 REV-1)
V27: 60- | W27: COB 30-36W 6000K 12LED 34-38V 890mA 19x19mm CRI-90 | AA27: 08ID- | AB27: Dali Driver DC-10W PE694R4230(AI-Dimming)-25-40V
AA28: 08BTD- | AB28: PS CCT 8W 170MA 36V BT-DC (PCB LT 7-20W-CCT-V 1.1 REV-1)
V29: 27T- | W29: COB 30W 2700K 12LED 34-38V 890mA 19x19mm CRI-90
V30: 30T- | W30: COB 30-36W 3000K 12LED 34-38V 890mA 19x19mm CRI-90 | AA30: 12- | AB30: PS 12-20W 300mA 36-72V Maxic (PCB LT-MX-20W-V2)
V31: 40T- | W31: COB 30-36W 4000K 12LED 34-38V 890mA 19x19mm CRI-90 | AA31: 12T- | AB31: PS 12W 300mA 36V Triac Dimming
V32: 50T- | W32: COB 30-36W 5000K 12LED 34-38V 890mA 19x19mm CRI-90 | AA32: 12I- | AB32: Dali Driver SC-10W PE19DA4240 (AI-Dimming)-25-40V
V33: 60T- | W33: COB 30-36W 6000K 12LED 34-38V 890mA 19x19mm CRI-90 | AA33: 12BT- | AB33: PS CCT 12W 250MA 36V BT-SC (PCB LT 7-20W-CCT-V 1.1 REV-1)
AA34: 12ID- | AB34: Dali Driver DC-10W PE694R4230(AI-Dimming)-25-40V
V35: 27I- | W35: COB 30W 2700K 12LED 34-38V 890mA 19x19mm CRI-90 | AA35: 12BTD- | AB35: PS CCT 12W 250MA 36V BT-DC (PCB LT 7-20W-CCT-V 1.1 REV-1)
V36: 30I- | W36: COB 30-36W 3000K 12LED 34-38V 890mA 19x19mm CRI-90
V37: 40I- | W37: COB 30-36W 4000K 12LED 34-38V 890mA 19x19mm CRI-90 | AA37: 15- | AB37: PS 15W 370mA 36V Maxic(PCB LT-MX-20W-V2)
V38: 50I- | W38: COB 30-36W 5000K 12LED 34-38V 890mA 19x19mm CRI-90 | AA38: 15T- | AB38: PS 15W 350mA 25-42V Triac Dimm
V39: 60I- | W39: COB 30-36W 6000K 12LED 34-38V 890mA 19x19mm CRI-90 | AA39: 15I- | AB39: Dali Driver SC-15-20W PE19DA4240 (AI-Dimming)9-42V
V40: 26ID- | W40: LED COB Dual Colour 30W 2700K-5000k | AA40: 15BT- | AB40: PS CCT 15W 320MA 36V BT-SC (PCB LT 7-20W-CCT-V 1.1 REV-1)
AA41: 15ID- | AB41: Dali Driver DC-20W PE69R4240 (AI-Dimming)-25-40V
V42: 27BT- | W42: COB 30W 2700K 12LED 34-38V 890mA 19x19mm CRI-90 | AA42: 15BTD- | AB42: PS CCT 15W 320MA 36V BT-DC (PCB LT 7-20W-CCT-V 1.1 REV-1)
V43: 30BT- | W43: COB 30-36W 3000K 12LED 34-38V 890mA 19x19mm CRI-90
V44: 40BT- | W44: COB 30-36W 4000K 12LED 34-38V 890mA 19x19mm CRI-90 | AA44: 18- | AB44: PS 18W 440mA 36V Maxic(PCB LT-MX-20W-V2)
V45: 50BT- | W45: COB 30-36W 5000K 12LED 34-38V 890mA 19x19mm CRI-90 | AA45: 18T- | AB45: PS 18W 450mA 36V Track Dimming
V46: 60BT- | W46: COB 30-36W 6000K 12LED 34-38V 890mA 19x19mm CRI-90 | AA46: 18I- | AB46: Dali Driver SC-15-20W PE19DA4240 (AI-Dimming)9-42V
V47: 26BTD- | W47: LED COB Dual Colour 30W 2700K-5000k | AA47: 18BT- | AB47: PS CCT 18W 375MA 36V BT-SC (PCB LT 7-20W-CCT-V 1.1 REV-1)
AA48: 18ID- | AB48: Dali Driver DC-20W PE69R4240 (AI-Dimming)-25-40V
AA49: 18BTD- | AB49: PS CCT 18W 375MA 36V BT-DC (PCB LT 7-20W-CCT-V 1.1 REV-1)

Sheet Result
A1: SKU Id | B1: SKU Code | C1: Product Name | D1: Cost Price | E1: Retail Price | F1: Selling Price | G1: Weight | H1: Width | I1: Height | J1: Depth | K1: Beam Angle | L1: Color Temp | M1: Driving System | N1: Trim | O1: Watt
A2: 204003 | B2: NRRR08F50 | D2: 0 | E2: 0 | F2: 0 | G2: 0 | H2: 0 | I2: 0 | J2: 0 | K2: Flood - 50° | L2: 5000K | M2: Constant Current | N2: Round White Trim | O2: 08 Watt
A3: 204004 | B3: NRRR08F40 | D3: 0 | E3: 0 | F3: 0 | G3: 0 | H3: 0 | I3: 0 | J3: 0 | K3: Flood - 50° | L3: 4000K | M3: Constant Current | N3: Round White Trim | O3: 08 Watt
A4: 204005 | B4: NRRR08F30 | D4: 0 | E4: 0 | F4: 0 | G4: 0 | H4: 0 | I4: 0 | J4: 0 | K4: Flood - 50° | L4: 3000K | M4: Constant Current | N4: Round White Trim | O4: 08 Watt
A5: 204007 | B5: NRRB08F50 | D5: 0 | E5: 0 | F5: 0 | G5: 0 | H5: 0 | I5: 0 | J5: 0 | K5: Flood - 50° | L5: 5000K | M5: Constant Current | N5: Round Black Trim | O5: 08 Watt
A6: 204008 | B6: NRRB08F40 | D6: 0 | E6: 0 | F6: 0 | G6: 0 | H6: 0 | I6: 0 | J6: 0 | K6: Flood - 50° | L6: 4000K | M6: Constant Current | N6: Round Black Trim | O6: 08 Watt
A7: 204009 | B7: NRRB08F30 | D7: 0 | E7: 0 | F7: 0 | G7: 0 | H7: 0 | I7: 0 | J7: 0 | K7: Flood - 50° | L7: 3000K | M7: Constant Current | N7: Round Black Trim | O7: 08 Watt
A8: 204011 | B8: NRRT08F50 | D8: 0 | E8: 0 | F8: 0 | G8: 0 | H8: 0 | I8: 0 | J8: 0 | K8: Flood - 50° | L8: 5000K | M8: Constant Current | N8: Round Two Color Trim | O8: 08 Watt
A9: 204012 | B9: NRRT08F40 | D9: 0 | E9: 0 | F9: 0 | G9: 0 | H9: 0 | I9: 0 | J9: 0 | K9: Flood - 50° | L9: 4000K | M9: Constant Current | N9: Round Two Color Trim | O9: 08 Watt
A10: 204013 | B10: NRRT08F30 | D10: 0 | E10: 0 | F10: 0 | G10: 0 | H10: 0 | I10: 0 | J10: 0 | K10: Flood - 50° | L10: 3000K | M10: Constant Current | N10: Round Two Color Trim | O10: 08 Watt
A11: 204051 | B11: NRRR08F50T | D11: 0 | E11: 0 | F11: 0 | G11: 0 | H11: 0 | I11: 0 | J11: 0 | K11: Flood - 50° | L11: 5000K | M11: TRIAC Dimming | N11: Round White Trim | O11: 08 Watt
A12: 204052 | B12: NRRR08F40T | D12: 0 | E12: 0 | F12: 0 | G12: 0 | H12: 0 | I12: 0 | J12: 0 | K12: Flood - 50° | L12: 4000K | M12: TRIAC Dimming | N12: Round White Trim | O12: 08 Watt
A13: 204053 | B13: NRRR08F30T | D13: 0 | E13: 0 | F13: 0 | G13: 0 | H13: 0 | I13: 0 | J13: 0 | K13: Flood - 50° | L13: 3000K | M13: TRIAC Dimming | N13: Round White Trim | O13: 08 Watt
... A43: 204254 | B43: NRRT08F26BTD | D43: 0 | E43: 0 | F43: 0 | G43: 0 | H43: 0 | I43: 0 | J43: 0 | K43: Flood - 50° | L43: 2700K - 6000K Dual Color | M43: Bluetooth + Dual Color (2700K - 6000K) | N43: Round Two Color Trim | O43: 08 Watt
