Workbook

Sheet Stock Item
A1: Name | B1: Group Name | C1: Units | D1: Name of BOM | E1: Unit of manufacture | F1: BOM Component - Item Name | G1: BOM Component - Quantity | H1: BOM Component - Godown | I1: BOM Component - Type of Item | J1: BOM Component - Rate (%) | K1: BOM Component - Location | L1: Unit Price | M1: Cost | N1: USD | O1: INS&FRED | P1: BCD | Q1: Total Cost
A2: =$D$2 -> SRDR18F50 | B2: Down Light Series | C2: Nos. | D2: SRDR18F50 | E2: 1 | F2: ='Backend data'!C6 -> Trim-O-85 I-51 H-50mm White SRD-12/15/18W | G2: 1 | H2: Mechanical Store | I2: Component | L2: 7 | M2: =G2*L2 -> 7
F3: ='Backend data'!D6 -> HS-50X50.5mm (SR-DR-NR-18W) | G3: 1 | H3: Mechanical Store | I3: Component | L3: =Q3*87 -> 77.3865 | M3: =G3*L3 -> 77.3865 | N3: 0.593 | O3: 0.5 | Q3: =N3+(N3*(O3+P3)) -> 0.8895
F4: Refl O-50 H-14.2 L-20mm PC (DLO6) | G4: 1 | H4: Mechanical Store | I4: Component | L4: =Q4*87 -> 5.481 | M4: =G4*L4 -> 5.481 | N4: 0.042 | O4: 0.5 | Q4: =N4+(N4*(O4+P4)) -> 0.063
F5: Diff. Film 48.4mm DRDR8-12W Paper | G5: 1 | H5: Mechanical Store | I5: Component | Q5: =N5+(N5*(O5+P5)) -> 0
F6: Diff. 48.5x1.5mm Prismatic DRDR8-12W | G6: 1 | H6: Mechanical Store | I6: Component | Q6: =N6+(N6*(O6+P6)) -> 0
F7: Torsion Spring - L-49 W-18mm Coil D-1mm D-8 Black | G7: 2 | H7: Mechanical Store | I7: Component | L7: =Q7*87 -> 1.044 | M7: =G7*L7 -> 2.088 | N7: 0.008 | O7: 0.5 | Q7: =N7+(N7*(O7+P7)) -> 0.012
F8: Spring Holding Clip L-37 W-25 T-0.70mm MS | G8: 2 | H8: Mechanical Store | I8: Component | L8: 2 | M8: =G8*L8 -> 4
F9: PBX - COB 8-15W | G9: 1 | H9: Mechanical Store | I9: Component | L9: 8.5 | M9: =G9*L9 -> 8.5
F10: SBX - COB 8-18W (12Nos) | G10: 0.08 | H10: Mechanical Store | I10: Component | L10: 27 | M10: =G10*L10 -> 2.16
F11: Conn. 2Pin Ass. Wire Black Male (Small) | G11: 1 | H11: Mechanical Store | I11: Component | L11: =Q11*87 -> 3.915 | M11: =G11*L11 -> 3.915 | N11: 0.03 | O11: 0.5 | Q11: =N11+(N11*(O11+P11)) -> 0.045
F12: Sleeve M4mm Fiber Glass White | G12: 0.12 | H12: Mechanical Store | I12: Component | L12: =5.7/1000*120 -> 0.684 | M12: =G12*L12 -> 0.08208
F13: Wire Clip-M3-MS | G13: 1 | H13: Mechanical Store | I13: Component | L13: 0.6 | M13: =G13*L13 -> 0.6
F14: Screw No. 4X6.5mm Self Pan Combi. PH - SS | G14: 1 | H14: Mechanical Store | I14: Component | L14: 0.21 | M14: =G14*L14 -> 0.21
F15: Screw M3X6mm CSK PH - SS | G15: 3 | H15: Mechanical Store | I15: Component | L15: 0.5 | M15: =G15*L15 -> 1.5
F16: Rivet 1/8" x 1/4" MS (Big) | G16: 2 | H16: Mechanical Store | I16: Component | L16: 0.26 | M16: =G16*L16 -> 0.52
F17: Rivet 3/32" X 3/16" MS (Small) | G17: 4 | H17: Mechanical Store | I17: Component | L17: 0.32 | M17: =G17*L17 -> 1.28
F18: =D20 -> SRDR18F50 BOM LED PCB | G18: 1 | H18: Mechanical Store | I18: Component
A20: SRDR18F50 BOM LED PCB | B20: Down Light Series | C20: Nos. | D20: =CONCATENATE($D$2," ","BOM LED PCB" ) -> SRDR18F50 BOM LED PCB | E20: 1 | F20: =VLOOKUP('[1]SRD12-15-18W-DATA'!$V$13,'[1]SRD12-15-18W-DATA'!Q2:R12,2,0) -> PCB SRDR12W 2835 - 9V (36X1mm) | G20: 1 | H20: Electronics store | I20: Component | L20: 5.43 | M20: =G20*L20 -> 5.43
F21: LED SMD 2835-100mA 9V 3000K | G21: 30 | H21: Electronics store | I21: Component | L21: 0.29 | M21: =G21*L21 -> 8.7
M22: =SUM(M2:M21) -> 128.85258

Sheet Stock Item (Read Me)
A1: List of Fields | B1: Applicable Countries | C1: Applicable Values
A2: General Details
A3: Name | B3: All | E3: Read the following, before you start using the sample file:
A4: Group Name | B4: All | E4: Stock Item worksheet:
A5: B | B5: All | E5: - Use the worksheet without making any changes to the column headers to enter your business data. - The column headers represent field names in TallyPrime. Mandatory fields are marked in bold for easy reference. - Add new columns, if needed. Ensure to enter Column Headers exactly as mentioned under the List of Fields of the Read Me worksheet. - Delete unwanted columns. However, do not delete columns that represent mandatory fields for masters.
A6: Part No. | B6: All
A7: Alias - Part No. | B7: All
A8: Description | B8: All
A9: Notes | B9: All
A10: Category | B10: All
A11: Units | B11: All | E11: Stock Item (Read Me)
A12: Conversion | B12: All | E12: - The Read Me worksheet is only for your reference. It lists all the fields, with related details, applicable for Stock Item.
A13: Denominator | B13: All
A14: Alternate Units | B14: All | E14: For more information on using Sample Excel File for importing data, refer to | M14: TallyHelp
A15: GST Applicability | B15: All | C15: Applicable, Not Applicable
A16: Opening Balance - Quantity | B16: All
A17: Opening Balance - Rate | B17: All
A18: Opening Balance - Rate Per | B18: All
A19: Opening Balance - Value | B19: All
A20: Language for Name (Except English) | B20: All
A21: Is TCS Applicable | B21: All
A22: Item Allocations Details
A23: Item Allocations - Godown | B23: (When Accounting Terminology is set to "India/SAARC")
A24: Item Allocations - Batch | B24: All
A25: Item Allocations - Quantity | B25: All
A26: Item Allocations - Rate | B26: All
A27: Item Allocations - Rate per | B27: All
A28: Item Allocations - Amount | B28: All
A29: Item Allocations - Mfg. Date | B29: All
A30: Item Allocations - Expiry Date | B30: All
A31: Item Allocations - Location | B31: (When Accounting Terminology is set to "International")
A32: Additional Details
A33: Maintain in Batches | B33: All
A34: Track date of manufacturing | B34: All
A35: Use expiry dates | B35: All
A36: Enable Cost Tracking | B36: All
A37: Costing Method | B37: All | C37: At Zero Cost, Avg. Cost, FIFO, FIFO Perpetual, Last Purchase Cost, LIFO Annual, LIFO Perpetual, Monthly Avg. Cost, Std. Cost
A38: Market Valuation Method | B38: All | C38: At Zero Price, Avg. Price, Last Sale Price, Std. Price
A39: Behaviour
A40: Ignore difference due to physical counting | B40: All
...

Sheet Backend data
C2: TRIM | D2: HOUSING/HS | E2: REFLECTOR | F2: BEAM ANGLE | G2: COLOR TEMP | H2: DRIVING SYSTEM | I2: PCB
C3: =MID('Stock Item'!$D$2,4,1) -> R | D3: =MID('Stock Item'!$D$2,5,2) -> 18 | E3: =MID('Stock Item'!$D$2,3,1) -> D | F3: =MID('Stock Item'!$D$2,7,1) -> F | G3: =MID('Stock Item'!$D$2,8,2) -> 50 | H3: =MID('Stock Item'!$D$2,10,11) | I3: =MID('Stock Item'!$D$2,2,1) -> R
D4: =CONCATENATE($D$3,$F$3) -> 18F | G4: =CONCATENATE($D$3,$F$3,G3) -> 18F50 | H4: =CONCATENATE($D$3,$H$3,"-") -> 18- | I4: =CONCATENATE(C3,D3) -> R18
H5: =CONCATENATE('Stock Item'!D2) -> SRDR18F50
B6: Formulae | C6: =VLOOKUP($C$3,$B$23:$E$72,2,0) -> Trim-O-85 I-51 H-50mm White SRD-12/15/18W | D6: =VLOOKUP($D$4,G23:$J$100,2,0) -> HS-50X50.5mm (SR-DR-NR-18W) | E6: =VLOOKUP($E$3,$L$23:$O$72,2,0) -> #N/A | F6: =VLOOKUP($F$3,$Q$23:$T$72,2,0) -> #N/A | G6: =VLOOKUP($G$4,$V$23:$Y$72,2,0) -> LED 2835 100mA 9V 5000K | H6: =VLOOKUP($H$4,$AA$23:$AD$72,2,0) -> PS 18W 440mA 12LED 36V Maxic | I6: =VLOOKUP($I$3,AF23:$AI$100,2,0) -> #N/A
B7: Formulae for COST | C7: =VLOOKUP($C$3,$B$23:$E$72,4,0) -> 0 | D7: =VLOOKUP($D$4,G23:$J$100,4,0) -> 0 | E7: =VLOOKUP($E$3,$L$23:$O$72,4,0) -> #N/A | F7: =VLOOKUP($F$3,$Q$23:$T$72,4,0) -> #N/A | G7: =VLOOKUP($G$4,$V$23:$Y$72,4,0) -> 0 | H7: =VLOOKUP($H$4,$AA$23:$AD$72,4,0) -> 0 | I7: =VLOOKUP($I$3,$AF$23:$AI$100,4,0) -> #N/A
B8: Formulae for Quantity | C8: =VLOOKUP($C$3,$B$23:$E$72,3,0) -> 0 | D8: =VLOOKUP($D$4,G23:$J$100,3,0) -> 0 | E8: =VLOOKUP($E$3,$L$23:$O$72,3,0) -> #N/A | F8: =VLOOKUP($F$3,$Q$23:$T$72,3,0) -> #N/A | G8: =VLOOKUP($G$4,$V$23:$Y$72,3,0) -> 0 | H8: =VLOOKUP($H$4,$AA$23:$AD$72,3,0) -> 0 | I8: =VLOOKUP($I$3,$AF$23:$AI$100,3,0) -> #N/A
H10: BOM LED PCB
B21: TRIM | G21: HOUSING/HS | L21: REFLECTOR | Q21: BEAM ANGLE | V21: COLOUR TEMPERATURE | AA21: DRIVING SYSTEM | AF21: PCB
B22: Code | C22: Item Name | D22: Quantity | E22: Cost | G22: Code | H22: Item Name | I22: Quantity | J22: Cost | L22: Code | M22: Item Name | N22: Quantity | O22: Cost | Q22: Code | R22: Item Name | S22: Quantity | T22: Cost | V22: Code | W22: Item Name | X22: Quantity | Y22: Cost | AA22: Code | AB22: Item Name | AC22: Quantity | AD22: Cost | AF22: Code | AG22: Item Name | AH22: Quantity | AI22: Cost
B23: R | C23: Trim-O-85 I-51 H-50mm White SRD-12/15/18W | G23: 12F | H23: HS 50x34.5mm (SR-DR-NR-12W) | V23: 12F60 | W23: LED SMD 2835-100mA 9V 6000K | AA23: 12- | AB23: PS 12-20W 300mA 36-72V Maxic (PCB LT-MX-20W-V2) | AF23: R12 | AG23: PCB SRDR12W 2835 - 9V (36X1mm)
B24: B | C24: Trim-O-85 I-51 H-50mm Black SRD-12/15/18W | G24: 15F | H24: HS-50X40.5mm (SR-DR-NR-15W) | V24: 12F50 | W24: LED 2835 100mA 9V 5000K | AA24: 12T- | AB24: PS-12W 300mA 36V-TRIAC | AF24: R15 | AG24: PCB SRDR12W 2835 - 9V (36X1mm)
B25: T | C25: Trim-O-85 I-51 H-50mm Two Color SRD-12/15/18W | G25: 18F | H25: HS-50X50.5mm (SR-DR-NR-18W) | V25: 12F40 | W25: LED SMD 2835-100mA 9V 4000K | AA25: 12I- | AB25: PS-12W 300mA 36V-DALI | AF25: R18 | AG25: PCB SRDR12W 2835 - 9V (36X1mm)
V26: 12F30 | W26: LED SMD 2835-100mA 9V 3000K | AA26: 12BT- | AB26: PS-12W 300mA 36V-BT
V27: 12F27 | W27: LED SMD 2835 100mA 9V 2700K | AA27: 12ID- | AB27: PS-12W 300mA 36V-DALI DC | AF27: B12 | AG27: PCB SRDR12W 2835 - 9V (36X1mm)
V28: 12F25 | W28: LED SMD 2835 9V 100mA (2700K-5000) | AA28: 12BTD- | AB28: PS-12W 300mA 36V-BT DC | AF28: B15 | AG28: PCB SRDR12W 2835 - 9V (36X1mm)
V29: 15F60 | W29: LED SMD 2835-100mA 9V 6000K | AF29: B18 | AG29: PCB SRDR12W 2835 - 9V (36X1mm)
V30: 15F50 | W30: LED 2835 100mA 9V 5000K | AA30: 15- | AB30: PS 15W 370mA 36V Maxic New
V31: 15F40 | W31: LED SMD 2835-100mA 9V 4000K | AA31: 15T- | AB31: PS-15W 360mA 36V-TRIAC | AF31: T12 | AG31: PCB SRDR12W 2835 - 9V (36X1mm)
V32: 15F30 | W32: LED SMD 2835-100mA 9V 3000K | AA32: 15I- | AB32: PS-15W 360mA 36V-DALI | AF32: T15 | AG32: PCB SRDR12W 2835 - 9V (36X1mm)
V33: 15F27 | W33: LED SMD 2835 100mA 9V 2700K | AA33: 15BT- | AB33: PS-15W 360mA 36V-BT | AF33: T18 | AG33: PCB SRDR12W 2835 - 9V (36X1mm)
V34: 15F25 | W34: LED SMD 2835 9V 100mA (2700K-5000) | AA34: 15ID- | AB34: PS-15W 360mA 36V-DALI DC
V35: 18F60 | W35: LED SMD 2835-100mA 9V 6000K | AA35: 15BTD- | AB35: PS-15W 360mA 36V-BT DC
V36: 18F50 | W36: LED 2835 100mA 9V 5000K
V37: 18F40 | W37: LED SMD 2835-100mA 9V 4000K | AA37: 18- | AB37: PS 18W 440mA 12LED 36V Maxic
V38: 18F30 | W38: LED SMD 2835-100mA 9V 3000K | AA38: 18T- | AB38: PS-18W 440mA 36V-TRIAC
V39: 18F27 | W39: LED SMD 2835 100mA 9V 2700K | AA39: 18I- | AB39: PS-18W 440mA 36V-DALI
V40: 18F25 | W40: LED SMD 2835 9V 100mA (2700K-5000) | AA40: 18BT- | AB40: PS-18W 440mA 36V-BT
AA41: 18ID- | AB41: PS-18W 440mA 36V-DALI DC
AA42: 18BTD- | AB42: PS-18W 440mA 36V-BT DC

Sheet SRDR12-15-18W-SKU
A1: SKU Id | B1: SKU Code | C1: Product Name | D1: Cost Price | E1: Retail Price | F1: Selling Price | G1: Weight | H1: Width | I1: Height | J1: Depth | K1: Trim | L1: Beam Angle | M1: Color Temp | N1: Driving System | O1: Watt
A2: 134803 | B2: SRDR18F60- | C2: =CONCATENATE(Q2,R2,S2,T2,U2) -> SRDR18F60 | D2: 0 | E2: 0 | F2: 1192 | G2: 0 | H2: 0 | I2: 0 | J2: 0 | K2: Round White Trim | L2: Flood - 77° | M2: 6000K | N2: Constant Current | O2: 18 Watt | Q2: =MID(B2,1,3) -> SRD | R2: =MID(B2,4,1) -> R | S2: =MID(B2,5,2) -> 18 | T2: =MID(B2,7,1) -> F | U2: =MID(B2,8,2) -> 60
A3: 134804 | B3: SRDR18F50- | C3: =CONCATENATE(Q3,R3,S3,T3,U3) -> SRDR18F50 | D3: 0 | E3: 0 | F3: 1192 | G3: 0 | H3: 0 | I3: 0 | J3: 0 | K3: Round White Trim | L3: Flood - 77° | M3: 5000K | N3: Constant Current | O3: 18 Watt | Q3: =MID(B3,1,3) -> SRD | R3: =MID(B3,4,1) -> R | S3: =MID(B3,5,2) -> 18 | T3: =MID(B3,7,1) -> F | U3: =MID(B3,8,2) -> 50
A4: 134805 | B4: SRDR18F40- | C4: =CONCATENATE(Q4,R4,S4,T4,U4) -> SRDR18F40 | D4: 0 | E4: 0 | F4: 1192 | G4: 0 | H4: 0 | I4: 0 | J4: 0 | K4: Round White Trim | L4: Flood - 77° | M4: 4000K | N4: Constant Current | O4: 18 Watt | Q4: =MID(B4,1,3) -> SRD | R4: =MID(B4,4,1) -> R | S4: =MID(B4,5,2) -> 18 | T4: =MID(B4,7,1) -> F | U4: =MID(B4,8,2) -> 40
A5: 134806 | B5: SRDR18F30- | C5: =CONCATENATE(Q5,R5,S5,T5,U5) -> SRDR18F30 | D5: 0 | E5: 0 | F5: 1192 | G5: 0 | H5: 0 | I5: 0 | J5: 0 | K5: Round White Trim | L5: Flood - 77° | M5: 3000K | N5: Constant Current | O5: 18 Watt | Q5: =MID(B5,1,3) -> SRD | R5: =MID(B5,4,1) -> R | S5: =MID(B5,5,2) -> 18 | T5: =MID(B5,7,1) -> F | U5: =MID(B5,8,2) -> 30
A6: 134807 | B6: SRDR18F27- | C6: =CONCATENATE(Q6,R6,S6,T6,U6) -> SRDR18F27 | D6: 0 | E6: 0 | F6: 1192 | G6: 0 | H6: 0 | I6: 0 | J6: 0 | K6: Round White Trim | L6: Flood - 77° | M6: 2700K | N6: Constant Current | O6: 18 Watt | Q6: =MID(B6,1,3) -> SRD | R6: =MID(B6,4,1) -> R | S6: =MID(B6,5,2) -> 18 | T6: =MID(B6,7,1) -> F | U6: =MID(B6,8,2) -> 27
A7: 134811 | B7: SRDB18F60- | C7: =CONCATENATE(Q7,R7,S7,T7,U7) -> SRDB18F60 | D7: 0 | E7: 0 | F7: 1254 | G7: 0 | H7: 0 | I7: 0 | J7: 0 | K7: Round Black Trim | L7: Flood - 77° | M7: 6000K | N7: Constant Current | O7: 18 Watt | Q7: =MID(B7,1,3) -> SRD | R7: =MID(B7,4,1) -> B | S7: =MID(B7,5,2) -> 18 | T7: =MID(B7,7,1) -> F | U7: =MID(B7,8,2) -> 60
A8: 134812 | B8: SRDB18F50- | C8: =CONCATENATE(Q8,R8,S8,T8,U8) -> SRDB18F50 | D8: 0 | E8: 0 | F8: 1254 | G8: 0 | H8: 0 | I8: 0 | J8: 0 | K8: Round Black Trim | L8: Flood - 77° | M8: 5000K | N8: Constant Current | O8: 18 Watt | Q8: =MID(B8,1,3) -> SRD | R8: =MID(B8,4,1) -> B | S8: =MID(B8,5,2) -> 18 | T8: =MID(B8,7,1) -> F | U8: =MID(B8,8,2) -> 50
A9: 134813 | B9: SRDB18F40- | C9: =CONCATENATE(Q9,R9,S9,T9,U9) -> SRDB18F40 | D9: 0 | E9: 0 | F9: 1254 | G9: 0 | H9: 0 | I9: 0 | J9: 0 | K9: Round Black Trim | L9: Flood - 77° | M9: 4000K | N9: Constant Current | O9: 18 Watt | Q9: =MID(B9,1,3) -> SRD | R9: =MID(B9,4,1) -> B | S9: =MID(B9,5,2) -> 18 | T9: =MID(B9,7,1) -> F | U9: =MID(B9,8,2) -> 40
A10: 134814 | B10: SRDB18F30- | C10: =CONCATENATE(Q10,R10,S10,T10,U10) -> SRDB18F30 | D10: 0 | E10: 0 | F10: 1254 | G10: 0 | H10: 0 | I10: 0 | J10: 0 | K10: Round Black Trim | L10: Flood - 77° | M10: 3000K | N10: Constant Current | O10: 18 Watt | Q10: =MID(B10,1,3) -> SRD | R10: =MID(B10,4,1) -> B | S10: =MID(B10,5,2) -> 18 | T10: =MID(B10,7,1) -> F | U10: =MID(B10,8,2) -> 30
A11: 134815 | B11: SRDB18F27- | C11: =CONCATENATE(Q11,R11,S11,T11,U11) -> SRDB18F27 | D11: 0 | E11: 0 | F11: 1254 | G11: 0 | H11: 0 | I11: 0 | J11: 0 | K11: Round Black Trim | L11: Flood - 77° | M11: 2700K | N11: Constant Current | O11: 18 Watt | Q11: =MID(B11,1,3) -> SRD | R11: =MID(B11,4,1) -> B | S11: =MID(B11,5,2) -> 18 | T11: =MID(B11,7,1) -> F | U11: =MID(B11,8,2) -> 27
A12: 134819 | B12: SRDT18F60- | C12: =CONCATENATE(Q12,R12,S12,T12,U12) -> SRDT18F60 | D12: 0 | E12: 0 | F12: 1324 | G12: 0 | H12: 0 | I12: 0 | J12: 0 | K12: Round Two Color Trim | L12: Flood - 77° | M12: 6000K | N12: Constant Current | O12: 18 Watt | Q12: =MID(B12,1,3) -> SRD | R12: =MID(B12,4,1) -> T | S12: =MID(B12,5,2) -> 18 | T12: =MID(B12,7,1) -> F | U12: =MID(B12,8,2) -> 60
A13: 134820 | B13: SRDT18F50- | C13: =CONCATENATE(Q13,R13,S13,T13,U13) -> SRDT18F50 | D13: 0 | E13: 0 | F13: 1324 | G13: 0 | H13: 0 | I13: 0 | J13: 0 | K13: Round Two Color Trim | L13: Flood - 77° | M13: 5000K | N13: Constant Current | O13: 18 Watt | Q13: =MID(B13,1,3) -> SRD | R13: =MID(B13,4,1) -> T | S13: =MID(B13,5,2) -> 18 | T13: =MID(B13,7,1) -> F | U13: =MID(B13,8,2) -> 50
... A16: 134823 | B16: SRDT18F27- | C16: =CONCATENATE(Q16,R16,S16,T16,U16) -> SRDT18F27 | D16: 0 | E16: 0 | F16: 1324 | G16: 0 | H16: 0 | I16: 0 | J16: 0 | K16: Round Two Color Trim | L16: Flood - 77° | M16: 2700K | N16: Constant Current | O16: 18 Watt | Q16: =MID(B16,1,3) -> SRD | R16: =MID(B16,4,1) -> T | S16: =MID(B16,5,2) -> 18 | T16: =MID(B16,7,1) -> F | U16: =MID(B16,8,2) -> 27
