Workbook

Sheet Stock Item
A1: Name | B1: Group Name | C1: Units | D1: Name of BOM | E1: Unit of manufacture | F1: BOM Component - Item Name | G1: BOM Component - Quantity | H1: BOM Component - Godown | I1: BOM Component - Type of Item | J1: MODEL NAME | K1: Unit Price | L1: Cost | M1: USD | N1: INS&FRED | O1: BCD | P1: Total Cost
A2: =CONCATENATE(D2) -> DMLR08M30 | B2: Down Light Series | C2: Nos. | D2: DMLR08M30 | E2: 1 | F2: =VLOOKUP('DMLR08-12W-DATA'!V9,'DMLR08-12W-DATA'!A2:B4,2,0) -> Trim-O-85.5 I-65 H-24.5mm White DMLR08/12W (DLOR6) | G2: 1 | H2: Mechanical Store | I2: Component | K2: 7 | L2: =G2*K2 -> 7 | M2: 0 | N2: 0.5 | P2: =M2+(M2*(N2+O2)) -> 0
F3: Rotating Bracket-O-70 I-55.5 H-34mm DMLR08/12W-Ring | G3: 1 | H3: Mechanical Store | I3: Component | K3: =P3*87 -> 0 | L3: =G3*K3 -> 0 | M3: 0 | N3: 0.5 | P3: =M3+(M3*(N3+O3)) -> 0
F4: =VLOOKUP('DMLR08-12W-DATA'!$V$9,'DMLR08-12W-DATA'!$A$7:$B$9,2,0) -> Inner Ring-O-54 I-44.8 H-60mm White DMLR08/12W | G4: 1 | H4: Mechanical Store | I4: Component | K4: 7 | L4: =G4*K4 -> 7 | M4: 0 | N4: 0.5 | P4: =M4+(M4*(N4+O4)) -> 0
F5: =VLOOKUP('DMLR08-12W-DATA'!V10,'DMLR08-12W-DATA'!E2:F5,2,0) -> HS 50x34.5mm (SR-DR-NR-12W) | G5: 1 | H5: Mechanical Store | I5: Component | K5: =P5*87 -> 60.291 | L5: =G5*K5 -> 60.291 | M5: 0.462 | N5: 0.5 | P5: =M5+(M5*(N5+O5)) -> 0.693
F6: =VLOOKUP('DMLR08-12W-DATA'!V12,'DMLR08-12W-DATA'!Q2:R3,2,0) -> Lens-O-49.8 H-13.5 L-13.5mm 36°-PC (CR36G-50012) 8-12W | G6: 1 | H6: Mechanical Store | I6: Component | K6: =P6*87 -> 36.54 | L6: =G6*K6 -> 36.54 | M6: 0.28 | N6: 0.5 | P6: =M6+(M6*(N6+O6)) -> 0.42
F7: =VLOOKUP('DMLR08-12W-DATA'!V11,'DMLR08-12W-DATA'!M2:N26,2,0) -> COB 12&15W 3000K 12LED 36V 350mA 13.5x13.5mm CRI-90 | G7: 1 | H7: Electronics store | I7: Component | K7: =P7*87 -> 41.76 | L7: =G7*K7 -> 41.76 | M7: 0.32 | N7: 0.5 | P7: =M7+(M7*(N7+O7)) -> 0.48
F8: Conn. 2Pin Ass. Wire Black Male (Small) | G8: 1 | H8: Mechanical Store | I8: Component | K8: =P8*87 -> 3.915 | L8: =G8*K8 -> 3.915 | M8: 0.03 | N8: 0.5 | P8: =M8+(M8*(N8+O8)) -> 0.045
F9: Sleeve M4mm Fiber Glass White | G9: 0.12 | H9: Mechanical Store | I9: Component | K9: =5.7/1000*120 -> 0.684 | L9: =G9*K9 -> 0.08208
F10: Torsion Spring - L-49 W-18mm Coil D-1mm D-8 Black | G10: 2 | H10: Mechanical Store | I10: Component | K10: =P10*87 -> 1.044 | L10: =G10*K10 -> 2.088 | M10: 0.008 | N10: 0.5 | P10: =M10+(M10*(N10+O10)) -> 0.012
F11: Wire Clip M-3 MS | G11: 1 | H11: Mechanical Store | I11: Component | K11: 0.6 | L11: =G11*K11 -> 0.6
F12: Screw M3X6mm Pan Washer Combi + Head-SS | G12: 1 | H12: Mechanical Store | I12: Component | K12: 0.77 | L12: =G12*K12 -> 0.77
F13: Rivet 1/8" x 1/4" MS (Big) | G13: 6 | H13: Mechanical Store | I13: Component | K13: 0.26 | L13: =G13*K13 -> 1.56
F14: =VLOOKUP('DMLR08-12W-DATA'!V13,'DMLR08-12W-DATA'!I2:J14,2,0) -> PS 8W 200MA 36V LPF (PCB MT43-8-12W-V2 LPF) | G14: 1 | H14: Mechanical Store | I14: Component | M14: PS Rate Mention with Total Amt
F15: PBX - COB 8-15W | G15: 1 | H15: Mechanical Store | I15: Component | K15: 8.5 | L15: =G15*K15 -> 8.5
F16: SBX - COB 8-18W (12Nos) | G16: 0.08 | H16: Mechanical Store | I16: Component | K16: 27 | L16: =G16*K16 -> 2.16
L17: =SUM(L2:L16) -> 172.26608
J19: DMLR08W-CC | L19: =L17+98+42 -> 312.26608
J20: DMLR08W Track Dimming | L20: =L17+275+275 -> 722.26608 | Q20: Rate
J21: DMLR08W Dali Single Color | L21: =((L17)+(P21*87)) -> 829.98608 | M21: 5.04 | N21: 0.5 | P21: =M21+(M21*(N21+O21)) -> 7.56 | Q21: =P21*87 -> 657.72
J22: DMLR08W BT Single Color | L22: =L17+330 -> 502.26608
J23: DMLR08W Dali Dual Color | L23: =((L17)+(P23*87)) -> 886.75358 | M23: 5.475 | N23: 0.5 | P23: =M23+(M23*(N23+O23)) -> 8.2125 | Q23: =P23*87 -> 714.4875
J24: DMLR08W BT Dual Color | L24: =L17+330 -> 502.26608

Sheet DMLR08-12W-DATA
A1: CODE | B1: TRIM | C1: COST | E1: CODE | F1: Heatsink | G1: COST | I1: CODE | J1: DRIVER | K1: COST | M1: CODE | N1: TEMPERATURE | O1: COST | Q1: CODE | R1: BEAM ANGLE | S1: COST
A2: R | B2: Trim-O-85.5 I-65 H-24.5mm White DMLR08/12W (DLOR6) | E2: 08M | F2: HS 50x34.5mm (SR-DR-NR-12W) | I2: 08- | J2: PS 8W 200MA 36V LPF (PCB MT43-8-12W-V2 LPF) | K2: 42 | M2: 27- | N2: COB 12&15W 2700K 12LED 36V 350mA 13.5x13.5mm CRI-95 | O2: =X19 -> 41.28 | Q2: M | R2: Lens-O-49.8 H-13.5 L-13.5mm 36°-PC (CR36G-50012) 8-12W | U2: Reflector | V2: Trim | W2: Temperature
A3: B | B3: Trim-O-85.5 I-65 H-24.5mm Black DMLR08/12W (DLOR6) | E3: 12M | F3: HS 50x34.5mm (SR-DR-NR-12W) | I3: 08-T | J3: PS 8W 200MA 36V Triac Dimming | K3: 275 | M3: 30- | N3: COB 12&15W 3000K 12LED 36V 350mA 13.5x13.5mm CRI-90 | O3: =X19 -> 41.28 | Q3: W | R3: Lens-O-49.8 H-13.5 L-15.5mm 60°-PC (CR60G-5012) 8-12W | U3: =LEFT('Stock Item'!D2,4) -> DMLR | V3: =LEFT('Stock Item'!D2,6) -> DMLR08 | W3: =LEFT('Stock Item'!D2,7) -> DMLR08M | X3: =LEFT('Stock Item'!D2,9) -> DMLR08M30 | Y3: =LEFT('Stock Item'!D2,13) -> DMLR08M30 | Z3: - | AA3: =MID('Stock Item'!D2,1,9) -> DMLR08M30 | AB3: CC
A4: T | B4: Trim-O-85.5 I-65 H-24.5mm White DMLR08/12W (DLOR6) | E4: 08W | F4: HS 50x34.5mm (SR-DR-NR-12W) | I4: 08-I | J4: Dali Driver SC-10W PE19DA4240 (AI-Dimming)-25-40V | K4: 621 | M4: 40- | N4: COB 12&15W 4000K 12LED 36V 350mA 13.5x13.5mm CRI-90 | O4: ='DMLR08-12W-DATA'!X19 -> 41.28 | AB4: I
E5: 12W | F5: HS 50x34.5mm (SR-DR-NR-12W) | I5: 08-BT | J5: PS CCT 8W 170MA 36V BT-SC (PCB LT 7-20W-CCT-V 1.1 REV-1) | K5: 270 | M5: 50- | N5: COB 12&15W 5000K 12LED 36V 350mA 13.5x13.5mm CRI-90 | O5: =X19 -> 41.28 | U5: =MID(U3,4,1) -> R | V5: =MID(V3,5,2) -> 08 | W5: =MID(W3,7,1) -> M | X5: =MID(X3,8,2) -> 30 | Y5: =MID(Y3,10,4) | AB5: T
A6: CODE | B6: TRIM Ring | C6: COST | I6: 08-ID | J6: Dali Driver DC-10W PE694R4230(AI-Dimming)-25-40V | K6: 706 | M6: 60- | N6: COB 12&15W 6000K 12LED 36V 350mA 13.5x13.5mm CRI-90 | O6: =X19 -> 41.28 | AB6: BT
A7: R | B7: Inner Ring-O-54 I-44.8 H-60mm White DMLR08/12W | I7: 08-BTD | J7: PS CCT 8W 170MA 36V BT-DC (PCB LT 7-20W-CCT-V 1.1 REV-1) | K7: 340 | AB7: ID
A8: B | B8: Inner Ring-O-54 I-44.8 H-60mm Black DMLR08/12W | M8: 27-T | N8: COB 12&15W 2700K 12LED 36V 350mA 13.5x13.5mm CRI-95 | O8: =X19 -> 41.28 | AB8: BTD
A9: T | B9: Inner Ring-O-54 I-44.8 H-60mm Black DMLR08/12W | I9: 12- | J9: PS 8W 200MA 36V LPF (PCB MT43-8-12W-V2 LPF) | K9: 98 | M9: 30-T | N9: COB 12&15W 3000K 12LED 36V 350mA 13.5x13.5mm L-11mm | O9: =X19 -> 41.28 | U9: Trim | V9: =CONCATENATE(U5) -> R
I10: 12-T | J10: PS 8W 200MA 36V Triac Dimming | K10: 275 | M10: 40-T | N10: COB 12&15W 4000K 12LED 36V 350mA 13.5x13.5mm L-11mm | O10: =Y19 -> 41.28 | U10: Heatsink | V10: =CONCATENATE(V5,W5) -> 08M
I11: 12-I | J11: Dali Driver SC-10W PE19DA4240 (AI-Dimming)-25-40V | K11: 621 | M11: 50-T | N11: COB 12&15W 5000K 12LED 36V 350mA 13.5x13.5mm L-11mm | O11: =Y19 -> 41.28 | U11: Temperature | V11: =CONCATENATE(X5,Z3,Y5) -> 30-
I12: 12-BT | J12: PS CCT 8W 170MA 36V BT-SC (PCB LT 7-20W-CCT-V 1.1 REV-1) | K12: 270 | M12: 60-T | N12: COB 12&15W 6000K 12LED 36V 350mA 13.5x13.5mm L-11mm | O12: =Y19 -> 41.28 | U12: Beam Angle | V12: =CONCATENATE(W5) -> M
I13: 12-ID | J13: Dali Driver DC-10W PE694R4230(AI-Dimming)-25-40V | K13: 706 | U13: Driver | V13: =CONCATENATE(V5,Z3,Y5) -> 08-
I14: 12-BTD | J14: PS CCT 8W 170MA 36V BT-DC (PCB LT 7-20W-CCT-V 1.1 REV-1) | K14: 340 | M14: 27-I | N14: COB 12&15W 2700K 12LED 36V 350mA 13.5x13.5mm CRI-95 | O14: =Y19 -> 41.28
M15: 30-I | N15: COB 12&15W 3000K 12LED 36V 350mA 13.5x13.5mm CRI-90 | O15: =X19 -> 41.28
M16: 40-I | N16: COB 12&15W 4000K 12LED 36V 350mA 13.5x13.5mm CRI-90 | O16: =X19 -> 41.28 | T16: Part Number | W16: Qty | X16: Unit Price | Y16: Cost | Z16: USD | AA16: INS&FRED | AB16: BCD | AC16: Total Cost
M17: 50-I | N17: COB 12&15W 5000K 12LED 36V 350mA 13.5x13.5mm CRI-90 | O17: =X19 -> 41.28 | T17: FITTING DMLRO8 -12W ALL SET | W17: 1 | X17: =86*AC17 -> 0 | Y17: =W17*X17 -> 0 | Z17: 0 | AA17: 0.5 | AC17: =Z17+(Z17*(AA17+AB17)) -> 0
M18: 60-I | N18: COB 12&15W 6000K 12LED 36V 350mA 13.5x13.5mm CRI-90 | O18: =X19 -> 41.28 | T18: Conn. 2Pin Ass. Wire Black Male (Small) | W18: 1 | X18: =86*AC18 -> 3.483 | Y18: =W18*X18 -> 3.483 | Z18: 0.027 | AA18: 0.5 | AC18: =Z18+(Z18*(AA18+AB18)) -> 0.0405
M19: 25-ID | N19: COB 12&15W 2700-5000K 12LED 36V 350mA 13.5x13.5mm CRI-90 | O19: =X20 -> 193.5 | T19: COB 12&15W 2700K 12LED 36V 350mA 13.5x13.5mm L-11mm | W19: 1 | X19: =86*AC19 -> 41.28 | Y19: =W19*X19 -> 41.28 | Z19: 0.32 | AA19: 0.5 | AC19: =Z19+(Z19*(AA19+AB19)) -> 0.48
T20: COB 12&15W 2700-5000K 12LED 36V 350mA 13.5x13.5mm L-11mm | W20: 1 | X20: =86*AC20 -> 193.5 | Y20: =W20*X20 -> 193.5 | Z20: 1.5 | AA20: 0.5 | AC20: =Z20+(Z20*(AA20+AB20)) -> 2.25
M21: 27-BT | N21: COB 12&15W 2700K 12LED 36V 350mA 13.5x13.5mm CRI-95 | O21: =X19 -> 41.28 | T21: HS-50X34mm DMLR08W | W21: 1 | X21: =86*AC21 -> 0 | Y21: =W21*X21 -> 0 | Z21: 0 | AA21: 1.5 | AC21: =Z21+(Z21*(AA21+AB21)) -> 0
M22: 30-BT | N22: COB 12&15W 3000K 12LED 36V 350mA 13.5x13.5mm CRI-90 | O22: =X19 -> 41.28
M23: 40-BT | N23: COB 12&15W 4000K 12LED 36V 350mA 13.5x13.5mm CRI-90 | O23: =X19 -> 41.28
M24: 50-BT | N24: COB 12&15W 5000K 12LED 36V 350mA 13.5x13.5mm CRI-90 | O24: =X19 -> 41.28
M25: 60-BT | N25: COB 12&15W 6000K 12LED 36V 350mA 13.5x13.5mm CRI-90 | O25: =X19 -> 41.28
M26: 25-BTD | N26: COB 12&15W 2700-5000K 12LED 36V 350mA 13.5x13.5mm CRI-90 | O26: =X20 -> 193.5

Sheet DMLR08-12W-SKU
A1: SKU Id | B1: SKU Code | C1: Product Name | D1: Cost Price | E1: Retail Price | F1: Selling Price | G1: Weight | H1: Width | I1: Height | J1: Depth | K1: Watt | L1: Trim | M1: Beam Angle | N1: Color Temp | O1: Driving System
A2: 144972 | B2: DMLR08M60- | C2: =_xlfn.CONCAT(Q2,R2,S2,T2,U2) -> DMLR08M60 | D2: 0 | E2: 0 | F2: 1147 | G2: 0 | H2: 0 | I2: 0 | J2: 0 | K2: 08 Watt | L2: Round White Trim | M2: Medium - 36° | N2: 6000K | O2: Constant Current | Q2: =MID(B2,1,3) -> DML | R2: =MID(B2,4,1) -> R | S2: =MID(B2,5,2) -> 08 | T2: =MID(B2,7,1) -> M | U2: =MID(B2,8,2) -> 60
A3: 144973 | B3: DMLR08W60- | C3: =_xlfn.CONCAT(Q3,R3,S3,T3,U3) -> DMLR08W60 | D3: 0 | E3: 0 | F3: 1147 | G3: 0 | H3: 0 | I3: 0 | J3: 0 | K3: 08 Watt | L3: Round White Trim | M3: Wide - 50° | N3: 6000K | O3: Constant Current | Q3: =MID(B3,1,3) -> DML | R3: =MID(B3,4,1) -> R | S3: =MID(B3,5,2) -> 08 | T3: =MID(B3,7,1) -> W | U3: =MID(B3,8,2) -> 60
A4: 144974 | B4: DMLR08M50- | C4: =_xlfn.CONCAT(Q4,R4,S4,T4,U4) -> DMLR08M50 | D4: 0 | E4: 0 | F4: 1147 | G4: 0 | H4: 0 | I4: 0 | J4: 0 | K4: 08 Watt | L4: Round White Trim | M4: Medium - 36° | N4: 5000k | O4: Constant Current | Q4: =MID(B4,1,3) -> DML | R4: =MID(B4,4,1) -> R | S4: =MID(B4,5,2) -> 08 | T4: =MID(B4,7,1) -> M | U4: =MID(B4,8,2) -> 50
A5: 144975 | B5: DMLR08W50- | C5: =_xlfn.CONCAT(Q5,R5,S5,T5,U5) -> DMLR08W50 | D5: 0 | E5: 0 | F5: 1147 | G5: 0 | H5: 0 | I5: 0 | J5: 0 | K5: 08 Watt | L5: Round White Trim | M5: Wide - 50° | N5: 5000k | O5: Constant Current | Q5: =MID(B5,1,3) -> DML | R5: =MID(B5,4,1) -> R | S5: =MID(B5,5,2) -> 08 | T5: =MID(B5,7,1) -> W | U5: =MID(B5,8,2) -> 50
A6: 144976 | B6: DMLR08M40- | C6: =_xlfn.CONCAT(Q6,R6,S6,T6,U6) -> DMLR08M40 | D6: 0 | E6: 0 | F6: 1147 | G6: 0 | H6: 0 | I6: 0 | J6: 0 | K6: 08 Watt | L6: Round White Trim | M6: Medium - 36° | N6: 4000k | O6: Constant Current | Q6: =MID(B6,1,3) -> DML | R6: =MID(B6,4,1) -> R | S6: =MID(B6,5,2) -> 08 | T6: =MID(B6,7,1) -> M | U6: =MID(B6,8,2) -> 40
A7: 144977 | B7: DMLR08W40- | C7: =_xlfn.CONCAT(Q7,R7,S7,T7,U7) -> DMLR08W40 | D7: 0 | E7: 0 | F7: 1147 | G7: 0 | H7: 0 | I7: 0 | J7: 0 | K7: 08 Watt | L7: Round White Trim | M7: Wide - 50° | N7: 4000k | O7: Constant Current | Q7: =MID(B7,1,3) -> DML | R7: =MID(B7,4,1) -> R | S7: =MID(B7,5,2) -> 08 | T7: =MID(B7,7,1) -> W | U7: =MID(B7,8,2) -> 40
A8: 144978 | B8: DMLR08M30- | C8: =_xlfn.CONCAT(Q8,R8,S8,T8,U8) -> DMLR08M30 | D8: 0 | E8: 0 | F8: 1147 | G8: 0 | H8: 0 | I8: 0 | J8: 0 | K8: 08 Watt | L8: Round White Trim | M8: Medium - 36° | N8: 3000k | O8: Constant Current | Q8: =MID(B8,1,3) -> DML | R8: =MID(B8,4,1) -> R | S8: =MID(B8,5,2) -> 08 | T8: =MID(B8,7,1) -> M | U8: =MID(B8,8,2) -> 30
A9: 144979 | B9: DMLR08W30- | C9: =_xlfn.CONCAT(Q9,R9,S9,T9,U9) -> DMLR08W30 | D9: 0 | E9: 0 | F9: 1147 | G9: 0 | H9: 0 | I9: 0 | J9: 0 | K9: 08 Watt | L9: Round White Trim | M9: Wide - 50° | N9: 3000k | O9: Constant Current | Q9: =MID(B9,1,3) -> DML | R9: =MID(B9,4,1) -> R | S9: =MID(B9,5,2) -> 08 | T9: =MID(B9,7,1) -> W | U9: =MID(B9,8,2) -> 30
A10: 144980 | B10: DMLR08M27- | C10: =_xlfn.CONCAT(Q10,R10,S10,T10,U10) -> DMLR08M27 | D10: 0 | E10: 0 | F10: 1147 | G10: 0 | H10: 0 | I10: 0 | J10: 0 | K10: 08 Watt | L10: Round White Trim | M10: Medium - 36° | N10: 2700k | O10: Constant Current | Q10: =MID(B10,1,3) -> DML | R10: =MID(B10,4,1) -> R | S10: =MID(B10,5,2) -> 08 | T10: =MID(B10,7,1) -> M | U10: =MID(B10,8,2) -> 27
A11: 144981 | B11: DMLR08W27- | C11: =_xlfn.CONCAT(Q11,R11,S11,T11,U11) -> DMLR08W27 | D11: 0 | E11: 0 | F11: 1147 | G11: 0 | H11: 0 | I11: 0 | J11: 0 | K11: 08 Watt | L11: Round White Trim | M11: Wide - 50° | N11: 2700k | O11: Constant Current | Q11: =MID(B11,1,3) -> DML | R11: =MID(B11,4,1) -> R | S11: =MID(B11,5,2) -> 08 | T11: =MID(B11,7,1) -> W | U11: =MID(B11,8,2) -> 27
A12: 144988 | B12: DMLB08M60- | C12: =_xlfn.CONCAT(Q12,R12,S12,T12,U12) -> DMLB08M60 | D12: 0 | E12: 0 | F12: 1203 | G12: 0 | H12: 0 | I12: 0 | J12: 0 | K12: 08 Watt | L12: Round Black Trim | M12: Medium - 36° | N12: 6000K | O12: Constant Current | Q12: =MID(B12,1,3) -> DML | R12: =MID(B12,4,1) -> B | S12: =MID(B12,5,2) -> 08 | T12: =MID(B12,7,1) -> M | U12: =MID(B12,8,2) -> 60
A13: 144989 | B13: DMLB08W60- | C13: =_xlfn.CONCAT(Q13,R13,S13,T13,U13) -> DMLB08W60 | D13: 0 | E13: 0 | F13: 1203 | G13: 0 | H13: 0 | I13: 0 | J13: 0 | K13: 08 Watt | L13: Round Black Trim | M13: Wide - 50° | N13: 6000K | O13: Constant Current | Q13: =MID(B13,1,3) -> DML | R13: =MID(B13,4,1) -> B | S13: =MID(B13,5,2) -> 08 | T13: =MID(B13,7,1) -> W | U13: =MID(B13,8,2) -> 60
... A31: 145013 | B31: DMLT08W27- | C31: =_xlfn.CONCAT(Q31,R31,S31,T31,U31) -> DMLT08W27 | D31: 0 | E31: 0 | F31: 1264 | G31: 0 | H31: 0 | I31: 0 | J31: 0 | K31: 08 Watt | L31: Round Two Color Trim | M31: Wide - 50° | N31: 2700k | O31: Constant Current | Q31: =MID(B31,1,3) -> DML | R31: =MID(B31,4,1) -> T | S31: =MID(B31,5,2) -> 08 | T31: =MID(B31,7,1) -> W | U31: =MID(B31,8,2) -> 27
A32: 145068 | B32: DMLR08M60T | C32: =_xlfn.CONCAT(Q32,R32,S32,T32,U32) -> DMLR08M60T | D32: 0 | E32: 0 | F32: 1603 | G32: 0 | H32: 0 | I32: 0 | J32: 0 | K32: 08 Watt | L32: Round White Trim | M32: Medium - 36° | N32: 6000K | O32: TRIAC Dimming | Q32: =MID(B32,1,3) -> DML | R32: =MID(B32,4,1) -> R | S32: =MID(B32,5,2) -> 08 | T32: =MID(B32,7,1) -> M | U32: =MID(B32,8,5) -> 60T
A33: 145069 | B33: DMLR08W60T | C33: =_xlfn.CONCAT(Q33,R33,S33,T33,U33) -> DMLR08W60T | D33: 0 | E33: 0 | F33: 1603 | G33: 0 | H33: 0 | I33: 0 | J33: 0 | K33: 08 Watt | L33: Round White Trim | M33: Wide - 50° | N33: 6000K | O33: TRIAC Dimming | Q33: =MID(B33,1,3) -> DML | R33: =MID(B33,4,1) -> R | S33: =MID(B33,5,2) -> 08 | T33: =MID(B33,7,1) -> W | U33: =MID(B33,8,5) -> 60T
A34: 145070 | B34: DMLR08M50T | C34: =_xlfn.CONCAT(Q34,R34,S34,T34,U34) -> DMLR08M50T | D34: 0 | E34: 0 | F34: 1603 | G34: 0 | H34: 0 | I34: 0 | J34: 0 | K34: 08 Watt | L34: Round White Trim | M34: Medium - 36° | N34: 5000k | O34: TRIAC Dimming | Q34: =MID(B34,1,3) -> DML | R34: =MID(B34,4,1) -> R | S34: =MID(B34,5,2) -> 08 | T34: =MID(B34,7,1) -> M | U34: =MID(B34,8,5) -> 50T
A35: 145071 | B35: DMLR08W50T | C35: =_xlfn.CONCAT(Q35,R35,S35,T35,U35) -> DMLR08W50T | D35: 0 | E35: 0 | F35: 1603 | G35: 0 | H35: 0 | I35: 0 | J35: 0 | K35: 08 Watt | L35: Round White Trim | M35: Wide - 50° | N35: 5000k | O35: TRIAC Dimming | Q35: =MID(B35,1,3) -> DML | R35: =MID(B35,4,1) -> R | S35: =MID(B35,5,2) -> 08 | T35: =MID(B35,7,1) -> W | U35: =MID(B35,8,5) -> 50T
A36: 145072 | B36: DMLR08M40T | C36: =_xlfn.CONCAT(Q36,R36,S36,T36,U36) -> DMLR08M40T | D36: 0 | E36: 0 | F36: 1603 | G36: 0 | H36: 0 | I36: 0 | J36: 0 | K36: 08 Watt | L36: Round White Trim | M36: Medium - 36° | N36: 4000k | O36: TRIAC Dimming | Q36: =MID(B36,1,3) -> DML | R36: =MID(B36,4,1) -> R | S36: =MID(B36,5,2) -> 08 | T36: =MID(B36,7,1) -> M | U36: =MID(B36,8,5) -> 40T
A37: 145073 | B37: DMLR08W40T | C37: =_xlfn.CONCAT(Q37,R37,S37,T37,U37) -> DMLR08W40T | D37: 0 | E37: 0 | F37: 1603 | G37: 0 | H37: 0 | I37: 0 | J37: 0 | K37: 08 Watt | L37: Round White Trim | M37: Wide - 50° | N37: 4000k | O37: TRIAC Dimming | Q37: =MID(B37,1,3) -> DML | R37: =MID(B37,4,1) -> R | S37: =MID(B37,5,2) -> 08 | T37: =MID(B37,7,1) -> W | U37: =MID(B37,8,5) -> 40T
A38: 145074 | B38: DMLR08M30T | C38: =_xlfn.CONCAT(Q38,R38,S38,T38,U38) -> DMLR08M30T | D38: 0 | E38: 0 | F38: 1603 | G38: 0 | H38: 0 | I38: 0 | J38: 0 | K38: 08 Watt | L38: Round White Trim | M38: Medium - 36° | N38: 3000k | O38: TRIAC Dimming | Q38: =MID(B38,1,3) -> DML | R38: =MID(B38,4,1) -> R | S38: =MID(B38,5,2) -> 08 | T38: =MID(B38,7,1) -> M | U38: =MID(B38,8,5) -> 30T
A39: 145075 | B39: DMLR08W30T | C39: =_xlfn.CONCAT(Q39,R39,S39,T39,U39) -> DMLR08W30T | D39: 0 | E39: 0 | F39: 1603 | G39: 0 | H39: 0 | I39: 0 | J39: 0 | K39: 08 Watt | L39: Round White Trim | M39: Wide - 50° | N39: 3000k | O39: TRIAC Dimming | Q39: =MID(B39,1,3) -> DML | R39: =MID(B39,4,1) -> R | S39: =MID(B39,5,2) -> 08 | T39: =MID(B39,7,1) -> W | U39: =MID(B39,8,5) -> 30T
A40: 145076 | B40: DMLR08M27T | C40: =_xlfn.CONCAT(Q40,R40,S40,T40,U40) -> DMLR08M27T | D40: 0 | E40: 0 | F40: 1603 | G40: 0 | H40: 0 | I40: 0 | J40: 0 | K40: 08 Watt | L40: Round White Trim | M40: Medium - 36° | N40: 2700k | O40: TRIAC Dimming | Q40: =MID(B40,1,3) -> DML | R40: =MID(B40,4,1) -> R | S40: =MID(B40,5,2) -> 08 | T40: =MID(B40,7,1) -> M | U40: =MID(B40,8,5) -> 27T
A41: 145077 | B41: DMLR08W27T | C41: =_xlfn.CONCAT(Q41,R41,S41,T41,U41) -> DMLR08W27T | D41: 0 | E41: 0 | F41: 1603 | G41: 0 | H41: 0 | I41: 0 | J41: 0 | K41: 08 Watt | L41: Round White Trim | M41: Wide - 50° | N41: 2700k | O41: TRIAC Dimming | Q41: =MID(B41,1,3) -> DML | R41: =MID(B41,4,1) -> R | S41: =MID(B41,5,2) -> 08 | T41: =MID(B41,7,1) -> W | U41: =MID(B41,8,5) -> 27T
A42: 145084 | B42: DMLB08M60T | C42: =_xlfn.CONCAT(Q42,R42,S42,T42,U42) -> DMLB08M60T | D42: 0 | E42: 0 | F42: 1660 | G42: 0 | H42: 0 | I42: 0 | J42: 0 | K42: 08 Watt | L42: Round Black Trim | M42: Medium - 36° | N42: 6000K | O42: TRIAC Dimming | Q42: =MID(B42,1,3) -> DML | R42: =MID(B42,4,1) -> B | S42: =MID(B42,5,2) -> 08 | T42: =MID(B42,7,1) -> M | U42: =MID(B42,8,5) -> 60T
A43: 145085 | B43: DMLB08W60T | C43: =_xlfn.CONCAT(Q43,R43,S43,T43,U43) -> DMLB08W60T | D43: 0 | E43: 0 | F43: 1660 | G43: 0 | H43: 0 | I43: 0 | J43: 0 | K43: 08 Watt | L43: Round Black Trim | M43: Wide - 50° | N43: 6000K | O43: TRIAC Dimming | Q43: =MID(B43,1,3) -> DML | R43: =MID(B43,4,1) -> B | S43: =MID(B43,5,2) -> 08 | T43: =MID(B43,7,1) -> W | U43: =MID(B43,8,5) -> 60T
... A133: 145691 | B133: DMLT08W25BTD | C133: =_xlfn.CONCAT(Q133,R133,S133,T133,U133) -> DMLT08W25BTD | D133: 0 | E133: 0 | F133: 2709 | G133: 0 | H133: 0 | I133: 0 | J133: 0 | K133: 08 Watt | L133: Round Two Color Trim | M133: Wide - 50° | N133: 2700K - 5000K Bluetooth + Dual Color (Driving System) | O133: Bluetooth Dimming + Dual Color (2700K - 5000K) | Q133: =MID(B133,1,3) -> DML | R133: =MID(B133,4,1) -> T | S133: =MID(B133,5,2) -> 08 | T133: =MID(B133,7,1) -> W | U133: =MID(B133,8,5) -> 25BTD

Sheet Stock Item (Read Me)
A1: List of Fields | B1: Applicable Countries | C1: Applicable Values
A2: General Details
A3: Name | B3: All | E3: Read the following, before you start using the sample file:
A4: Group Name | B4: All | E4: Stock Item worksheet:
A5: B | B5: All | E5: - Use the worksheet without making any changes to the column headers to enter your business data. - The column headers represent field names in TallyPrime. Mandatory fields are marked in bold for easy reference. - Add new columns, if needed. Ensure to enter Column Headers exactly as mentioned under the List of Fields of the Read Me worksheet. - Delete unwanted columns. However, do not delete columns that represent mandatory fields for masters.
A6: Part No. | B6: All
A7: Alias - Part No. | B7: All
A8: Description | B8: All
A9: Notes | B9: All
A10: Category | B10: All
A11: Units | B11: All | E11: Stock Item (Read Me)
A12: Conversion | B12: All | E12: - The Read Me worksheet is only for your reference. It lists all the fields, with related details, applicable for Stock Item.
A13: Denominator | B13: All
A14: Alternate Units | B14: All | E14: For more information on using Sample Excel File for importing data, refer to | M14: TallyHelp
A15: GST Applicability | B15: All | C15: Applicable, Not Applicable
A16: Opening Balance - Quantity | B16: All
A17: Opening Balance - Rate | B17: All
A18: Opening Balance - Rate Per | B18: All
A19: Opening Balance - Value | B19: All
A20: Language for Name (Except English) | B20: All
A21: Is TCS Applicable | B21: All
A22: Item Allocations Details
A23: Item Allocations - Godown | B23: (When Accounting Terminology is set to "India/SAARC")
A24: Item Allocations - Batch | B24: All
A25: Item Allocations - Quantity | B25: All
A26: Item Allocations - Rate | B26: All
A27: Item Allocations - Rate per | B27: All
A28: Item Allocations - Amount | B28: All
A29: Item Allocations - Mfg. Date | B29: All
A30: Item Allocations - Expiry Date | B30: All
A31: Item Allocations - Location | B31: (When Accounting Terminology is set to "International")
A32: Additional Details
A33: Maintain in Batches | B33: All
A34: Track date of manufacturing | B34: All
A35: Use expiry dates | B35: All
A36: Enable Cost Tracking | B36: All
A37: Costing Method | B37: All | C37: At Zero Cost, Avg. Cost, FIFO, FIFO Perpetual, Last Purchase Cost, LIFO Annual, LIFO Perpetual, Monthly Avg. Cost, Std. Cost
A38: Market Valuation Method | B38: All | C38: At Zero Price, Avg. Price, Last Sale Price, Std. Price
A39: Behaviour
A40: Ignore difference due to physical counting | B40: All
...
