Workbook

Sheet Stock Item
A1: Name | B1: Group Name | C1: Units | D1: Name of BOM | E1: Unit of manufacture | F1: BOM Component - Item Name | G1: BOM Component - Quantity | H1: BOM Component - Godown | I1: BOM Component - Type of Item | J1: BOM Component - Rate (%) | K1: BOM Component - Location | L1: Unit Price | M1: Cost | N1: USD | O1: INS&FRED | P1: BCD | Q1: Total Cost
A2: =$D$2 -> DPLR08N30 | B2: Down Light Series | C2: Nos. | D2: DPLR08N30 | E2: 1 | F2: ='Backend data'!C6 -> HS Trim Spot Light 114x81mm White (Yuanchi) DPLR8W | G2: 1 | H2: Mechanical Store | I2: Component | L2: =Q2*87 -> 528.525 | M2: =G2*L2 -> 528.525 | N2: 4.05 | O2: 0.5 | Q2: =N2+(N2*(O2+P2)) -> 6.075
F3: Anti Glare Trim-O-34.7 H-18.5 L-23.7mm DPL08W | G3: 1 | H3: Mechanical Store | I3: Component
F4: ='Backend data'!F6 -> Lens-O-28.8 H-14.5 L-9.6mm 15°-PC DPL08W | G4: 1 | H4: Mechanical Store | I4: Component
F5: COB Holder-O-25 H-3.5 L-12mm | G5: 1 | H5: Mechanical Store | I5: Component
F6: Pipe-O-36.5 H-68.5 L-34.5mm DPL08W | G6: 1 | H6: Mechanical Store | I6: Component
F7: Connecting Rod-L-31.5 W-10.8 H-24.6mm DPL08W | G7: 1 | H7: Mechanical Store | I7: Component
F8: Rotating Mechanism-O-30.8 H-43 L-15mm DPL08W | G8: 1 | H8: Mechanical Store | I8: Component
F9: Inner locking swivel-O-38 H-21 L-23mm DPL08W | G9: 1 | H9: Mechanical Store | I9: Component
F10: Pull out rail-O-46.5 H-117 L-39mm DPL08W | G10: 1 | H10: Mechanical Store | I10: Component
F11: ='Backend data'!D6 -> Mounting Clip-L-41 H-28.5 T-0.2mm-SS DPL08W | G11: 2 | H11: Mechanical Store | I11: Component
F12: Locking Plate-27.5X2mm-PC | G12: 1 | H12: Mechanical Store | I12: Component
F13: 2 Core Red & Black Wire | G13: 1 | H13: Mechanical Store | I13: Component
F14: PBX - L=150, W=100, H=130mm. | G14: 1 | H14: Mechanical Store | I14: Component
F15: SBX | G15: 0.08 | H15: Mechanical Store | I15: Component
F16: Screw M3x8 Pan Head Philips Star -SS | G16: 4 | H16: Mechanical Store | I16: Component | L16: 0.6 | M16: =G16*L16 -> 2.4 | N16: 0 | O16: 0.5 | Q16: =N16+(N16*(O16+P16)) -> 0
F17: Screw M3X4 Pan + Head S.S | G17: 2 | H17: Mechanical Store | I17: Component | L17: 0.58 | M17: =G17*L17 -> 1.16 | N17: 0 | O17: 0.5 | Q17: =N17+(N17*(O17+P17)) -> 0
F18: ='Backend data'!G6 -> COB 12&15W 3000K 12LED 36V 350mA 13.5x13.5mm CRI-90 | G18: 1 | H18: Electronics store | I18: Component | L18: =Q18*87 -> 41.76 | M18: =G18*L18 -> 41.76 | N18: 0.32 | O18: 0.5 | Q18: =N18+(N18*(O18+P18)) -> 0.48
F19: ='Backend data'!H6 -> PS 8W 200MA 36V LPF (PCB MT43-8-12W-V2 LPF) | G19: 1 | H19: Mechanical Store | I19: Component | N19: PS Rate Mention with Total Amt
M20: =SUM(M2:M19) -> 573.845
K22: DPLR08-CC | M22: =M20+42 -> 615.845
K23: DPLR08 Dali Single Color | M23: =((M20)+(Q23*87)) -> 1231.565 | N23: 5.04 | O23: 0.5 | Q23: =N23+(N23*(O23+P23)) -> 7.56 | R23: =Q23*87 -> 657.72

Sheet Stock Item (Read Me)
A1: List of Fields | B1: Applicable Countries | C1: Applicable Values
A2: General Details
A3: Name | B3: All | E3: Read the following, before you start using the sample file:
A4: Group Name | B4: All | E4: Stock Item worksheet:
A5: B | B5: All | E5: - Use the worksheet without making any changes to the column headers to enter your business data. - The column headers represent field names in TallyPrime. Mandatory fields are marked in bold for easy reference. - Add new columns, if needed. Ensure to enter Column Headers exactly as mentioned under the List of Fields of the Read Me worksheet. - Delete unwanted columns. However, do not delete columns that represent mandatory fields for masters.
A6: Part No. | B6: All
A7: Alias - Part No. | B7: All
A8: Description | B8: All
A9: Notes | B9: All
A10: Category | B10: All
A11: Units | B11: All | E11: Stock Item (Read Me)
A12: Conversion | B12: All | E12: - The Read Me worksheet is only for your reference. It lists all the fields, with related details, applicable for Stock Item.
A13: Denominator | B13: All
A14: Alternate Units | B14: All | E14: For more information on using Sample Excel File for importing data, refer to | M14: TallyHelp
A15: GST Applicability | B15: All | C15: Applicable, Not Applicable
A16: Opening Balance - Quantity | B16: All
A17: Opening Balance - Rate | B17: All
A18: Opening Balance - Rate Per | B18: All
A19: Opening Balance - Value | B19: All
A20: Language for Name (Except English) | B20: All
A21: Is TCS Applicable | B21: All
A22: Item Allocations Details
A23: Item Allocations - Godown | B23: (When Accounting Terminology is set to "India/SAARC")
A24: Item Allocations - Batch | B24: All
A25: Item Allocations - Quantity | B25: All
A26: Item Allocations - Rate | B26: All
A27: Item Allocations - Rate per | B27: All
A28: Item Allocations - Amount | B28: All
A29: Item Allocations - Mfg. Date | B29: All
A30: Item Allocations - Expiry Date | B30: All
A31: Item Allocations - Location | B31: (When Accounting Terminology is set to "International")
A32: Additional Details
A33: Maintain in Batches | B33: All
A34: Track date of manufacturing | B34: All
A35: Use expiry dates | B35: All
A36: Enable Cost Tracking | B36: All
A37: Costing Method | B37: All | C37: At Zero Cost, Avg. Cost, FIFO, FIFO Perpetual, Last Purchase Cost, LIFO Annual, LIFO Perpetual, Monthly Avg. Cost, Std. Cost
A38: Market Valuation Method | B38: All | C38: At Zero Price, Avg. Price, Last Sale Price, Std. Price
A39: Behaviour
A40: Ignore difference due to physical counting | B40: All
...

Sheet Backend data
C2: TRIM | D2: HOUSING/HS | E2: REFLECTOR | F2: BEAM ANGLE | G2: COLOR TEMP | H2: DRIVING SYSTEM | I2: EXTRA
C3: =MID('Stock Item'!$D$2,4,1) -> R | D3: =MID('Stock Item'!$D$2,6,2) -> 8N | E3: =MID('Stock Item'!$D$2,3,1) -> L | F3: =MID('Stock Item'!$D$2,7,1) -> N | G3: =MID('Stock Item'!$D$2,8,2) -> 30 | H3: =MID('Stock Item'!$D$2,10,11) | I3: =MID('Stock Item'!$D$2,2,1) -> P
D4: =CONCATENATE(C3) -> R | G4: =CONCATENATE($F$3,$G$3) -> N30 | H4: =CONCATENATE("-",H3) -> -
H5: =CONCATENATE('Stock Item'!D2) -> DPLR08N30
B6: Formulae | C6: =VLOOKUP($C$3,$B$23:$E$72,2,0) -> HS Trim Spot Light 114x81mm White (Yuanchi) DPLR8W | D6: =VLOOKUP($D$4,G23:$J$100,2,0) -> Mounting Clip-L-41 H-28.5 T-0.2mm-SS DPL08W | E6: =VLOOKUP($E$3,$L$23:$O$72,2,0) -> #N/A | F6: =VLOOKUP($F$3,$Q$23:$T$72,2,0) -> Lens-O-28.8 H-14.5 L-9.6mm 15°-PC DPL08W | G6: =VLOOKUP($G$4,$V$23:$Y$72,2,0) -> COB 12&15W 3000K 12LED 36V 350mA 13.5x13.5mm CRI-90 | H6: =VLOOKUP($H$4,$AA$23:$AD$72,2,0) -> PS 8W 200MA 36V LPF (PCB MT43-8-12W-V2 LPF) | I6: =VLOOKUP($I$3,AF23:$AI$100,2,0) -> #N/A
B7: Formulae for COST | C7: =VLOOKUP($C$3,$B$23:$E$72,4,0) -> 0 | D7: =VLOOKUP($D$4,G23:$J$100,4,0) -> 0 | E7: =VLOOKUP($E$3,$L$23:$O$72,4,0) -> #N/A | F7: =VLOOKUP($F$3,$Q$23:$T$72,4,0) -> 0 | G7: =VLOOKUP($G$4,$V$23:$Y$72,4,0) -> 0 | H7: =VLOOKUP($H$4,$AA$23:$AD$72,4,0) -> 0 | I7: =VLOOKUP($I$3,$AF$23:$AI$100,4,0) -> #N/A
B8: Formulae for Quantity | C8: =VLOOKUP($C$3,$B$23:$E$72,3,0) -> 0 | D8: =VLOOKUP($D$4,G23:$J$100,3,0) -> 0 | E8: =VLOOKUP($E$3,$L$23:$O$72,3,0) -> #N/A | F8: =VLOOKUP($F$3,$Q$23:$T$72,3,0) -> 0 | G8: =VLOOKUP($G$4,$V$23:$Y$72,3,0) -> 0 | H8: =VLOOKUP($H$4,$AA$23:$AD$72,3,0) -> 0 | I8: =VLOOKUP($I$3,$AF$23:$AI$100,3,0) -> #N/A
H10: BOM LED PCB
B21: TRIM | G21: MOUNTING TRIM | L21: REFLECTOR | Q21: BEAM ANGLE | V21: COLOUR TEMPERATURE | AA21: DRIVING SYSTEM | AF21: EXTRA
B22: Code | C22: Item Name | D22: Quantity | E22: Cost | G22: Code | H22: Item Name | I22: Quantity | J22: Cost | L22: Code | M22: Item Name | N22: Quantity | O22: Cost | Q22: Code | R22: Item Name | S22: Quantity | T22: Cost | V22: Code | W22: Item Name | X22: Quantity | Y22: Cost | AA22: Code | AB22: Item Name | AC22: Quantity | AD22: Cost | AF22: Code | AG22: Item Name | AH22: Quantity | AI22: Cost
B23: R | C23: HS Trim Spot Light 114x81mm White (Yuanchi) DPLR8W | G23: R | H23: Mounting Clip-L-41 H-28.5 T-0.2mm-SS DPL08W | Q23: M | R23: Lens-O-28.8 H-14.5 L-9.6mm 32°-PC DPL08W | V23: M27 | W23: COB 12&15W 2700K 12LED 36V 350mA 13.5x13.5mm CRI-95 | AA23: - | AB23: PS 8W 200MA 36V LPF (PCB MT43-8-12W-V2 LPF)
B24: T | C24: HS Trimless Spot Light 114x81mm White (Yuanchi) DPLT8W | G24: T | H24: Mounting Bracket-L-57.8 H-20 T-1mm-MS DPL08W | Q24: N | R24: Lens-O-28.8 H-14.5 L-9.6mm 15°-PC DPL08W | V24: M30 | W24: COB 12&15W 3000K 12LED 36V 350mA 13.5x13.5mm CRI-90 | AA24: -I | AB24: Dali Driver SC-10W PE19DA4240 (AI-Dimming)-25-40V
V25: M40 | W25: COB 12&15W 4000K 12LED 36V 350mA 13.5x13.5mm CRI-90
V26: M50 | W26: COB 12&15W 5000K 12LED 36V 350mA 13.5x13.5mm CRI-90
V27: M60 | W27: COB 12&15W 6000K 12LED 36V 350mA 13.5x13.5mm CRI-90
V31: N27 | W31: COB 12&15W 2700K 12LED 36V 350mA 13.5x13.5mm CRI-95
V32: N30 | W32: COB 12&15W 3000K 12LED 36V 350mA 13.5x13.5mm CRI-90
V33: N40 | W33: COB 12&15W 4000K 12LED 36V 350mA 13.5x13.5mm CRI-90
V34: N50 | W34: COB 12&15W 5000K 12LED 36V 350mA 13.5x13.5mm CRI-90
V35: N60 | W35: COB 12&15W 6000K 12LED 36V 350mA 13.5x13.5mm CRI-90

Sheet DPL08-SKU (Seprate N,M)
A1: SKU Id | B1: SKU Code | C1: Product Name | D1: Cost Price | E1: Retail Price | F1: Selling Price | G1: Weight | H1: Width | I1: Height | J1: Depth | K1: Fixture | L1: Beam Angle | M1: Driving System | N1: Color temp
A2: 97760 | B2: DPLR08N60- | C2: =_xlfn.CONCAT(O2,P2,Q2,R2,S2) -> DPLR08N60 | D2: 0 | E2: 0 | F2: 3379 | G2: 0 | H2: 0 | I2: 0 | J2: 0 | K2: Trim | L2: Narrow - 15° | M2: Constant Current | N2: 6000k | O2: =MID(B2,1,3) -> DPL | P2: =MID(B2,4,1) -> R | Q2: =MID(B2,5,2) -> 08 | R2: =MID(B2,7,1) -> N | S2: =MID(B2,8,2) -> 60
A3: 97761 | B3: DPLR08N50- | C3: =_xlfn.CONCAT(O3,P3,Q3,R3,S3) -> DPLR08N50 | D3: 0 | E3: 0 | F3: 3379 | G3: 0 | H3: 0 | I3: 0 | J3: 0 | K3: Trim | L3: Narrow - 15° | M3: Constant Current | N3: 5000k | O3: =MID(B3,1,3) -> DPL | P3: =MID(B3,4,1) -> R | Q3: =MID(B3,5,2) -> 08 | R3: =MID(B3,7,1) -> N | S3: =MID(B3,8,2) -> 50
A4: 97762 | B4: DPLR08N40- | C4: =_xlfn.CONCAT(O4,P4,Q4,R4,S4) -> DPLR08N40 | D4: 0 | E4: 0 | F4: 3379 | G4: 0 | H4: 0 | I4: 0 | J4: 0 | K4: Trim | L4: Narrow - 15° | M4: Constant Current | N4: 4000k | O4: =MID(B4,1,3) -> DPL | P4: =MID(B4,4,1) -> R | Q4: =MID(B4,5,2) -> 08 | R4: =MID(B4,7,1) -> N | S4: =MID(B4,8,2) -> 40
A5: 97763 | B5: DPLR08N30- | C5: =_xlfn.CONCAT(O5,P5,Q5,R5,S5) -> DPLR08N30 | D5: 0 | E5: 0 | F5: 3379 | G5: 0 | H5: 0 | I5: 0 | J5: 0 | K5: Trim | L5: Narrow - 15° | M5: Constant Current | N5: 3000k | O5: =MID(B5,1,3) -> DPL | P5: =MID(B5,4,1) -> R | Q5: =MID(B5,5,2) -> 08 | R5: =MID(B5,7,1) -> N | S5: =MID(B5,8,2) -> 30
A6: 97764 | B6: DPLR08N27- | C6: =_xlfn.CONCAT(O6,P6,Q6,R6,S6) -> DPLR08N27 | D6: 0 | E6: 0 | F6: 3379 | G6: 0 | H6: 0 | I6: 0 | J6: 0 | K6: Trim | L6: Narrow - 15° | M6: Constant Current | N6: 2700k | O6: =MID(B6,1,3) -> DPL | P6: =MID(B6,4,1) -> R | Q6: =MID(B6,5,2) -> 08 | R6: =MID(B6,7,1) -> N | S6: =MID(B6,8,2) -> 27
A7: 97800 | B7: DPLR08N60I | C7: =_xlfn.CONCAT(O7,P7,Q7,R7,S7) -> DPLR08N60I | D7: 0 | E7: 0 | F7: 6089 | G7: 0 | H7: 0 | I7: 0 | J7: 0 | K7: Trim | L7: Narrow - 15° | M7: DALI Dimming | N7: 6000k | O7: =MID(B7,1,3) -> DPL | P7: =MID(B7,4,1) -> R | Q7: =MID(B7,5,2) -> 08 | R7: =MID(B7,7,1) -> N | S7: =MID(B7,8,3) -> 60I
A8: 97801 | B8: DPLR08N50I | C8: =_xlfn.CONCAT(O8,P8,Q8,R8,S8) -> DPLR08N50I | D8: 0 | E8: 0 | F8: 6089 | G8: 0 | H8: 0 | I8: 0 | J8: 0 | K8: Trim | L8: Narrow - 15° | M8: DALI Dimming | N8: 5000k | O8: =MID(B8,1,3) -> DPL | P8: =MID(B8,4,1) -> R | Q8: =MID(B8,5,2) -> 08 | R8: =MID(B8,7,1) -> N | S8: =MID(B8,8,3) -> 50I
A9: 97802 | B9: DPLR08N40I | C9: =_xlfn.CONCAT(O9,P9,Q9,R9,S9) -> DPLR08N40I | D9: 0 | E9: 0 | F9: 6089 | G9: 0 | H9: 0 | I9: 0 | J9: 0 | K9: Trim | L9: Narrow - 15° | M9: DALI Dimming | N9: 4000k | O9: =MID(B9,1,3) -> DPL | P9: =MID(B9,4,1) -> R | Q9: =MID(B9,5,2) -> 08 | R9: =MID(B9,7,1) -> N | S9: =MID(B9,8,3) -> 40I
A10: 97803 | B10: DPLR08N30I | C10: =_xlfn.CONCAT(O10,P10,Q10,R10,S10) -> DPLR08N30I | D10: 0 | E10: 0 | F10: 6089 | G10: 0 | H10: 0 | I10: 0 | J10: 0 | K10: Trim | L10: Narrow - 15° | M10: DALI Dimming | N10: 3000k | O10: =MID(B10,1,3) -> DPL | P10: =MID(B10,4,1) -> R | Q10: =MID(B10,5,2) -> 08 | R10: =MID(B10,7,1) -> N | S10: =MID(B10,8,3) -> 30I
A11: 97804 | B11: DPLR08N27I | C11: =_xlfn.CONCAT(O11,P11,Q11,R11,S11) -> DPLR08N27I | D11: 0 | E11: 0 | F11: 6089 | G11: 0 | H11: 0 | I11: 0 | J11: 0 | K11: Trim | L11: Narrow - 15° | M11: DALI Dimming | N11: 2700k | O11: =MID(B11,1,3) -> DPL | P11: =MID(B11,4,1) -> R | Q11: =MID(B11,5,2) -> 08 | R11: =MID(B11,7,1) -> N | S11: =MID(B11,8,3) -> 27I
A12: 97765 | B12: DPLR08M60- | C12: =_xlfn.CONCAT(O12,P12,Q12,R12,S12) -> DPLR08M60 | D12: 0 | E12: 0 | F12: 3379 | G12: 0 | H12: 0 | I12: 0 | J12: 0 | K12: Trim | L12: Medium - 32° | M12: Constant Current | N12: 6000k | O12: =MID(B12,1,3) -> DPL | P12: =MID(B12,4,1) -> R | Q12: =MID(B12,5,2) -> 08 | R12: =MID(B12,7,1) -> M | S12: =MID(B12,8,2) -> 60
A13: 97766 | B13: DPLR08M50- | C13: =_xlfn.CONCAT(O13,P13,Q13,R13,S13) -> DPLR08M50 | D13: 0 | E13: 0 | F13: 3379 | G13: 0 | H13: 0 | I13: 0 | J13: 0 | K13: Trim | L13: Medium - 32° | M13: Constant Current | N13: 5000k | O13: =MID(B13,1,3) -> DPL | P13: =MID(B13,4,1) -> R | Q13: =MID(B13,5,2) -> 08 | R13: =MID(B13,7,1) -> M | S13: =MID(B13,8,2) -> 50
A14: 97767 | B14: DPLR08M40- | C14: =_xlfn.CONCAT(O14,P14,Q14,R14,S14) -> DPLR08M40 | D14: 0 | E14: 0 | F14: 3379 | G14: 0 | H14: 0 | I14: 0 | J14: 0 | K14: Trim | L14: Medium - 32° | M14: Constant Current | N14: 4000k | O14: =MID(B14,1,3) -> DPL | P14: =MID(B14,4,1) -> R | Q14: =MID(B14,5,2) -> 08 | R14: =MID(B14,7,1) -> M | S14: =MID(B14,8,2) -> 40
A15: 97768 | B15: DPLR08M30- | C15: =_xlfn.CONCAT(O15,P15,Q15,R15,S15) -> DPLR08M30 | D15: 0 | E15: 0 | F15: 3379 | G15: 0 | H15: 0 | I15: 0 | J15: 0 | K15: Trim | L15: Medium - 32° | M15: Constant Current | N15: 3000k | O15: =MID(B15,1,3) -> DPL | P15: =MID(B15,4,1) -> R | Q15: =MID(B15,5,2) -> 08 | R15: =MID(B15,7,1) -> M | S15: =MID(B15,8,2) -> 30
A16: 97769 | B16: DPLR08M27- | C16: =_xlfn.CONCAT(O16,P16,Q16,R16,S16) -> DPLR08M27 | D16: 0 | E16: 0 | F16: 3379 | G16: 0 | H16: 0 | I16: 0 | J16: 0 | K16: Trim | L16: Medium - 32° | M16: Constant Current | N16: 2700k | O16: =MID(B16,1,3) -> DPL | P16: =MID(B16,4,1) -> R | Q16: =MID(B16,5,2) -> 08 | R16: =MID(B16,7,1) -> M | S16: =MID(B16,8,2) -> 27
A17: 97805 | B17: DPLR08M60I | C17: =_xlfn.CONCAT(O17,P17,Q17,R17,S17) -> DPLR08M60I | D17: 0 | E17: 0 | F17: 6089 | G17: 0 | H17: 0 | I17: 0 | J17: 0 | K17: Trim | L17: Medium - 32° | M17: DALI Dimming | N17: 6000k | O17: =MID(B17,1,3) -> DPL | P17: =MID(B17,4,1) -> R | Q17: =MID(B17,5,2) -> 08 | R17: =MID(B17,7,1) -> M | S17: =MID(B17,8,3) -> 60I
A18: 97806 | B18: DPLR08M50I | C18: =_xlfn.CONCAT(O18,P18,Q18,R18,S18) -> DPLR08M50I | D18: 0 | E18: 0 | F18: 6089 | G18: 0 | H18: 0 | I18: 0 | J18: 0 | K18: Trim | L18: Medium - 32° | M18: DALI Dimming | N18: 5000k | O18: =MID(B18,1,3) -> DPL | P18: =MID(B18,4,1) -> R | Q18: =MID(B18,5,2) -> 08 | R18: =MID(B18,7,1) -> M | S18: =MID(B18,8,3) -> 50I
A19: 97807 | B19: DPLR08M40I | C19: =_xlfn.CONCAT(O19,P19,Q19,R19,S19) -> DPLR08M40I | D19: 0 | E19: 0 | F19: 6089 | G19: 0 | H19: 0 | I19: 0 | J19: 0 | K19: Trim | L19: Medium - 32° | M19: DALI Dimming | N19: 4000k | O19: =MID(B19,1,3) -> DPL | P19: =MID(B19,4,1) -> R | Q19: =MID(B19,5,2) -> 08 | R19: =MID(B19,7,1) -> M | S19: =MID(B19,8,3) -> 40I
A20: 97808 | B20: DPLR08M30I | C20: =_xlfn.CONCAT(O20,P20,Q20,R20,S20) -> DPLR08M30I | D20: 0 | E20: 0 | F20: 6089 | G20: 0 | H20: 0 | I20: 0 | J20: 0 | K20: Trim | L20: Medium - 32° | M20: DALI Dimming | N20: 3000k | O20: =MID(B20,1,3) -> DPL | P20: =MID(B20,4,1) -> R | Q20: =MID(B20,5,2) -> 08 | R20: =MID(B20,7,1) -> M | S20: =MID(B20,8,3) -> 30I
A21: 97809 | B21: DPLR08M27I | C21: =_xlfn.CONCAT(O21,P21,Q21,R21,S21) -> DPLR08M27I | D21: 0 | E21: 0 | F21: 6089 | G21: 0 | H21: 0 | I21: 0 | J21: 0 | K21: Trim | L21: Medium - 32° | M21: DALI Dimming | N21: 2700k | O21: =MID(B21,1,3) -> DPL | P21: =MID(B21,4,1) -> R | Q21: =MID(B21,5,2) -> 08 | R21: =MID(B21,7,1) -> M | S21: =MID(B21,8,3) -> 27I
