Workbook

Sheet Stock Item
A1: Name | B1: Group Name | C1: Units | D1: Name of BOM | E1: Unit of manufacture | F1: BOM Component - Item Name | G1: BOM Component - Quantity | H1: BOM Component - Godown | I1: BOM Component - Type of Item | J1: BOM Component - Rate (%) | K1: DICRIPTION | L1: BOM Component - Location | M1: Unit Price | N1: Cost | O1: USD | P1: INS&FRED | Q1: BCD | R1: Total Cost
A2: =$D$2 -> DRLR05N30 | B2: Down Light Series | C2: Nos. | D2: DRLR05N30 | E2: 1 | F2: ='Backend data'!C6 -> Trim O-46.50 H-60mm White DRLR5/7 & DRRR10W | G2: 1 | H2: Mechanical Store | I2: Component | M2: =R2*87 -> 43.1955 | N2: =G2*M2 -> 43.1955 | O2: 0.331 | P2: 0.5 | R2: =O2+(O2*(P2+Q2)) -> 0.4965
F3: HS 35x20.5mm DR-5W DRLR5W | G3: 1 | H3: Mechanical Store | I3: Component | M3: =R3*87 -> 46.197 | N3: =G3*M3 -> 46.197 | O3: 0.354 | P3: 0.5 | R3: =O3+(O3*(P3+Q3)) -> 0.531
F4: Lens L-35 H-26 L-10.7mm- 15° M PMMA GLC-35 x 11-15* ( Zhenglian) | G4: 1 | H4: Mechanical Store | I4: Component | M4: =R4*87 -> 21.2715 | N4: =G4*M4 -> 21.2715 | O4: 0.163 | P4: 0.5 | R4: =O4+(O4*(P4+Q4)) -> 0.2445
F5: Locking Spring L-57 W-10mm T-0.2mm DR/NR-5/18W | G5: 1 | H5: Mechanical Store | I5: Component | M5: =R5*87 -> 2.2185 | N5: =G5*M5 -> 2.2185 | O5: 0.017 | P5: 0.5 | R5: =O5+(O5*(P5+Q5)) -> 0.0255
F6: PBX - COB 8-15W | G6: 1 | H6: Mechanical Store | I6: Component | M6: 8.5 | N6: =G6*M6 -> 8.5
F7: SBX - COB 8-18W (12Nos) | G7: 0.08 | H7: Mechanical Store | I7: Component | M7: 27 | N7: =G7*M7 -> 2.16
F8: Conn. 2Pin Ass. Wire Black Male (Small) | G8: 2 | H8: Mechanical Store | I8: Component | M8: =R8*87 -> 3.915 | N8: =G8*M8 -> 7.83 | O8: 0.03 | P8: 0.5 | R8: =O8+(O8*(P8+Q8)) -> 0.045
F9: Sleeve M4mm fiber Glass White | G9: 0.12 | H9: Mechanical Store | I9: Component | K9: L-120mm | M9: =5.7/1000*120 -> 0.684 | N9: =G9*M9 -> 0.08208 | O9: 0 | P9: 0.5 | R9: =O9+(O9*(P9+Q9)) -> 0
F10: Wire Clip-M3-MS | G10: 1 | H10: Mechanical Store | I10: Component | M10: 0.6 | N10: =G10*M10 -> 0.6 | O10: 0 | P10: 0.5 | R10: =O10+(O10*(P10+Q10)) -> 0
F11: Screw M3X6mm CSK PH-SS | G11: 1 | H11: Mechanical Store | I11: Component | K11: screw-M3X6mm use for cob holder | M11: 0.5 | N11: =G11*M11 -> 0.5 | O11: 0 | P11: 0.5 | R11: =O11+(O11*(P11+Q11)) -> 0
F12: Rivet 3/32 X3/16 Head - 6mm | G12: 4 | H12: Mechanical Store | I12: Component | M12: 0.29 | N12: =G12*M12 -> 1.16 | O12: 0 | P12: 0.5 | R12: =O12+(O12*(P12+Q12)) -> 0
F14: ='Backend data'!G6 -> COB 12&15W 3000K 12LED 36V 350mA 13.5x13.5mm CRI-90 | G14: 2 | H14: Electronics Store | I14: Component | M14: =R14*87 -> 41.76 | N14: =G14*M14 -> 83.52 | O14: 0.32 | P14: 0.5 | R14: =O14+(O14*(P14+Q14)) -> 0.48
F15: ='Backend data'!H6 -> PS 5W 130MA 36V LPF (PCB MT43-8-12W-V2 LPF) | G15: 1 | H15: Mechanical Store | I15: Component | M15: =R15*87 -> 0 | N15: =G15*M15 -> 0 | O15: PS Rate Mention with Total Amt
N16: =SUM(N2:N15) -> 217.23458
L18: DRLR05-CC | N18: =N16+42 -> 259.23458
L19: DRLR05 Track Dimming | N19: =N16+275 -> 492.23458
L20: DRLR05 Dali Single Color | N20: =((N16)+(R20*87)) -> 874.95458 | O20: 5.04 | P20: 0.5 | R20: =O20+(O20*(P20+Q20)) -> 7.56
L21: DRLR05 BT Single Color | N21: =N16+330 -> 547.23458
L22: DRLR05 Dali Dual Color | N22: =((N16)+(R22*87)) -> 931.72208 | O22: 5.475 | P22: 0.5 | R22: =O22+(O22*(P22+Q22)) -> 8.2125
L23: DRLR05 BT Dual Color | N23: =N16+330 -> 547.23458

Sheet Stock Item (Read Me)
A1: List of Fields | B1: Applicable Countries | C1: Applicable Values
A2: General Details
A3: Name | B3: All | E3: Read the following, before you start using the sample file:
A4: Group Name | B4: All | E4: Stock Item worksheet:
A5: B | B5: All | E5: - Use the worksheet without making any changes to the column headers to enter your business data. - The column headers represent field names in TallyPrime. Mandatory fields are marked in bold for easy reference. - Add new columns, if needed. Ensure to enter Column Headers exactly as mentioned under the List of Fields of the Read Me worksheet. - Delete unwanted columns. However, do not delete columns that represent mandatory fields for masters.
A6: Part No. | B6: All
A7: Alias - Part No. | B7: All
A8: Description | B8: All
A9: Notes | B9: All
A10: Category | B10: All
A11: Units | B11: All | E11: Stock Item (Read Me)
A12: Conversion | B12: All | E12: - The Read Me worksheet is only for your reference. It lists all the fields, with related details, applicable for Stock Item.
A13: Denominator | B13: All
A14: Alternate Units | B14: All | E14: For more information on using Sample Excel File for importing data, refer to | M14: TallyHelp
A15: GST Applicability | B15: All | C15: Applicable, Not Applicable
A16: Opening Balance - Quantity | B16: All
A17: Opening Balance - Rate | B17: All
A18: Opening Balance - Rate Per | B18: All
A19: Opening Balance - Value | B19: All
A20: Language for Name (Except English) | B20: All
A21: Is TCS Applicable | B21: All
A22: Item Allocations Details
A23: Item Allocations - Godown | B23: (When Accounting Terminology is set to "India/SAARC")
A24: Item Allocations - Batch | B24: All
A25: Item Allocations - Quantity | B25: All
A26: Item Allocations - Rate | B26: All
A27: Item Allocations - Rate per | B27: All
A28: Item Allocations - Amount | B28: All
A29: Item Allocations - Mfg. Date | B29: All
A30: Item Allocations - Expiry Date | B30: All
A31: Item Allocations - Location | B31: (When Accounting Terminology is set to "International")
A32: Additional Details
A33: Maintain in Batches | B33: All
A34: Track date of manufacturing | B34: All
A35: Use expiry dates | B35: All
A36: Enable Cost Tracking | B36: All
A37: Costing Method | B37: All | C37: At Zero Cost, Avg. Cost, FIFO, FIFO Perpetual, Last Purchase Cost, LIFO Annual, LIFO Perpetual, Monthly Avg. Cost, Std. Cost
A38: Market Valuation Method | B38: All | C38: At Zero Price, Avg. Price, Last Sale Price, Std. Price
A39: Behaviour
A40: Ignore difference due to physical counting | B40: All
...

Sheet Backend data
C2: TRIM | D2: HOUSING/HS | E2: REFLECTOR | F2: BEAM ANGLE | G2: COLOR TEMP | H2: DRIVING SYSTEM | I2: EXTRA
C3: =MID('Stock Item'!$D$2,4,1) -> R | D3: =MID('Stock Item'!$D$2,5,2) -> 05 | E3: =MID('Stock Item'!$D$2,3,1) -> L | F3: =MID('Stock Item'!$D$2,7,1) -> N | G3: =MID('Stock Item'!$D$2,8,2) -> 30 | H3: =MID('Stock Item'!$D$2,10,9) | I3: =MID('Stock Item'!$D$2,2,1) -> R
D4: =CONCATENATE(D3,F3) -> 05N | G4: =_xlfn.NUMBERVALUE(G3) -> #NAME? | H4: =CONCATENATE($D$3,$H$3,"-") -> 05-
B6: Formulae | C6: =VLOOKUP($C$3,$B$23:$E$72,2,0) -> Trim O-46.50 H-60mm White DRLR5/7 & DRRR10W | D6: =VLOOKUP($D$4,G23:$J$100,2,0) -> HS 35x44.5mm 7-10W (DRLR7&10W) | E6: =VLOOKUP($E$3,$L$23:$O$72,2,0) -> #N/A | F6: =VLOOKUP($F$3,$Q$23:$T$72,2,0) -> Lens L-35 H-26 L-10.7mm- 15° M PMMA GLC-35 x 11-15* ( Zhenglian) | G6: COB 12&15W 3000K 12LED 36V 350mA 13.5x13.5mm CRI-90 | H6: =VLOOKUP($H$4,$AA$23:$AD$72,2,0) -> PS 5W 130MA 36V LPF (PCB MT43-8-12W-V2 LPF) | I6: =VLOOKUP($I$3,AF23:$AI$100,2,0) -> #N/A
B7: Formulae for COST | C7: =VLOOKUP($C$3,$B$23:$E$72,4,0) -> 0 | D7: =VLOOKUP($D$4,G23:$J$100,4,0) -> 0 | E7: =VLOOKUP($E$3,$L$23:$O$72,4,0) -> #N/A | F7: =VLOOKUP($F$3,$Q$23:$T$72,4,0) -> 0 | G7: =VLOOKUP($G$4,$V$23:$Y$72,4,0) -> #NAME? | H7: =VLOOKUP($H$4,$AA$23:$AD$72,4,0) -> 0 | I7: =VLOOKUP($I$3,$AF$23:$AI$100,4,0) -> #N/A
B8: Formulae for Quantity | C8: =VLOOKUP($C$3,$B$23:$E$72,3,0) -> 0 | D8: =VLOOKUP($D$4,G23:$J$100,3,0) -> 0 | E8: =VLOOKUP($E$3,$L$23:$O$72,3,0) -> #N/A | F8: =VLOOKUP($F$3,$Q$23:$T$72,3,0) -> 0 | G8: =VLOOKUP($G$4,$V$23:$Y$72,3,0) -> #NAME? | H8: =VLOOKUP($H$4,$AA$23:$AD$72,3,0) -> 0 | I8: =VLOOKUP($I$3,$AF$23:$AI$100,3,0) -> #N/A
C10: =MID('Stock Item'!D2,1,9) -> DRLR05N30
B21: TRIM | G21: HOUSING/HS | L21: REFLECTOR | Q21: BEAM ANGLE | V21: COLOR TEMPERATURE | AA21: DRIVING SYSTEM | AF21: EXTRA
B22: Code | C22: Item Name | D22: Quantity | E22: Cost | G22: Code | H22: Item Name | I22: Quantity | J22: Cost | L22: Code | M22: Item Name | N22: Quantity | O22: Cost | Q22: Code | R22: Item Name | S22: Quantity | T22: Cost | V22: Code | W22: Item Name | X22: Quantity | Y22: Cost | AA22: Code | AB22: Item Name | AC22: Quantity | AD22: Cost | AF22: Code | AG22: Item Name | AH22: Quantity | AI22: Cost
B23: R | C23: Trim O-46.50 H-60mm White DRLR5/7 & DRRR10W | G23: 05M | H23: HS 35x20.5mm DR-5W DRLR5W | Q23: N | R23: Lens L-35 H-26 L-10.7mm- 15° M PMMA GLC-35 x 11-15* ( Zhenglian) | AA23: 05- | AB23: PS 5W 130MA 36V LPF (PCB MT43-8-12W-V2 LPF)
B24: B | C24: Trim O-46.50 H-60mm Black DRLR5/7 & DRRR10W | G24: 05N | H24: HS 35x44.5mm 7-10W (DRLR7&10W) | Q24: M | R24: Lens L-35 H-26 L-10.7mm- 24° M PMMA GLC-35 x 11-15* ( Zhenglian) | V24: 30 | W24: COB 12&15W 3000K 12LED 36V 350mA 13.5x13.5mm CRI-90 | AA24: 05T- | AB24: PS 5W 130mA 36V Triac Dimming
B25: T | C25: Trim O-46.50 H-60mm Inner Black DRLR5/7 & DRRR10W | G25: 07M | V25: 40 | W25: COB 12&15W 4000K 12LED 36V 350mA 13.5x13.5mm CRI-90 | AA25: 05I- | AB25: Dali Driver SC-10W PE19DA4240 (AI-Dimming)-25-40V
G26: 07N | V26: 50 | W26: COB 12&15W 5000K 12LED 36V 350mA 13.5x13.5mm CRI-91 | AA26: 05BT- | AB26: PS CCT 5W 110MA 36V BT-SC (PCB LT 7-20W-CCT-V 1.1 REV-1)
V27: 26 | W27: COB 12&15W 2700-5000K 12LED 36V 350mA 13.5x13.5mm CRI-90 | AA27: 05ID- | AB27: Dali Driver SC-10W PE19DA4240 (AI-Dimming)-25-40V
AA28: 05BTD- | AB28: PS CCT 5W 110MA 36V BT-DC- (PCB LT 7-20W-CCT-V 1.1 REV-1)

Sheet Result
A1: SKU Id | B1: SKU Code | C1: Product Name | D1: Cost Price | E1: Retail Price | F1: Selling Price | G1: Weight | H1: Width | I1: Height | J1: Depth | K1: Trim | L1: Beam Angle | M1: Color Temperature | N1: Driving System | O1: Watt
A2: 203823 | B2: DRLR05N30 | D2: 0 | E2: 0 | F2: 0 | G2: 0 | H2: 0 | I2: 0 | J2: 0 | K2: White | L2: Narrow | M2: 3000K | N2: Constant Current | O2: 05W
A3: 203824 | B3: DRLR05N40 | D3: 0 | E3: 0 | F3: 0 | G3: 0 | H3: 0 | I3: 0 | J3: 0 | K3: White | L3: Narrow | M3: 4000K | N3: Constant Current | O3: 05W
A4: 203825 | B4: DRLR05N50 | D4: 0 | E4: 0 | F4: 0 | G4: 0 | H4: 0 | I4: 0 | J4: 0 | K4: White | L4: Narrow | M4: 5000K | N4: Constant Current | O4: 05W
A5: 203831 | B5: DRLB05N30 | D5: 0 | E5: 0 | F5: 0 | G5: 0 | H5: 0 | I5: 0 | J5: 0 | K5: Black | L5: Narrow | M5: 3000K | N5: Constant Current | O5: 05W
A6: 203832 | B6: DRLB05N40 | D6: 0 | E6: 0 | F6: 0 | G6: 0 | H6: 0 | I6: 0 | J6: 0 | K6: Black | L6: Narrow | M6: 4000K | N6: Constant Current | O6: 05W
A7: 203833 | B7: DRLB05N50 | D7: 0 | E7: 0 | F7: 0 | G7: 0 | H7: 0 | I7: 0 | J7: 0 | K7: Black | L7: Narrow | M7: 5000K | N7: Constant Current | O7: 05W
A8: 203839 | B8: DRLT05N30 | D8: 0 | E8: 0 | F8: 0 | G8: 0 | H8: 0 | I8: 0 | J8: 0 | K8: Two Color | L8: Narrow | M8: 3000K | N8: Constant Current | O8: 05W
A9: 203840 | B9: DRLT05N40 | D9: 0 | E9: 0 | F9: 0 | G9: 0 | H9: 0 | I9: 0 | J9: 0 | K9: Two Color | L9: Narrow | M9: 4000K | N9: Constant Current | O9: 05W
A10: 203841 | B10: DRLT05N50 | D10: 0 | E10: 0 | F10: 0 | G10: 0 | H10: 0 | I10: 0 | J10: 0 | K10: Two Color | L10: Narrow | M10: 5000K | N10: Constant Current | O10: 05W
A11: 203847 | B11: DRLR05N30T | D11: 0 | E11: 0 | F11: 0 | G11: 0 | H11: 0 | I11: 0 | J11: 0 | K11: White | L11: Narrow | M11: 3000K | N11: TRIAC Dimming | O11: 05W
A12: 203848 | B12: DRLR05N40T | D12: 0 | E12: 0 | F12: 0 | G12: 0 | H12: 0 | I12: 0 | J12: 0 | K12: White | L12: Narrow | M12: 4000K | N12: TRIAC Dimming | O12: 05W
A13: 203849 | B13: DRLR05N50T | D13: 0 | E13: 0 | F13: 0 | G13: 0 | H13: 0 | I13: 0 | J13: 0 | K13: White | L13: Narrow | M13: 5000K | N13: TRIAC Dimming | O13: 05W
... A43: 203962 | B43: DRLT05N26BTD | D43: 0 | E43: 0 | F43: 0 | G43: 0 | H43: 0 | I43: 0 | J43: 0 | K43: Two Color | L43: Narrow | M43: 2700K - 6000K | N43: Bluetooth Dual | O43: 05W
