Workbook

Sheet Stock Item
A1: Name | B1: Group Name | C1: Units | D1: Name of BOM | E1: Unit of manufacture | F1: BOM Component - Item Name | G1: BOM Component - Quantity | H1: BOM Component - Godown | I1: BOM Component - Type of Item | J1: BOM Component - Rate (%) | K1: BOM Component - Location | L1: Unit Price | M1: Cost | N1: USD | O1: INS&FRED | P1: BCD | Q1: Total Cost
A2: =$D$2 -> DSDR15F30 | B2: Down light Series | C2: Nos. | D2: DSDR15F30 | E2: 1 | F2: ='Backend data'!C6 -> HS Surface 20W Round White (Gumi) DSDR15W | G2: 1 | H2: Mechanical Store | I2: Component | L2: =Q2*87 -> 352.35 | M2: =G2*L2 -> 352.35 | N2: 2.7 | O2: 0.5 | Q2: =N2+(N2*(O2+P2)) -> 4.05
F3: Refl. OD-90 ID-80 H-29mm | G3: 1 | H3: Mechanical Store | I3: Component
F4: Diff. OD-90 T-1mm | G4: 1 | H4: Mechanical Store | I4: Component
F5: End Cap-OD-116 H-15.3 Les-10mm | G5: 1 | H5: Mechanical Store | I5: Component
F6: Wire 0.5sqmm 2 core wire L -200mm | G6: 0.2 | H6: Mechanical Store | I6: Component
F7: Gromment 133 | G7: 1 | H7: Mechanical Store | I7: Component | L7: 0.85 | M7: =G7*L7 -> 0.85 | N7: 0 | O7: 0.5 | Q7: =N7+(N7*(O7+P7)) -> 0
F8: Conn. 2pin Ass.wire Black Male (Small) | G8: 1 | H8: Mechanical Store | I8: Component | L8: =Q8*87 -> 3.915 | M8: =G8*L8 -> 3.915 | N8: 0.03 | O8: 0.5 | Q8: =N8+(N8*(O8+P8)) -> 0.045
F9: Sleeve M4mm fiber glass white | G9: 0.15 | H9: Mechanical Store | I9: Component | L9: =5.7/1000*120 -> 0.684 | M9: =G9*L9 -> 0.1026
F10: Screw M3x6mm CSK Head SS | G10: 3 | H10: Mechanical Store | I10: Component | L10: 0.48 | M10: =G10*L10 -> 1.44
F11: Screw No. 4X6.5mm Self Pan Combi. PH - SS | G11: 1 | H11: Mechanical Store | I11: Component | L11: 0.21 | M11: =G11*L11 -> 0.21
F12: =D15 -> DSDR15F30 BOM LED PCB | G12: 1 | H12: Mechanical Store | I12: Component | L12: =Q12*87 -> 0 | M12: =G12*L12 -> 0
F13: ='Backend data'!H6 -> PS 15W 225mA 60V Maxic(PCB LT-MX-20W-V2) | G13: 1 | H13: Mechanical Store | I13: Component | N13: PS Rate Mention with Total Amt
L14: =Q14*87 -> 0 | M14: =G14*L14 -> 0
A15: =CONCATENATE(A2) -> DSDR15F30 | B15: Down Light Series | D15: =CONCATENATE('Backend data'!$H$5," ",'Backend data'!H10) -> DSDR15F30 BOM LED PCB | E15: 1 | F15: ='Backend data'!G6 -> LED SMD 2835-100mA 9V 3000K | G15: 28 | H15: Electronics Store | I15: Component | L15: 0.29 | M15: =G15*L15 -> 8.12
F16: PCB DCLR15N-30 | G16: 1 | H16: Electronics Store | I16: Component | L16: 9.54 | M16: =G16*L16 -> 9.54
M17: =SUM(M2:M16) -> 376.5276
K19: DSDR15-CC | M19: =M17+98 -> 474.5276

Sheet Stock Item (Read Me)
A1: List of Fields | B1: Applicable Countries | C1: Applicable Values
A2: General Details
A3: Name | B3: All | E3: Read the following, before you start using the sample file:
A4: Group Name | B4: All | E4: Stock Item worksheet:
A5: B | B5: All | E5: - Use the worksheet without making any changes to the column headers to enter your business data. - The column headers represent field names in TallyPrime. Mandatory fields are marked in bold for easy reference. - Add new columns, if needed. Ensure to enter Column Headers exactly as mentioned under the List of Fields of the Read Me worksheet. - Delete unwanted columns. However, do not delete columns that represent mandatory fields for masters.
A6: Part No. | B6: All
A7: Alias - Part No. | B7: All
A8: Description | B8: All
A9: Notes | B9: All
A10: Category | B10: All
A11: Units | B11: All | E11: Stock Item (Read Me)
A12: Conversion | B12: All | E12: - The Read Me worksheet is only for your reference. It lists all the fields, with related details, applicable for Stock Item.
A13: Denominator | B13: All
A14: Alternate Units | B14: All | E14: For more information on using Sample Excel File for importing data, refer to | M14: TallyHelp
A15: GST Applicability | B15: All | C15: Applicable, Not Applicable
A16: Opening Balance - Quantity | B16: All
A17: Opening Balance - Rate | B17: All
A18: Opening Balance - Rate Per | B18: All
A19: Opening Balance - Value | B19: All
A20: Language for Name (Except English) | B20: All
A21: Is TCS Applicable | B21: All
A22: Item Allocations Details
A23: Item Allocations - Godown | B23: (When Accounting Terminology is set to "India/SAARC")
A24: Item Allocations - Batch | B24: All
A25: Item Allocations - Quantity | B25: All
A26: Item Allocations - Rate | B26: All
A27: Item Allocations - Rate per | B27: All
A28: Item Allocations - Amount | B28: All
A29: Item Allocations - Mfg. Date | B29: All
A30: Item Allocations - Expiry Date | B30: All
A31: Item Allocations - Location | B31: (When Accounting Terminology is set to "International")
A32: Additional Details
A33: Maintain in Batches | B33: All
A34: Track date of manufacturing | B34: All
A35: Use expiry dates | B35: All
A36: Enable Cost Tracking | B36: All
A37: Costing Method | B37: All | C37: At Zero Cost, Avg. Cost, FIFO, FIFO Perpetual, Last Purchase Cost, LIFO Annual, LIFO Perpetual, Monthly Avg. Cost, Std. Cost
A38: Market Valuation Method | B38: All | C38: At Zero Price, Avg. Price, Last Sale Price, Std. Price
A39: Behaviour
A40: Ignore difference due to physical counting | B40: All
...

Sheet Backend data
C2: TRIM | D2: HOUSING/HS | E2: REFLECTOR | F2: BEAM ANGLE | G2: COLOR TEMP | H2: DRIVING SYSTEM | I2: EXTRA
C3: =MID('Stock Item'!$D$2,4,1) -> R | D3: =MID('Stock Item'!$D$2,6,2) -> 5F | E3: =MID('Stock Item'!$D$2,3,1) -> D | F3: =MID('Stock Item'!$D$2,7,1) -> F | G3: =MID('Stock Item'!$D$2,8,2) -> 30 | H3: =MID('Stock Item'!$D$2,10,11) | I3: =MID('Stock Item'!$D$2,2,1) -> S
D4: =CONCATENATE(C3) -> R | G4: =CONCATENATE($G$3,("-")) -> 30- | H4: =CONCATENATE("-",H3) -> -
H5: =CONCATENATE('Stock Item'!D2) -> DSDR15F30
B6: Formulae | C6: =VLOOKUP($C$3,$B$23:$E$72,2,0) -> HS Surface 20W Round White (Gumi) DSDR15W | D6: =VLOOKUP($D$4,G23:$J$100,2,0) -> #N/A | E6: =VLOOKUP($E$3,$L$23:$O$72,2,0) -> #N/A | F6: =VLOOKUP($F$3,$Q$23:$T$72,2,0) -> #N/A | G6: =VLOOKUP($G$4,$V$23:$Y$72,2,0) -> LED SMD 2835-100mA 9V 3000K | H6: =VLOOKUP($H$4,$AA$23:$AD$72,2,0) -> PS 15W 225mA 60V Maxic(PCB LT-MX-20W-V2) | I6: =VLOOKUP($I$3,AF23:$AI$100,2,0) -> #N/A
B7: Formulae for COST | C7: =VLOOKUP($C$3,$B$23:$E$72,4,0) -> 0 | D7: =VLOOKUP($D$4,G23:$J$100,4,0) -> #N/A | E7: =VLOOKUP($E$3,$L$23:$O$72,4,0) -> #N/A | F7: =VLOOKUP($F$3,$Q$23:$T$72,4,0) -> #N/A | G7: =VLOOKUP($G$4,$V$23:$Y$72,4,0) -> 0 | H7: =VLOOKUP($H$4,$AA$23:$AD$72,4,0) -> 0 | I7: =VLOOKUP($I$3,$AF$23:$AI$100,4,0) -> #N/A
B8: Formulae for Quantity | C8: =VLOOKUP($C$3,$B$23:$E$72,3,0) -> 0 | D8: =VLOOKUP($D$4,G23:$J$100,3,0) -> #N/A | E8: =VLOOKUP($E$3,$L$23:$O$72,3,0) -> #N/A | F8: =VLOOKUP($F$3,$Q$23:$T$72,3,0) -> #N/A | G8: =VLOOKUP($G$4,$V$23:$Y$72,3,0) -> 0 | H8: =VLOOKUP($H$4,$AA$23:$AD$72,3,0) -> 0 | I8: =VLOOKUP($I$3,$AF$23:$AI$100,3,0) -> #N/A
H10: BOM LED PCB
B21: TRIM | G21: MOUNTING TRIM | L21: REFLECTOR | Q21: BEAM ANGLE | V21: COLOUR TEMPERATURE | AA21: DRIVING SYSTEM | AF21: EXTRA
B22: Code | C22: Item Name | D22: Quantity | E22: Cost | G22: Code | H22: Item Name | I22: Quantity | J22: Cost | L22: Code | M22: Item Name | N22: Quantity | O22: Cost | Q22: Code | R22: Item Name | S22: Quantity | T22: Cost | V22: Code | W22: Item Name | X22: Quantity | Y22: Cost | AA22: Code | AB22: Item Name | AC22: Quantity | AD22: Cost | AF22: Code | AG22: Item Name | AH22: Quantity | AI22: Cost
B23: R | C23: HS Surface 20W Round White (Gumi) DSDR15W | Q23: M | V23: 27- | W23: LED SMD 2835 100mA 9V 2700K | AA23: - | AB23: PS 15W 225mA 60V Maxic(PCB LT-MX-20W-V2)
B24: B | C24: HS Surface 20W Round Black (Gumi) DSDR15W | V24: 30- | W24: LED SMD 2835-100mA 9V 3000K | AA24: -I | AB24: PS -15W 45V 260mA-DALI
V25: 40- | W25: LED SMD 2835-100mA 9V 4000K | AA25: -T | AB25: PS -15W 45V 260mA-TRAIC
V26: 50- | W26: LED SMD 2835-100mA 9V 5000K | AA26: -BT | AB26: PS -15W 45V 260mA -BT
V27: 60- | W27: LED SMD 2835-100mA 9V 6000K

Sheet Result
A1: SKU Id | B1: SKU Code | C1: Product Name | D1: Cost Price | E1: Retail Price | F1: Selling Price | G1: Weight | H1: Width | I1: Height | J1: Depth | K1: Fixture | L1: Beam Angle | M1: Color Temp | N1: Driving System
A2: 149002 | B2: DSDR15F60 | D2: 0 | E2: 0 | F2: 1362 | G2: 0 | H2: 0 | I2: 0 | J2: 0 | K2: White | L2: Flood - 95° | M2: 6000K | N2: Constant Current
A3: 149003 | B3: DSDR15F40 | D3: 0 | E3: 0 | F3: 1362 | G3: 0 | H3: 0 | I3: 0 | J3: 0 | K3: White | L3: Flood - 95° | M3: 4000K | N3: Constant Current
A4: 149004 | B4: DSDR15F30 | D4: 0 | E4: 0 | F4: 1362 | G4: 0 | H4: 0 | I4: 0 | J4: 0 | K4: White | L4: Flood - 95° | M4: 3000K | N4: Constant Current
A5: 149005 | B5: DSDR15F50 | D5: 0 | E5: 0 | F5: 1362 | G5: 0 | H5: 0 | I5: 0 | J5: 0 | K5: White | L5: Flood - 95° | M5: 5000K | N5: Constant Current
A6: 149006 | B6: DSDR15F60T | D6: 0 | E6: 0 | F6: 1952 | G6: 0 | H6: 0 | I6: 0 | J6: 0 | K6: White | L6: Flood - 95° | M6: 6000K | N6: TRIAC Dimming
A7: 149007 | B7: DSDR15F40T | D7: 0 | E7: 0 | F7: 1952 | G7: 0 | H7: 0 | I7: 0 | J7: 0 | K7: White | L7: Flood - 95° | M7: 4000K | N7: TRIAC Dimming
A8: 149008 | B8: DSDR15F30T | D8: 0 | E8: 0 | F8: 1952 | G8: 0 | H8: 0 | I8: 0 | J8: 0 | K8: White | L8: Flood - 95° | M8: 3000K | N8: TRIAC Dimming
A9: 149009 | B9: DSDR15F60BT | D9: 0 | E9: 0 | F9: 2257 | G9: 0 | H9: 0 | I9: 0 | J9: 0 | K9: White | L9: Flood - 95° | M9: 6000K | N9: Bluetooth Dimming
A10: 149010 | B10: DSDR15F40BT | D10: 0 | E10: 0 | F10: 2257 | G10: 0 | H10: 0 | I10: 0 | J10: 0 | K10: White | L10: Flood - 95° | M10: 4000K | N10: Bluetooth Dimming
A11: 149011 | B11: DSDR15F30BT | D11: 0 | E11: 0 | F11: 2257 | G11: 0 | H11: 0 | I11: 0 | J11: 0 | K11: White | L11: Flood - 95° | M11: 3000K | N11: Bluetooth Dimming
A12: 149012 | B12: DSDR15F60I | D12: 0 | E12: 0 | F12: 3524 | G12: 0 | H12: 0 | I12: 0 | J12: 0 | K12: White | L12: Flood - 95° | M12: 6000K | N12: DALI Dimming
A13: 149013 | B13: DSDR15F40I | D13: 0 | E13: 0 | F13: 3524 | G13: 0 | H13: 0 | I13: 0 | J13: 0 | K13: White | L13: Flood - 95° | M13: 4000K | N13: DALI Dimming
... A27: 149027 | B27: DSDB15F30I | D27: 0 | E27: 0 | F27: 3524 | G27: 0 | H27: 0 | I27: 0 | J27: 0 | K27: White | L27: Flood - 95° | M27: 3000K | N27: DALI Dimming
