Workbook

Sheet Stock Item
A1: Name | B1: Group Name | C1: Units | D1: Name of BOM | E1: Unit of manufacture | F1: BOM Component - Item Name | G1: BOM Component - Quantity | H1: BOM Component - Godown | I1: BOM Component - Type of Item | J1: BOM Component - Rate (%) | K1: BOM Component - Location | L1: Unit Price | M1: Cost | N1: USD | O1: INS&FRED | P1: BCD | Q1: Total Cost
A2: =$D$2 -> FRDR15F30 | B2: Down light Series | C2: Nos. | D2: FRDR15F30 | E2: 1 | F2: ='Backend data'!C6 -> Trim-OD-118 ,ID-94mm H-27mm - 96mm White - FRDR15W | G2: 1 | H2: Mechanical Store | I2: Component | L2: 7 | M2: =G2*L2 -> 7
F3: HS COB YL96x20.5mm FRDR15/DLER15 | G3: 1 | H3: Mechanical Store | I3: Component | L3: =Q3*87 -> 144.4635 | M3: =G3*L3 -> 144.4635 | N3: 1.107 | O3: 0.5 | Q3: =N3+(N3*(O3+P3)) -> 1.6605
F4: Diff. -OD- 92 H-1.5mm - FRDR15W/DLER15 | G4: 1 | H4: Mechanical Store | I4: Component | L4: 5 | M4: =G4*L4 -> 5
F5: Conn. 2Pin Ass. Wire Black Male (Small) | G5: 1 | H5: Mechanical Store | I5: Component | L5: =Q5*87 -> 3.915 | M5: =G5*L5 -> 3.915 | N5: 0.03 | O5: 0.5 | Q5: =N5+(N5*(O5+P5)) -> 0.045
F6: Refl. P DLER15 96mm | G6: 1 | H6: Mechanical Store | I6: Component | L6: 9.37 | M6: =G6*L6 -> 9.37
F7: PBX-FRDR15W & SBDR16W | G7: 1 | H7: Mechanical Store | I7: Component | L7: 8.5 | M7: =G7*L7 -> 8.5
F8: SBX FRDR15-20W (12Nos) | G8: 0.08 | H8: Mechanical Store | I8: Component | L8: 27 | M8: =G8*L8 -> 2.16
F9: =D20 -> FRDR15F30 BOM LED PCB | G9: 1 | H9: Mechanical Store | I9: Component
F10: Sleeve M4mm Fiber Glass White | G10: 0.12 | H10: Mechanical Store | I10: Component | L10: =5.7/1000*120 -> 0.684 | M10: =G10*L10 -> 0.08208
F11: SH. Sleeve Black 10mm Dia | G11: 0.1 | H11: Mechanical Store | I11: Component | L11: 8.5 | M11: =G11*L11 -> 0.85
F12: Wire Clip M-3 MS | G12: 1 | H12: Mechanical Store | I12: Component | L12: 0.6 | M12: =G12*L12 -> 0.6
F13: Locking Spring DLE15 to, DLO18 | G13: 2 | H13: Mechanical Store | I13: Component | L13: 4.5 | M13: =G13*L13 -> 9
F14: Screw M3x6mm CSK Head SS | G14: 4 | H14: Mechanical Store | I14: Component | L14: 0.48 | M14: =G14*L14 -> 1.92
F15: Screw M3X6mm Pan Washer Combi + Head-SS | G15: 1 | H15: Mechanical Store | I15: Component | L15: 0.77 | M15: =G15*L15 -> 0.77
F16: Nut Square M3 7X2mm (DLER15&20) | G16: 2 | H16: Mechanical Store | I16: Component | L16: 1.2 | M16: =G16*L16 -> 2.4
F17: Rivet 3/32" X 3/16" MS (Small) | G17: 2 | H17: Mechanical Store | I17: Component | L17: 0.4 | M17: =G17*L17 -> 0.8
F18: SCREW 2X7 CSK MS | G18: 2 | H18: Mechanical Store | I18: Component | L18: 0.16 | M18: =G18*L18 -> 0.32
F19: ='Backend data'!H6 -> PS 15W 225mA 60V Maxic(PCB LT-MX-20W-V2) | G19: 1 | H19: Mechanical Store | I19: Component | N19: PS Rate Mention with Total Amt
A20: =CONCATENATE(A2) -> FRDR15F30 | B20: Down light Series | C20: Nos | D20: =CONCATENATE('Backend data'!$H$5," ",'Backend data'!H10) -> FRDR15F30 BOM LED PCB | E20: 1 | F20: ='Backend data'!G6 -> LED 2835-60mA-3000K (WW) | G20: 120 | H20: Electronics store | I20: Component | L20: 0.09 | M20: =G20*L20 -> 10.8
F21: LED PCB DLER20N-120 | G21: 1 | H21: Electronics store | I21: Component | L21: 19.67 | M21: =G21*L21 -> 19.67
M22: =SUM(M2:M21) -> 227.62058
K24: FRDR15-CC | M24: =M22+98 -> 325.62058

Sheet Stock Item (Read Me)
A1: List of Fields | B1: Applicable Countries | C1: Applicable Values
A2: General Details
A3: Name | B3: All | E3: Read the following, before you start using the sample file:
A4: Group Name | B4: All | E4: Stock Item worksheet:
A5: B | B5: All | E5: - Use the worksheet without making any changes to the column headers to enter your business data. - The column headers represent field names in TallyPrime. Mandatory fields are marked in bold for easy reference. - Add new columns, if needed. Ensure to enter Column Headers exactly as mentioned under the List of Fields of the Read Me worksheet. - Delete unwanted columns. However, do not delete columns that represent mandatory fields for masters.
A6: Part No. | B6: All
A7: Alias - Part No. | B7: All
A8: Description | B8: All
A9: Notes | B9: All
A10: Category | B10: All
A11: Units | B11: All | E11: Stock Item (Read Me)
A12: Conversion | B12: All | E12: - The Read Me worksheet is only for your reference. It lists all the fields, with related details, applicable for Stock Item.
A13: Denominator | B13: All
A14: Alternate Units | B14: All | E14: For more information on using Sample Excel File for importing data, refer to | M14: TallyHelp
A15: GST Applicability | B15: All | C15: Applicable, Not Applicable
A16: Opening Balance - Quantity | B16: All
A17: Opening Balance - Rate | B17: All
A18: Opening Balance - Rate Per | B18: All
A19: Opening Balance - Value | B19: All
A20: Language for Name (Except English) | B20: All
A21: Is TCS Applicable | B21: All
A22: Item Allocations Details
A23: Item Allocations - Godown | B23: (When Accounting Terminology is set to "India/SAARC")
A24: Item Allocations - Batch | B24: All
A25: Item Allocations - Quantity | B25: All
A26: Item Allocations - Rate | B26: All
A27: Item Allocations - Rate per | B27: All
A28: Item Allocations - Amount | B28: All
A29: Item Allocations - Mfg. Date | B29: All
A30: Item Allocations - Expiry Date | B30: All
A31: Item Allocations - Location | B31: (When Accounting Terminology is set to "International")
A32: Additional Details
A33: Maintain in Batches | B33: All
A34: Track date of manufacturing | B34: All
A35: Use expiry dates | B35: All
A36: Enable Cost Tracking | B36: All
A37: Costing Method | B37: All | C37: At Zero Cost, Avg. Cost, FIFO, FIFO Perpetual, Last Purchase Cost, LIFO Annual, LIFO Perpetual, Monthly Avg. Cost, Std. Cost
A38: Market Valuation Method | B38: All | C38: At Zero Price, Avg. Price, Last Sale Price, Std. Price
A39: Behaviour
A40: Ignore difference due to physical counting | B40: All
...

Sheet Backend data
C2: TRIM | D2: HOUSING/HS | E2: REFLECTOR | F2: BEAM ANGLE | G2: COLOR TEMP | H2: DRIVING SYSTEM | I2: EXTRA
C3: =MID('Stock Item'!D2,4,1) -> R | D3: =MID('Stock Item'!$D$2,6,2) -> 5F | E3: =MID('Stock Item'!$D$2,3,1) -> D | F3: =MID('Stock Item'!$D$2,7,1) -> F | G3: =MID('Stock Item'!$D$2,8,2) -> 30 | H3: =MID('Stock Item'!$D$2,10,10) | I3: =MID('Stock Item'!$D$2,2,1) -> R
D4: =CONCATENATE(C3) -> R | G4: =CONCATENATE(G3) -> 30 | H4: =CONCATENATE(H3,"-") -> -
H5: =CONCATENATE('Stock Item'!D2) -> FRDR15F30
B6: Formulae | C6: =VLOOKUP($C$3,$B$23:$E$72,2,0) -> Trim-OD-118 ,ID-94mm H-27mm - 96mm White - FRDR15W | D6: =VLOOKUP($D$4,G23:$J$100,2,0) -> 0 | E6: =VLOOKUP($E$3,$L$23:$O$72,2,0) -> #N/A | F6: =VLOOKUP($F$3,$Q$23:$T$72,2,0) -> 0 | G6: =VLOOKUP($G$4,$V$23:$Y$72,2,0) -> LED 2835-60mA-3000K (WW) | H6: =VLOOKUP($H$4,$AA$23:$AD$72,2,0) -> PS 15W 225mA 60V Maxic(PCB LT-MX-20W-V2) | I6: =VLOOKUP($I$3,AF23:$AI$100,2,0) -> #N/A
B7: Formulae for COST | C7: =VLOOKUP($C$3,$B$23:$E$72,4,0) -> 0 | D7: =VLOOKUP($D$4,G23:$J$100,4,0) -> 0 | E7: =VLOOKUP($E$3,$L$23:$O$72,4,0) -> #N/A | F7: =VLOOKUP($F$3,$Q$23:$T$72,4,0) -> 0 | G7: =VLOOKUP($G$4,$V$23:$Y$72,4,0) -> 0 | H7: =VLOOKUP($H$4,$AA$23:$AD$72,4,0) -> 0 | I7: =VLOOKUP($I$3,$AF$23:$AI$100,4,0) -> #N/A
B8: Formulae for Quantity | C8: =VLOOKUP($C$3,$B$23:$E$72,3,0) -> 0 | D8: =VLOOKUP($D$4,G23:$J$100,3,0) -> 0 | E8: =VLOOKUP($E$3,$L$23:$O$72,3,0) -> #N/A | F8: =VLOOKUP($F$3,$Q$23:$T$72,3,0) -> 0 | G8: =VLOOKUP($G$4,$V$23:$Y$72,3,0) -> 0 | H8: =VLOOKUP($H$4,$AA$23:$AD$72,3,0) -> 0 | I8: =VLOOKUP($I$3,$AF$23:$AI$100,3,0) -> #N/A
H10: BOM LED PCB
B21: TRIM | G21: HEATSINK | L21: REFLECTOR | Q21: BEAM ANGLE | V21: COLOUR TEMPERATURE | AA21: DRIVING SYSTEM | AF21: EXTRA
B22: Code | C22: Item Name | D22: Quantity | E22: Cost | G22: Code | H22: Item Name | I22: Quantity | J22: Cost | L22: Code | M22: Item Name | N22: Quantity | O22: Cost | Q22: Code | R22: Item Name | S22: Quantity | T22: Cost | V22: Code | W22: Item Name | X22: Quantity | Y22: Cost | AA22: Code | AB22: Item Name | AC22: Quantity | AD22: Cost | AF22: Code | AG22: Item Name | AH22: Quantity | AI22: Cost
B23: R | C23: Trim-OD-118 ,ID-94mm H-27mm - 96mm White - FRDR15W | G23: R | Q23: F | V23: 60 | W23: LED 2835-60mA-6000K (PW) | AA23: - | AB23: PS 15W 225mA 60V Maxic(PCB LT-MX-20W-V2)
G24: T | V24: 50 | W24: LED 2835-60mA-5000K (PW) | AA24: T- | AB24: PCB 15W 360mA 36V-TRIAC
V25: 40 | W25: LED 2835-60mA-4000K (NW) | AA25: I- | AB25: PCB 15W 360mA 36V-DALI
V26: 30 | W26: LED 2835-60mA-3000K (WW) | AA26: BT- | AB26: PCB 15W 360mA 36V-BT

Sheet Result
A1: SKU Id | B1: SKU Code | C1: Product Name | D1: Cost Price | E1: Retail Price | F1: Selling Price | G1: Weight | H1: Width | I1: Height | J1: Depth | K1: Beam Angle | L1: Trim | M1: Color Temp | N1: Driving System | O1: Watt
A2: 144636 | B2: FRDR15F60 | D2: 0 | E2: 0 | F2: 940 | G2: 0 | H2: 0 | I2: 0 | J2: 0 | K2: Flood - 100° | L2: Round White Trim | M2: 6000K | N2: Constant Current | O2: 15 Watt
A3: 144637 | B3: FRDR15F50 | D3: 0 | E3: 0 | F3: 940 | G3: 0 | H3: 0 | I3: 0 | J3: 0 | K3: Flood - 100° | L3: Round White Trim | M3: 5000K | N3: Constant Current | O3: 15 Watt
A4: 144638 | B4: FRDR15F40 | D4: 0 | E4: 0 | F4: 940 | G4: 0 | H4: 0 | I4: 0 | J4: 0 | K4: Flood - 100° | L4: Round White Trim | M4: 4000K | N4: Constant Current | O4: 15 Watt
A5: 144639 | B5: FRDR15F30 | D5: 0 | E5: 0 | F5: 940 | G5: 0 | H5: 0 | I5: 0 | J5: 0 | K5: Flood - 100° | L5: Round White Trim | M5: 3000K | N5: Constant Current | O5: 15 Watt
A6: 144644 | B6: FRDR15F60T | D6: 0 | E6: 0 | F6: 1530 | G6: 0 | H6: 0 | I6: 0 | J6: 0 | K6: Flood - 100° | L6: Round White Trim | M6: 6000K | N6: TRIAC Dimming | O6: 15 Watt
A7: 144645 | B7: FRDR15F50T | D7: 0 | E7: 0 | F7: 1530 | G7: 0 | H7: 0 | I7: 0 | J7: 0 | K7: Flood - 100° | L7: Round White Trim | M7: 5000K | N7: TRIAC Dimming | O7: 15 Watt
A8: 144646 | B8: FRDR15F40T | D8: 0 | E8: 0 | F8: 1530 | G8: 0 | H8: 0 | I8: 0 | J8: 0 | K8: Flood - 100° | L8: Round White Trim | M8: 4000K | N8: TRIAC Dimming | O8: 15 Watt
A9: 144647 | B9: FRDR15F30T | D9: 0 | E9: 0 | F9: 1530 | G9: 0 | H9: 0 | I9: 0 | J9: 0 | K9: Flood - 100° | L9: Round White Trim | M9: 3000K | N9: TRIAC Dimming | O9: 15 Watt
A10: 144668 | B10: FRDR15F60BT | D10: 0 | E10: 0 | F10: 1834 | G10: 0 | H10: 0 | I10: 0 | J10: 0 | K10: Flood - 100° | L10: Round White Trim | M10: 6000K | N10: Bluetooth Dimming | O10: 15 Watt
A11: 144669 | B11: FRDR15F50BT | D11: 0 | E11: 0 | F11: 1834 | G11: 0 | H11: 0 | I11: 0 | J11: 0 | K11: Flood - 100° | L11: Round White Trim | M11: 5000K | N11: Bluetooth Dimming | O11: 15 Watt
A12: 144670 | B12: FRDR15F40BT | D12: 0 | E12: 0 | F12: 1834 | G12: 0 | H12: 0 | I12: 0 | J12: 0 | K12: Flood - 100° | L12: Round White Trim | M12: 4000K | N12: Bluetooth Dimming | O12: 15 Watt
A13: 144671 | B13: FRDR15F30BT | D13: 0 | E13: 0 | F13: 1834 | G13: 0 | H13: 0 | I13: 0 | J13: 0 | K13: Flood - 100° | L13: Round White Trim | M13: 3000K | N13: Bluetooth Dimming | O13: 15 Watt
... A17: 144655 | B17: FRDR15F30I | D17: 0 | E17: 0 | F17: 3102 | G17: 0 | H17: 0 | I17: 0 | J17: 0 | K17: Flood - 100° | L17: Round White Trim | M17: 3000K | N17: DALI Dimming | O17: 15 Watt
