Workbook

Sheet Stock Item
A1: Name | B1: Group Name | C1: Units | D1: Name of BOM | E1: Unit of manufacture | F1: BOM Component - Item Name | G1: BOM Component - Quantity | H1: BOM Component - Godown | I1: BOM Component - Type of Item | J1: BOM Component - Rate (%) | K1: BOM Component - Location | L1: Unit Price | M1: Cost | N1: USD | O1: INS&FRED | P1: BCD | Q1: Total Cost | S1: description
A2: =$D$2 -> H50562530 | B2: Down light Series | C2: Nos. | D2: H50562530 | E2: 1 | F2: Alluminum Profile HLP5056 12ft [White] | G2: 0.33 | H2: Mechanical Store | I2: Component | L2: =340*1.8 -> 612 | M2: =G2*L2 -> 201.96 | S2: Allum Profile L -1200 W-50 H-56 T-1mm.Weight-0.900kg
F3: Diff. 50mm for Profile 5056 | G3: 0.33 | H3: Mechanical Store | I3: Component | L3: =Q3*87 -> 183.3525 | M3: =G3*L3 -> 60.506325 | N3: 1.405 | O3: 0.5 | Q3: =N3+(N3*(O3+P3)) -> 2.1075 | S3: Diff. L-1200mm,T-1mm
F4: Allum End Cap 5056 - White | G4: 2 | H4: Mechanical Store | I4: Component | S4: End-cap L - 56 W-50 T-1.5mm
F5: Wire Single Core 0.5Sq mm L-120mm Red & Black | G5: 2 | H5: Mechanical Store | I5: Component | L5: =2/1000*120 -> 0.24 | M5: =G5*L5 -> 0.48 | S5: Wire Single Core 0.5Sq mm L-120mm Red & Black
F6: Wire 3 Core 0.75Sq L-1500mm | G6: 1 | H6: Mechanical Store | I6: Component | L6: =27.78/1000*1.5 -> 0.04167 | M6: =G6*L6 -> 0.04167 | S6: Wire 3 Core 0.75Sq L-1500mm
F7: DOUBLE SIDE TAPE 8MM BLUE | G7: 3.6 | H7: Mechanical Store | I7: Component | L7: =82/20 -> 4.1 | M7: =G7*L7 -> 14.76 | S7: Blue Tape L-3.6 Mtr
F8: Connecter White Terminal 5Amp | G8: 0.2 | H8: Mechanical Store | I8: Component | L8: 21 | M8: =G8*L8 -> 4.2 | S8: Conn. 4pin Ass.wire
F9: Suspension 1.5 Mtr | G9: 2 | H9: Mechanical Store | I9: Component | L9: 30.5 | M9: =G9*L9 -> 61 | S9: Suspension Kit - 1.5Mtr
F10: SH. Sleeve Black 3mm | G10: 0.12 | H10: Mechanical Store | I10: Component | L10: 3.5 | M10: =G10*L10 -> 0.42 | S10: Sleeve M4mm Black
F11: Screw M3x6.5mm Self Csk Head Ss | G11: 8 | H11: Mechanical Store | I11: Component | L11: 0.15 | M11: =G11*L11 -> 1.2 | S11: Screw M3X6 Self CSK PH-SS
F12: Gromment (White) | G12: 1 | H12: Mechanical Store | I12: Component | L12: =Q12*87 -> 9.2655 | M12: =G12*L12 -> 9.2655 | N12: 0.071 | O12: 0.5 | Q12: =N12+(N12*(O12+P12)) -> 0.1065 | S12: Grommet - 5X11mm
F13: =D16 -> H50562530 BOM LED PCB | G13: 1 | H13: Mechanical Store | I13: Component
F14: ='Backend data'!H6 -> PS 24W 300mA 72V Maxic(PCB LT-MX-20W-V2) | G14: 1 | H14: Mechanical Store | I14: Component | N14: PS Rate Mention with Total Amt
A16: =D16 -> H50562530 BOM LED PCB | B16: Down Light Series | C16: Nos. | D16: =CONCATENATE('Backend data'!$H$5, " ",'Backend data'!H10) -> H50562530 BOM LED PCB | F16: ='Backend data'!G6 -> LED 2835-60mA-3000K (WW) | G16: 360 | H16: Electronics Store | I16: Component | L16: 0.09 | M16: =G16*L16 -> 32.4
F17: Flexible PCB for HLP-Profile (FPC-2) LYW-1Mtr | G17: 3.6 | H17: Electronics Store | I17: Component | L17: =Q17*87 -> 20.358 | M17: =G17*L17 -> 73.2888 | N17: 0.156 | O17: 0.5 | Q17: =N17+(N17*(O17+P17)) -> 0.234 | S17: 4mtr
M18: =SUM(M2:M17) -> 459.52229
K20: H5056-25W-CC | M20: =M18+190 -> 649.52229 | N20: 24W Rate Applied
K21: H5056-25W Dali Single Color | M21: =((M18)+(Q21*87)) -> 1536.1473 | N21: 8.25 | O21: 0.5 | Q21: =N21+(N21*(O21+P21)) -> 12.375 | R21: =Q21*87 -> 1076.625

Sheet Stock Item (Read Me)
A1: List of Fields | B1: Applicable Countries | C1: Applicable Values
A2: General Details
A3: Name | B3: All | E3: Read the following, before you start using the sample file:
A4: Group Name | B4: All | E4: Stock Item worksheet:
A5: B | B5: All | E5: - Use the worksheet without making any changes to the column headers to enter your business data. - The column headers represent field names in TallyPrime. Mandatory fields are marked in bold for easy reference. - Add new columns, if needed. Ensure to enter Column Headers exactly as mentioned under the List of Fields of the Read Me worksheet. - Delete unwanted columns. However, do not delete columns that represent mandatory fields for masters.
A6: Part No. | B6: All
A7: Alias - Part No. | B7: All
A8: Description | B8: All
A9: Notes | B9: All
A10: Category | B10: All
A11: Units | B11: All | E11: Stock Item (Read Me)
A12: Conversion | B12: All | E12: - The Read Me worksheet is only for your reference. It lists all the fields, with related details, applicable for Stock Item.
A13: Denominator | B13: All
A14: Alternate Units | B14: All | E14: For more information on using Sample Excel File for importing data, refer to | M14: TallyHelp
A15: GST Applicability | B15: All | C15: Applicable, Not Applicable
A16: Opening Balance - Quantity | B16: All
A17: Opening Balance - Rate | B17: All
A18: Opening Balance - Rate Per | B18: All
A19: Opening Balance - Value | B19: All
A20: Language for Name (Except English) | B20: All
A21: Is TCS Applicable | B21: All
A22: Item Allocations Details
A23: Item Allocations - Godown | B23: (When Accounting Terminology is set to "India/SAARC")
A24: Item Allocations - Batch | B24: All
A25: Item Allocations - Quantity | B25: All
A26: Item Allocations - Rate | B26: All
A27: Item Allocations - Rate per | B27: All
A28: Item Allocations - Amount | B28: All
A29: Item Allocations - Mfg. Date | B29: All
A30: Item Allocations - Expiry Date | B30: All
A31: Item Allocations - Location | B31: (When Accounting Terminology is set to "International")
A32: Additional Details
A33: Maintain in Batches | B33: All
A34: Track date of manufacturing | B34: All
A35: Use expiry dates | B35: All
A36: Enable Cost Tracking | B36: All
A37: Costing Method | B37: All | C37: At Zero Cost, Avg. Cost, FIFO, FIFO Perpetual, Last Purchase Cost, LIFO Annual, LIFO Perpetual, Monthly Avg. Cost, Std. Cost
A38: Market Valuation Method | B38: All | C38: At Zero Price, Avg. Price, Last Sale Price, Std. Price
A39: Behaviour
A40: Ignore difference due to physical counting | B40: All
...

Sheet Backend data
C2: TRIM | D2: HOUSING/HS | E2: REFLECTOR | F2: BEAM ANGLE | G2: COLOR TEMP | H2: DRIVING SYSTEM | I2: EXTRA
C3: =MID('Stock Item'!$D$2,4,1) -> 5 | D3: =MID('Stock Item'!$D$2,6,2) -> 25 | E3: =MID('Stock Item'!$D$2,7,1) -> 5 | F3: =MID('Stock Item'!$D$2,5,2) -> 62 | G3: =MID('Stock Item'!$D$2,8,2) -> 30 | H3: =MID('Stock Item'!$D$2,10,11) | I3: =MID('Stock Item'!$D$2,2,1) -> 5
D4: =CONCATENATE(C3) -> 5 | G4: =CONCATENATE($G$3,"-") -> 30- | H4: =CONCATENATE($H$3,"-") -> -
H5: =CONCATENATE('Stock Item'!D2) -> H50562530
B6: Formulae | C6: =VLOOKUP($C$3,$B$23:$E$72,2,0) -> #N/A | D6: =VLOOKUP($D$4,G23:$J$100,2,0) -> #N/A | E6: =VLOOKUP($E$3,$L$23:$O$72,2,0) -> #N/A | F6: =VLOOKUP($F$3,$Q$23:$T$72,2,0) -> #N/A | G6: =VLOOKUP($G$4,$V$23:$Y$72,2,0) -> LED 2835-60mA-3000K (WW) | H6: =VLOOKUP($H$4,$AA$23:$AD$72,2,0) -> PS 24W 300mA 72V Maxic(PCB LT-MX-20W-V2) | I6: =VLOOKUP($I$3,AF23:$AI$100,2,0) -> #N/A
B7: Formulae for COST | C7: =VLOOKUP($C$3,$B$23:$E$72,4,0) -> #N/A | D7: =VLOOKUP($D$4,G23:$J$100,4,0) -> #N/A | E7: =VLOOKUP($E$3,$L$23:$O$72,4,0) -> #N/A | F7: =VLOOKUP($F$3,$Q$23:$T$72,4,0) -> #N/A | G7: =VLOOKUP($G$4,$V$23:$Y$72,4,0) -> 0 | H7: =VLOOKUP($H$4,$AA$23:$AD$72,4,0) -> 0 | I7: =VLOOKUP($I$3,$AF$23:$AI$100,4,0) -> #N/A
B8: Formulae for Quantity | C8: =VLOOKUP($C$3,$B$23:$E$72,3,0) -> #N/A | D8: =VLOOKUP($D$4,G23:$J$100,3,0) -> #N/A | E8: =VLOOKUP($E$3,$L$23:$O$72,3,0) -> #N/A | F8: =VLOOKUP($F$3,$Q$23:$T$72,3,0) -> #N/A | G8: =VLOOKUP($G$4,$V$23:$Y$72,3,0) -> 0 | H8: =VLOOKUP($H$4,$AA$23:$AD$72,3,0) -> 0 | I8: =VLOOKUP($I$3,$AF$23:$AI$100,3,0) -> #N/A
H10: BOM LED PCB
B21: TRIM | G21: MOUNTING TRIM | L21: REFLECTOR | Q21: BEAM ANGLE | V21: COLOUR TEMPERATURE | AA21: DRIVING SYSTEM | AF21: EXTRA
B22: Code | C22: Item Name | D22: Quantity | E22: Cost | G22: Code | H22: Item Name | I22: Quantity | J22: Cost | L22: Code | M22: Item Name | N22: Quantity | O22: Cost | Q22: Code | R22: Item Name | S22: Quantity | T22: Cost | V22: Code | W22: Item Name | X22: Quantity | Y22: Cost | AA22: Code | AB22: Item Name | AC22: Quantity | AD22: Cost | AF22: Code | AG22: Item Name | AH22: Quantity | AI22: Cost
B23: R | Q23: M | V23: 60- | W23: LED 2835-60mA-6000K (PW) | AA23: - | AB23: PS 24W 300mA 72V Maxic(PCB LT-MX-20W-V2)
B24: B | V24: 50- | W24: LED 2835-60mA-5000K (PW) | AA24: I- | AB24: Dali Driver SC 30-45W PE19DA4240(AI-DIMMING)9-42V
B25: T | V25: 40- | W25: LED 2835-60mA-4000K (NW) | AA25: BT- | AB25: PS 25W 72V 320mA BT
V26: 30- | W26: LED 2835-60mA-3000K (WW)

Sheet Result
A1: SKU Id | B1: SKU Code | C1: Product Name | D1: Cost Price | E1: Retail Price | F1: Selling Price | G1: Weight | H1: Width | I1: Height | J1: Depth | K1: Input power (Watts) | L1: Color Temp | M1: Driving System
A2: 151394 | B2: H50562560 | D2: 0 | E2: 0 | F2: 2754 | G2: 0 | H2: 0 | I2: 0 | J2: 0 | K2: 25 Watts / 1180mm | L2: 6000K | M2: Constant Current
A3: 151395 | B3: H50562550 | D3: 0 | E3: 0 | F3: 2754 | G3: 0 | H3: 0 | I3: 0 | J3: 0 | K3: 25 Watts / 1180mm | L3: 5000K | M3: Constant Current
A4: 151396 | B4: H50562540 | D4: 0 | E4: 0 | F4: 2754 | G4: 0 | H4: 0 | I4: 0 | J4: 0 | K4: 25 Watts / 1180mm | L4: 4000K | M4: Constant Current
A5: 151397 | B5: H50562530 | D5: 0 | E5: 0 | F5: 2754 | G5: 0 | H5: 0 | I5: 0 | J5: 0 | K5: 25 Watts / 1180mm | L5: 3000K | M5: Constant Current
A6: 151418 | B6: H50562560I | D6: 0 | E6: 0 | F6: 0 | G6: 0 | H6: 0 | I6: 0 | J6: 0 | K6: 25 Watts / 1180mm | L6: 6000K | M6: Dali Dimming
A7: 151419 | B7: H50562550I | D7: 0 | E7: 0 | F7: 0 | G7: 0 | H7: 0 | I7: 0 | J7: 0 | K7: 25 Watts / 1180mm | L7: 5000K | M7: Dali Dimming
A8: 151420 | B8: H50562540I | D8: 0 | E8: 0 | F8: 0 | G8: 0 | H8: 0 | I8: 0 | J8: 0 | K8: 25 Watts / 1180mm | L8: 4000K | M8: Dali Dimming
A9: 151421 | B9: H50562530I | D9: 0 | E9: 0 | F9: 0 | G9: 0 | H9: 0 | I9: 0 | J9: 0 | K9: 25 Watts / 1180mm | L9: 3000K | M9: Dali Dimming
A10: 151442 | B10: H50562560BT | D10: 0 | E10: 0 | F10: 0 | G10: 0 | H10: 0 | I10: 0 | J10: 0 | K10: 25 Watts / 1180mm | L10: 6000K | M10: Bluetooth Dimming
A11: 151443 | B11: H50562550BT | D11: 0 | E11: 0 | F11: 0 | G11: 0 | H11: 0 | I11: 0 | J11: 0 | K11: 25 Watts / 1180mm | L11: 5000K | M11: Bluetooth Dimming
A12: 151444 | B12: H50562540BT | D12: 0 | E12: 0 | F12: 0 | G12: 0 | H12: 0 | I12: 0 | J12: 0 | K12: 25 Watts / 1180mm | L12: 4000K | M12: Bluetooth Dimming
A13: 151445 | B13: H50562530BT | D13: 0 | E13: 0 | F13: 0 | G13: 0 | H13: 0 | I13: 0 | J13: 0 | K13: 25 Watts / 1180mm | L13: 3000K | M13: Bluetooth Dimming
