Workbook

Sheet Stock Item
A1: Name | B1: Group Name | C1: Units | D1: Name of BOM | E1: Unit of manufacture | F1: BOM Component - Item Name | G1: BOM Component - Quantity | H1: BOM Component - Godown | I1: BOM Component - Type of Item | J1: MODEL NAME | K1: Unit Price | L1: Cost | M1: USD | N1: INS&FRED | O1: BCD | P1: Total Cost
A2: =D2 -> MFRR06M30 | B2: Down Light Series | C2: Nos. | D2: MFRR06M30 | E2: 1 | F2: =VLOOKUP('MFR06W-DATA'!W10,'MFR06W-DATA'!A2:B3,2,0) -> HS Spot Light Single (10W) GSD8305R-MFRR6W | G2: 1 | H2: Mechanical Store | I2: Component | K2: =P2*87 -> 43.1955 | L2: =G2*K2 -> 43.1955 | M2: 0.331 | N2: 0.5 | P2: =M2+(M2*(N2+O2)) -> 0.4965
F3: Anti Glare Refl-O-48.5 H-33.5 L-30.8mm-PC | G3: 1 | H3: Mechanical Store | I3: Component
F4: HS-O-28 H-65 L-23 | G4: 1 | H4: Mechanical Store | I4: Component
F5: Refl-O-22 H-10 L-11mm-PC | G5: 1 | H5: Mechanical Store | I5: Component
F6: Diff-22X1.5mm-PC | G6: 1 | H6: Mechanical Store | I6: Component
F7: Holder Clip-O-37 H-9 L-30mm-PC | G7: 1 | H7: Mechanical Store | I7: Component
F8: Diff-O-24.5 H-14 L-21mm-PC | G8: 1 | H8: Mechanical Store | I8: Component
F9: Spring-L-50 W-18 Coil Dia.-1 D-8mm-SS | G9: 2 | H9: Mechanical Store | I9: Component
F10: COB Holder-O-22.5 H-2.5 L-11mm-PC | G10: 1 | H10: Mechanical Store | I10: Component
F11: =VLOOKUP('MFR06W-DATA'!W11,'MFR06W-DATA'!M2:O21,2,0) -> COB 12&15W 3000K 12LED 36V 350mA 13.5x13.5mm CRI-90 | G11: 1 | H11: Electronics Store | I11: Component | K11: =P11*87 -> 41.76 | L11: =G11*K11 -> 41.76 | M11: 0.32 | N11: 0.5 | P11: =M11+(M11*(N11+O11)) -> 0.48
F12: Conn. 2 Pin Ass. Wire Black Male (Small) | G12: 1 | H12: Mechanical Store | I12: Component | K12: =P12*87 -> 3.915 | L12: =G12*K12 -> 3.915 | M12: =0.06/2 -> 0.03 | N12: 0.5 | P12: =M12+(M12*(N12+O12)) -> 0.045
F13: Sleeve M4mm Fiber Glass White | G13: 0.12 | H13: Mechanical Store | I13: Component | K13: =5.7/1000*120 -> 0.684 | L13: =G13*K13 -> 0.08208
F14: Wire Clip-M3-MS | G14: 1 | H14: Mechanical Store | I14: Component | K14: 0.6 | L14: =G14*K14 -> 0.6
F15: Screw M3X4 Pan + Head S.S | G15: 4 | H15: Mechanical Store | I15: Component | K15: 0.58 | L15: =G15*K15 -> 2.32
F16: Screw M3X6mm CSK PH - SS | G16: 4 | H16: Mechanical Store | I16: Component | K16: 0.5 | L16: =G16*K16 -> 2
F17: Screw No. 4X6.5mm Self Pan Combi. PH - SS | G17: 1 | H17: Mechanical Store | I17: Component | K17: 0.21 | L17: =G17*K17 -> 0.21
F18: Screw M3X4 Pan + Head S.S | G18: 2 | H18: Mechanical Store | I18: Component | K18: 0.58 | L18: =G18*K18 -> 1.16
F19: =VLOOKUP('MFR06W-DATA'!W12,'MFR06W-DATA'!I2:J7,2,0) -> PS 6W 150MA 36V LPF (PCB MT43-8-12W-V2 LPF) | G19: 1 | H19: Mechanical Store | I19: Component | K19: =P19*87 -> 0 | L19: =G19*K19 -> 0 | M19: PS Rate Mention with Total Amt
F20: PBX - L= 88mm, W =72mm , H=81mm . | G20: 1 | H20: Mechanical Store | I20: Component | K20: =P20*87 -> 0 | L20: =G20*K20 -> 0
F21: SBX | G21: 1 | H21: Mechanical Store | I21: Component | K21: =P21*87 -> 0 | L21: =G21*K21 -> 0
L22: =SUM(L2:L21) -> 95.24258
J24: DRRR6W-CC | L24: =L22+42 -> 137.24258
J25: DRRR6W Track Dimming | L25: =L22+275 -> 370.24258
J26: DRRR6W Dali Single Color | L26: =((L22)+(P26*87)) -> 752.96258 | M26: 5.04 | N26: 0.5 | P26: =M26+(M26*(N26+O26)) -> 7.56
J27: DRRR6W BT Single Color | L27: =L22+330 -> 425.24258
J28: DRRR6W Dali Dual Color | L28: =((L22)+(P28*87)) -> 809.73008 | M28: 5.475 | N28: 0.5 | P28: =M28+(M28*(N28+O28)) -> 8.2125
J29: DRRR6W BT Dual Color | L29: =L22+330 -> 425.24258

Sheet MFR06W-DATA
A1: CODE | B1: TRIM | C1: COST | E1: CODE | F1: REFLECTOR | G1: COST | I1: CODE | J1: DRIVER | K1: COST | M1: CODE | N1: TEMPERATURE | O1: COST | Q1: CODE | R1: BEAM ANGLE | S1: COST
A2: R | B2: HS Spot Light Single (10W) GSD8305R-MFRR6W | I2: 06- | J2: PS 6W 150MA 36V LPF (PCB MT43-8-12W-V2 LPF) | K2: 42 | M2: 50- | N2: COB 12&15W 5000K 12LED 36V 350mA 13.5x13.5mm CRI-90 | O2: =X17 -> 41.28 | V2: Trim | W2: Temperature | X2: Driver | AA2: =MID('Stock Item'!D2,1,9) -> MFRR06M30 | AB2: CC
A3: B | B3: HS Spot Light Single (10W) GSD8305R-MFRR6W-BLACK | I3: 06-T | J3: PS 6W 150mA 36V Traic Dimming | K3: 275 | M3: 40- | N3: COB 12&15W 4000K 12LED 36V 350mA 13.5x13.5mm CRI-90 | O3: =X17 -> 41.28 | V3: =LEFT('Stock Item'!D2,4) -> MFRR | W3: =LEFT('Stock Item'!D2,10) -> MFRR06M30 | X3: =LEFT('Stock Item'!D2,14) -> MFRR06M30 | Y3: - | AB3: T
I4: 06-I | J4: Dali Driver SC-10W PE19DA4240 (AI-Dimming)-25-40V | K4: 621 | M4: 30- | N4: COB 12&15W 3000K 12LED 36V 350mA 13.5x13.5mm CRI-90 | O4: =X17 -> 41.28 | AB4: I
I5: 06-BT | J5: PS CCT 6W 125MA 36V BT-SC (PCB LT 7-20W-CCT-V 1.1 REV-1) | K5: 270 | M5: 27- | N5: COB 12&15W 2700K 12LED 36V 350mA 13.5x13.5mm CRI-95 | O5: =X17 -> 41.28 | V5: =MID(V3,4,1) -> R | W5: =MID(W3,8,2) -> 30 | X5: =MID(X3,10,3) | AB5: BT
I6: 06-ID | J6: Dali Driver DC-10W PE694R4230(AI-Dimming)-25-40V | K6: 706 | AB6: ID
I7: 06-BTD | J7: PS CCT 6W 125MA 36V BT-DC- (PCB LT 7-20W-CCT-V 1.1 REV-1) | K7: 340 | M7: 50-T | N7: COB 12&15W 5000K 12LED 36V 350mA 13.5x13.5mm CRI-90 | O7: =X17 -> 41.28 | W7: =MID(W3,5,2) -> 06 | AB7: BTD
M8: 40-T | N8: COB 12&15W 4000K 12LED 36V 350mA 13.5x13.5mm CRI-90 | O8: =X17 -> 41.28
M9: 30-T | N9: COB 12&15W 3000K 12LED 36V 350mA 13.5x13.5mm CRI-90 | O9: =X17 -> 41.28
M10: 27-T | N10: COB 12&15W 2700K 12LED 36V 350mA 13.5x13.5mm CRI-95 | O10: =X17 -> 41.28 | V10: Trim | W10: =CONCATENATE(V5) -> R
V11: Temperature | W11: =CONCATENATE(W5,Y3,X5) -> 30-
M12: 50-I | N12: COB 12&15W 5000K 12LED 36V 350mA 13.5x13.5mm CRI-90 | O12: =Y17 -> 41.28 | V12: Driver | W12: =CONCATENATE(W7,Y3,X5) -> 06-
M13: 40-I | N13: COB 12&15W 4000K 12LED 36V 350mA 13.5x13.5mm CRI-90 | O13: =X17 -> 41.28
M14: 30-I | N14: COB 12&15W 3000K 12LED 36V 350mA 13.5x13.5mm CRI-90 | O14: =X17 -> 41.28 | T14: Part Number | W14: Qty | X14: Unit Price | Y14: Cost | Z14: USD | AA14: INS&FRED | AB14: BCD | AC14: Total Cost
M15: 27-I | N15: COB 12&15W 2700K 12LED 36V 350mA 13.5x13.5mm CRI-95 | O15: =X17 -> 41.28 | T15: FITTING MFR06W ALL SET | W15: 1 | X15: =86*AC15 -> 0 | Y15: =W15*X15 -> 0 | Z15: 0 | AA15: 0.5 | AC15: =Z15+(Z15*(AA15+AB15)) -> 0
T16: Conn. 2 Pin Ass. Wire Black Male (Small) | W16: 1 | X16: =86*AC16 -> 3.483 | Y16: =W16*X16 -> 3.483 | Z16: 0.027 | AA16: 0.5 | AC16: =Z16+(Z16*(AA16+AB16)) -> 0.0405
M17: 50-BT | N17: COB 12&15W 5000K 12LED 36V 350mA 13.5x13.5mm CRI-90 | O17: =X17 -> 41.28 | T17: COB 12&15W 5000K 12LED 36V 350mA 13.5x13.5mm L-11mm | W17: 1 | X17: =86*AC17 -> 41.28 | Y17: =W17*X17 -> 41.28 | Z17: 0.32 | AA17: 0.5 | AC17: =Z17+(Z17*(AA17+AB17)) -> 0.48
M18: 40-BT | N18: COB 12&15W 4000K 12LED 36V 350mA 13.5x13.5mm CRI-90 | O18: =X17 -> 41.28 | T18: COB-12&15W 2700K+5000K 12LED 350mA 16X16mm L-11mm(BT+DC) | W18: 1 | X18: =86*AC18 -> 193.5 | Y18: =W18*X18 -> 193.5 | Z18: 1.5 | AA18: 0.5 | AC18: =Z18+(Z18*(AA18+AB18)) -> 2.25
M19: 30-BT | N19: COB 12&15W 3000K 12LED 36V 350mA 13.5x13.5mm CRI-90 | O19: =X17 -> 41.28
M20: 27-BT | N20: COB 12&15W 2700K 12LED 36V 350mA 13.5x13.5mm CRI-95 | O20: =X17 -> 41.28
M21: 25-BTD | N21: COB 12&15W 2700-5000K 12LED 36V 350mA 13.5x13.5mm CRI-90 | O21: =X18 -> 193.5

Sheet Stock Item (Read Me)
A1: List of Fields | B1: Applicable Countries | C1: Applicable Values
A2: General Details
A3: Name | B3: All | E3: Read the following, before you start using the sample file:
A4: Group Name | B4: All | E4: Stock Item worksheet:
A5: B | B5: All | E5: - Use the worksheet without making any changes to the column headers to enter your business data. - The column headers represent field names in TallyPrime. Mandatory fields are marked in bold for easy reference. - Add new columns, if needed. Ensure to enter Column Headers exactly as mentioned under the List of Fields of the Read Me worksheet. - Delete unwanted columns. However, do not delete columns that represent mandatory fields for masters.
A6: Part No. | B6: All
A7: Alias - Part No. | B7: All
A8: Description | B8: All
A9: Notes | B9: All
A10: Category | B10: All
A11: Units | B11: All | E11: Stock Item (Read Me)
A12: Conversion | B12: All | E12: - The Read Me worksheet is only for your reference. It lists all the fields, with related details, applicable for Stock Item.
A13: Denominator | B13: All
A14: Alternate Units | B14: All | E14: For more information on using Sample Excel File for importing data, refer to | M14: TallyHelp
A15: GST Applicability | B15: All | C15: Applicable, Not Applicable
A16: Opening Balance - Quantity | B16: All
A17: Opening Balance - Rate | B17: All
A18: Opening Balance - Rate Per | B18: All
A19: Opening Balance - Value | B19: All
A20: Language for Name (Except English) | B20: All
A21: Is TCS Applicable | B21: All
A22: Item Allocations Details
A23: Item Allocations - Godown | B23: (When Accounting Terminology is set to "India/SAARC")
A24: Item Allocations - Batch | B24: All
A25: Item Allocations - Quantity | B25: All
A26: Item Allocations - Rate | B26: All
A27: Item Allocations - Rate per | B27: All
A28: Item Allocations - Amount | B28: All
A29: Item Allocations - Mfg. Date | B29: All
A30: Item Allocations - Expiry Date | B30: All
A31: Item Allocations - Location | B31: (When Accounting Terminology is set to "International")
A32: Additional Details
A33: Maintain in Batches | B33: All
A34: Track date of manufacturing | B34: All
A35: Use expiry dates | B35: All
A36: Enable Cost Tracking | B36: All
A37: Costing Method | B37: All | C37: At Zero Cost, Avg. Cost, FIFO, FIFO Perpetual, Last Purchase Cost, LIFO Annual, LIFO Perpetual, Monthly Avg. Cost, Std. Cost
A38: Market Valuation Method | B38: All | C38: At Zero Price, Avg. Price, Last Sale Price, Std. Price
A39: Behaviour
A40: Ignore difference due to physical counting | B40: All
...

Sheet MFR06W-SKU
A1: SKU Id | B1: SKU Code | C1: Product Name | D1: Cost Price | E1: Retail Price | F1: Selling Price | G1: Weight | H1: Width | I1: Height | J1: Depth | K1: Beam Angle | L1: Color Temp | M1: Driving System | N1: Trim | O1: Watt
A2: 145904 | B2: MFRR06M50- | C2: =_xlfn.CONCAT(Q2,R2,S2,T2,U2) -> MFRR06M50 | D2: 0 | E2: 0 | F2: 1247 | G2: 0 | H2: 0 | I2: 0 | J2: 0 | K2: Medium - 32° | L2: 5000k | M2: Constant Current | N2: White Trim | O2: 06 Watt | Q2: =MID(B2,1,3) -> MFR | R2: =MID(B2,4,1) -> R | S2: =MID(B2,5,2) -> 06 | T2: =MID(B2,7,1) -> M | U2: =MID(B2,8,2) -> 50
A3: 145905 | B3: MFRR06M40- | C3: =_xlfn.CONCAT(Q3,R3,S3,T3,U3) -> MFRR06M40 | D3: 0 | E3: 0 | F3: 1247 | G3: 0 | H3: 0 | I3: 0 | J3: 0 | K3: Medium - 32° | L3: 4000k | M3: Constant Current | N3: White Trim | O3: 06 Watt | Q3: =MID(B3,1,3) -> MFR | R3: =MID(B3,4,1) -> R | S3: =MID(B3,5,2) -> 06 | T3: =MID(B3,7,1) -> M | U3: =MID(B3,8,2) -> 40
A4: 145906 | B4: MFRR06M30- | C4: =_xlfn.CONCAT(Q4,R4,S4,T4,U4) -> MFRR06M30 | D4: 0 | E4: 0 | F4: 1247 | G4: 0 | H4: 0 | I4: 0 | J4: 0 | K4: Medium - 32° | L4: 3000k | M4: Constant Current | N4: White Trim | O4: 06 Watt | Q4: =MID(B4,1,3) -> MFR | R4: =MID(B4,4,1) -> R | S4: =MID(B4,5,2) -> 06 | T4: =MID(B4,7,1) -> M | U4: =MID(B4,8,2) -> 30
A5: 145907 | B5: MFRR06M27- | C5: =_xlfn.CONCAT(Q5,R5,S5,T5,U5) -> MFRR06M27 | D5: 0 | E5: 0 | F5: 1247 | G5: 0 | H5: 0 | I5: 0 | J5: 0 | K5: Medium - 32° | L5: 2700k | M5: Constant Current | N5: White Trim | O5: 06 Watt | Q5: =MID(B5,1,3) -> MFR | R5: =MID(B5,4,1) -> R | S5: =MID(B5,5,2) -> 06 | T5: =MID(B5,7,1) -> M | U5: =MID(B5,8,2) -> 27
A6: 145911 | B6: MFRB06M50- | C6: =_xlfn.CONCAT(Q6,R6,S6,T6,U6) -> MFRB06M50 | D6: 0 | E6: 0 | F6: 1371 | G6: 0 | H6: 0 | I6: 0 | J6: 0 | K6: Medium - 32° | L6: 5000k | M6: Constant Current | N6: Black Trim | O6: 06 Watt | Q6: =MID(B6,1,3) -> MFR | R6: =MID(B6,4,1) -> B | S6: =MID(B6,5,2) -> 06 | T6: =MID(B6,7,1) -> M | U6: =MID(B6,8,2) -> 50
A7: 145912 | B7: MFRB06M40- | C7: =_xlfn.CONCAT(Q7,R7,S7,T7,U7) -> MFRB06M40 | D7: 0 | E7: 0 | F7: 1371 | G7: 0 | H7: 0 | I7: 0 | J7: 0 | K7: Medium - 32° | L7: 4000k | M7: Constant Current | N7: Black Trim | O7: 06 Watt | Q7: =MID(B7,1,3) -> MFR | R7: =MID(B7,4,1) -> B | S7: =MID(B7,5,2) -> 06 | T7: =MID(B7,7,1) -> M | U7: =MID(B7,8,2) -> 40
A8: 145913 | B8: MFRB06M30- | C8: =_xlfn.CONCAT(Q8,R8,S8,T8,U8) -> MFRB06M30 | D8: 0 | E8: 0 | F8: 1371 | G8: 0 | H8: 0 | I8: 0 | J8: 0 | K8: Medium - 32° | L8: 3000k | M8: Constant Current | N8: Black Trim | O8: 06 Watt | Q8: =MID(B8,1,3) -> MFR | R8: =MID(B8,4,1) -> B | S8: =MID(B8,5,2) -> 06 | T8: =MID(B8,7,1) -> M | U8: =MID(B8,8,2) -> 30
A9: 145914 | B9: MFRB06M27- | C9: =_xlfn.CONCAT(Q9,R9,S9,T9,U9) -> MFRB06M27 | D9: 0 | E9: 0 | F9: 1371 | G9: 0 | H9: 0 | I9: 0 | J9: 0 | K9: Medium - 32° | L9: 2700k | M9: Constant Current | N9: Black Trim | O9: 06 Watt | Q9: =MID(B9,1,3) -> MFR | R9: =MID(B9,4,1) -> B | S9: =MID(B9,5,2) -> 06 | T9: =MID(B9,7,1) -> M | U9: =MID(B9,8,2) -> 27
A10: 145918 | B10: MFRR06M50T | C10: =_xlfn.CONCAT(Q10,R10,S10,T10,U10) -> MFRR06M50T | D10: 0 | E10: 0 | F10: 1703 | G10: 0 | H10: 0 | I10: 0 | J10: 0 | K10: Medium - 32° | L10: 5000k | M10: TRIAC Dimming | N10: White Trim | O10: 06 Watt | Q10: =MID(B10,1,3) -> MFR | R10: =MID(B10,4,1) -> R | S10: =MID(B10,5,2) -> 06 | T10: =MID(B10,7,1) -> M | U10: =MID(B10,8,6) -> 50T
A11: 145919 | B11: MFRR06M40T | C11: =_xlfn.CONCAT(Q11,R11,S11,T11,U11) -> MFRR06M40T | D11: 0 | E11: 0 | F11: 1703 | G11: 0 | H11: 0 | I11: 0 | J11: 0 | K11: Medium - 32° | L11: 4000k | M11: TRIAC Dimming | N11: White Trim | O11: 06 Watt | Q11: =MID(B11,1,3) -> MFR | R11: =MID(B11,4,1) -> R | S11: =MID(B11,5,2) -> 06 | T11: =MID(B11,7,1) -> M | U11: =MID(B11,8,6) -> 40T
A12: 145920 | B12: MFRR06M30T | C12: =_xlfn.CONCAT(Q12,R12,S12,T12,U12) -> MFRR06M30T | D12: 0 | E12: 0 | F12: 1703 | G12: 0 | H12: 0 | I12: 0 | J12: 0 | K12: Medium - 32° | L12: 3000k | M12: TRIAC Dimming | N12: White Trim | O12: 06 Watt | Q12: =MID(B12,1,3) -> MFR | R12: =MID(B12,4,1) -> R | S12: =MID(B12,5,2) -> 06 | T12: =MID(B12,7,1) -> M | U12: =MID(B12,8,6) -> 30T
A13: 145921 | B13: MFRR06M27T | C13: =_xlfn.CONCAT(Q13,R13,S13,T13,U13) -> MFRR06M27T | D13: 0 | E13: 0 | F13: 1703 | G13: 0 | H13: 0 | I13: 0 | J13: 0 | K13: Medium - 32° | L13: 2700k | M13: TRIAC Dimming | N13: White Trim | O13: 06 Watt | Q13: =MID(B13,1,3) -> MFR | R13: =MID(B13,4,1) -> R | S13: =MID(B13,5,2) -> 06 | T13: =MID(B13,7,1) -> M | U13: =MID(B13,8,6) -> 27T
A14: 145925 | B14: MFRB06M50T | C14: =_xlfn.CONCAT(Q14,R14,S14,T14,U14) -> MFRB06M50T | D14: 0 | E14: 0 | F14: 1828 | G14: 0 | H14: 0 | I14: 0 | J14: 0 | K14: Medium - 32° | L14: 5000k | M14: TRIAC Dimming | N14: Black Trim | O14: 06 Watt | Q14: =MID(B14,1,3) -> MFR | R14: =MID(B14,4,1) -> B | S14: =MID(B14,5,2) -> 06 | T14: =MID(B14,7,1) -> M | U14: =MID(B14,8,6) -> 50T
A15: 145926 | B15: MFRB06M40T | C15: =_xlfn.CONCAT(Q15,R15,S15,T15,U15) -> MFRB06M40T | D15: 0 | E15: 0 | F15: 1828 | G15: 0 | H15: 0 | I15: 0 | J15: 0 | K15: Medium - 32° | L15: 4000k | M15: TRIAC Dimming | N15: Black Trim | O15: 06 Watt | Q15: =MID(B15,1,3) -> MFR | R15: =MID(B15,4,1) -> B | S15: =MID(B15,5,2) -> 06 | T15: =MID(B15,7,1) -> M | U15: =MID(B15,8,6) -> 40T
A16: 145927 | B16: MFRB06M30T | C16: =_xlfn.CONCAT(Q16,R16,S16,T16,U16) -> MFRB06M30T | D16: 0 | E16: 0 | F16: 1828 | G16: 0 | H16: 0 | I16: 0 | J16: 0 | K16: Medium - 32° | L16: 3000k | M16: TRIAC Dimming | N16: Black Trim | O16: 06 Watt | Q16: =MID(B16,1,3) -> MFR | R16: =MID(B16,4,1) -> B | S16: =MID(B16,5,2) -> 06 | T16: =MID(B16,7,1) -> M | U16: =MID(B16,8,6) -> 30T
A17: 145928 | B17: MFRB06M27T | C17: =_xlfn.CONCAT(Q17,R17,S17,T17,U17) -> MFRB06M27T | D17: 0 | E17: 0 | F17: 1828 | G17: 0 | H17: 0 | I17: 0 | J17: 0 | K17: Medium - 32° | L17: 2700k | M17: TRIAC Dimming | N17: Black Trim | O17: 06 Watt | Q17: =MID(B17,1,3) -> MFR | R17: =MID(B17,4,1) -> B | S17: =MID(B17,5,2) -> 06 | T17: =MID(B17,7,1) -> M | U17: =MID(B17,8,6) -> 27T
A18: 145932 | B18: MFRR06M50I | C18: =_xlfn.CONCAT(Q18,R18,S18,T18,U18) -> MFRR06M50I | D18: 0 | E18: 0 | F18: 2842 | G18: 0 | H18: 0 | I18: 0 | J18: 0 | K18: Medium - 32° | L18: 5000k | M18: DALI Dimming | N18: White Trim | O18: 06 Watt | Q18: =MID(B18,1,3) -> MFR | R18: =MID(B18,4,1) -> R | S18: =MID(B18,5,2) -> 06 | T18: =MID(B18,7,1) -> M | U18: =MID(B18,8,6) -> 50I
A19: 145933 | B19: MFRR06M40I | C19: =_xlfn.CONCAT(Q19,R19,S19,T19,U19) -> MFRR06M40I | D19: 0 | E19: 0 | F19: 2842 | G19: 0 | H19: 0 | I19: 0 | J19: 0 | K19: Medium - 32° | L19: 4000k | M19: DALI Dimming | N19: White Trim | O19: 06 Watt | Q19: =MID(B19,1,3) -> MFR | R19: =MID(B19,4,1) -> R | S19: =MID(B19,5,2) -> 06 | T19: =MID(B19,7,1) -> M | U19: =MID(B19,8,6) -> 40I
A20: 145934 | B20: MFRR06M30I | C20: =_xlfn.CONCAT(Q20,R20,S20,T20,U20) -> MFRR06M30I | D20: 0 | E20: 0 | F20: 2842 | G20: 0 | H20: 0 | I20: 0 | J20: 0 | K20: Medium - 32° | L20: 3000k | M20: DALI Dimming | N20: White Trim | O20: 06 Watt | Q20: =MID(B20,1,3) -> MFR | R20: =MID(B20,4,1) -> R | S20: =MID(B20,5,2) -> 06 | T20: =MID(B20,7,1) -> M | U20: =MID(B20,8,6) -> 30I
A21: 145935 | B21: MFRR06M27I | C21: =_xlfn.CONCAT(Q21,R21,S21,T21,U21) -> MFRR06M27I | D21: 0 | E21: 0 | F21: 2842 | G21: 0 | H21: 0 | I21: 0 | J21: 0 | K21: Medium - 32° | L21: 2700k | M21: DALI Dimming | N21: White Trim | O21: 06 Watt | Q21: =MID(B21,1,3) -> MFR | R21: =MID(B21,4,1) -> R | S21: =MID(B21,5,2) -> 06 | T21: =MID(B21,7,1) -> M | U21: =MID(B21,8,6) -> 27I
... A37: 145999 | B37: MFRB06M25ID | C37: =_xlfn.CONCAT(Q37,R37,S37,T37,U37) -> MFRB06M25ID | D37: 0 | E37: 0 | F37: 3527 | G37: 0 | H37: 0 | I37: 0 | J37: 0 | K37: Medium - 32° | L37: 2700K - 5000K Dali + Dual Color (Driving System) | M37: DALI + Dual Color (2700K - 5000K) | N37: Black Trim | O37: 06 Watt | Q37: =MID(B37,1,3) -> MFR | R37: =MID(B37,4,1) -> B | S37: =MID(B37,5,2) -> 06 | T37: =MID(B37,7,1) -> M | U37: =MID(B37,8,6) -> 25ID
