Workbook

Sheet Stock Item
A1: Name | B1: Group Name | C1: Units | D1: Name of BOM | E1: Unit of manufacture | F1: BOM Component - Item Name | G1: BOM Component - Quantity | H1: BOM Component - Godown | I1: BOM Component - Type of Item | J1: BOM Component - Rate (%) | K1: BOM Component - Location | L1: Unit Price | M1: Cost | N1: USD | O1: INS&FRED | P1: BCD | Q1: Total Cost
A2: =$D$2 -> NGAB08N30 | B2: Down Light Series | C2: Nos. | D2: NGAB08N30 | E2: 1 | F2: ='Backend data'!C6 -> Trim-O-50 I-37.5 H-22.5mm 0.5W Black NGWR8W (OUCHI) | G2: 1 | H2: Mechanical Store | I2: Component | L2: =Q2*87 -> 463.1445 | M2: =L2*G2 -> 463.1445 | N2: 3.549 | O2: 0.5 | Q2: =N2+(N2*(O2+P2)) -> 5.3235
F3: HS-O-35.8 I-30.5 H-68mm 0.5W NGWR8W (OUCHI) | G3: 1 | H3: Mechanical Store | I3: Component
F4: ='Backend data'!E6 -> Refl.O-39 H-14.8 L-23mm 0.5W -Silver NGWR8W (OUCHI) | G4: 1 | H4: Mechanical Store | I4: Component
F5: Diff-25.2x0.25mm PS 0.5W NGWR8W (OUCHI) | G5: 1 | H5: Mechanical Store | I5: Component
F6: ='Backend data'!F6 -> Lens-O-24.8 H-12.9 L-8.5mm 24°-PMMA 0.5W NGWR8W (OUCHI) | G6: 1 | H6: Mechanical Store | I6: Component
F7: Housing-O-37 I-25.5 H-31mm 0.5W NGWR8W (OUCHI) | G7: 1 | H7: Mechanical Store | I7: Component
F8: Gasket-30X1.3mm 0.5W NGWR8W (OUCHI) | G8: 1 | H8: Mechanical Store | I8: Component
F9: COB Holder-O-25 H-4 L-11.3mm-PC NGWR8W (OUCHI) | G9: 1 | H9: Mechanical Store | I9: Component
F10: PBX-L-85 W-66 H-130mm NGWR8W (OUCHI) | G10: 1 | H10: Mechanical Store | I10: Component
F11: SBX | G11: 0.08 | H11: Mechanical Store | I11: Component
F12: Screw-M3X4mm CSK + Head-MS | G12: 2 | H12: Mechanical Store | I12: Component
F13: Screw M4x4mm , SS , Allen grub screw | G13: 1 | H13: Mechanical Store | I13: Component
F14: Conn. 2Pin Ass. Wire Black Male (Small) | G14: 1 | H14: Mechanical Store | I14: Component | L14: =Q14*87 -> 3.915 | M14: =L14*G14 -> 3.915 | N14: =0.06/2 -> 0.03 | O14: 0.5 | Q14: =N14+(N14*(O14+P14)) -> 0.045
F15: Sleeve M4mm Fiber Glass White | G15: 0.12 | H15: Mechanical Store | I15: Component | L15: =5.7/1000*120 -> 0.684 | M15: =L15*G15 -> 0.08208
F16: ='Backend data'!G6 -> COB 12&15W 3000K 12LED 36V 350mA 13.5x13.5mm CRI-90 | G16: 1 | H16: Electronics Store | I16: Component | L16: =Q16*87 -> 41.76 | M16: =L16*G16 -> 41.76 | N16: 0.32 | O16: 0.5 | Q16: =N16+(N16*(O16+P16)) -> 0.48
F17: ='Backend data'!H6 -> PS 8W 200MA 36V LPF (PCB MT43-8-12W-V2 LPF) | G17: 1 | H17: Mechanical Store | I17: Component | L17: 0 | M17: =L17*G17 -> 0 | N17: PS Rate Mention with Total Amt
M18: =SUM(M2:M17) -> 508.90158
K20: NGWR08-CC | M20: =M18+42 -> 550.90158
K21: NGWR08 Track Dimming | M21: =M18+275 -> 783.90158
K22: NGWR08 Dali Single Color | M22: =((M18)+(Q22*87)) -> 1166.6216 | N22: 5.04 | O22: 0.5 | Q22: =N22+(N22*(O22+P22)) -> 7.56
K23: NGWR08 BT Single Color | M23: =M18+330 -> 838.90158
K24: NGWR08 Dali Dual Color | M24: =((M18)+(Q24*87)) -> 1223.3891 | N24: =5.475 -> 5.475 | O24: 0.5 | Q24: =N24+(N24*(O24+P24)) -> 8.2125
K25: NGWR08 BT Dual Color | M25: =M18+330 -> 838.90158

Sheet Stock Item (Read Me)
A1: List of Fields | B1: Applicable Countries | C1: Applicable Values
A2: General Details
A3: Name | B3: All | E3: Read the following, before you start using the sample file:
A4: Group Name | B4: All | E4: Stock Item worksheet:
A5: B | B5: All | E5: - Use the worksheet without making any changes to the column headers to enter your business data. - The column headers represent field names in TallyPrime. Mandatory fields are marked in bold for easy reference. - Add new columns, if needed. Ensure to enter Column Headers exactly as mentioned under the List of Fields of the Read Me worksheet. - Delete unwanted columns. However, do not delete columns that represent mandatory fields for masters.
A6: Part No. | B6: All
A7: Alias - Part No. | B7: All
A8: Description | B8: All
A9: Notes | B9: All
A10: Category | B10: All
A11: Units | B11: All | E11: Stock Item (Read Me)
A12: Conversion | B12: All | E12: - The Read Me worksheet is only for your reference. It lists all the fields, with related details, applicable for Stock Item.
A13: Denominator | B13: All
A14: Alternate Units | B14: All | E14: For more information on using Sample Excel File for importing data, refer to | M14: TallyHelp
A15: GST Applicability | B15: All | C15: Applicable, Not Applicable
A16: Opening Balance - Quantity | B16: All
A17: Opening Balance - Rate | B17: All
A18: Opening Balance - Rate Per | B18: All
A19: Opening Balance - Value | B19: All
A20: Language for Name (Except English) | B20: All
A21: Is TCS Applicable | B21: All
A22: Item Allocations Details
A23: Item Allocations - Godown | B23: (When Accounting Terminology is set to "India/SAARC")
A24: Item Allocations - Batch | B24: All
A25: Item Allocations - Quantity | B25: All
A26: Item Allocations - Rate | B26: All
A27: Item Allocations - Rate per | B27: All
A28: Item Allocations - Amount | B28: All
A29: Item Allocations - Mfg. Date | B29: All
A30: Item Allocations - Expiry Date | B30: All
A31: Item Allocations - Location | B31: (When Accounting Terminology is set to "International")
A32: Additional Details
A33: Maintain in Batches | B33: All
A34: Track date of manufacturing | B34: All
A35: Use expiry dates | B35: All
A36: Enable Cost Tracking | B36: All
A37: Costing Method | B37: All | C37: At Zero Cost, Avg. Cost, FIFO, FIFO Perpetual, Last Purchase Cost, LIFO Annual, LIFO Perpetual, Monthly Avg. Cost, Std. Cost
A38: Market Valuation Method | B38: All | C38: At Zero Price, Avg. Price, Last Sale Price, Std. Price
A39: Behaviour
A40: Ignore difference due to physical counting | B40: All
...

Sheet Backend data
C2: TRIM | D2: HOUSING/HS | E2: REFLECTOR | F2: BEAM ANGLE | G2: COLOR TEMP | H2: DRIVING SYSTEM | I2: EXTRA
C3: =MID('Stock Item'!$D$2,4,1) -> B | D3: =MID('Stock Item'!$D$2,6,2) -> 8N | E3: =MID('Stock Item'!$D$2,3,1) -> A | F3: =MID('Stock Item'!$D$2,7,1) -> N | G3: =MID('Stock Item'!$D$2,8,2) -> 30 | H3: =MID('Stock Item'!$D$2,10,11) | I3: =MID('Stock Item'!$D$2,2,1) -> G
D4: =CONCATENATE($D$3,$F$3) -> 8NN | G4: =CONCATENATE(G3,H4) -> 30- | H4: =CONCATENATE($H$3,"-") -> -
J5: =CONCATENATE('Stock Item'!D2) -> NGAB08N30
B6: Formulae | C6: =VLOOKUP($C$3,$B$23:$E$68,2,0) -> Trim-O-50 I-37.5 H-22.5mm 0.5W Black NGWR8W (OUCHI) | D6: =VLOOKUP($D$4,G23:$J$96,2,0) -> #N/A | E6: =VLOOKUP($E$3,$L$23:$O$68,2,0) -> Refl.O-39 H-14.8 L-23mm 0.5W -Silver NGWR8W (OUCHI) | F6: =VLOOKUP($F$3,$Q$23:$T$68,2,0) -> Lens-O-24.8 H-12.9 L-8.5mm 24°-PMMA 0.5W NGWR8W (OUCHI) | G6: =VLOOKUP($G$4,$V$23:$Y$68,2,0) -> COB 12&15W 3000K 12LED 36V 350mA 13.5x13.5mm CRI-90 | H6: =VLOOKUP($H$4,$AA$23:$AD$68,2,0) -> PS 8W 200MA 36V LPF (PCB MT43-8-12W-V2 LPF) | I6: =VLOOKUP($I$3,AF23:$AI$96,2,0) -> #N/A
B7: Formulae for COST | C7: =VLOOKUP($C$3,$B$23:$E$68,4,0) -> 0 | D7: =VLOOKUP($D$4,G23:$J$96,4,0) -> #N/A | E7: =VLOOKUP($E$3,$L$23:$O$68,4,0) -> 0 | F7: =VLOOKUP($F$3,$Q$23:$T$68,4,0) -> 0 | G7: =VLOOKUP($G$4,$V$23:$Y$68,4,0) -> 0 | H7: =VLOOKUP($H$4,$AA$23:$AD$68,4,0) -> 0 | I7: =VLOOKUP($I$3,$AF$23:$AI$96,4,0) -> #N/A
B8: Formulae for Quantity | C8: =VLOOKUP($C$3,$B$23:$E$68,3,0) -> 0 | D8: =VLOOKUP($D$4,G23:$J$96,3,0) -> #N/A | E8: =VLOOKUP($E$3,$L$23:$O$68,3,0) -> 0 | F8: =VLOOKUP($F$3,$Q$23:$T$68,3,0) -> 0 | G8: =VLOOKUP($G$4,$V$23:$Y$68,3,0) -> 0 | H8: =VLOOKUP($H$4,$AA$23:$AD$68,3,0) -> 0 | I8: =VLOOKUP($I$3,$AF$23:$AI$96,3,0) -> #N/A
J9: BOM LED PCB
B21: TRIM | G21: HOUSING/HS | L21: REFLECTOR | Q21: BEAM ANGLE | V21: COLOR TEMPERATURE | AA21: DRIVING SYSTEM | AF21: EXTRA
B22: Code | C22: Item Name | D22: Quantity | E22: Cost | G22: Code | H22: Item Name | I22: Quantity | J22: Cost | L22: Code | M22: Item Name | N22: Quantity | O22: Cost | Q22: Code | R22: Item Name | S22: Quantity | T22: Cost | V22: Code | W22: Item Name | X22: Quantity | Y22: Cost | AA22: Code | AB22: Item Name | AC22: Quantity | AD22: Cost | AF22: Code | AG22: Item Name | AH22: Quantity | AI22: Cost
B23: R | C23: Trim-O-50 I-37.5 H-22.5mm 0.5W White NGWR8W (OUCHI) | L23: W | M23: Refl O-39 H.14.8 L-23mm0.5W-White- NGWR8W (OUCHI) | Q23: N | R23: Lens-O-24.8 H-12.9 L-8.5mm 24°-PMMA 0.5W NGWR8W (OUCHI) | V23: 30- | W23: COB 12&15W 3000K 12LED 36V 350mA 13.5x13.5mm CRI-90 | AA23: - | AB23: PS 8W 200MA 36V LPF (PCB MT43-8-12W-V2 LPF)
B24: B | C24: Trim-O-50 I-37.5 H-22.5mm 0.5W Black NGWR8W (OUCHI) | L24: B | M24: Refl O-39 H-14.8-L-23mm 0.5W - Black NGWR8W (OUCHI) | Q24: M | R24: Lens-O-24.8 H-12.9 L-8.5mm 36°-PMMA 0.5W NGWR8&12W (OUCHI) | V24: 40- | W24: COB 12&15W 4000K 12LED 36V 350mA 13.5x13.5mm CRI-90 | AA24: T- | AB24: PS 8W 200MA 36V Triac Dimming
B25: T | C25: Trimles O-64 I-37 H-22.6mm 0.5W White NGWR8 (OUCHI) | L25: A | M25: Refl.O-39 H-14.8 L-23mm 0.5W -Silver NGWR8W (OUCHI) | V25: 50- | W25: COB 12&15W 5000K 12LED 36V 350mA 13.5x13.5mm CRI-90 | AA25: I- | AB25: Dali Driver SC-10W PE19DA4240 (AI-Dimming)-25-40V
L26: C | M26: Refl.O-39 H-14.8 L-23mm 0.5W - Chrome NWR8W (OUCHI) | V26: 60- | W26: COB 12&15W 6000K 12LED 36V 350mA 13.5x13.5mm CRI-90 | AA26: BT- | AB26: PS CCT 8W 170MA 36V BT-SC (PCB LT 7-20W-CCT-V 1.1 REV-1)
AA27: ID- | AB27: Dali Driver DC-10W PE694R4230(AI-Dimming)-25-40V
V28: 30BT- | W28: COB 12&15W 3000K 12LED 36V 350mA 13.5x13.5mm CRI-90 | AA28: BTD- | AB28: PS CCT 8W 170MA 36V BT-DC (PCB LT 7-20W-CCT-V 1.1 REV-1)
V29: 40BT- | W29: COB 12&15W 4000K 12LED 36V 350mA 13.5x13.5mm CRI-90
V30: 50BT- | W30: COB 12&15W 5000K 12LED 36V 350mA 13.5x13.5mm CRI-90
V31: 60BT- | W31: COB 12&15W 6000K 12LED 36V 350mA 13.5x13.5mm CRI-90
V32: 26BTD- | W32: COB 12&15W 2700-5000K 12LED 36V 350mA 13.5x13.5mm CRI-90
V34: 30I- | W34: COB 12&15W 3000K 12LED 36V 350mA 13.5x13.5mm CRI-90
V35: 40I- | W35: COB 12&15W 4000K 12LED 36V 350mA 13.5x13.5mm CRI-90
V36: 50I- | W36: COB 12&15W 5000K 12LED 36V 350mA 13.5x13.5mm CRI-90
V37: 60I- | W37: COB 12&15W 6000K 12LED 36V 350mA 13.5x13.5mm CRI-90
V38: 26ID- | W38: COB 12&15W 2700-5000K 12LED 36V 350mA 13.5x13.5mm CRI-90
V40: 30T- | W40: COB 12&15W 3000K 12LED 36V 350mA 13.5x13.5mm CRI-90
V41: 40T- | W41: COB 12&15W 4000K 12LED 36V 350mA 13.5x13.5mm CRI-90
V42: 50T- | W42: COB 12&15W 5000K 12LED 36V 350mA 13.5x13.5mm CRI-90
V43: 60T- | W43: COB 12&15W 6000K 12LED 36V 350mA 13.5x13.5mm CRI-90

Sheet Result
A1: SKU Id | B1: SKU Code | C1: Product Name | D1: Cost Price | E1: Retail Price | F1: Selling Price | G1: Weight | H1: Width | I1: Height | J1: Depth | K1: Beam Angle | L1: Color Temp | M1: Driving System | N1: Input Power | O1: Reflector | P1: Trim | R1: SKU
A2: 195477 | B2: NGWR08M30 | D2: 0 | E2: 0 | F2: 0 | G2: 0 | H2: 0 | I2: 0 | J2: 0 | K2: Medium - 36° | L2: 3000K | M2: Constant Current | N2: 08 Watt | O2: White Reflector | P2: Round White Trim | R2: =MID(B2,1,9) -> NGWR08M30
A3: 195478 | B3: NGWT08M30 | D3: 0 | E3: 0 | F3: 0 | G3: 0 | H3: 0 | I3: 0 | J3: 0 | K3: Medium - 36° | L3: 3000K | M3: Constant Current | N3: 08 Watt | O3: White Reflector | P3: Round White Trimless | R3: =MID(B3,1,9) -> NGWT08M30
A4: 195479 | B4: NGWB08M30 | D4: 0 | E4: 0 | F4: 0 | G4: 0 | H4: 0 | I4: 0 | J4: 0 | K4: Medium - 36° | L4: 3000K | M4: Constant Current | N4: 08 Watt | O4: White Reflector | P4: Round Black Trim | R4: =MID(B4,1,9) -> NGWB08M30
A5: 195480 | B5: NGWR08N30 | D5: 0 | E5: 0 | F5: 0 | G5: 0 | H5: 0 | I5: 0 | J5: 0 | K5: Narrow - 28° | L5: 3000K | M5: Constant Current | N5: 08 Watt | O5: White Reflector | P5: Round White Trim | R5: =MID(B5,1,9) -> NGWR08N30
A6: 195481 | B6: NGWT08N30 | D6: 0 | E6: 0 | F6: 0 | G6: 0 | H6: 0 | I6: 0 | J6: 0 | K6: Narrow - 28° | L6: 3000K | M6: Constant Current | N6: 08 Watt | O6: White Reflector | P6: Round White Trimless | R6: =MID(B6,1,9) -> NGWT08N30
A7: 195482 | B7: NGWB08N30 | D7: 0 | E7: 0 | F7: 0 | G7: 0 | H7: 0 | I7: 0 | J7: 0 | K7: Narrow - 28° | L7: 3000K | M7: Constant Current | N7: 08 Watt | O7: White Reflector | P7: Round Black Trim | R7: =MID(B7,1,9) -> NGWB08N30
A8: 195483 | B8: NGWR08M40 | D8: 0 | E8: 0 | F8: 0 | G8: 0 | H8: 0 | I8: 0 | J8: 0 | K8: Medium - 36° | L8: 4000K | M8: Constant Current | N8: 08 Watt | O8: White Reflector | P8: Round White Trim | R8: =MID(B8,1,9) -> NGWR08M40
A9: 195484 | B9: NGWT08M40 | D9: 0 | E9: 0 | F9: 0 | G9: 0 | H9: 0 | I9: 0 | J9: 0 | K9: Medium - 36° | L9: 4000K | M9: Constant Current | N9: 08 Watt | O9: White Reflector | P9: Round White Trimless | R9: =MID(B9,1,9) -> NGWT08M40
A10: 195485 | B10: NGWB08M40 | D10: 0 | E10: 0 | F10: 0 | G10: 0 | H10: 0 | I10: 0 | J10: 0 | K10: Medium - 36° | L10: 4000K | M10: Constant Current | N10: 08 Watt | O10: White Reflector | P10: Round Black Trim | R10: =MID(B10,1,9) -> NGWB08M40
A11: 195486 | B11: NGWR08N40 | D11: 0 | E11: 0 | F11: 0 | G11: 0 | H11: 0 | I11: 0 | J11: 0 | K11: Narrow - 28° | L11: 4000K | M11: Constant Current | N11: 08 Watt | O11: White Reflector | P11: Round White Trim | R11: =MID(B11,1,9) -> NGWR08N40
A12: 195487 | B12: NGWT08N40 | D12: 0 | E12: 0 | F12: 0 | G12: 0 | H12: 0 | I12: 0 | J12: 0 | K12: Narrow - 28° | L12: 4000K | M12: Constant Current | N12: 08 Watt | O12: White Reflector | P12: Round White Trimless | R12: =MID(B12,1,9) -> NGWT08N40
A13: 195488 | B13: NGWB08N40 | D13: 0 | E13: 0 | F13: 0 | G13: 0 | H13: 0 | I13: 0 | J13: 0 | K13: Narrow - 28° | L13: 4000K | M13: Constant Current | N13: 08 Watt | O13: White Reflector | P13: Round Black Trim | R13: =MID(B13,1,9) -> NGWB08N40
... A73: 195566 | B73: NGCB08N60 | D73: 0 | E73: 0 | F73: 0 | G73: 0 | H73: 0 | I73: 0 | J73: 0 | K73: Narrow - 28° | L73: 6000k | M73: Constant Current | N73: 08 Watt | O73: Chrome Reflector | P73: Round Black Trim | R73: =MID(B73,1,9) -> NGCB08N60
A74: 195573 | B74: NGWR08M30T | D74: 0 | E74: 0 | F74: 0 | G74: 0 | H74: 0 | I74: 0 | J74: 0 | K74: Medium - 36° | L74: 3000K | M74: TRIAC Dimming | N74: 08 Watt | O74: White Reflector | P74: Round White Trim | R74: =MID(B74,1,10) -> NGWR08M30T
A75: 195574 | B75: NGWT08M30T | D75: 0 | E75: 0 | F75: 0 | G75: 0 | H75: 0 | I75: 0 | J75: 0 | K75: Medium - 36° | L75: 3000K | M75: TRIAC Dimming | N75: 08 Watt | O75: White Reflector | P75: Round White Trimless | R75: =MID(B75,1,10) -> NGWT08M30T
A76: 195575 | B76: NGWB08M30T | D76: 0 | E76: 0 | F76: 0 | G76: 0 | H76: 0 | I76: 0 | J76: 0 | K76: Medium - 36° | L76: 3000K | M76: TRIAC Dimming | N76: 08 Watt | O76: White Reflector | P76: Round Black Trim | R76: =MID(B76,1,10) -> NGWB08M30T
A77: 195576 | B77: NGWR08N30T | D77: 0 | E77: 0 | F77: 0 | G77: 0 | H77: 0 | I77: 0 | J77: 0 | K77: Narrow - 28° | L77: 3000K | M77: TRIAC Dimming | N77: 08 Watt | O77: White Reflector | P77: Round White Trim | R77: =MID(B77,1,10) -> NGWR08N30T
A78: 195577 | B78: NGWT08N30T | D78: 0 | E78: 0 | F78: 0 | G78: 0 | H78: 0 | I78: 0 | J78: 0 | K78: Narrow - 28° | L78: 3000K | M78: TRIAC Dimming | N78: 08 Watt | O78: White Reflector | P78: Round White Trimless | R78: =MID(B78,1,10) -> NGWT08N30T
A79: 195578 | B79: NGWB08N30T | D79: 0 | E79: 0 | F79: 0 | G79: 0 | H79: 0 | I79: 0 | J79: 0 | K79: Narrow - 28° | L79: 3000K | M79: TRIAC Dimming | N79: 08 Watt | O79: White Reflector | P79: Round Black Trim | R79: =MID(B79,1,10) -> NGWB08N30T
A80: 195579 | B80: NGWR08M40T | D80: 0 | E80: 0 | F80: 0 | G80: 0 | H80: 0 | I80: 0 | J80: 0 | K80: Medium - 36° | L80: 4000K | M80: TRIAC Dimming | N80: 08 Watt | O80: White Reflector | P80: Round White Trim | R80: =MID(B80,1,10) -> NGWR08M40T
A81: 195580 | B81: NGWT08M40T | D81: 0 | E81: 0 | F81: 0 | G81: 0 | H81: 0 | I81: 0 | J81: 0 | K81: Medium - 36° | L81: 4000K | M81: TRIAC Dimming | N81: 08 Watt | O81: White Reflector | P81: Round White Trimless | R81: =MID(B81,1,10) -> NGWT08M40T
A82: 195581 | B82: NGWB08M40T | D82: 0 | E82: 0 | F82: 0 | G82: 0 | H82: 0 | I82: 0 | J82: 0 | K82: Medium - 36° | L82: 4000K | M82: TRIAC Dimming | N82: 08 Watt | O82: White Reflector | P82: Round Black Trim | R82: =MID(B82,1,10) -> NGWB08M40T
A83: 195582 | B83: NGWR08N40T | D83: 0 | E83: 0 | F83: 0 | G83: 0 | H83: 0 | I83: 0 | J83: 0 | K83: Narrow - 28° | L83: 4000K | M83: TRIAC Dimming | N83: 08 Watt | O83: White Reflector | P83: Round White Trim | R83: =MID(B83,1,10) -> NGWR08N40T
A84: 195583 | B84: NGWT08N40T | D84: 0 | E84: 0 | F84: 0 | G84: 0 | H84: 0 | I84: 0 | J84: 0 | K84: Narrow - 28° | L84: 4000K | M84: TRIAC Dimming | N84: 08 Watt | O84: White Reflector | P84: Round White Trimless | R84: =MID(B84,1,10) -> NGWT08N40T
A85: 195584 | B85: NGWB08N40T | D85: 0 | E85: 0 | F85: 0 | G85: 0 | H85: 0 | I85: 0 | J85: 0 | K85: Narrow - 28° | L85: 4000K | M85: TRIAC Dimming | N85: 08 Watt | O85: White Reflector | P85: Round Black Trim | R85: =MID(B85,1,10) -> NGWB08N40T
... A217: 195758 | B217: NGCB08N60I | D217: 0 | E217: 0 | F217: 0 | G217: 0 | H217: 0 | I217: 0 | J217: 0 | K217: Narrow - 28° | L217: 6000k | M217: DALI Dimming - 48V DC | N217: 08 Watt | O217: Chrome Reflector | P217: Round Black Trim | R217: =MID(B217,1,10) -> NGCB08N60I
A218: 195765 | B218: NGWR08M30BT | D218: 0 | E218: 0 | F218: 0 | G218: 0 | H218: 0 | I218: 0 | J218: 0 | K218: Medium - 36° | L218: 3000K | M218: Bluetooth Dimming - 48V DC | N218: 08 Watt | O218: White Reflector | P218: Round White Trim | R218: =MID(B218,1,11) -> NGWR08M30BT
A219: 195766 | B219: NGWT08M30BT | D219: 0 | E219: 0 | F219: 0 | G219: 0 | H219: 0 | I219: 0 | J219: 0 | K219: Medium - 36° | L219: 3000K | M219: Bluetooth Dimming - 48V DC | N219: 08 Watt | O219: White Reflector | P219: Round White Trimless | R219: =MID(B219,1,11) -> NGWT08M30BT
A220: 195767 | B220: NGWB08M30BT | D220: 0 | E220: 0 | F220: 0 | G220: 0 | H220: 0 | I220: 0 | J220: 0 | K220: Medium - 36° | L220: 3000K | M220: Bluetooth Dimming - 48V DC | N220: 08 Watt | O220: White Reflector | P220: Round Black Trim | R220: =MID(B220,1,11) -> NGWB08M30BT
A221: 195768 | B221: NGWR08N30BT | D221: 0 | E221: 0 | F221: 0 | G221: 0 | H221: 0 | I221: 0 | J221: 0 | K221: Narrow - 28° | L221: 3000K | M221: Bluetooth Dimming - 48V DC | N221: 08 Watt | O221: White Reflector | P221: Round White Trim | R221: =MID(B221,1,11) -> NGWR08N30BT
A222: 195769 | B222: NGWT08N30BT | D222: 0 | E222: 0 | F222: 0 | G222: 0 | H222: 0 | I222: 0 | J222: 0 | K222: Narrow - 28° | L222: 3000K | M222: Bluetooth Dimming - 48V DC | N222: 08 Watt | O222: White Reflector | P222: Round White Trimless | R222: =MID(B222,1,11) -> NGWT08N30BT
A223: 195770 | B223: NGWB08N30BT | D223: 0 | E223: 0 | F223: 0 | G223: 0 | H223: 0 | I223: 0 | J223: 0 | K223: Narrow - 28° | L223: 3000K | M223: Bluetooth Dimming - 48V DC | N223: 08 Watt | O223: White Reflector | P223: Round Black Trim | R223: =MID(B223,1,11) -> NGWB08N30BT
A224: 195771 | B224: NGWR08M40BT | D224: 0 | E224: 0 | F224: 0 | G224: 0 | H224: 0 | I224: 0 | J224: 0 | K224: Medium - 36° | L224: 4000K | M224: Bluetooth Dimming - 48V DC | N224: 08 Watt | O224: White Reflector | P224: Round White Trim | R224: =MID(B224,1,11) -> NGWR08M40BT
A225: 195772 | B225: NGWT08M40BT | D225: 0 | E225: 0 | F225: 0 | G225: 0 | H225: 0 | I225: 0 | J225: 0 | K225: Medium - 36° | L225: 4000K | M225: Bluetooth Dimming - 48V DC | N225: 08 Watt | O225: White Reflector | P225: Round White Trimless | R225: =MID(B225,1,11) -> NGWT08M40BT
A226: 195773 | B226: NGWB08M40BT | D226: 0 | E226: 0 | F226: 0 | G226: 0 | H226: 0 | I226: 0 | J226: 0 | K226: Medium - 36° | L226: 4000K | M226: Bluetooth Dimming - 48V DC | N226: 08 Watt | O226: White Reflector | P226: Round Black Trim | R226: =MID(B226,1,11) -> NGWB08M40BT
A227: 195774 | B227: NGWR08N40BT | D227: 0 | E227: 0 | F227: 0 | G227: 0 | H227: 0 | I227: 0 | J227: 0 | K227: Narrow - 28° | L227: 4000K | M227: Bluetooth Dimming - 48V DC | N227: 08 Watt | O227: White Reflector | P227: Round White Trim | R227: =MID(B227,1,11) -> NGWR08N40BT
A228: 195775 | B228: NGWT08N40BT | D228: 0 | E228: 0 | F228: 0 | G228: 0 | H228: 0 | I228: 0 | J228: 0 | K228: Narrow - 28° | L228: 4000K | M228: Bluetooth Dimming - 48V DC | N228: 08 Watt | O228: White Reflector | P228: Round White Trimless | R228: =MID(B228,1,11) -> NGWT08N40BT
A229: 195776 | B229: NGWB08N40BT | D229: 0 | E229: 0 | F229: 0 | G229: 0 | H229: 0 | I229: 0 | J229: 0 | K229: Narrow - 28° | L229: 4000K | M229: Bluetooth Dimming - 48V DC | N229: 08 Watt | O229: White Reflector | P229: Round Black Trim | R229: =MID(B229,1,11) -> NGWB08N40BT
... A313: 195956 | B313: NGCB08N26ID | D313: 0 | E313: 0 | F313: 0 | G313: 0 | H313: 0 | I313: 0 | J313: 0 | K313: Narrow - 28° | L313: 2700K - 6000K Dual Color | M313: Dali + Dual Color (2700K - 6000K) | N313: 08 Watt | O313: Chrome Reflector | P313: Round Black Trim | R313: =MID(B313,1,11) -> NGCB08N26ID
...
