Workbook

Sheet Stock Item
A1: Name | B1: Group Name | C1: Units | D1: Name of BOM | E1: Unit of manufacture | F1: BOM Component - Item Name | G1: BOM Component - Quantity | H1: BOM Component - Godown | I1: BOM Component - Type of Item | J1: BOM Component - Rate (%) | K1: BOM Component - Location | L1: Unit Price | M1: Cost | N1: USD | O1: INS&FRED | P1: BCD | Q1: Total Cost
A2: =$D$2 -> NGWR18M30 | B2: Downlight Series | C2: Nos. | D2: NGWR18M30 | E2: 1 | F2: ='Backend data'!C6 -> Trim-O-82 I-66 H-33mm 3W White NGWR18W (OUCHI) | G2: 1 | H2: Mechanical Store | I2: Component | L2: =Q2*87 -> 0 | M2: =L2*G2 -> 0 | N2: 0 | O2: 0.5 | Q2: =N2+(N2*(O2+P2)) -> 0
F3: HS-62 I-58.8 H-53.8mm 3W NGWR18W (OUCHI) | G3: 1 | H3: Mechanical Store | I3: Component | L3: =Q3*87 -> 548.1 | M3: =L3*G3 -> 548.1 | N3: 4.2 | O3: 0.5 | Q3: =N3+(N3*(O3+P3)) -> 6.3
F4: ='Backend data'!E6 -> Refl-O-70 H-27 L-38mm 3W White-PC NGWR18W (OUCHI) | G4: 1 | H4: Mechanical Store | I4: Component | L4: =Q4*87 -> 0 | M4: =L4*G4 -> 0 | N4: 0 | O4: 0.5 | Q4: =N4+(N4*(O4+P4)) -> 0
F5: HS Ring R-O-57 I-29.2 H-22mm 3W NGWR18W (OUCHI) | G5: 1 | H5: Mechanical Store | I5: Component | L5: =Q5*87 -> 0 | M5: =L5*G5 -> 0 | N5: 0 | O5: 0.5 | Q5: =N5+(N5*(O5+P5)) -> 0
F6: Housing-O-66 I-41 H-42mm 3W NGWR18W (OUCHI) | G6: 1 | H6: Mechanical Store | I6: Component | L6: =Q6*87 -> 0 | M6: =L6*G6 -> 0 | N6: 0 | O6: 0.5 | Q6: =N6+(N6*(O6+P6)) -> 0
F7: Gasket-51X1.3mm 3W NGWR18W (OUCHI) | G7: 1 | H7: Mechanical Store | I7: Component | L7: =Q7*87 -> 0 | M7: =L7*G7 -> 0 | N7: 0 | O7: 0.5 | Q7: =N7+(N7*(O7+P7)) -> 0
F8: Refl. NGWR18W - 35016 - (Honghui) | G8: 1 | H8: Mechanical Store | I8: Component | L8: =Q8*87 -> 11.745 | M8: =L8*G8 -> 11.745 | N8: 0.09 | O8: 0.5 | Q8: =N8+(N8*(O8+P8)) -> 0.135
F9: Lens NGWR18W - 35016 - (Honghui) | G9: 1 | H9: Mechanical Store | I9: Component
F10: Diff-25.5x0.25mm-PS 3W NGWR18W (Honghui) | G10: 1 | H10: Mechanical Store | I10: Component
F11: COB Holder-O-34.7 H-5 L-17.5mm-PC NGWR18W (Honghui) | G11: 1 | H11: Mechanical Store | I11: Component
F12: PBX-L-124 W-120 H-120mm NGWR18W (OUCHI) | G12: 1 | H12: Mechanical Store | I12: Component | L12: =Q12*87 -> 0 | M12: =L12*G12 -> 0 | N12: 0 | O12: 0.5 | Q12: =N12+(N12*(O12+P12)) -> 0
F13: Screw M4x6.5 Coller Comb Head Philips | G13: 1 | H13: Mechanical Store | I13: Component | L13: =Q13*87 -> 0 | M13: =L13*G13 -> 0 | N13: 0 | O13: 0.5 | Q13: =N13+(N13*(O13+P13)) -> 0
F14: Screw-M3X6mm CSK + Head-SS | G14: 2 | H14: Mechanical Store | I14: Component | L14: 0.48 | M14: =L14*G14 -> 0.96 | N14: 0 | O14: 0.5 | Q14: =N14+(N14*(O14+P14)) -> 0
F15: Cable Gland-M8-SS - NGWR12 & NGWR18W | G15: 1 | H15: Mechanical Store | I15: Component | L15: =Q15*87 -> 0 | M15: =L15*G15 -> 0 | N15: 0 | O15: 0.5 | Q15: =N15+(N15*(O15+P15)) -> 0
F16: Conn. 2Pin Ass. Wire Black Male (Small) | G16: 1 | H16: Mechanical Store | I16: Component | L16: =Q16*87 -> 3.915 | M16: =L16*G16 -> 3.915 | N16: =0.06/2 -> 0.03 | O16: 0.5 | Q16: =N16+(N16*(O16+P16)) -> 0.045
F17: Sleeve M4mm Fiber Glass White | G17: 0.12 | H17: Mechanical Store | I17: Component | L17: =5.7/1000*120 -> 0.684 | M17: =L17*G17 -> 0.08208 | N17: 0 | O17: 0.5 | Q17: =N17+(N17*(O17+P17)) -> 0
F18: ='Backend data'!G6 -> COB 30-36W 3000K 12LED 34-38V 890mA 19x19mm L-17mm | G18: 1 | H18: Electronics Store | I18: Component | L18: =Q18*87 -> 84.825 | M18: =L18*G18 -> 84.825 | N18: 0.65 | O18: 0.5 | Q18: =N18+(N18*(O18+P18)) -> 0.975
F19: =VLOOKUP('[1]NGWR18W-DATA'!$X$6,'[1]NGWR18W-DATA'!$I$2:$J$6,2,0) -> PS 18W 440mA Maxic New Pcb | G19: 1 | H19: Electronics Store | I19: Component | L19: 0 | M19: =L19*G19 -> 0 | N19: PS Rate Mention with Total Amt
M20: =SUM(M2:M19) -> 649.62708
K22: NGWR18-CC | M22: =M20+98 -> 747.62708
K23: NGWR18 Dali Single Color | M23: =((M20)+(Q23*87)) -> 1393.4771 | N23: 5.7 | O23: 0.5 | Q23: =N23+(N23*(O23+P23)) -> 8.55 | R23: =Q23*87 -> 743.85
K24: NGWR18 BT Single Color | M24: =M20+330 -> 979.62708
K25: NGWR18 Dali Dual Color | M25: =((M20)+(Q25*87)) -> 1452.2021 | N25: 6.15 | O25: 0.5 | Q25: =N25+(N25*(O25+P25)) -> 9.225 | R25: =Q25*87 -> 802.575
K26: NGWR18 BT Dual Color | M26: =M20+330 -> 979.62708

Sheet Stock Item (Read Me)
A1: List of Fields | B1: Applicable Countries | C1: Applicable Values
A2: General Details
A3: Name | B3: All | E3: Read the following, before you start using the sample file:
A4: Group Name | B4: All | E4: Stock Item worksheet:
A5: B | B5: All | E5: - Use the worksheet without making any changes to the column headers to enter your business data. - The column headers represent field names in TallyPrime. Mandatory fields are marked in bold for easy reference. - Add new columns, if needed. Ensure to enter Column Headers exactly as mentioned under the List of Fields of the Read Me worksheet. - Delete unwanted columns. However, do not delete columns that represent mandatory fields for masters.
A6: Part No. | B6: All
A7: Alias - Part No. | B7: All
A8: Description | B8: All
A9: Notes | B9: All
A10: Category | B10: All
A11: Units | B11: All | E11: Stock Item (Read Me)
A12: Conversion | B12: All | E12: - The Read Me worksheet is only for your reference. It lists all the fields, with related details, applicable for Stock Item.
A13: Denominator | B13: All
A14: Alternate Units | B14: All | E14: For more information on using Sample Excel File for importing data, refer to | M14: TallyHelp
A15: GST Applicability | B15: All | C15: Applicable, Not Applicable
A16: Opening Balance - Quantity | B16: All
A17: Opening Balance - Rate | B17: All
A18: Opening Balance - Rate Per | B18: All
A19: Opening Balance - Value | B19: All
A20: Language for Name (Except English) | B20: All
A21: Is TCS Applicable | B21: All
A22: Item Allocations Details
A23: Item Allocations - Godown | B23: (When Accounting Terminology is set to "India/SAARC")
A24: Item Allocations - Batch | B24: All
A25: Item Allocations - Quantity | B25: All
A26: Item Allocations - Rate | B26: All
A27: Item Allocations - Rate per | B27: All
A28: Item Allocations - Amount | B28: All
A29: Item Allocations - Mfg. Date | B29: All
A30: Item Allocations - Expiry Date | B30: All
A31: Item Allocations - Location | B31: (When Accounting Terminology is set to "International")
A32: Additional Details
A33: Maintain in Batches | B33: All
A34: Track date of manufacturing | B34: All
A35: Use expiry dates | B35: All
A36: Enable Cost Tracking | B36: All
A37: Costing Method | B37: All | C37: At Zero Cost, Avg. Cost, FIFO, FIFO Perpetual, Last Purchase Cost, LIFO Annual, LIFO Perpetual, Monthly Avg. Cost, Std. Cost
A38: Market Valuation Method | B38: All | C38: At Zero Price, Avg. Price, Last Sale Price, Std. Price
A39: Behaviour
A40: Ignore difference due to physical counting | B40: All
...

Sheet Backend data
C2: TRIM | D2: HOUSING/HS | E2: REFLECTOR | F2: BEAM ANGLE | G2: COLOR TEMP | H2: DRIVING SYSTEM | I2: EXTRA
C3: =MID('Stock Item'!$D$2,4,1) -> R | D3: =MID('Stock Item'!$D$2,6,2) -> 8M | E3: =MID('Stock Item'!$D$2,3,1) -> W | F3: =MID('Stock Item'!$D$2,7,1) -> M | G3: =MID('Stock Item'!$D$2,8,2) -> 30 | H3: =MID('Stock Item'!$D$2,10,11) | I3: =MID('Stock Item'!$D$2,2,1) -> G
D4: =CONCATENATE($D$3,$F$3) -> 8MM | G4: =CONCATENATE($G$3,$H$4) -> 30- | H4: =CONCATENATE($H$3,"-") -> -
H5: =CONCATENATE('Stock Item'!D2) -> NGWR18M30
B6: Formulae | C6: =VLOOKUP($C$3,$B$23:$E$72,2,0) -> Trim-O-82 I-66 H-33mm 3W White NGWR18W (OUCHI) | D6: =VLOOKUP($D$4,G23:$J$100,2,0) -> #N/A | E6: =VLOOKUP($E$3,$L$23:$O$72,2,0) -> Refl-O-70 H-27 L-38mm 3W White-PC NGWR18W (OUCHI) | F6: =VLOOKUP($F$3,$Q$23:$T$72,2,0) -> #N/A | G6: =VLOOKUP($G$4,$V$23:$Y$72,2,0) -> COB 30-36W 3000K 12LED 34-38V 890mA 19x19mm L-17mm | H6: =VLOOKUP($H$4,$AA$23:$AD$72,2,0) -> PS 18W 440mA Maxic New Pcb | I6: =VLOOKUP($I$3,AF23:$AI$100,2,0) -> #N/A
B7: Formulae for COST | C7: =VLOOKUP($C$3,$B$23:$E$72,4,0) -> 0 | D7: =VLOOKUP($D$4,G23:$J$100,4,0) -> #N/A | E7: =VLOOKUP($E$3,$L$23:$O$72,4,0) -> 0 | F7: =VLOOKUP($F$3,$Q$23:$T$72,4,0) -> #N/A | G7: =VLOOKUP($G$4,$V$23:$Y$72,4,0) -> 0 | H7: =VLOOKUP($H$4,$AA$23:$AD$72,4,0) -> 0 | I7: =VLOOKUP($I$3,$AF$23:$AI$100,4,0) -> #N/A
B8: Formulae for Quantity | C8: =VLOOKUP($C$3,$B$23:$E$72,3,0) -> 0 | D8: =VLOOKUP($D$4,G23:$J$100,3,0) -> #N/A | E8: =VLOOKUP($E$3,$L$23:$O$72,3,0) -> 0 | F8: =VLOOKUP($F$3,$Q$23:$T$72,3,0) -> #N/A | G8: =VLOOKUP($G$4,$V$23:$Y$72,3,0) -> 0 | H8: =VLOOKUP($H$4,$AA$23:$AD$72,3,0) -> 0 | I8: =VLOOKUP($I$3,$AF$23:$AI$100,3,0) -> #N/A
H10: BOM LED PCB
B21: TRIM | G21: HOUSING/HS | L21: REFLECTOR | Q21: BEAM ANGLE | V21: COLOR TEMPERATURE | AA21: DRIVING SYSTEM | AF21: EXTRA
B22: Code | C22: Item Name | D22: Quantity | E22: Cost | G22: Code | H22: Item Name | I22: Quantity | J22: Cost | L22: Code | M22: Item Name | N22: Quantity | O22: Cost | Q22: Code | R22: Item Name | S22: Quantity | T22: Cost | V22: Code | W22: Item Name | X22: Quantity | Y22: Cost | AA22: Code | AB22: Item Name | AC22: Quantity | AD22: Cost | AF22: Code | AG22: Item Name | AH22: Quantity | AI22: Cost
B23: R | C23: Trim-O-82 I-66 H-33mm 3W White NGWR18W (OUCHI) | L23: W | M23: Refl-O-70 H-27 L-38mm 3W White-PC NGWR18W (OUCHI) | V23: 30- | W23: COB 30-36W 3000K 12LED 34-38V 890mA 19x19mm L-17mm | AA23: - | AB23: PS 18W 440mA Maxic New Pcb
B24: B | C24: Trim-O-82 I-66 H-33mm 3W Black NGWR18W (OUCHI) | L24: B | M24: Refl-O-70 H-27 L-38mm 3W Black-PC NGWR18W (OUCHI) | V24: 40- | W24: COB 30-36W 4000K 12LED 34-38V 890mA 19x19mm L-17mm | AA24: I- | AB24: PS 18W 450MA 36V DALI SINGLE COLOUR
B25: T | C25: Trimless Trim-O-107 I-66 H-33mm 3W White NGWR18W (OUCHI) | L25: A | M25: Refl-O-70 H-27 L-38mm 3W Alloy Black-PC NGWR18W (OUCHI) | V25: 60- | W25: COB 30-36W 6000K 12LED 34-38V 890mA 19x19mm L-17mm | AA25: BT- | AB25: PS 18W 400MA 36V BT SINGLE COLOUR
L26: C | M26: Refl-O-70 H-27 L-38mm 3W Chrome-PC NGWR18W (OUCHI) | AA26: ID- | AB26: PS 18W440mA 36V Dali Dual Colour
V27: 30BT- | W27: COB 30-36W 3000K 12LED 34-38V 890mA 19x19mm L-17mm | AA27: BTD- | AB27: PS 18W 400MA 36V BT DUAL COLOUR
V28: 40BT- | W28: COB 30-36W 4000K 12LED 34-38V 890mA 19x19mm L-17mm
V29: 60BT- | W29: COB 30-36W 6000K 12LED 34-38V 890mA 19x19mm L-17mm
V30: 26BTD- | W30: COB-30-36W 2700-6000K 12LED 34-38V 2X640mA 19x19mm L-17mm- (BT+DC)
V32: 30I- | W32: COB 30-36W 3000K 12LED 34-38V 890mA 19x19mm L-17mm
V33: 40I- | W33: COB 30-36W 4000K 12LED 34-38V 890mA 19x19mm L-17mm
V34: 60I- | W34: COB 30-36W 6000K 12LED 34-38V 890mA 19x19mm L-17mm
V35: 26ID- | W35: COB-30-36W 2700-6000K 12LED 34-38V 2X640mA 19x19mm L-17mm- (DALI+DC)

Sheet NGWR18W-SKU
A1: SKU Id | B1: SKU Code | C1: Product Name | D1: Cost Price | E1: Retail Price | F1: Selling Price | G1: Weight | H1: Width | I1: Height | J1: Depth | K1: Beam Angle | L1: Color Temp | M1: Driving System | N1: Input Power | O1: Reflector | P1: Trim
A2: 186845 | B2: NGR18WRM30- | C2: =CONCATENATE(R2,S2,T2,U2,V2) -> NGWR18M30 | D2: =VLOOKUP(C2,'[1]NGWR18W-DATA'!$AC$3:$AD$3,2,0) -> #N/A | E2: 0 | F2: 0 | G2: 0 | H2: 0 | I2: 0 | J2: 0 | K2: Medium - 32° | L2: 3000K | M2: Constant Current | N2: 18 Watt | O2: White Reflector | P2: Round White Trim | R2: =MID(B2,1,2) -> NG | S2: =MID(B2,6,2) -> WR | T2: =MID(B2,4,2) -> 18 | U2: =MID(B2,8,1) -> M | V2: =MID(B2,9,2) -> 30
A3: 186846 | B3: NGR18WTM30- | C3: =CONCATENATE(R3,S3,T3,U3,V3) -> NGWT18M30 | D3: =VLOOKUP(C3,'[1]NGWR18W-DATA'!$AC$3:$AD$3,2,0) -> #N/A | E3: 0 | F3: 0 | G3: 0 | H3: 0 | I3: 0 | J3: 0 | K3: Medium - 32° | L3: 3000K | M3: Constant Current | N3: 18 Watt | O3: White Reflector | P3: Round White Trimless | R3: =MID(B3,1,2) -> NG | S3: =MID(B3,6,2) -> WT | T3: =MID(B3,4,2) -> 18 | U3: =MID(B3,8,1) -> M | V3: =MID(B3,9,2) -> 30
A4: 186847 | B4: NGR18WBM30- | C4: =CONCATENATE(R4,S4,T4,U4,V4) -> NGWB18M30 | D4: =VLOOKUP(C4,'[1]NGWR18W-DATA'!$AC$3:$AD$3,2,0) -> #N/A | E4: 0 | F4: 0 | G4: 0 | H4: 0 | I4: 0 | J4: 0 | K4: Medium - 32° | L4: 3000K | M4: Constant Current | N4: 18 Watt | O4: White Reflector | P4: Round Black Trim | R4: =MID(B4,1,2) -> NG | S4: =MID(B4,6,2) -> WB | T4: =MID(B4,4,2) -> 18 | U4: =MID(B4,8,1) -> M | V4: =MID(B4,9,2) -> 30
A5: 186848 | B5: NGR18WRM40- | C5: =CONCATENATE(R5,S5,T5,U5,V5) -> NGWR18M40 | D5: =VLOOKUP(C5,'[1]NGWR18W-DATA'!$AC$3:$AD$3,2,0) -> #N/A | E5: 0 | F5: 0 | G5: 0 | H5: 0 | I5: 0 | J5: 0 | K5: Medium - 32° | L5: 4000K | M5: Constant Current | N5: 18 Watt | O5: White Reflector | P5: Round White Trim | R5: =MID(B5,1,2) -> NG | S5: =MID(B5,6,2) -> WR | T5: =MID(B5,4,2) -> 18 | U5: =MID(B5,8,1) -> M | V5: =MID(B5,9,2) -> 40
A6: 186849 | B6: NGR18WTM40- | C6: =CONCATENATE(R6,S6,T6,U6,V6) -> NGWT18M40 | D6: =VLOOKUP(C6,'[1]NGWR18W-DATA'!$AC$3:$AD$3,2,0) -> #N/A | E6: 0 | F6: 0 | G6: 0 | H6: 0 | I6: 0 | J6: 0 | K6: Medium - 32° | L6: 4000K | M6: Constant Current | N6: 18 Watt | O6: White Reflector | P6: Round White Trimless | R6: =MID(B6,1,2) -> NG | S6: =MID(B6,6,2) -> WT | T6: =MID(B6,4,2) -> 18 | U6: =MID(B6,8,1) -> M | V6: =MID(B6,9,2) -> 40
A7: 186850 | B7: NGR18WBM40- | C7: =CONCATENATE(R7,S7,T7,U7,V7) -> NGWB18M40 | D7: =VLOOKUP(C7,'[1]NGWR18W-DATA'!$AC$3:$AD$3,2,0) -> #N/A | E7: 0 | F7: 0 | G7: 0 | H7: 0 | I7: 0 | J7: 0 | K7: Medium - 32° | L7: 4000K | M7: Constant Current | N7: 18 Watt | O7: White Reflector | P7: Round Black Trim | R7: =MID(B7,1,2) -> NG | S7: =MID(B7,6,2) -> WB | T7: =MID(B7,4,2) -> 18 | U7: =MID(B7,8,1) -> M | V7: =MID(B7,9,2) -> 40
A8: 186851 | B8: NGR18WRM60- | C8: =CONCATENATE(R8,S8,T8,U8,V8) -> NGWR18M60 | D8: =VLOOKUP(C8,'[1]NGWR18W-DATA'!$AC$3:$AD$3,2,0) -> #N/A | E8: 0 | F8: 0 | G8: 0 | H8: 0 | I8: 0 | J8: 0 | K8: Medium - 32° | L8: 6000k | M8: Constant Current | N8: 18 Watt | O8: White Reflector | P8: Round White Trim | R8: =MID(B8,1,2) -> NG | S8: =MID(B8,6,2) -> WR | T8: =MID(B8,4,2) -> 18 | U8: =MID(B8,8,1) -> M | V8: =MID(B8,9,2) -> 60
A9: 186852 | B9: NGR18WTM60- | C9: =CONCATENATE(R9,S9,T9,U9,V9) -> NGWT18M60 | D9: =VLOOKUP(C9,'[1]NGWR18W-DATA'!$AC$3:$AD$3,2,0) -> #N/A | E9: 0 | F9: 0 | G9: 0 | H9: 0 | I9: 0 | J9: 0 | K9: Medium - 32° | L9: 6000k | M9: Constant Current | N9: 18 Watt | O9: White Reflector | P9: Round White Trimless | R9: =MID(B9,1,2) -> NG | S9: =MID(B9,6,2) -> WT | T9: =MID(B9,4,2) -> 18 | U9: =MID(B9,8,1) -> M | V9: =MID(B9,9,2) -> 60
A10: 186853 | B10: NGR18WBM60- | C10: =CONCATENATE(R10,S10,T10,U10,V10) -> NGWB18M60 | D10: =VLOOKUP(C10,'[1]NGWR18W-DATA'!$AC$3:$AD$3,2,0) -> #N/A | E10: 0 | F10: 0 | G10: 0 | H10: 0 | I10: 0 | J10: 0 | K10: Medium - 32° | L10: 6000k | M10: Constant Current | N10: 18 Watt | O10: White Reflector | P10: Round Black Trim | R10: =MID(B10,1,2) -> NG | S10: =MID(B10,6,2) -> WB | T10: =MID(B10,4,2) -> 18 | U10: =MID(B10,8,1) -> M | V10: =MID(B10,9,2) -> 60
A11: 186863 | B11: NGR18BRM30- | C11: =CONCATENATE(R11,S11,T11,U11,V11) -> NGBR18M30 | D11: =VLOOKUP(C11,'[1]NGWR18W-DATA'!$AC$3:$AD$3,2,0) -> #N/A | E11: 0 | F11: 0 | G11: 0 | H11: 0 | I11: 0 | J11: 0 | K11: Medium - 32° | L11: 3000K | M11: Constant Current | N11: 18 Watt | O11: Black Reflector | P11: Round White Trim | R11: =MID(B11,1,2) -> NG | S11: =MID(B11,6,2) -> BR | T11: =MID(B11,4,2) -> 18 | U11: =MID(B11,8,1) -> M | V11: =MID(B11,9,2) -> 30
A12: 186864 | B12: NGR18BTM30- | C12: =CONCATENATE(R12,S12,T12,U12,V12) -> NGBT18M30 | D12: =VLOOKUP(C12,'[1]NGWR18W-DATA'!$AC$3:$AD$3,2,0) -> #N/A | E12: 0 | F12: 0 | G12: 0 | H12: 0 | I12: 0 | J12: 0 | K12: Medium - 32° | L12: 3000K | M12: Constant Current | N12: 18 Watt | O12: Black Reflector | P12: Round White Trimless | R12: =MID(B12,1,2) -> NG | S12: =MID(B12,6,2) -> BT | T12: =MID(B12,4,2) -> 18 | U12: =MID(B12,8,1) -> M | V12: =MID(B12,9,2) -> 30
A13: 186865 | B13: NGR18BBM30- | C13: =CONCATENATE(R13,S13,T13,U13,V13) -> NGBB18M30 | D13: =VLOOKUP(C13,'[1]NGWR18W-DATA'!$AC$3:$AD$3,2,0) -> #N/A | E13: 0 | F13: 0 | G13: 0 | H13: 0 | I13: 0 | J13: 0 | K13: Medium - 32° | L13: 3000K | M13: Constant Current | N13: 18 Watt | O13: Black Reflector | P13: Round Black Trim | R13: =MID(B13,1,2) -> NG | S13: =MID(B13,6,2) -> BB | T13: =MID(B13,4,2) -> 18 | U13: =MID(B13,8,1) -> M | V13: =MID(B13,9,2) -> 30
... A37: 186907 | B37: NGR18CBM60- | C37: =CONCATENATE(R37,S37,T37,U37,V37) -> NGCB18M60 | D37: =VLOOKUP(C37,'[1]NGWR18W-DATA'!$AC$3:$AD$3,2,0) -> #N/A | E37: 0 | F37: 0 | G37: 0 | H37: 0 | I37: 0 | J37: 0 | K37: Medium - 32° | L37: 6000k | M37: Constant Current | N37: 18 Watt | O37: Chrome Reflector | P37: Round Black Trim | R37: =MID(B37,1,2) -> NG | S37: =MID(B37,6,2) -> CB | T37: =MID(B37,4,2) -> 18 | U37: =MID(B37,8,1) -> M | V37: =MID(B37,9,2) -> 60
A38: 186989 | B38: NGR18WRM30I | C38: =CONCATENATE(R38,S38,T38,U38,V38) -> NGWR18M30I | D38: =VLOOKUP(C38,'[1]NGWR18W-DATA'!$AC$3:$AD$3,2,0) -> #N/A | E38: 0 | F38: 0 | G38: 0 | H38: 0 | I38: 0 | J38: 0 | K38: Medium - 32° | L38: 3000K | M38: DALI Dimming - 48V DC | N38: 18 Watt | O38: White Reflector | P38: Round White Trim | R38: =MID(B38,1,2) -> NG | S38: =MID(B38,6,2) -> WR | T38: =MID(B38,4,2) -> 18 | U38: =MID(B38,8,1) -> M | V38: =MID(B38,9,5) -> 30I
A39: 186990 | B39: NGR18WTM30I | C39: =CONCATENATE(R39,S39,T39,U39,V39) -> NGWT18M30I | D39: =VLOOKUP(C39,'[1]NGWR18W-DATA'!$AC$3:$AD$3,2,0) -> #N/A | E39: 0 | F39: 0 | G39: 0 | H39: 0 | I39: 0 | J39: 0 | K39: Medium - 32° | L39: 3000K | M39: DALI Dimming - 48V DC | N39: 18 Watt | O39: White Reflector | P39: Round White Trimless | R39: =MID(B39,1,2) -> NG | S39: =MID(B39,6,2) -> WT | T39: =MID(B39,4,2) -> 18 | U39: =MID(B39,8,1) -> M | V39: =MID(B39,9,5) -> 30I
A40: 186991 | B40: NGR18WBM30I | C40: =CONCATENATE(R40,S40,T40,U40,V40) -> NGWB18M30I | D40: =VLOOKUP(C40,'[1]NGWR18W-DATA'!$AC$3:$AD$3,2,0) -> #N/A | E40: 0 | F40: 0 | G40: 0 | H40: 0 | I40: 0 | J40: 0 | K40: Medium - 32° | L40: 3000K | M40: DALI Dimming - 48V DC | N40: 18 Watt | O40: White Reflector | P40: Round Black Trim | R40: =MID(B40,1,2) -> NG | S40: =MID(B40,6,2) -> WB | T40: =MID(B40,4,2) -> 18 | U40: =MID(B40,8,1) -> M | V40: =MID(B40,9,5) -> 30I
A41: 186992 | B41: NGR18WRM40I | C41: =CONCATENATE(R41,S41,T41,U41,V41) -> NGWR18M40I | D41: =VLOOKUP(C41,'[1]NGWR18W-DATA'!$AC$3:$AD$3,2,0) -> #N/A | E41: 0 | F41: 0 | G41: 0 | H41: 0 | I41: 0 | J41: 0 | K41: Medium - 32° | L41: 4000K | M41: DALI Dimming - 48V DC | N41: 18 Watt | O41: White Reflector | P41: Round White Trim | R41: =MID(B41,1,2) -> NG | S41: =MID(B41,6,2) -> WR | T41: =MID(B41,4,2) -> 18 | U41: =MID(B41,8,1) -> M | V41: =MID(B41,9,5) -> 40I
A42: 186993 | B42: NGR18WTM40I | C42: =CONCATENATE(R42,S42,T42,U42,V42) -> NGWT18M40I | D42: =VLOOKUP(C42,'[1]NGWR18W-DATA'!$AC$3:$AD$3,2,0) -> #N/A | E42: 0 | F42: 0 | G42: 0 | H42: 0 | I42: 0 | J42: 0 | K42: Medium - 32° | L42: 4000K | M42: DALI Dimming - 48V DC | N42: 18 Watt | O42: White Reflector | P42: Round White Trimless | R42: =MID(B42,1,2) -> NG | S42: =MID(B42,6,2) -> WT | T42: =MID(B42,4,2) -> 18 | U42: =MID(B42,8,1) -> M | V42: =MID(B42,9,5) -> 40I
A43: 186994 | B43: NGR18WBM40I | C43: =CONCATENATE(R43,S43,T43,U43,V43) -> NGWB18M40I | D43: =VLOOKUP(C43,'[1]NGWR18W-DATA'!$AC$3:$AD$3,2,0) -> #N/A | E43: 0 | F43: 0 | G43: 0 | H43: 0 | I43: 0 | J43: 0 | K43: Medium - 32° | L43: 4000K | M43: DALI Dimming - 48V DC | N43: 18 Watt | O43: White Reflector | P43: Round Black Trim | R43: =MID(B43,1,2) -> NG | S43: =MID(B43,6,2) -> WB | T43: =MID(B43,4,2) -> 18 | U43: =MID(B43,8,1) -> M | V43: =MID(B43,9,5) -> 40I
A44: 186995 | B44: NGR18WRM60I | C44: =CONCATENATE(R44,S44,T44,U44,V44) -> NGWR18M60I | D44: =VLOOKUP(C44,'[1]NGWR18W-DATA'!$AC$3:$AD$3,2,0) -> #N/A | E44: 0 | F44: 0 | G44: 0 | H44: 0 | I44: 0 | J44: 0 | K44: Medium - 32° | L44: 6000k | M44: DALI Dimming - 48V DC | N44: 18 Watt | O44: White Reflector | P44: Round White Trim | R44: =MID(B44,1,2) -> NG | S44: =MID(B44,6,2) -> WR | T44: =MID(B44,4,2) -> 18 | U44: =MID(B44,8,1) -> M | V44: =MID(B44,9,5) -> 60I
A45: 186996 | B45: NGR18WTM60I | C45: =CONCATENATE(R45,S45,T45,U45,V45) -> NGWT18M60I | D45: =VLOOKUP(C45,'[1]NGWR18W-DATA'!$AC$3:$AD$3,2,0) -> #N/A | E45: 0 | F45: 0 | G45: 0 | H45: 0 | I45: 0 | J45: 0 | K45: Medium - 32° | L45: 6000k | M45: DALI Dimming - 48V DC | N45: 18 Watt | O45: White Reflector | P45: Round White Trimless | R45: =MID(B45,1,2) -> NG | S45: =MID(B45,6,2) -> WT | T45: =MID(B45,4,2) -> 18 | U45: =MID(B45,8,1) -> M | V45: =MID(B45,9,5) -> 60I
A46: 186997 | B46: NGR18WBM60I | C46: =CONCATENATE(R46,S46,T46,U46,V46) -> NGWB18M60I | D46: =VLOOKUP(C46,'[1]NGWR18W-DATA'!$AC$3:$AD$3,2,0) -> #N/A | E46: 0 | F46: 0 | G46: 0 | H46: 0 | I46: 0 | J46: 0 | K46: Medium - 32° | L46: 6000k | M46: DALI Dimming - 48V DC | N46: 18 Watt | O46: White Reflector | P46: Round Black Trim | R46: =MID(B46,1,2) -> NG | S46: =MID(B46,6,2) -> WB | T46: =MID(B46,4,2) -> 18 | U46: =MID(B46,8,1) -> M | V46: =MID(B46,9,5) -> 60I
A47: 187007 | B47: NGR18BRM30I | C47: =CONCATENATE(R47,S47,T47,U47,V47) -> NGBR18M30I | D47: =VLOOKUP(C47,'[1]NGWR18W-DATA'!$AC$3:$AD$3,2,0) -> #N/A | E47: 0 | F47: 0 | G47: 0 | H47: 0 | I47: 0 | J47: 0 | K47: Medium - 32° | L47: 3000K | M47: DALI Dimming - 48V DC | N47: 18 Watt | O47: Black Reflector | P47: Round White Trim | R47: =MID(B47,1,2) -> NG | S47: =MID(B47,6,2) -> BR | T47: =MID(B47,4,2) -> 18 | U47: =MID(B47,8,1) -> M | V47: =MID(B47,9,5) -> 30I
A48: 187008 | B48: NGR18BTM30I | C48: =CONCATENATE(R48,S48,T48,U48,V48) -> NGBT18M30I | D48: =VLOOKUP(C48,'[1]NGWR18W-DATA'!$AC$3:$AD$3,2,0) -> #N/A | E48: 0 | F48: 0 | G48: 0 | H48: 0 | I48: 0 | J48: 0 | K48: Medium - 32° | L48: 3000K | M48: DALI Dimming - 48V DC | N48: 18 Watt | O48: Black Reflector | P48: Round White Trimless | R48: =MID(B48,1,2) -> NG | S48: =MID(B48,6,2) -> BT | T48: =MID(B48,4,2) -> 18 | U48: =MID(B48,8,1) -> M | V48: =MID(B48,9,5) -> 30I
A49: 187009 | B49: NGR18BBM30I | C49: =CONCATENATE(R49,S49,T49,U49,V49) -> NGBB18M30I | D49: =VLOOKUP(C49,'[1]NGWR18W-DATA'!$AC$3:$AD$3,2,0) -> #N/A | E49: 0 | F49: 0 | G49: 0 | H49: 0 | I49: 0 | J49: 0 | K49: Medium - 32° | L49: 3000K | M49: DALI Dimming - 48V DC | N49: 18 Watt | O49: Black Reflector | P49: Round Black Trim | R49: =MID(B49,1,2) -> NG | S49: =MID(B49,6,2) -> BB | T49: =MID(B49,4,2) -> 18 | U49: =MID(B49,8,1) -> M | V49: =MID(B49,9,5) -> 30I
... A133: 187348 | B133: NGR18CBM26BTD | C133: =CONCATENATE(R133,S133,T133,U133,V133) -> NGCB18M26BTD | D133: =VLOOKUP(C133,'[1]NGWR18W-DATA'!$AC$3:$AD$3,2,0) -> #N/A | E133: 0 | F133: 0 | G133: 0 | H133: 0 | I133: 0 | J133: 0 | K133: Medium - 32° | L133: 2700K - 6000K Bluetooth + Dual Color (Driving System) | M133: Bluetooth + Dual Color (2700K - 6000K) | N133: 18 Watt | O133: Chrome Reflector | P133: Round Black Trim | R133: =MID(B133,1,2) -> NG | S133: =MID(B133,6,2) -> CB | T133: =MID(B133,4,2) -> 18 | U133: =MID(B133,8,1) -> M | V133: =MID(B133,9,5) -> 26BTD
