Workbook

Sheet Stock Item
A1: Name | B1: Group Name | C1: Units | D1: Name of BOM | E1: Unit of manufacture | F1: BOM Component - Item Name | G1: BOM Component - Quantity | H1: BOM Component - Godown | I1: BOM Component - Type of Item | J1: BOM Component - Rate (%) | K1: BOM Component - Location | L1: Unit Price | M1: Cost | N1: USD | O1: INS&FRED | P1: BCD | Q1: Total Cost
A2: =$D$2 -> NGWB05N30I | B2: Down Light Series | C2: Nos. | D2: NGWB05N30I | E2: 1 | F2: ='Backend data'!C6 -> Trim-O-39 I-27 H-22.6mm 0.3W Black NGWR5W (OUCHI) | G2: 1 | H2: Mechanical Store | I2: Component | L2: =Q2*87 -> 376.362 | M2: =L2*G2 -> 376.362 | N2: 2.884 | O2: 0.5 | Q2: =N2+(N2*(O2+P2)) -> 4.326
F3: HS-O-26 I-22 H-67mm 0.3W NGWR5W (OUCHI) | G3: 1 | H3: Mechanical Store | I3: Component
F4: ='Backend data'!E6 -> Refl-O-29.3 H-13 L-13mm 0.3W White NGWR5W (OUCHI) | G4: 1 | H4: Mechanical Store | I4: Component
F5: Diff-16.5x0.25mm-PS 0.3W NGWR5W (OUCHI) | G5: 1 | H5: Mechanical Store | I5: Component
F6: ='Backend data'!F6 -> Lens-O-16 H-10.4 L-3.4mm 15°-PC 0.3W NGWR5W (OUCHI) | G6: 1 | H6: Mechanical Store | I6: Component
F7: Housing-O-27.5 I-16.6 H-39mm 0.3W NGWR5W (OUCHI) | G7: 1 | H7: Mechanical Store | I7: Component
F8: Gasket-21x1.3mm 0.3W NGWR5W (OUCHI) | G8: 1 | H8: Mechanical Store | I8: Component
F9: PBX-L-77 W-58 H-120mm NGWR5W (OUCHI) | G9: 1 | H9: Mechanical Store | I9: Component
F10: SBX | G10: 0.08 | H10: Mechanical Store | I10: Component
F11: Screw-M3X4mm Allen Grub-MS | G11: 1 | H11: Mechanical Store | I11: Component
F12: Screw-M3X4mm CSK + Head-MS | G12: 2 | H12: Mechanical Store | I12: Component
F13: Conn. 2Pin Ass. Wire Black Male (Small) | G13: 1 | H13: Mechanical Store | I13: Component | L13: =Q13*87 -> 3.915 | M13: =L13*G13 -> 3.915 | N13: =0.06/2 -> 0.03 | O13: 0.5 | Q13: =N13+(N13*(O13+P13)) -> 0.045
F14: Sleeve M4mm Fiber Glass White | G14: 0.12 | H14: Mechanical Store | I14: Component | L14: =5.7/1000*120 -> 0.684 | M14: =L14*G14 -> 0.08208
F15: =CONCATENATE(D17) -> NGWB05N30I BOM LED PCB | G15: 1 | H15: SMD Department | I15: Component | L15: 0 | M15: =L15*G15 -> 0
F16: ='Backend data'!H6 -> PS 4W 300mA 12V Dali Magnetic Single Colour | G16: 1 | H16: Electronic Assembling Dep. | I16: Component | L16: 0 | M16: =L16*G16 -> 0 | N16: PS Rate Mention with Total Amt
A17: =CONCATENATE(D17) -> NGWB05N30I BOM LED PCB | B17: Down Light Series | C17: Nos | D17: =CONCATENATE('Backend data'!G5," ",'Backend data'!G10) -> NGWB05N30I BOM LED PCB | F17: PCB FS-OG TH-149 - 0.3W - NGRR6W (OUCHI) | G17: 1 | H17: Electronics Store | I17: Component | L17: 0 | M17: =L17*G17 -> 0 | N17: PCB Rate Including in Fitting
F18: ='Backend data'!G6 -> LED SMD 3535 12V 350MA 3000K | G18: 1 | H18: Electronics Store | I18: Component | L18: =Q18*87 -> 28.0575 | M18: =L18*G18 -> 28.0575 | N18: =0.215 -> 0.215 | O18: 0.5 | Q18: =N18+(N18*(O18+P18)) -> 0.3225
M19: =SUM(M2:M18) -> 408.41658
K21: NGWR05-CC | M21: =M19+24 -> 432.41658
K22: NGWR05-DALI - 24V | M22: =((M19)+(Q22*86)) -> 923.51358 | N22: 3.993 | O22: 0.5 | Q22: =N22+(N22*(O22+P22)) -> 5.9895
K23: NGWR05-BT - 24V | M23: =((M19)+(Q23*86)) -> 737.23758 | N23: 2.549 | O23: 0.5 | Q23: =N23+(N23*(O23+P23)) -> 3.8235

Sheet Stock Item (Read Me)
A1: List of Fields | B1: Applicable Countries | C1: Applicable Values
A2: General Details
A3: Name | B3: All | E3: Read the following, before you start using the sample file:
A4: Group Name | B4: All | E4: Stock Item worksheet:
A5: B | B5: All | E5: - Use the worksheet without making any changes to the column headers to enter your business data. - The column headers represent field names in TallyPrime. Mandatory fields are marked in bold for easy reference. - Add new columns, if needed. Ensure to enter Column Headers exactly as mentioned under the List of Fields of the Read Me worksheet. - Delete unwanted columns. However, do not delete columns that represent mandatory fields for masters.
A6: Part No. | B6: All
A7: Alias - Part No. | B7: All
A8: Description | B8: All
A9: Notes | B9: All
A10: Category | B10: All
A11: Units | B11: All | E11: Stock Item (Read Me)
A12: Conversion | B12: All | E12: - The Read Me worksheet is only for your reference. It lists all the fields, with related details, applicable for Stock Item.
A13: Denominator | B13: All
A14: Alternate Units | B14: All | E14: For more information on using Sample Excel File for importing data, refer to | M14: TallyHelp
A15: GST Applicability | B15: All | C15: Applicable, Not Applicable
A16: Opening Balance - Quantity | B16: All
A17: Opening Balance - Rate | B17: All
A18: Opening Balance - Rate Per | B18: All
A19: Opening Balance - Value | B19: All
A20: Language for Name (Except English) | B20: All
A21: Is TCS Applicable | B21: All
A22: Item Allocations Details
A23: Item Allocations - Godown | B23: (When Accounting Terminology is set to "India/SAARC")
A24: Item Allocations - Batch | B24: All
A25: Item Allocations - Quantity | B25: All
A26: Item Allocations - Rate | B26: All
A27: Item Allocations - Rate per | B27: All
A28: Item Allocations - Amount | B28: All
A29: Item Allocations - Mfg. Date | B29: All
A30: Item Allocations - Expiry Date | B30: All
A31: Item Allocations - Location | B31: (When Accounting Terminology is set to "International")
A32: Additional Details
A33: Maintain in Batches | B33: All
A34: Track date of manufacturing | B34: All
A35: Use expiry dates | B35: All
A36: Enable Cost Tracking | B36: All
A37: Costing Method | B37: All | C37: At Zero Cost, Avg. Cost, FIFO, FIFO Perpetual, Last Purchase Cost, LIFO Annual, LIFO Perpetual, Monthly Avg. Cost, Std. Cost
A38: Market Valuation Method | B38: All | C38: At Zero Price, Avg. Price, Last Sale Price, Std. Price
A39: Behaviour
A40: Ignore difference due to physical counting | B40: All
...

Sheet Backend data
C2: TRIM | D2: HOUSING/HS | E2: REFLECTOR | F2: BEAM ANGLE | G2: COLOR TEMP | H2: DRIVING SYSTEM | I2: EXTRA
C3: =MID('Stock Item'!$D$2,4,1) -> B | D3: =MID('Stock Item'!$D$2,6,1) -> 5 | E3: =MID('Stock Item'!$D$2,3,1) -> W | F3: =MID('Stock Item'!$D$2,5,3) -> 05N | G3: =MID('Stock Item'!$D$2,8,4) -> 30I | H3: =MID('Stock Item'!$D$2,10,10) -> I | I3: =MID('Stock Item'!$D$2,2,1) -> G
D4: =CONCATENATE(F3) -> 05N | G4: =CONCATENATE(G3,"-") -> 30I- | H4: =CONCATENATE($H$3,"-") -> I-
G5: =CONCATENATE('Stock Item'!D2) -> NGWB05N30I
B6: Formulae | C6: =VLOOKUP($C$3,$B$23:$E$72,2,0) -> Trim-O-39 I-27 H-22.6mm 0.3W Black NGWR5W (OUCHI) | D6: =VLOOKUP($D$4,G23:$J$100,2,0) -> #N/A | E6: =VLOOKUP($E$3,$L$23:$O$72,2,0) -> Refl-O-29.3 H-13 L-13mm 0.3W White NGWR5W (OUCHI) | F6: =VLOOKUP($F$3,$Q$23:$T$72,2,0) -> Lens-O-16 H-10.4 L-3.4mm 15°-PC 0.3W NGWR5W (OUCHI) | G6: =VLOOKUP($G$4,$V$23:$Y$72,2,0) -> LED SMD 3535 12V 350MA 3000K | H6: =VLOOKUP($H$4,$AA$23:$AD$72,2,0) -> PS 4W 300mA 12V Dali Magnetic Single Colour | I6: =VLOOKUP($I$3,AF23:$AI$100,2,0) -> #N/A
B7: Formulae for COST | C7: =VLOOKUP($C$3,$B$23:$E$72,4,0) -> 0 | D7: =VLOOKUP($D$4,G23:$J$100,4,0) -> #N/A | E7: =VLOOKUP($E$3,$L$23:$O$72,4,0) -> 0 | F7: =VLOOKUP($F$3,$Q$23:$T$72,4,0) -> 0 | G7: =VLOOKUP($G$4,$V$23:$Y$72,4,0) -> 0 | H7: =VLOOKUP($H$4,$AA$23:$AD$72,4,0) -> 0 | I7: =VLOOKUP($I$3,$AF$23:$AI$100,4,0) -> #N/A
B8: Formulae for Quantity | C8: =VLOOKUP($C$3,$B$23:$E$72,3,0) -> 0 | D8: =VLOOKUP($D$4,G23:$J$100,3,0) -> #N/A | E8: =VLOOKUP($E$3,$L$23:$O$72,3,0) -> 0 | F8: =VLOOKUP($F$3,$Q$23:$T$72,3,0) -> 0 | G8: =VLOOKUP($G$4,$V$23:$Y$72,3,0) -> 0 | H8: =VLOOKUP($H$4,$AA$23:$AD$72,3,0) -> 0 | I8: =VLOOKUP($I$3,$AF$23:$AI$100,3,0) -> #N/A
G10: BOM LED PCB
B21: TRIM | G21: HOUSING/HS | L21: REFLECTOR | Q21: BEAM ANGLE | V21: COLOR TEMPERATURE | AA21: DRIVING SYSTEM | AF21: EXTRA
B22: Code | C22: Item Name | D22: Quantity | E22: Cost | G22: Code | H22: Item Name | I22: Quantity | J22: Cost | L22: Code | M22: Item Name | N22: Quantity | O22: Cost | Q22: Code | R22: Item Name | S22: Quantity | T22: Cost | V22: Code | W22: Item Name | X22: Quantity | Y22: Cost | AA22: Code | AB22: Item Name | AC22: Quantity | AD22: Cost | AF22: Code | AG22: Item Name | AH22: Quantity | AI22: Cost
B23: R | C23: Trim O-39 ID-27 H-22.6mm 0.3W White NGWR5W (OUCHI) | L23: W | M23: Refl-O-29.3 H-13 L-13mm 0.3W White NGWR5W (OUCHI) | Q23: 05N | R23: Lens-O-16 H-10.4 L-3.4mm 15°-PC 0.3W NGWR5W (OUCHI) | V23: 30- | W23: LED SMD 3535 12V 350MA 3000K | AA23: - | AB23: PS 4W 300mA 9-12V LPF(PCB LPF-3W-V2)
B24: B | C24: Trim-O-39 I-27 H-22.6mm 0.3W Black NGWR5W (OUCHI) | L24: B | M24: Refl-O-29.3 H-13 L-13mm 0.3W Black NGWR5W (OUCHI) | Q24: 05M | R24: Lens-O-16 H-10.4 L-3.4mm 36°-PC 0.3W NGWR5W (OUCHI) | V24: 40- | W24: LED SMD 3535 12V 350MA 4000K | AA24: I- | AB24: PS 4W 300mA 12V Dali Magnetic Single Colour
B25: T | C25: Trimless Trim-O-55 I-27 H-22.6mm 0.3W White NGWR5W (OUCHI) | L25: A | M25: Refl-O-29.3 H-13 L-13mm 0.3W Alloy Black NGWR5W (OUCHI) | V25: 60- | W25: LED SMD 3535 12V 350MA 6000K | AA25: BT- | AB25: PS 4W 300mA 12V BT Magnetic Single Colour
L26: C | M26: Refl-O-29.3 H-13 L-13mm 0.3W Chrome NGWR5W (OUCHI)
V28: 30I- | W28: LED SMD 3535 12V 350MA 3000K
V29: 40I- | W29: LED SMD 3535 12V 350MA 4000K
V30: 60I- | W30: LED SMD 3535 12V 350MA 6000K
V33: 30BT- | W33: LED SMD 3535 12V 350MA 3000K
V34: 40BT- | W34: LED SMD 3535 12V 350MA 4000K
V35: 60BT- | W35: LED SMD 3535 12V 350MA 6000K

Sheet Result
A1: SKU Id | C1: Product Name | D1: Cost Price | E1: Retail Price | F1: Selling Price | G1: Weight | H1: Width | I1: Height | J1: Depth | K1: Input Power | L1: Trim | M1: Beam Angle | N1: Color Temp | O1: Driving System | P1: Reflector
A2: 191462 | B2: NGWR05N30 | D2: 0 | E2: 0 | F2: 0 | G2: 0 | H2: 0 | I2: 0 | J2: 0 | K2: 05 Watt | L2: Round White Trim | M2: Narrow - 15° | N2: 3000K | O2: Constant Current | P2: White Reflector
A3: 191463 | B3: NGBR05N30 | D3: 0 | E3: 0 | F3: 0 | G3: 0 | H3: 0 | I3: 0 | J3: 0 | K3: 05 Watt | L3: Round White Trim | M3: Narrow - 15° | N3: 3000K | O3: Constant Current | P3: Black Reflector
A4: 191464 | B4: NGAR05N30 | D4: 0 | E4: 0 | F4: 0 | G4: 0 | H4: 0 | I4: 0 | J4: 0 | K4: 05 Watt | L4: Round White Trim | M4: Narrow - 15° | N4: 3000K | O4: Constant Current | P4: Black Alloy Reflector
A5: 191465 | B5: NGCR05N30 | D5: 0 | E5: 0 | F5: 0 | G5: 0 | H5: 0 | I5: 0 | J5: 0 | K5: 05 Watt | L5: Round White Trim | M5: Narrow - 15° | N5: 3000K | O5: Constant Current | P5: Chrome Reflector
A6: 191466 | B6: NGWR05M30 | D6: 0 | E6: 0 | F6: 0 | G6: 0 | H6: 0 | I6: 0 | J6: 0 | K6: 05 Watt | L6: Round White Trim | M6: Medium - 30° | N6: 3000K | O6: Constant Current | P6: White Reflector
A7: 191467 | B7: NGBR05M30 | D7: 0 | E7: 0 | F7: 0 | G7: 0 | H7: 0 | I7: 0 | J7: 0 | K7: 05 Watt | L7: Round White Trim | M7: Medium - 30° | N7: 3000K | O7: Constant Current | P7: Black Reflector
A8: 191468 | B8: NGAR05M30 | D8: 0 | E8: 0 | F8: 0 | G8: 0 | H8: 0 | I8: 0 | J8: 0 | K8: 05 Watt | L8: Round White Trim | M8: Medium - 30° | N8: 3000K | O8: Constant Current | P8: Black Alloy Reflector
A9: 191469 | B9: NGCR05M30 | D9: 0 | E9: 0 | F9: 0 | G9: 0 | H9: 0 | I9: 0 | J9: 0 | K9: 05 Watt | L9: Round White Trim | M9: Medium - 30° | N9: 3000K | O9: Constant Current | P9: Chrome Reflector
A10: 191470 | B10: NGWR05N40 | D10: 0 | E10: 0 | F10: 0 | G10: 0 | H10: 0 | I10: 0 | J10: 0 | K10: 05 Watt | L10: Round White Trim | M10: Narrow - 15° | N10: 4000K | O10: Constant Current | P10: White Reflector
A11: 191471 | B11: NGBR05N40 | D11: 0 | E11: 0 | F11: 0 | G11: 0 | H11: 0 | I11: 0 | J11: 0 | K11: 05 Watt | L11: Round White Trim | M11: Narrow - 15° | N11: 4000K | O11: Constant Current | P11: Black Reflector
A12: 191472 | B12: NGAR05N40 | D12: 0 | E12: 0 | F12: 0 | G12: 0 | H12: 0 | I12: 0 | J12: 0 | K12: 05 Watt | L12: Round White Trim | M12: Narrow - 15° | N12: 4000K | O12: Constant Current | P12: Black Alloy Reflector
A13: 191473 | B13: NGCR05N40 | D13: 0 | E13: 0 | F13: 0 | G13: 0 | H13: 0 | I13: 0 | J13: 0 | K13: 05 Watt | L13: Round White Trim | M13: Narrow - 15° | N13: 4000K | O13: Constant Current | P13: Chrome Reflector
... A145: 191605 | B145: NGCB05M40BT | D145: 0 | E145: 0 | F145: 0 | G145: 0 | H145: 0 | I145: 0 | J145: 0 | K145: 05 Watt | L145: Round Black Trim | M145: Medium - 30° | N145: 4000K | O145: Bluetooth Dimming - 48V DC | P145: Chrome Reflector

Sheet NGWR05W-Possibility CODE
A1: SKU Id | B1: SKU Code | C1: Product Name | D1: SKU CODE-Possibilities | E1: Cost Price | F1: Retail Price | G1: Selling Price | H1: Weight | I1: Width | J1: Height | K1: Depth | L1: Color Temp | M1: Driving System | N1: Beam Angle | O1: Input Power | P1: Reflector | Q1: Trim
A2: 181634 | B2: NGR05WRM30- | D2: =CONCATENATE(T2,U2,V2,W2,X2) -> NGWR05M30 | E2: 0 | F2: 0 | G2: 0 | H2: 0 | I2: 0 | J2: 0 | K2: 0 | L2: 3000K | M2: Constant Current | N2: Medium - 35° | O2: 05 Watt | P2: White Reflector | Q2: Round White Trim | T2: =MID(B2,1,2) -> NG | U2: =MID(B2,6,2) -> WR | V2: =MID(B2,4,2) -> 05 | W2: =MID(B2,8,1) -> M | X2: =MID(B2,9,2) -> 30
A3: 181635 | B3: NGR05WTM30- | D3: =CONCATENATE(T3,U3,V3,W3,X3) -> NGWT05M30 | E3: 0 | F3: 0 | G3: 0 | H3: 0 | I3: 0 | J3: 0 | K3: 0 | L3: 3000K | M3: Constant Current | N3: Medium - 35° | O3: 05 Watt | P3: White Reflector | Q3: Round White Trimless | T3: =MID(B3,1,2) -> NG | U3: =MID(B3,6,2) -> WT | V3: =MID(B3,4,2) -> 05 | W3: =MID(B3,8,1) -> M | X3: =MID(B3,9,2) -> 30
A4: 181636 | B4: NGR05WBM30- | D4: =CONCATENATE(T4,U4,V4,W4,X4) -> NGWB05M30 | E4: 0 | F4: 0 | G4: 0 | H4: 0 | I4: 0 | J4: 0 | K4: 0 | L4: 3000K | M4: Constant Current | N4: Medium - 35° | O4: 05 Watt | P4: White Reflector | Q4: Round Black Trim | T4: =MID(B4,1,2) -> NG | U4: =MID(B4,6,2) -> WB | V4: =MID(B4,4,2) -> 05 | W4: =MID(B4,8,1) -> M | X4: =MID(B4,9,2) -> 30
A5: 181637 | B5: NGR05WRM40- | D5: =CONCATENATE(T5,U5,V5,W5,X5) -> NGWR05M40 | E5: 0 | F5: 0 | G5: 0 | H5: 0 | I5: 0 | J5: 0 | K5: 0 | L5: 4000K | M5: Constant Current | N5: Medium - 35° | O5: 05 Watt | P5: White Reflector | Q5: Round White Trim | T5: =MID(B5,1,2) -> NG | U5: =MID(B5,6,2) -> WR | V5: =MID(B5,4,2) -> 05 | W5: =MID(B5,8,1) -> M | X5: =MID(B5,9,2) -> 40
A6: 181638 | B6: NGR05WTM40- | D6: =CONCATENATE(T6,U6,V6,W6,X6) -> NGWT05M40 | E6: 0 | F6: 0 | G6: 0 | H6: 0 | I6: 0 | J6: 0 | K6: 0 | L6: 4000K | M6: Constant Current | N6: Medium - 35° | O6: 05 Watt | P6: White Reflector | Q6: Round White Trimless | T6: =MID(B6,1,2) -> NG | U6: =MID(B6,6,2) -> WT | V6: =MID(B6,4,2) -> 05 | W6: =MID(B6,8,1) -> M | X6: =MID(B6,9,2) -> 40
A7: 181639 | B7: NGR05WBM40- | D7: =CONCATENATE(T7,U7,V7,W7,X7) -> NGWB05M40 | E7: 0 | F7: 0 | G7: 0 | H7: 0 | I7: 0 | J7: 0 | K7: 0 | L7: 4000K | M7: Constant Current | N7: Medium - 35° | O7: 05 Watt | P7: White Reflector | Q7: Round Black Trim | T7: =MID(B7,1,2) -> NG | U7: =MID(B7,6,2) -> WB | V7: =MID(B7,4,2) -> 05 | W7: =MID(B7,8,1) -> M | X7: =MID(B7,9,2) -> 40
A8: 181640 | B8: NGR05WRM60- | D8: =CONCATENATE(T8,U8,V8,W8,X8) -> NGWR05M60 | E8: 0 | F8: 0 | G8: 0 | H8: 0 | I8: 0 | J8: 0 | K8: 0 | L8: 6000k | M8: Constant Current | N8: Medium - 35° | O8: 05 Watt | P8: White Reflector | Q8: Round White Trim | T8: =MID(B8,1,2) -> NG | U8: =MID(B8,6,2) -> WR | V8: =MID(B8,4,2) -> 05 | W8: =MID(B8,8,1) -> M | X8: =MID(B8,9,2) -> 60
A9: 181641 | B9: NGR05WTM60- | D9: =CONCATENATE(T9,U9,V9,W9,X9) -> NGWT05M60 | E9: 0 | F9: 0 | G9: 0 | H9: 0 | I9: 0 | J9: 0 | K9: 0 | L9: 6000k | M9: Constant Current | N9: Medium - 35° | O9: 05 Watt | P9: White Reflector | Q9: Round White Trimless | T9: =MID(B9,1,2) -> NG | U9: =MID(B9,6,2) -> WT | V9: =MID(B9,4,2) -> 05 | W9: =MID(B9,8,1) -> M | X9: =MID(B9,9,2) -> 60
A10: 181642 | B10: NGR05WBM60- | D10: =CONCATENATE(T10,U10,V10,W10,X10) -> NGWB05M60 | E10: 0 | F10: 0 | G10: 0 | H10: 0 | I10: 0 | J10: 0 | K10: 0 | L10: 6000k | M10: Constant Current | N10: Medium - 35° | O10: 05 Watt | P10: White Reflector | Q10: Round Black Trim | T10: =MID(B10,1,2) -> NG | U10: =MID(B10,6,2) -> WB | V10: =MID(B10,4,2) -> 05 | W10: =MID(B10,8,1) -> M | X10: =MID(B10,9,2) -> 60
A11: 181652 | B11: NGR05BRM30- | D11: =CONCATENATE(T11,U11,V11,W11,X11) -> NGBR05M30 | E11: 0 | F11: 0 | G11: 0 | H11: 0 | I11: 0 | J11: 0 | K11: 0 | L11: 3000K | M11: Constant Current | N11: Medium - 35° | O11: 05 Watt | P11: Black Reflector | Q11: Round White Trim | T11: =MID(B11,1,2) -> NG | U11: =MID(B11,6,2) -> BR | V11: =MID(B11,4,2) -> 05 | W11: =MID(B11,8,1) -> M | X11: =MID(B11,9,2) -> 30
A12: 181653 | B12: NGR05BTM30- | D12: =CONCATENATE(T12,U12,V12,W12,X12) -> NGBT05M30 | E12: 0 | F12: 0 | G12: 0 | H12: 0 | I12: 0 | J12: 0 | K12: 0 | L12: 3000K | M12: Constant Current | N12: Medium - 35° | O12: 05 Watt | P12: Black Reflector | Q12: Round White Trimless | T12: =MID(B12,1,2) -> NG | U12: =MID(B12,6,2) -> BT | V12: =MID(B12,4,2) -> 05 | W12: =MID(B12,8,1) -> M | X12: =MID(B12,9,2) -> 30
A13: 181654 | B13: NGR05BBM30- | D13: =CONCATENATE(T13,U13,V13,W13,X13) -> NGBB05M30 | E13: 0 | F13: 0 | G13: 0 | H13: 0 | I13: 0 | J13: 0 | K13: 0 | L13: 3000K | M13: Constant Current | N13: Medium - 35° | O13: 05 Watt | P13: Black Reflector | Q13: Round Black Trim | T13: =MID(B13,1,2) -> NG | U13: =MID(B13,6,2) -> BB | V13: =MID(B13,4,2) -> 05 | W13: =MID(B13,8,1) -> M | X13: =MID(B13,9,2) -> 30
... A37: 181696 | B37: NGR05CBM60- | D37: =CONCATENATE(T37,U37,V37,W37,X37) -> NGCB05M60 | E37: 0 | F37: 0 | G37: 0 | H37: 0 | I37: 0 | J37: 0 | K37: 0 | L37: 6000k | M37: Constant Current | N37: Medium - 35° | O37: 05 Watt | P37: Chrome Reflector | Q37: Round Black Trim | T37: =MID(B37,1,2) -> NG | U37: =MID(B37,6,2) -> CB | V37: =MID(B37,4,2) -> 05 | W37: =MID(B37,8,1) -> M | X37: =MID(B37,9,2) -> 60
A38: 181850 | B38: NGR05WRM30I | D38: =CONCATENATE(T38,U38,V38,W38,X38) -> NGWR05M30I | E38: 0 | F38: 0 | G38: 0 | H38: 0 | I38: 0 | J38: 0 | K38: 0 | L38: 3000K | M38: DALI Dimming - 48V DC | N38: Medium - 35° | O38: 05 Watt | P38: White Reflector | Q38: Round White Trim | T38: =MID(B38,1,2) -> NG | U38: =MID(B38,6,2) -> WR | V38: =MID(B38,4,2) -> 05 | W38: =MID(B38,8,1) -> M | X38: =MID(B38,9,4) -> 30I
A39: 181851 | B39: NGR05WTM30I | D39: =CONCATENATE(T39,U39,V39,W39,X39) -> NGWT05M30I | E39: 0 | F39: 0 | G39: 0 | H39: 0 | I39: 0 | J39: 0 | K39: 0 | L39: 3000K | M39: DALI Dimming - 48V DC | N39: Medium - 35° | O39: 05 Watt | P39: White Reflector | Q39: Round White Trimless | T39: =MID(B39,1,2) -> NG | U39: =MID(B39,6,2) -> WT | V39: =MID(B39,4,2) -> 05 | W39: =MID(B39,8,1) -> M | X39: =MID(B39,9,4) -> 30I
A40: 181852 | B40: NGR05WBM30I | D40: =CONCATENATE(T40,U40,V40,W40,X40) -> NGWB05M30I | E40: 0 | F40: 0 | G40: 0 | H40: 0 | I40: 0 | J40: 0 | K40: 0 | L40: 3000K | M40: DALI Dimming - 48V DC | N40: Medium - 35° | O40: 05 Watt | P40: White Reflector | Q40: Round Black Trim | T40: =MID(B40,1,2) -> NG | U40: =MID(B40,6,2) -> WB | V40: =MID(B40,4,2) -> 05 | W40: =MID(B40,8,1) -> M | X40: =MID(B40,9,4) -> 30I
A41: 181853 | B41: NGR05WRM40I | D41: =CONCATENATE(T41,U41,V41,W41,X41) -> NGWR05M40I | E41: 0 | F41: 0 | G41: 0 | H41: 0 | I41: 0 | J41: 0 | K41: 0 | L41: 4000K | M41: DALI Dimming - 48V DC | N41: Medium - 35° | O41: 05 Watt | P41: White Reflector | Q41: Round White Trim | T41: =MID(B41,1,2) -> NG | U41: =MID(B41,6,2) -> WR | V41: =MID(B41,4,2) -> 05 | W41: =MID(B41,8,1) -> M | X41: =MID(B41,9,4) -> 40I
A42: 181854 | B42: NGR05WTM40I | D42: =CONCATENATE(T42,U42,V42,W42,X42) -> NGWT05M40I | E42: 0 | F42: 0 | G42: 0 | H42: 0 | I42: 0 | J42: 0 | K42: 0 | L42: 4000K | M42: DALI Dimming - 48V DC | N42: Medium - 35° | O42: 05 Watt | P42: White Reflector | Q42: Round White Trimless | T42: =MID(B42,1,2) -> NG | U42: =MID(B42,6,2) -> WT | V42: =MID(B42,4,2) -> 05 | W42: =MID(B42,8,1) -> M | X42: =MID(B42,9,4) -> 40I
A43: 181855 | B43: NGR05WBM40I | D43: =CONCATENATE(T43,U43,V43,W43,X43) -> NGWB05M40I | E43: 0 | F43: 0 | G43: 0 | H43: 0 | I43: 0 | J43: 0 | K43: 0 | L43: 4000K | M43: DALI Dimming - 48V DC | N43: Medium - 35° | O43: 05 Watt | P43: White Reflector | Q43: Round Black Trim | T43: =MID(B43,1,2) -> NG | U43: =MID(B43,6,2) -> WB | V43: =MID(B43,4,2) -> 05 | W43: =MID(B43,8,1) -> M | X43: =MID(B43,9,4) -> 40I
A44: 181856 | B44: NGR05WRM60I | D44: =CONCATENATE(T44,U44,V44,W44,X44) -> NGWR05M60I | E44: 0 | F44: 0 | G44: 0 | H44: 0 | I44: 0 | J44: 0 | K44: 0 | L44: 6000k | M44: DALI Dimming - 48V DC | N44: Medium - 35° | O44: 05 Watt | P44: White Reflector | Q44: Round White Trim | T44: =MID(B44,1,2) -> NG | U44: =MID(B44,6,2) -> WR | V44: =MID(B44,4,2) -> 05 | W44: =MID(B44,8,1) -> M | X44: =MID(B44,9,4) -> 60I
A45: 181857 | B45: NGR05WTM60I | D45: =CONCATENATE(T45,U45,V45,W45,X45) -> NGWT05M60I | E45: 0 | F45: 0 | G45: 0 | H45: 0 | I45: 0 | J45: 0 | K45: 0 | L45: 6000k | M45: DALI Dimming - 48V DC | N45: Medium - 35° | O45: 05 Watt | P45: White Reflector | Q45: Round White Trimless | T45: =MID(B45,1,2) -> NG | U45: =MID(B45,6,2) -> WT | V45: =MID(B45,4,2) -> 05 | W45: =MID(B45,8,1) -> M | X45: =MID(B45,9,4) -> 60I
A46: 181858 | B46: NGR05WBM60I | D46: =CONCATENATE(T46,U46,V46,W46,X46) -> NGWB05M60I | E46: 0 | F46: 0 | G46: 0 | H46: 0 | I46: 0 | J46: 0 | K46: 0 | L46: 6000k | M46: DALI Dimming - 48V DC | N46: Medium - 35° | O46: 05 Watt | P46: White Reflector | Q46: Round Black Trim | T46: =MID(B46,1,2) -> NG | U46: =MID(B46,6,2) -> WB | V46: =MID(B46,4,2) -> 05 | W46: =MID(B46,8,1) -> M | X46: =MID(B46,9,4) -> 60I
A47: 181868 | B47: NGR05BRM30I | D47: =CONCATENATE(T47,U47,V47,W47,X47) -> NGBR05M30I | E47: 0 | F47: 0 | G47: 0 | H47: 0 | I47: 0 | J47: 0 | K47: 0 | L47: 3000K | M47: DALI Dimming - 48V DC | N47: Medium - 35° | O47: 05 Watt | P47: Black Reflector | Q47: Round White Trim | T47: =MID(B47,1,2) -> NG | U47: =MID(B47,6,2) -> BR | V47: =MID(B47,4,2) -> 05 | W47: =MID(B47,8,1) -> M | X47: =MID(B47,9,4) -> 30I
A48: 181869 | B48: NGR05BTM30I | D48: =CONCATENATE(T48,U48,V48,W48,X48) -> NGBT05M30I | E48: 0 | F48: 0 | G48: 0 | H48: 0 | I48: 0 | J48: 0 | K48: 0 | L48: 3000K | M48: DALI Dimming - 48V DC | N48: Medium - 35° | O48: 05 Watt | P48: Black Reflector | Q48: Round White Trimless | T48: =MID(B48,1,2) -> NG | U48: =MID(B48,6,2) -> BT | V48: =MID(B48,4,2) -> 05 | W48: =MID(B48,8,1) -> M | X48: =MID(B48,9,4) -> 30I
A49: 181870 | B49: NGR05BBM30I | D49: =CONCATENATE(T49,U49,V49,W49,X49) -> NGBB05M30I | E49: 0 | F49: 0 | G49: 0 | H49: 0 | I49: 0 | J49: 0 | K49: 0 | L49: 3000K | M49: DALI Dimming - 48V DC | N49: Medium - 35° | O49: 05 Watt | P49: Black Reflector | Q49: Round Black Trim | T49: =MID(B49,1,2) -> NG | U49: =MID(B49,6,2) -> BB | V49: =MID(B49,4,2) -> 05 | W49: =MID(B49,8,1) -> M | X49: =MID(B49,9,4) -> 30I
... A109: 181984 | B109: NGR05CBM60BT | D109: =CONCATENATE(T109,U109,V109,W109,X109) -> NGCB05M60BT | E109: 0 | F109: 0 | G109: 0 | H109: 0 | I109: 0 | J109: 0 | K109: 0 | L109: 6000k | M109: Bluetooth Dimming - 24V DC | N109: Medium - 35° | O109: 05 Watt | P109: Chrome Reflector | Q109: Round Black Trim | T109: =MID(B109,1,2) -> NG | U109: =MID(B109,6,2) -> CB | V109: =MID(B109,4,2) -> 05 | W109: =MID(B109,8,1) -> M | X109: =MID(B109,9,4) -> 60BT
