Workbook

Sheet Stock Item
A1: Name | B1: Group Name | C1: Units | D1: Name of BOM | E1: Unit of manufacture | F1: BOM Component - Item Name | G1: BOM Component - Quantity | H1: BOM Component - Godown | I1: BOM Component - Type of Item | J1: MODEL NAME | K1: Unit Price | L1: Cost | M1: USD | N1: INS&FRED | O1: BCD | P1: Total Cost
A2: =CONCATENATE(D2) -> NLBS20M30 | B2: Down Light Series | C2: Nos. | D2: NLBS20M30 | E2: 1 | F2: =VLOOKUP('NLBS-DATA'!$AV$5,'NLBS-DATA'!A2:B9,2,0) -> Housing-L-230 W-28 H-38mm White NLBS20W (FAFA) | G2: 1 | H2: Mechanical Store | I2: Component | K2: =P2*87 -> 812.232 | L2: =K2*G2 -> 812.232 | M2: 6.224 | N2: 0.5 | P2: =M2+(M2*(N2+O2)) -> 9.336
F3: =VLOOKUP('NLBS-DATA'!$AV$5,'NLBS-DATA'!$E$2:$G$9,2,0) -> Refl-L-110 W-18 H-11.5 LES ID-13.5mm-PC NLBS20W (FAFA) | G3: =VLOOKUP('NLBS-DATA'!$AV$5,'NLBS-DATA'!E2:G9,3,0) -> 2 | H3: Mechanical Store | I3: Component | M3: 0 | N3: 0.5 | P3: =M3+(M3*(N3+O3)) -> 0
F4: =VLOOKUP('NLBS-DATA'!$AV$5,'NLBS-DATA'!$N$2:$P$9,2,0) -> Refl Holder-L-110 W-18 H-12mm-PC NLBS20W (FAFA) | G4: =VLOOKUP('NLBS-DATA'!$AV$5,'NLBS-DATA'!$N$2:$P$9,3,0) -> 2 | H4: Mechanical Store | I4: Component | M4: 0 | N4: 0.5 | P4: =M4+(M4*(N4+O4)) -> 0
F5: Lens-O-16 L-3.5X3.5 H-10mm 31°-PC NLBS5/10/20 (FAFA | G5: =VLOOKUP('NLBS-DATA'!$AV$5,'NLBS-DATA'!$Y$3:$AB$9,3,0) -> 10 | H5: Mechanical Store | I5: Component | M5: 0 | N5: 0.5 | P5: =M5+(M5*(N5+O5)) -> 0
F6: Diff flim-16X0.10mm-PC NLBS5/10/12W (FAFA) | G6: =VLOOKUP('NLBS-DATA'!$AV$5,'NLBS-DATA'!$AD$3:$AF$9,3,0) -> 10 | H6: Mechanical Store | I6: Component | M6: 0 | N6: 0.5 | P6: =M6+(M6*(N6+O6)) -> 0
F7: Spring-L-45 W-16 Coil Dia.-1 D-7.5mm-MS NLBS5/10/20 | G7: 2 | H7: Mechanical Store | I7: Component | M7: 0 | N7: 0.5 | P7: =M7+(M7*(N7+O7)) -> 0
F8: Sleeve-O-20 L-21 T-0.20mm-Polyolefin Black | G8: 2 | H8: Mechanical Store | I8: Component | M8: 0 | N8: 0.5 | P8: =M8+(M8*(N8+O8)) -> 0
F9: Connector Cable Green Male 15mm | G9: 1 | H9: Mechanical Store | I9: Component | M9: 0 | N9: 0.5 | P9: =M9+(M9*(N9+O9)) -> 0
F10: Sleeve-25X30mm-Polyolefin Black | G10: 1 | H10: Mechanical Store | I10: Component | M10: 0 | N10: 0.5 | P10: =M10+(M10*(N10+O10)) -> 0
F11: =VLOOKUP('NLBS-DATA'!$AV$5,'NLBS-DATA'!$AI$3:$AK$9,2,0) -> Screw-M3X14mm- Pan + Head-MS | G11: =VLOOKUP('NLBS-DATA'!$AV$5,'NLBS-DATA'!$AI$3:$AK$9,3,0) -> 8 | H11: Mechanical Store | I11: Component | M11: 0 | N11: 0.5 | P11: =M11+(M11*(N11+O11)) -> 0
F12: Screw M4x4mm , SS , Allen grub screw | G12: 1 | H12: Mechanical Store | I12: Component | K12: 0.7 | L12: =K12*G12 -> 0.7
F13: =CONCATENATE($D$2," ", "BOM LED PCB") -> NLBS20M30 BOM LED PCB | G13: 1 | H13: Mechanical Store | I13: Component
F14: Sleeve M4mm Fiber Glass White | G14: 0.12 | H14: Mechanical Store | I14: Component | K14: =5.7/1000*120 -> 0.684 | L14: =K14*G14 -> 0.08208
F15: =VLOOKUP('NLBS-DATA'!$AY$6,'NLBS-DATA'!$J$2:$K$9,2,0) -> PS 15W 225mA 60V Maxic(PCB LT-MX-20W-V2) | G15: 1 | H15: Mechanical Store | I15: Component | M15: PS Rate Mention with Total Amt
F16: =VLOOKUP('NLBS-DATA'!AW9,'NLBS-DATA'!AR2:AS17,2,0) -> PBX-NLBS20W | G16: 1 | H16: Mechanical Store | I16: Component | M16: PBX Rate Including in Fitting
F17: SBX - COB 8-18W (12Nos) | G17: 0.08 | H17: Mechanical Store | I17: Component | K17: 27 | L17: =K17*G17 -> 2.16
A18: =CONCATENATE($D$2," ", "BOM LED PCB") -> NLBS20M30 BOM LED PCB | B18: Down Light Series | C18: Nos. | D18: =CONCATENATE($D$2," ", "BOM LED PCB") -> NLBS20M30 BOM LED PCB | E18: 1 | F18: =VLOOKUP('NLBS-DATA'!$AW$9,'NLBS-DATA'!AN2:AO8,2,0) -> PCB 10LED L-230 W-28 H-24 NLBS20W (FAFA) | G18: 1 | H18: Electronics Store | I18: Component | K18: =P18*87 -> 0 | L18: =K18*G18 -> 0 | M18: PCB Rate Including in Fitting
F19: =VLOOKUP('NLBS-DATA'!$AW$13,'NLBS-DATA'!$S$3:$T$12,2,0) -> LED SMD 3535 3000K WW | G19: =VLOOKUP('NLBS-DATA'!$AW$15,'NLBS-DATA'!$V$3:$W$5,2,0) -> 10 | H19: Electronics Store | I19: Component | K19: 11.5 | L19: =K19*G19 -> 115
L20: =SUM(L2:L19) -> 930.17408
J22: NLBS00W-CC | L22: =L20+98 -> 1028.1741
J23: NLBS20W Dali Dual Color | L23: =((L20)+(P23*87)) -> 1644.6616 | M23: 5.475 | N23: 0.5 | P23: =M23+(M23*(N23+O23)) -> 8.2125 | Q23: =P23*87 -> 714.4875

Sheet NLBS-DATA
A1: CODE | B1: HOUSING | C1: COST | E1: CODE | F1: REFLECTOR | G1: QTY | H1: COST | J1: CODE | K1: DRIVER | L1: COST | N1: CODE | O1: Reflector Holder | P1: QTY | Q1: COST | S1: CODE | T1: LED Temperature | U1: COST | V1: CODE | W1: QTY | Z1: Lens | AA1: QTY | AB1: Cost | AE1: Diffuser | AF1: QTY | AG1: COST | AJ1: Screw | AK1: QTY | AL1: COST | AN1: CODE | AO1: PCB | AP1: COST | AR1: CODE | AS1: BOX | AT1: COST
A2: S05 | B2: Housing-L-78.5 W-28.5 H-38mm White NLBS5W (FAFA) | E2: S05 | F2: Refl-L-68 W-18 H-11.5 LES ID-13.5mm-PC NLBS5W (FAFA) | G2: 1 | J2: 05- | K2: PS 5W 300mA 15V LPF | N2: S05 | O2: Refl Holder-L-68 W-18 H-12mm-PC NLBS5W (FAFA) | P2: 1 | T2: 05Watt | AN2: S05 | AO2: PCB 3LED L63 W-16 T-1.5mm NLBS5W (FAFA) | AR2: S05 | AS2: PBX-NLBS05W | AV2: Housing | AW2: Reflector | AX2: Temperature | AY2: Driver | BB2: =MID('Stock Item'!D2,1,9) -> NLBS20M30 | BC2: CC
A3: B05 | B3: Housing-L-78.5 W-28.5 H-38mm Black NLBS5W (FAFA) | E3: B05 | F3: Refl-L-68 W-18 H-11.5 LES ID-13.5mm-PC NLBS5W (FAFA) | G3: 1 | J3: 05-ID | K3: PS-5W 9V 500mA-DALI DC | N3: B05 | O3: Refl Holder-L-68 W-18 H-12mm-PC NLBS5W (FAFA) | P3: 1 | S3: 30S | T3: LED SMD 3535 3000K WW | V3: 05M | W3: 3 | Y3: S05 | Z3: Lens-O-16 L-3.5X3.5 H-10mm 31°-PC NLBS5/10/20 (FAFA | AA3: 3 | AD3: S05 | AE3: Diff flim-16X0.10mm-PC NLBS5/10/12W (FAFA) | AF3: 3 | AI3: S05 | AJ3: Screw-M3X14mm- Pan + Head-MS | AK3: 2 | AN3: B05 | AO3: PCB 3LED L63 W-16 T-1.5mm NLBS5W (FAFA) | AR3: S10 | AS3: PBX-NLBS10W | AV3: =MID('Stock Item'!$D$2,4,1) -> S | AW3: =LEFT('Stock Item'!D2,6) -> NLBS20 | AX3: =LEFT('Stock Item'!D2,9) -> NLBS20M30 | AY3: =MID('Stock Item'!$D$2,5,2) -> 20 | AZ3: =_xlfn.CONCAT(AY3) -> #NAME? | BA3: - | BC3: T
S4: 40S | T4: LED SMD 3535 3V 4000K 1500mA | V4: 10M | W4: 5 | Y4: S10 | Z4: Lens-O-16 L-3.5X3.5 H-10mm 31°-PC NLBS5/10/20 (FAFA | AA4: 5 | AD4: S10 | AE4: Diff flim-16X0.10mm-PC NLBS5/10/12W (FAFA) | AF4: 5 | AI4: S10 | AJ4: Screw-M3X14mm- Pan + Head-MS | AK4: 4 | AN4: S10 | AO4: PCB 5LED L-128 W-28 H-38 NLBS10W (FAFA) | AR4: S20 | AS4: PBX-NLBS20W | AW4: =MID('Stock Item'!$D$2,5,2) -> 20 | AX4: =MID('Stock Item'!$D$2,7,1) -> M | AY4: =MID('Stock Item'!$D$2,10,2) | BC4: I
A5: S10 | B5: Housing-L-120 W -28.5 H-38mm White NLBS10W (FAFA) | E5: S10 | F5: Refl-L-110 W-18 H-11.5 LES ID-13.5mm-PC NLBS10W (FAFA) | G5: 1 | J5: 10- | K5: PS 10W 250MA 36V LPF | N5: S10 | O5: Refl Holder-L-110 W-18 H-12mm-PC NLBS10W (FAFA) | P5: 1 | S5: 60S | T5: LED SMD 3535 6000K CW | V5: 20M | W5: 10 | Y5: S20 | Z5: Lens-O-16 L-3.5X3.5 H-10mm 31°-PC NLBS5/10/20 (FAFA | AA5: 10 | AD5: S20 | AE5: Diff flim-16X0.10mm-PC NLBS5/10/12W (FAFA) | AF5: 10 | AI5: S20 | AJ5: Screw-M3X14mm- Pan + Head-MS | AK5: 8 | AN5: B10 | AO5: PCB 5LED L-128 W-28 H-38 NLBS10W (FAFA) | AV5: =CONCATENATE($AV$3,$AW$4,) -> S20 | AW5: =RIGHT(AW4,1) -> 0 | AX5: =MID('Stock Item'!$D$2,8,2) -> 30 | AZ5: =MID(AZ3,10,1) -> #NAME? | BC5: BT
A6: B10 | B6: Housing-L-120 W -28.5 H-38mm Black NLBS10W (FAFA) | E6: B10 | F6: Refl-L-110 W-18 H-11.5 LES ID-13.5mm-PC NLBS10W (FAFA) | G6: 1 | J6: 10-ID | K6: Dali Driver DC-10W PE694R4230(AI-Dimming)-25-40V | N6: B10 | O6: Refl Holder-L-110 W-18 H-12mm-PC NLBS10W (FAFA) | P6: 1 | AN6: S20 | AO6: PCB 10LED L-230 W-28 H-24 NLBS20W (FAFA) | AR6: B05 | AS6: PBX-NLBS05W | AX6: =MID(AX3,5,2) -> 20 | AY6: =CONCATENATE($AY$3,$BA$3,$AY$4 ) -> 20- | AZ6: =MID('Stock Item'!D2,11,2) | BC6: ID
S7: 30B | T7: LED SMD 3535 3000K WW | Y7: B05 | Z7: Lens-O-16 L-3.5X3.5 H-10mm 31°-PC NLBS5/10/20 (FAFA | AA7: 3 | AD7: B05 | AE7: Diff flim-16X0.10mm-PC NLBS5/10/12W (FAFA) | AF7: 3 | AI7: B05 | AJ7: Screw-M3X14mm- Pan + Head-MS | AK7: 2 | AN7: B20 | AO7: PCB 10LED L-230 W-28 H-24 NLBS20W (FAFA) | AR7: B10 | AS7: PBX-NLBS10W | AZ7: =_xlfn.CONCAT(BA3,AZ5,AZ6) -> #NAME? | BC7: BTD
A8: S20 | B8: Housing-L-230 W-28 H-38mm White NLBS20W (FAFA) | E8: S20 | F8: Refl-L-110 W-18 H-11.5 LES ID-13.5mm-PC NLBS20W (FAFA) | G8: 2 | J8: 20- | K8: PS 15W 225mA 60V Maxic(PCB LT-MX-20W-V2) | N8: S20 | O8: Refl Holder-L-110 W-18 H-12mm-PC NLBS20W (FAFA) | P8: 2 | S8: 40B | T8: LED SMD 3535 3V 4000K 1500mA | Y8: B10 | Z8: Lens-O-16 L-3.5X3.5 H-10mm 31°-PC NLBS5/10/20 (FAFA | AA8: 5 | AD8: B10 | AE8: Diff flim-16X0.10mm-PC NLBS5/10/12W (FAFA) | AF8: 5 | AI8: B10 | AJ8: Screw-M3X14mm- Pan + Head-MS | AK8: 4 | AR8: B20 | AS8: PBX-NLBS20W
A9: B20 | B9: Housing-L-230 W-28 H-38mm Black NLBS20W (FAFA) | E9: B20 | F9: Refl-L-110 W-18 H-11.5 LES ID-13.5mm-PC NLBS20W (FAFA) | G9: 2 | J9: 20-ID | K9: Dali Driver DC-20W PE69R4240 (AI-Dimming)-25-40V | N9: B20 | O9: Refl Holder-L-110 W-18 H-12mm-PC NLBS20W (FAFA) | P9: 2 | S9: 60B | T9: LED SMD 3535 6000K CW | Y9: B20 | Z9: Lens-O-16 L-3.5X3.5 H-10mm 31°-PC NLBS5/10/20 (FAFA | AA9: 10 | AD9: B20 | AE9: Diff flim-16X0.10mm-PC NLBS5/10/12W (FAFA) | AF9: 10 | AI9: B20 | AJ9: Screw-M3X14mm- Pan + Head-MS | AK9: 8 | AV9: Housing | AW9: =$AV$5 -> S20
AV10: Reflector | AW10: =$AV$5 -> S20 | AX10: =CONCATENATE(AV5,AZ6,AY4) -> S20 | AY10: =CONCATENATE(AV3,AY6) -> S20-
S11: 25S | T11: LED SMD 3535 Dual Colour - 2700K - 5000K | AV11: Reflector Holder | AW11: =$AV$5 -> S20
S12: 25B | T12: LED SMD 3535 Dual Colour - 2700K - 5000K | AV12: Driver | AW12: =$AY$6 -> 20-
AV13: LED Temperature | AW13: =CONCATENATE($AX$5,$AV$3) -> 30S
AV14: Lens
AV15: LED Tem. QTY | AW15: =CONCATENATE($AW$4,$AX$4) -> 20M
AV17: SKUs
AV18: NLBS05M60
AV19: NLBS05M40
AV20: NLBS05M30
AV21: NLBB05M60
AV22: NLBB05M40
AV23: NLBB05M30
AV24: NLBS10M60
AV25: NLBS10M40
AV26: NLBS10M30
AV27: NLBB10M60
AV28: NLBB10M40
... AV41: NLBB20M25ID

Sheet Result
A1: SKU Id | B1: SKU Code | C1: Product Name | D1: Cost Price | E1: Retail Price | F1: Selling Price | G1: Weight | H1: Width | I1: Height | J1: Depth | K1: Trim | L1: Input Power / Size | M1: Beam Angle | N1: Color Temp | O1: Driving System
A2: 188716 | B2: NLBS20M60 | D2: 0 | E2: 0 | F2: 4378 | G2: 0 | H2: 0 | I2: 0 | J2: 0 | K2: Square White Trim | L2: 20 Watt / L230 X W28 X H38mm | M2: Medium - 31° | N2: 6000K | O2: Constant Current
A3: 188717 | B3: NLBS20M40 | D3: 0 | E3: 0 | F3: 4378 | G3: 0 | H3: 0 | I3: 0 | J3: 0 | K3: Square White Trim | L3: 20 Watt / L230 X W28 X H38mm | M3: Medium - 31° | N3: 4000k | O3: Constant Current
A4: 188718 | B4: NLBS20M30 | D4: 0 | E4: 0 | F4: 4378 | G4: 0 | H4: 0 | I4: 0 | J4: 0 | K4: Square White Trim | L4: 20 Watt / L230 X W28 X H38mm | M4: Medium - 31° | N4: 3000k | O4: Constant Current
A5: 188720 | B5: NLBB20M60 | D5: 0 | E5: 0 | F5: 4378 | G5: 0 | H5: 0 | I5: 0 | J5: 0 | K5: Square Black Trim | L5: 20 Watt / L230 X W28 X H38mm | M5: Medium - 31° | N5: 6000K | O5: Constant Current
A6: 188721 | B6: NLBB20M40 | D6: 0 | E6: 0 | F6: 4378 | G6: 0 | H6: 0 | I6: 0 | J6: 0 | K6: Square Black Trim | L6: 20 Watt / L230 X W28 X H38mm | M6: Medium - 31° | N6: 4000k | O6: Constant Current
A7: 188722 | B7: NLBB20M30 | D7: 0 | E7: 0 | F7: 4378 | G7: 0 | H7: 0 | I7: 0 | J7: 0 | K7: Square Black Trim | L7: 20 Watt / L230 X W28 X H38mm | M7: Medium - 31° | N7: 3000k | O7: Constant Current
A8: 188743 | B8: NLBS20M25ID | D8: 0 | E8: 0 | F8: 8140 | G8: 0 | H8: 0 | I8: 0 | J8: 0 | K8: Square White Trim | L8: 20 Watt / L230 X W28 X H38mm | M8: Medium - 31° | N8: 2700K - 5000K Dali + Dual Color (Driving System) | O8: Dali + Dual Color (2700K - 5000K)
A9: 188747 | B9: NLBB20M25ID | D9: 0 | E9: 0 | F9: 8140 | G9: 0 | H9: 0 | I9: 0 | J9: 0 | K9: Square Black Trim | L9: 20 Watt / L230 X W28 X H38mm | M9: Medium - 31° | N9: 2700K - 5000K Dali + Dual Color (Driving System) | O9: Dali + Dual Color (2700K - 5000K)

Sheet Stock Item (Read Me)
A1: List of Fields | B1: Applicable Countries | C1: Applicable Values
A2: General Details
A3: Name | B3: All | E3: Read the following, before you start using the sample file:
A4: Group Name | B4: All | E4: Stock Item worksheet:
A5: B | B5: All | E5: - Use the worksheet without making any changes to the column headers to enter your business data. - The column headers represent field names in TallyPrime. Mandatory fields are marked in bold for easy reference. - Add new columns, if needed. Ensure to enter Column Headers exactly as mentioned under the List of Fields of the Read Me worksheet. - Delete unwanted columns. However, do not delete columns that represent mandatory fields for masters.
A6: Part No. | B6: All
A7: Alias - Part No. | B7: All
A8: Description | B8: All
A9: Notes | B9: All
A10: Category | B10: All
A11: Units | B11: All | E11: Stock Item (Read Me)
A12: Conversion | B12: All | E12: - The Read Me worksheet is only for your reference. It lists all the fields, with related details, applicable for Stock Item.
A13: Denominator | B13: All
A14: Alternate Units | B14: All | E14: For more information on using Sample Excel File for importing data, refer to | M14: TallyHelp
A15: GST Applicability | B15: All | C15: Applicable, Not Applicable
A16: Opening Balance - Quantity | B16: All
A17: Opening Balance - Rate | B17: All
A18: Opening Balance - Rate Per | B18: All
A19: Opening Balance - Value | B19: All
A20: Language for Name (Except English) | B20: All
A21: Is TCS Applicable | B21: All
A22: Item Allocations Details
A23: Item Allocations - Godown | B23: (When Accounting Terminology is set to "India/SAARC")
A24: Item Allocations - Batch | B24: All
A25: Item Allocations - Quantity | B25: All
A26: Item Allocations - Rate | B26: All
A27: Item Allocations - Rate per | B27: All
A28: Item Allocations - Amount | B28: All
A29: Item Allocations - Mfg. Date | B29: All
A30: Item Allocations - Expiry Date | B30: All
A31: Item Allocations - Location | B31: (When Accounting Terminology is set to "International")
A32: Additional Details
A33: Maintain in Batches | B33: All
A34: Track date of manufacturing | B34: All
A35: Use expiry dates | B35: All
A36: Enable Cost Tracking | B36: All
A37: Costing Method | B37: All | C37: At Zero Cost, Avg. Cost, FIFO, FIFO Perpetual, Last Purchase Cost, LIFO Annual, LIFO Perpetual, Monthly Avg. Cost, Std. Cost
A38: Market Valuation Method | B38: All | C38: At Zero Price, Avg. Price, Last Sale Price, Std. Price
A39: Behaviour
A40: Ignore difference due to physical counting | B40: All
...
