Workbook

Sheet Stock Item
A1: Name | B1: Group Name | C1: Units | D1: Name of BOM | E1: Unit of manufacture | F1: BOM Component - Item Name | G1: BOM Component - Quantity | H1: BOM Component - Godown | I1: BOM Component - Type of Item | J1: BOM Component - Rate (%) | K1: BOM Component - Location | L1: Unit Price | M1: Cost | N1: USD | O1: INS&FRED | P1: BCD | Q1: Total Cost
A2: =$D$2 -> NRLR08VN30 | B2: Down Light Series | C2: Nos. | D2: NRLR08VN30 | E2: 1 | F2: ='Backend data'!C6 -> Trim-O-68 I-51 H-63mm White NRRR8-18W | G2: 1 | H2: Mechanical Store | I2: Component | L2: =Q2*87 -> 55.9845 | M2: =G2*L2 -> 55.9845 | N2: 0.429 | O2: 0.5 | Q2: =N2+(N2*(O2+P2)) -> 0.6435
F3: HS-50X24.5mm (SR-DR-NR-12W) | G3: 1 | H3: Mechanical Store | I3: Component | L3: =Q3*87 -> 57.2895 | M3: =G3*L3 -> 57.2895 | N3: 0.439 | O3: 0.5 | Q3: =N3+(N3*(O3+P3)) -> 0.6585
F4: Lens GLC-O-50 L-13.4 H-13.4 15° PC ( Zhenglian) | G4: 1 | H4: Mechanical Store | I4: Component | L4: =Q4*87 -> 25.839 | M4: =G4*L4 -> 25.839 | N4: 0.198 | O4: 0.5 | Q4: =N4+(N4*(O4+P4)) -> 0.297
F5: COB Holder -OD-32 , L-11 ,H-3.2mm. 13X13 Locable GLC | G5: 1 | H5: Mechanical Store | I5: Component
F6: Locking Spring L-57 W-10mm T-0.2mm DR/NR-5/18W | G6: 1 | H6: Mechanical Store | I6: Component | L6: =Q6*87 -> 2.2185 | M6: =G6*L6 -> 2.2185 | N6: 0.017 | O6: 0.5 | Q6: =N6+(N6*(O6+P6)) -> 0.0255
F7: Conn. 2Pin Ass. Wire Black Male (Small) | G7: 1 | H7: Mechanical Store | I7: Component | L7: =Q7*87 -> 3.915 | M7: =G7*L7 -> 3.915 | N7: 0.03 | O7: 0.5 | Q7: =N7+(N7*(O7+P7)) -> 0.045
F8: PBX-COB 8-15W | G8: 1 | H8: Mechanical Store | I8: Component | L8: 8.5 | M8: =G8*L8 -> 8.5 | N8: 0 | O8: 0.5 | Q8: =N8+(N8*(O8+P8)) -> 0
F9: SBX-COB 8-18W (12Nos) | G9: 0.08 | H9: Mechanical Store | I9: Component | L9: 27 | M9: =G9*L9 -> 2.16 | N9: 0 | O9: 0.5 | Q9: =N9+(N9*(O9+P9)) -> 0
F10: Sleeve M4mm Fiber Glass White | G10: 0.12 | H10: Mechanical Store | I10: Component | L10: =5.7/1000*120 -> 0.684 | M10: =G10*L10 -> 0.08208 | N10: 0 | O10: 0.5 | Q10: =N10+(N10*(O10+P10)) -> 0
F11: Wire Clip-M3-MS | G11: 1 | H11: Mechanical Store | I11: Component | L11: 0.6 | M11: =G11*L11 -> 0.6 | N11: 0 | O11: 0.5 | Q11: =N11+(N11*(O11+P11)) -> 0
F12: Screw No. 4X6.5mm Self Pan Combi. PH - SS | G12: 1 | H12: Mechanical Store | I12: Component | L12: 0.21 | M12: =G12*L12 -> 0.21 | N12: 0 | O12: 0.5 | Q12: =N12+(N12*(O12+P12)) -> 0
F13: Screw M3X6mm CSK PH - SS | G13: 2 | H13: Mechanical Store | I13: Component | L13: 0.48 | M13: =G13*L13 -> 0.96 | N13: 0 | O13: 0.5 | Q13: =N13+(N13*(O13+P13)) -> 0
F14: Rivet 1/8" x 1/4" MS (Big) | G14: 4 | H14: Mechanical Store | I14: Component | L14: 0.26 | M14: =G14*L14 -> 1.04
F15: ='Backend data'!G6 -> COB 12&15W 3000K 12LED 36V 350mA 13.5x13.5mm CRI-90 | G15: 1 | H15: Electronics Store | I15: Component | L15: =Q15*87 -> 41.76 | M15: =G15*L15 -> 41.76 | N15: 0.32 | O15: 0.5 | Q15: =N15+(N15*(O15+P15)) -> 0.48
F16: ='Backend data'!H6 -> PS 8W 200MA 36V LPF (PCB MT43-8-12W-V2 LPF) | G16: 1 | H16: Mechanical Store | I16: Component | N16: PS Rate Mention with Total Amt
M17: =SUM(M2:M16) -> 200.55858
K19: NRLR08-CC | M19: =M17+42 -> 242.55858
K20: NRLR08 Track Dimming | M20: =M17+275 -> 475.55858 | R20: Rate
K21: NRLR08 Dali Single Color | M21: =((M17)+(Q21*87)) -> 858.27858 | N21: 5.04 | O21: 0.5 | Q21: =N21+(N21*(O21+P21)) -> 7.56 | R21: =Q21*87 -> 657.72
K22: NRLR08 BT Single Color | M22: =M17+330 -> 530.55858
K23: NRLR08 Dali Dual Color | M23: =((M17)+(Q23*87)) -> 915.04608 | N23: 5.475 | O23: 0.5 | Q23: =N23+(N23*(O23+P23)) -> 8.2125 | R23: =Q23*87 -> 714.4875
K24: NRLR08 BT Dual Color | M24: =M17+330 -> 530.55858

Sheet Stock Item (Read Me)
A1: List of Fields | B1: Applicable Countries | C1: Applicable Values
A2: General Details
A3: Name | B3: All | E3: Read the following, before you start using the sample file:
A4: Group Name | B4: All | E4: Stock Item worksheet:
A5: B | B5: All | E5: - Use the worksheet without making any changes to the column headers to enter your business data. - The column headers represent field names in TallyPrime. Mandatory fields are marked in bold for easy reference. - Add new columns, if needed. Ensure to enter Column Headers exactly as mentioned under the List of Fields of the Read Me worksheet. - Delete unwanted columns. However, do not delete columns that represent mandatory fields for masters.
A6: Part No. | B6: All
A7: Alias - Part No. | B7: All
A8: Description | B8: All
A9: Notes | B9: All
A10: Category | B10: All
A11: Units | B11: All | E11: Stock Item (Read Me)
A12: Conversion | B12: All | E12: - The Read Me worksheet is only for your reference. It lists all the fields, with related details, applicable for Stock Item.
A13: Denominator | B13: All
A14: Alternate Units | B14: All | E14: For more information on using Sample Excel File for importing data, refer to | M14: TallyHelp
A15: GST Applicability | B15: All | C15: Applicable, Not Applicable
A16: Opening Balance - Quantity | B16: All
A17: Opening Balance - Rate | B17: All
A18: Opening Balance - Rate Per | B18: All
A19: Opening Balance - Value | B19: All
A20: Language for Name (Except English) | B20: All
A21: Is TCS Applicable | B21: All
A22: Item Allocations Details
A23: Item Allocations - Godown | B23: (When Accounting Terminology is set to "India/SAARC")
A24: Item Allocations - Batch | B24: All
A25: Item Allocations - Quantity | B25: All
A26: Item Allocations - Rate | B26: All
A27: Item Allocations - Rate per | B27: All
A28: Item Allocations - Amount | B28: All
A29: Item Allocations - Mfg. Date | B29: All
A30: Item Allocations - Expiry Date | B30: All
A31: Item Allocations - Location | B31: (When Accounting Terminology is set to "International")
A32: Additional Details
A33: Maintain in Batches | B33: All
A34: Track date of manufacturing | B34: All
A35: Use expiry dates | B35: All
A36: Enable Cost Tracking | B36: All
A37: Costing Method | B37: All | C37: At Zero Cost, Avg. Cost, FIFO, FIFO Perpetual, Last Purchase Cost, LIFO Annual, LIFO Perpetual, Monthly Avg. Cost, Std. Cost
A38: Market Valuation Method | B38: All | C38: At Zero Price, Avg. Price, Last Sale Price, Std. Price
A39: Behaviour
A40: Ignore difference due to physical counting | B40: All
...

Sheet Backend data
C2: TRIM | D2: HOUSING/HS | E2: REFLECTOR | F2: BEAM ANGLE | G2: COLOR TEMP | H2: DRIVING SYSTEM | I2: EXTRA
C3: =MID('Stock Item'!$D$2,4,1) -> R | D3: =MID('Stock Item'!$D$2,4,3) -> R08 | E3: =MID('Stock Item'!$D$2,3,1) -> L | F3: =MID('Stock Item'!$D$2,7,2) -> VN | G3: =MID('Stock Item'!$D$2,9,2) -> 30 | H3: =MID('Stock Item'!$D$2,11,11) | I3: =MID('Stock Item'!$D$2,2,1) -> R
D4: =CONCATENATE($D$3) -> R08 | G4: =CONCATENATE($G$3,$H$4) -> 30- | H4: =CONCATENATE($H$3,"-") -> -
H5: =CONCATENATE('Stock Item'!D2) -> NRLR08VN30
B6: Formulae | C6: =VLOOKUP($C$3,$B$23:$E$73,2,0) -> Trim-O-68 I-51 H-63mm White NRRR8-18W | D6: =VLOOKUP($D$4,G23:$J$101,2,0) -> HS 50X24mm 8W DR-NR-SR | E6: =VLOOKUP($E$3,$L$23:$O$73,2,0) -> #N/A | F6: =VLOOKUP($F$3,$Q$23:$T$73,2,0) -> Lens GLC-O-50 L-13.4 H-13.4 15° PC ( Zhenglian) | G6: =VLOOKUP($G$4,$V$23:$Y$73,2,0) -> COB 12&15W 3000K 12LED 36V 350mA 13.5x13.5mm CRI-90 | H6: =VLOOKUP($H$4,$AA$23:$AD$73,2,0) -> PS 8W 200MA 36V LPF (PCB MT43-8-12W-V2 LPF) | I6: =VLOOKUP($I$3,AF23:$AI$101,2,0) -> #N/A
B7: Formulae for COST | C7: =VLOOKUP($C$3,$B$23:$E$73,4,0) -> 0 | D7: =VLOOKUP($D$4,G23:$J$101,4,0) -> 0 | E7: =VLOOKUP($E$3,$L$23:$O$73,4,0) -> #N/A | F7: =VLOOKUP($F$3,$Q$23:$T$73,4,0) -> 0 | G7: =VLOOKUP($G$4,$V$23:$Y$73,4,0) -> 0 | H7: =VLOOKUP($H$4,$AA$23:$AD$73,4,0) -> 0 | I7: =VLOOKUP($I$3,$AF$23:$AI$101,4,0) -> #N/A
B8: Formulae for Quantity | C8: =VLOOKUP($C$3,$B$23:$E$73,3,0) -> 0 | D8: =VLOOKUP($D$4,G23:$J$101,3,0) -> 0 | E8: =VLOOKUP($E$3,$L$23:$O$73,3,0) -> #N/A | F8: =VLOOKUP($F$3,$Q$23:$T$73,3,0) -> 0 | G8: =VLOOKUP($G$4,$V$23:$Y$73,3,0) -> 0 | H8: =VLOOKUP($H$4,$AA$23:$AD$73,3,0) -> 0 | I8: =VLOOKUP($I$3,$AF$23:$AI$101,3,0) -> #N/A
H10: BOM LED PCB
B21: TRIM | G21: HOUSING/HS | L21: REFLECTOR | Q21: BEAM ANGLE | V21: COLOR TEMPERATURE | AA21: DRIVING SYSTEM | AF21: EXTRA
B22: Code | C22: Item Name | D22: Quantity | E22: Cost | G22: Code | H22: Item Name | I22: Quantity | J22: Cost | L22: Code | M22: Item Name | N22: Quantity | O22: Cost | Q22: Code | R22: Item Name | S22: Quantity | T22: Cost | V22: Code | W22: Item Name | X22: Quantity | Y22: Cost | AA22: Code | AB22: Item Name | AC22: Quantity | AD22: Cost | AF22: Code | AG22: Item Name | AH22: Quantity | AI22: Cost
B23: R | C23: Trim-O-68 I-51 H-63mm White NRRR8-18W | G23: R08 | H23: HS 50X24mm 8W DR-NR-SR | Q23: VN | R23: Lens GLC-O-50 L-13.4 H-13.4 15° PC ( Zhenglian) | V23: 27- | W23: COB 12&15W 2700K 12LED 36V 350mA 13.5x13.5mm CRI-95 | AA23: - | AB23: PS 8W 200MA 36V LPF (PCB MT43-8-12W-V2 LPF)
B24: B | C24: Trim-O-68 I-51 H-63mm Black NRRR8-18W | V24: 30- | W24: COB 12&15W 3000K 12LED 36V 350mA 13.5x13.5mm CRI-90 | AA24: T- | AB24: PS 8W 200MA 36V Triac Dimming
B25: T | C25: Trim-O-68 I-51 H-63mm Inner Black NRRR8-18W | V25: 40- | W25: COB 12&15W 4000K 12LED 36V 350mA 13.5x13.5mm CRI-90 | AA25: I- | AB25: Dali Driver SC-10W PE19DA4240 (AI-Dimming)-25-40V
V26: 50- | W26: COB 12&15W 5000K 12LED 36V 350mA 13.5x13.5mm CRI-90 | AA26: BT- | AB26: PS CCT 8W 170MA 36V BT-SC (PCB LT 7-20W-CCT-V 1.1 REV-1)
V27: 60- | W27: COB 12&15W 6000K 12LED 36V 350mA 13.5x13.5mm CRI-90 | AA27: ID- | AB27: Dali Driver DC-10W PE694R4230(AI-Dimming)-25-40V
AA28: BTD- | AB28: PS CCT 8W 170MA 36V BT-DC (PCB LT 7-20W-CCT-V 1.1 REV-1)
V29: 27T- | W29: COB 12&15W 2700K 12LED 36V 350mA 13.5x13.5mm CRI-95
V30: 30T- | W30: COB 12&15W 3000K 12LED 36V 350mA 13.5x13.5mm CRI-90
V31: 40T- | W31: COB 12&15W 4000K 12LED 36V 350mA 13.5x13.5mm CRI-90
V32: 50T- | W32: COB 12&15W 5000K 12LED 36V 350mA 13.5x13.5mm CRI-90
V33: 60T- | W33: COB 12&15W 6000K 12LED 36V 350mA 13.5x13.5mm CRI-90
V35: 27I- | W35: COB 12&15W 2700K 12LED 36V 350mA 13.5x13.5mm CRI-95
V36: 30I- | W36: COB 12&15W 3000K 12LED 36V 350mA 13.5x13.5mm CRI-90
V37: 40I- | W37: COB 12&15W 4000K 12LED 36V 350mA 13.5x13.5mm CRI-90
V38: 50I- | W38: COB 12&15W 5000K 12LED 36V 350mA 13.5x13.5mm CRI-90
V39: 60I- | W39: COB 12&15W 6000K 12LED 36V 350mA 13.5x13.5mm CRI-90
V40: 26ID- | W40: COB 12&15W 2700-5000K 12LED 36V 350mA 13.5x13.5mm CRI-90
V42: 27BT- | W42: COB 12&15W 2700K 12LED 36V 350mA 13.5x13.5mm CRI-95
... V47: 26BTD- | W47: COB 12&15W 2700-5000K 12LED 36V 350mA 13.5x13.5mm CRI-90

Sheet Result
A1: SKU Id | B1: SKU Code | C1: Product Name | D1: Cost Price | E1: Retail Price | F1: Selling Price | G1: Weight | H1: Width | I1: Height | J1: Depth | K1: Trim | L1: Beam Angle | M1: Color Temperature | N1: Driving System | O1: Watt
A2: 206778 | B2: NRLR08VN30 | D2: 0 | E2: 0 | F2: 0 | G2: 0 | H2: 0 | I2: 0 | J2: 0 | K2: White | L2: Very Narrow | M2: 3000K | N2: Constant Current | O2: 08W
A3: 206779 | B3: NRLR08VN40 | D3: 0 | E3: 0 | F3: 0 | G3: 0 | H3: 0 | I3: 0 | J3: 0 | K3: White | L3: Very Narrow | M3: 4000K | N3: Constant Current | O3: 08W
A4: 206780 | B4: NRLR08VN50 | D4: 0 | E4: 0 | F4: 0 | G4: 0 | H4: 0 | I4: 0 | J4: 0 | K4: White | L4: Very Narrow | M4: 5000K | N4: Constant Current | O4: 08W
A5: 206786 | B5: NRLB08VN30 | D5: 0 | E5: 0 | F5: 0 | G5: 0 | H5: 0 | I5: 0 | J5: 0 | K5: Black | L5: Very Narrow | M5: 3000K | N5: Constant Current | O5: 08W
A6: 206787 | B6: NRLB08VN40 | D6: 0 | E6: 0 | F6: 0 | G6: 0 | H6: 0 | I6: 0 | J6: 0 | K6: Black | L6: Very Narrow | M6: 4000K | N6: Constant Current | O6: 08W
A7: 206788 | B7: NRLB08VN50 | D7: 0 | E7: 0 | F7: 0 | G7: 0 | H7: 0 | I7: 0 | J7: 0 | K7: Black | L7: Very Narrow | M7: 5000K | N7: Constant Current | O7: 08W
A8: 206794 | B8: NRLT08VN30 | D8: 0 | E8: 0 | F8: 0 | G8: 0 | H8: 0 | I8: 0 | J8: 0 | K8: Two Color | L8: Very Narrow | M8: 3000K | N8: Constant Current | O8: 08W
A9: 206795 | B9: NRLT08VN40 | D9: 0 | E9: 0 | F9: 0 | G9: 0 | H9: 0 | I9: 0 | J9: 0 | K9: Two Color | L9: Very Narrow | M9: 4000K | N9: Constant Current | O9: 08W
A10: 206796 | B10: NRLT08VN50 | D10: 0 | E10: 0 | F10: 0 | G10: 0 | H10: 0 | I10: 0 | J10: 0 | K10: Two Color | L10: Very Narrow | M10: 5000K | N10: Constant Current | O10: 08W
A11: 206802 | B11: NRLR08VN30T | D11: 0 | E11: 0 | F11: 0 | G11: 0 | H11: 0 | I11: 0 | J11: 0 | K11: White | L11: Very Narrow | M11: 3000K | N11: TRIAC Dimming | O11: 08W
A12: 206803 | B12: NRLR08VN40T | D12: 0 | E12: 0 | F12: 0 | G12: 0 | H12: 0 | I12: 0 | J12: 0 | K12: White | L12: Very Narrow | M12: 4000K | N12: TRIAC Dimming | O12: 08W
A13: 206804 | B13: NRLR08VN50T | D13: 0 | E13: 0 | F13: 0 | G13: 0 | H13: 0 | I13: 0 | J13: 0 | K13: White | L13: Very Narrow | M13: 5000K | N13: TRIAC Dimming | O13: 08W
... A43: 206917 | B43: NRLT08VN26BTD | D43: 0 | E43: 0 | F43: 0 | G43: 0 | H43: 0 | I43: 0 | J43: 0 | K43: Two Color | L43: Very Narrow | M43: 2700K - 6000K | N43: Bluetooth Dual | O43: 08W
