Workbook

Sheet Stock Item
A1: Name | B1: Group Name | C1: Units | D1: Name of BOM | E1: Unit of manufacture | F1: BOM Component - Item Name | G1: BOM Component - Quantity | H1: BOM Component - Godown | I1: BOM Component - Type of Item | J1: BOM Component - Rate (%) | K1: BOM Component - Location | L1: Unit Price | M1: Cost | N1: USD | O1: INS&FRED | P1: BCD | Q1: Total Cost
A2: =$D$2 -> NRRR12W30 | B2: Down light Series | C2: Nos. | D2: NRRR12W30 | E2: 1 | F2: ='Backend data'!C6 -> Trim-O-68 I-51 H-63mm White NRRR8-18W | G2: 1 | H2: Mechanical Store | I2: Component | L2: =Q2*87 -> 55.9845 | M2: =L2*G2 -> 55.9845 | N2: 0.429 | O2: 0.5 | Q2: =N2+(N2*(O2+P2)) -> 0.6435
F3: HS 50x34.5mm (SR-DR-NR-12W) | G3: 1 | H3: Mechanical Store | I3: Component | L3: =Q3*87 -> 60.291 | M3: =L3*G3 -> 60.291 | N3: 0.462 | O3: 0.5 | Q3: =N3+(N3*(O3+P3)) -> 0.693
F4: Refl. 50027-W OD-50 LES ID-20 H-26.5mm 8-18W (Honghui) | G4: 1 | H4: Mechanical Store | I4: Component | L4: =Q4*87 -> 7.83 | M4: =L4*G4 -> 7.83 | N4: =0.06 -> 0.06 | O4: 0.5 | Q4: =N4+(N4*(O4+P4)) -> 0.09
F5: ='Backend data'!F6 -> Lens 50027-W D-20 H-11.82 ID-15mm 40° - 8-18W | G5: 1 | H5: Mechanical Store | I5: Component
F6: COB Holder 50027-W OD-38 ID-17 H-3.5mm 8-18W (Honghui) | G6: 1 | H6: Mechanical Store | I6: Component
F7: Locking Spring L-57 W-10mm T-0.2mm DR/NR-5/18W | G7: 2 | H7: Mechanical Store | I7: Component | L7: 2.22 | M7: =L7*G7 -> 4.44 | N7: =0.06/2 -> 0.03 | O7: 0.5 | Q7: =N7+(N7*(O7+P7)) -> 0.045
F8: PBX-COB 8-15W | G8: 1 | H8: Mechanical Store | I8: Component | L8: 8.5 | M8: =L8*G8 -> 8.5
F9: SBX-COB 8-18W (12Nos) | G9: 0.08 | H9: Mechanical Store | I9: Component | L9: 27 | M9: =L9*G9 -> 2.16
F10: Conn. 2Pin Ass. Wire Black Male (Small) | G10: 1 | H10: Mechanical Store | I10: Component | L10: =Q10*87 -> 3.915 | M10: =L10*G10 -> 3.915 | N10: =0.06/2 -> 0.03 | O10: 0.5 | Q10: =N10+(N10*(O10+P10)) -> 0.045
F11: Sleeve M4mm Fiber Glass White | G11: 0.12 | H11: Mechanical Store | I11: Component | L11: =5.7/1000*120 -> 0.684 | M11: =L11*G11 -> 0.08208
F12: Wire Clip-M3-MS | G12: 1 | H12: Mechanical Store | I12: Component | L12: 0.6 | M12: =L12*G12 -> 0.6
F13: Screw No. 4X6.5mm Self Pan Combi. PH - SS | G13: 1 | H13: Mechanical Store | I13: Component | L13: 0.21 | M13: =L13*G13 -> 0.21
F14: Screw M3X6mm CSK PH - SS | G14: 2 | H14: Mechanical Store | I14: Component | L14: 0.48 | M14: =L14*G14 -> 0.96
F15: Rivet 1/8" x 1/4" MS (Big) | G15: 4 | H15: Mechanical Store | I15: Component | L15: 0.23 | M15: =L15*G15 -> 0.92
I16: Component | L16: 0 | M16: =L16*G16 -> 0
F17: ='Backend data'!G6 -> COB 30-36W 3000K 12LED 34-38V 890mA 19x19mm CRI-90 | G17: 1 | H17: Electronics Store | I17: Component | L17: =Q17*87 -> 84.825 | M17: =L17*G17 -> 84.825 | N17: =0.65 -> 0.65 | O17: 0.5 | Q17: =N17+(N17*(O17+P17)) -> 0.975
F18: ='Backend data'!H6 -> PS 12-20W 300mA 36-72V Maxic (PCB LT-MX-20W-V2) | G18: 1 | H18: Mechanical Store | I18: Component | L18: 0 | M18: =L18*G18 -> 0 | N18: PS Rate Mention with Total Amt
M19: =SUM(M2:M18) -> 230.71758
K21: NRRR12-CC | M21: =M19+98 -> 328.71758
K22: NRRR12 Track Dimming | M22: =M19+275 -> 505.71758
K23: NRRR12 Dali Single Color | M23: =((M19)+(Q23*87)) -> 888.43758 | N23: 5.04 | O23: 0.5 | Q23: =N23+(N23*(O23+P23)) -> 7.56
K24: NRRR12 BT Single Color | M24: =M19+330 -> 560.71758
K25: NRRR12 Dali Dual Color | M25: =((M19)+(Q25*87)) -> 945.20508 | N25: 5.475 | O25: 0.5 | Q25: =N25+(N25*(O25+P25)) -> 8.2125
K26: NRRR12 BT Dual Color | M26: =M19+330 -> 560.71758

Sheet Stock Item (Read Me)
A1: List of Fields | B1: Applicable Countries | C1: Applicable Values
A2: General Details
A3: Name | B3: All | E3: Read the following, before you start using the sample file:
A4: Group Name | B4: All | E4: Stock Item worksheet:
A5: B | B5: All | E5: - Use the worksheet without making any changes to the column headers to enter your business data. - The column headers represent field names in TallyPrime. Mandatory fields are marked in bold for easy reference. - Add new columns, if needed. Ensure to enter Column Headers exactly as mentioned under the List of Fields of the Read Me worksheet. - Delete unwanted columns. However, do not delete columns that represent mandatory fields for masters.
A6: Part No. | B6: All
A7: Alias - Part No. | B7: All
A8: Description | B8: All
A9: Notes | B9: All
A10: Category | B10: All
A11: Units | B11: All | E11: Stock Item (Read Me)
A12: Conversion | B12: All | E12: - The Read Me worksheet is only for your reference. It lists all the fields, with related details, applicable for Stock Item.
A13: Denominator | B13: All
A14: Alternate Units | B14: All | E14: For more information on using Sample Excel File for importing data, refer to | M14: TallyHelp
A15: GST Applicability | B15: All | C15: Applicable, Not Applicable
A16: Opening Balance - Quantity | B16: All
A17: Opening Balance - Rate | B17: All
A18: Opening Balance - Rate Per | B18: All
A19: Opening Balance - Value | B19: All
A20: Language for Name (Except English) | B20: All
A21: Is TCS Applicable | B21: All
A22: Item Allocations Details
A23: Item Allocations - Godown | B23: (When Accounting Terminology is set to "India/SAARC")
A24: Item Allocations - Batch | B24: All
A25: Item Allocations - Quantity | B25: All
A26: Item Allocations - Rate | B26: All
A27: Item Allocations - Rate per | B27: All
A28: Item Allocations - Amount | B28: All
A29: Item Allocations - Mfg. Date | B29: All
A30: Item Allocations - Expiry Date | B30: All
A31: Item Allocations - Location | B31: (When Accounting Terminology is set to "International")
A32: Additional Details
A33: Maintain in Batches | B33: All
A34: Track date of manufacturing | B34: All
A35: Use expiry dates | B35: All
A36: Enable Cost Tracking | B36: All
A37: Costing Method | B37: All | C37: At Zero Cost, Avg. Cost, FIFO, FIFO Perpetual, Last Purchase Cost, LIFO Annual, LIFO Perpetual, Monthly Avg. Cost, Std. Cost
A38: Market Valuation Method | B38: All | C38: At Zero Price, Avg. Price, Last Sale Price, Std. Price
A39: Behaviour
A40: Ignore difference due to physical counting | B40: All
...

Sheet Backend data
C2: TRIM | D2: HOUSING/HS | E2: REFLECTOR | F2: BEAM ANGLE | G2: COLOR TEMP | H2: DRIVING SYSTEM | I2: EXTRA
C3: =MID('Stock Item'!$D$2,4,1) -> R | D3: =MID('Stock Item'!$D$2,5,2) -> 12 | E3: =MID('Stock Item'!$D$2,3,1) -> R | F3: =MID('Stock Item'!$D$2,7,1) -> W | G3: =MID('Stock Item'!$D$2,8,2) -> 30 | H3: =MID('Stock Item'!$D$2,10,11) | I3: =MID('Stock Item'!$D$2,2,1) -> R
D4: =CONCATENATE($C$3,$D$3) -> R12 | G4: =CONCATENATE($G$3,$H$3,"-") -> 30- | H4: =CONCATENATE($D$3,H3,"-") -> 12-
H5: =CONCATENATE('Stock Item'!D2) -> NRRR12W30
B6: Formulae | C6: =VLOOKUP($C$3,$B$23:$E$72,2,0) -> Trim-O-68 I-51 H-63mm White NRRR8-18W | D6: =VLOOKUP($D$4,G23:$J$100,2,0) -> HS 50x34.5mm (SR-DR-NR-12W) | E6: =VLOOKUP($E$3,$L$23:$O$72,2,0) -> #N/A | F6: =VLOOKUP($F$3,$Q$23:$T$72,2,0) -> Lens 50027-W D-20 H-11.82 ID-15mm 40° - 8-18W | G6: =VLOOKUP($G$4,$V$23:$Y$72,2,0) -> COB 30-36W 3000K 12LED 34-38V 890mA 19x19mm CRI-90 | H6: =VLOOKUP($H$4,$AA$23:$AD$72,2,0) -> PS 12-20W 300mA 36-72V Maxic (PCB LT-MX-20W-V2) | I6: =VLOOKUP($I$3,AF23:$AI$100,2,0) -> #N/A
B7: Formulae for COST | C7: =VLOOKUP($C$3,$B$23:$E$72,4,0) -> 0 | D7: =VLOOKUP($D$4,G23:$J$100,4,0) -> 0 | E7: =VLOOKUP($E$3,$L$23:$O$72,4,0) -> #N/A | F7: =VLOOKUP($F$3,$Q$23:$T$72,4,0) -> 0 | G7: =VLOOKUP($G$4,$V$23:$Y$72,4,0) -> 0 | H7: =VLOOKUP($H$4,$AA$23:$AD$72,4,0) -> 0 | I7: =VLOOKUP($I$3,$AF$23:$AI$100,4,0) -> #N/A
B8: Formulae for Quantity | C8: =VLOOKUP($C$3,$B$23:$E$72,3,0) -> 0 | D8: =VLOOKUP($D$4,G23:$J$100,3,0) -> 0 | E8: =VLOOKUP($E$3,$L$23:$O$72,3,0) -> #N/A | F8: =VLOOKUP($F$3,$Q$23:$T$72,3,0) -> 0 | G8: =VLOOKUP($G$4,$V$23:$Y$72,3,0) -> 0 | H8: =VLOOKUP($H$4,$AA$23:$AD$72,3,0) -> 0 | I8: =VLOOKUP($I$3,$AF$23:$AI$100,3,0) -> #N/A
H10: BOM LED PCB
B21: TRIM | G21: HOUSING/HS | L21: REFLECTOR | Q21: BEAM ANGLE | V21: COLOUR TEMPERATURE | AA21: DRIVING SYSTEM | AF21: EXTRA
B22: Code | C22: Item Name | D22: Quantity | E22: Cost | G22: Code | H22: Item Name | I22: Quantity | J22: Cost | L22: Code | M22: Item Name | N22: Quantity | O22: Cost | Q22: Code | R22: Item Name | S22: Quantity | T22: Cost | V22: Code | W22: Item Name | X22: Quantity | Y22: Cost | AA22: Code | AB22: Item Name | AC22: Quantity | AD22: Cost | AF22: Code | AG22: Item Name | AH22: Quantity | AI22: Cost
B23: R | C23: Trim-O-68 I-51 H-63mm White NRRR8-18W | Q23: W | R23: Lens 50027-W D-20 H-11.82 ID-15mm 40° - 8-18W | V23: 27- | W23: COB 30W 2700K 12LED 34-38V 890mA 19x19mm CRI-90 | AA23: 08- | AB23: PS 8W 200MA 36V LPF (PCB MT43-8-12W-V2 LPF)
B24: B | C24: Trim-O-68 I-51 H-63mm Black NRRR8-18W | V24: 30- | W24: COB 30-36W 3000K 12LED 34-38V 890mA 19x19mm CRI-90 | AA24: 08T- | AB24: PS 8W 200MA 36V Triac Dimming
B25: T | C25: Trim-O-68 I-51 H-63mm Inner Black NRRR8-18W | V25: 40- | W25: COB 30-36W 4000K 12LED 34-38V 890mA 19x19mm CRI-90 | AA25: 08I- | AB25: Dali Driver SC-10W PE19DA4240 (AI-Dimming)-25-40V
G26: R12 | H26: HS 50x34.5mm (SR-DR-NR-12W) | V26: 50- | W26: COB 30-36W 5000K 12LED 34-38V 890mA 19x19mm CRI-90 | AA26: 08BT- | AB26: PS CCT 8W 170MA 36V BT-SC (PCB LT 7-20W-CCT-V 1.1 REV-1)
V27: 60- | W27: COB 30-36W 6000K 12LED 34-38V 890mA 19x19mm CRI-90 | AA27: 08ID- | AB27: Dali Driver DC-10W PE694R4230(AI-Dimming)-25-40V
AA28: 08BTD- | AB28: PS CCT 8W 170MA 36V BT-DC (PCB LT 7-20W-CCT-V 1.1 REV-1)
V29: 27T- | W29: COB 30W 2700K 12LED 34-38V 890mA 19x19mm CRI-90
V30: 30T- | W30: COB 30-36W 3000K 12LED 34-38V 890mA 19x19mm CRI-90 | AA30: 12- | AB30: PS 12-20W 300mA 36-72V Maxic (PCB LT-MX-20W-V2)
V31: 40T- | W31: COB 30-36W 4000K 12LED 34-38V 890mA 19x19mm CRI-90 | AA31: 12T- | AB31: PS 12W 300mA 36V Triac Dimming
V32: 50T- | W32: COB 30-36W 5000K 12LED 34-38V 890mA 19x19mm CRI-90 | AA32: 12I- | AB32: Dali Driver SC-10W PE19DA4240 (AI-Dimming)-25-40V
V33: 60T- | W33: COB 30-36W 6000K 12LED 34-38V 890mA 19x19mm CRI-90 | AA33: 12BT- | AB33: PS CCT 12W 250MA 36V BT-SC (PCB LT 7-20W-CCT-V 1.1 REV-1)
AA34: 12ID- | AB34: Dali Driver DC-10W PE694R4230(AI-Dimming)-25-40V
V35: 27I- | W35: COB 30W 2700K 12LED 34-38V 890mA 19x19mm CRI-90 | AA35: 12BTD- | AB35: PS CCT 12W 250MA 36V BT-DC (PCB LT 7-20W-CCT-V 1.1 REV-1)
V36: 30I- | W36: COB 30-36W 3000K 12LED 34-38V 890mA 19x19mm CRI-90
V37: 40I- | W37: COB 30-36W 4000K 12LED 34-38V 890mA 19x19mm CRI-90 | AA37: 15- | AB37: PS 15W 370mA 36V Maxic(PCB LT-MX-20W-V2)
V38: 50I- | W38: COB 30-36W 5000K 12LED 34-38V 890mA 19x19mm CRI-90 | AA38: 15T- | AB38: PS 15W 350mA 25-42V Triac Dimm
V39: 60I- | W39: COB 30-36W 6000K 12LED 34-38V 890mA 19x19mm CRI-90 | AA39: 15I- | AB39: Dali Driver SC-15-20W PE19DA4240 (AI-Dimming)9-42V
V40: 26ID- | W40: LED COB Dual Colour 30W (2700K-5000k) | AA40: 15BT- | AB40: PS CCT 15W 320MA 36V BT-SC (PCB LT 7-20W-CCT-V 1.1 REV-1)
AA41: 15ID- | AB41: Dali Driver DC-20W PE69R4240 (AI-Dimming)-25-40V
V42: 27BT- | W42: COB 30W 2700K 12LED 34-38V 890mA 19x19mm CRI-90 | AA42: 15BTD- | AB42: PS CCT 15W 320MA 36V BT-DC (PCB LT 7-20W-CCT-V 1.1 REV-1)
V43: 30BT- | W43: COB 30-36W 3000K 12LED 34-38V 890mA 19x19mm CRI-90
V44: 40BT- | W44: COB 30-36W 4000K 12LED 34-38V 890mA 19x19mm CRI-90 | AA44: 18- | AB44: PS 18W 440mA 36V Maxic(PCB LT-MX-20W-V2)
V45: 50BT- | W45: COB 30-36W 5000K 12LED 34-38V 890mA 19x19mm CRI-90 | AA45: 18T- | AB45: PS 18W 450mA 36V Track Dimming
V46: 60BT- | W46: COB 30-36W 6000K 12LED 34-38V 890mA 19x19mm CRI-90 | AA46: 18I- | AB46: Dali Driver SC-15-20W PE19DA4240 (AI-Dimming)9-42V
V47: 26BTD- | W47: LED COB Dual Colour 30W (2700K-5000k) | AA47: 18BT- | AB47: PS CCT 18W 375MA 36V BT-SC (PCB LT 7-20W-CCT-V 1.1 REV-1)
AA48: 18ID- | AB48: Dali Driver DC-20W PE69R4240 (AI-Dimming)-25-40V
AA49: 18BTD- | AB49: PS CCT 18W 375MA 36V BT-DC (PCB LT 7-20W-CCT-V 1.1 REV-1)

Sheet Result (2)
A1: SKU Id | B1: SKU Code | C1: Product Name | D1: Cost Price | E1: Retail Price | F1: Selling Price | G1: Weight | H1: Width | I1: Height | J1: Depth | K1: Beam Angle | L1: Color Temp | M1: Driving System | N1: Trim | O1: Watt
A2: 203535 | B2: NRRR12W50 | D2: 0 | E2: 0 | F2: 0 | G2: 0 | H2: 0 | I2: 0 | J2: 0 | K2: Wide - 40° | L2: 5000K | M2: Constant Current | N2: Round White Trim | O2: 12 Watt
A3: 203536 | B3: NRRR12W40 | D3: 0 | E3: 0 | F3: 0 | G3: 0 | H3: 0 | I3: 0 | J3: 0 | K3: Wide - 40° | L3: 4000K | M3: Constant Current | N3: Round White Trim | O3: 12 Watt
A4: 203537 | B4: NRRR12W30 | D4: 0 | E4: 0 | F4: 0 | G4: 0 | H4: 0 | I4: 0 | J4: 0 | K4: Wide - 40° | L4: 3000K | M4: Constant Current | N4: Round White Trim | O4: 12 Watt
A5: 203539 | B5: NRRB12W50 | D5: 0 | E5: 0 | F5: 0 | G5: 0 | H5: 0 | I5: 0 | J5: 0 | K5: Wide - 40° | L5: 5000K | M5: Constant Current | N5: Round Black Trim | O5: 12 Watt
A6: 203540 | B6: NRRB12W40 | D6: 0 | E6: 0 | F6: 0 | G6: 0 | H6: 0 | I6: 0 | J6: 0 | K6: Wide - 40° | L6: 4000K | M6: Constant Current | N6: Round Black Trim | O6: 12 Watt
A7: 203541 | B7: NRRB12W30 | D7: 0 | E7: 0 | F7: 0 | G7: 0 | H7: 0 | I7: 0 | J7: 0 | K7: Wide - 40° | L7: 3000K | M7: Constant Current | N7: Round Black Trim | O7: 12 Watt
A8: 203543 | B8: NRRT12W50 | D8: 0 | E8: 0 | F8: 0 | G8: 0 | H8: 0 | I8: 0 | J8: 0 | K8: Wide - 40° | L8: 5000K | M8: Constant Current | N8: Round Two Color Trim | O8: 12 Watt
A9: 203544 | B9: NRRT12W40 | D9: 0 | E9: 0 | F9: 0 | G9: 0 | H9: 0 | I9: 0 | J9: 0 | K9: Wide - 40° | L9: 4000K | M9: Constant Current | N9: Round Two Color Trim | O9: 12 Watt
A10: 203545 | B10: NRRT12W30 | D10: 0 | E10: 0 | F10: 0 | G10: 0 | H10: 0 | I10: 0 | J10: 0 | K10: Wide - 40° | L10: 3000K | M10: Constant Current | N10: Round Two Color Trim | O10: 12 Watt
A11: 203583 | B11: NRRR12W50T | D11: 0 | E11: 0 | F11: 0 | G11: 0 | H11: 0 | I11: 0 | J11: 0 | K11: Wide - 40° | L11: 5000K | M11: TRIAC Dimming | N11: Round White Trim | O11: 12 Watt
A12: 203584 | B12: NRRR12W40T | D12: 0 | E12: 0 | F12: 0 | G12: 0 | H12: 0 | I12: 0 | J12: 0 | K12: Wide - 40° | L12: 4000K | M12: TRIAC Dimming | N12: Round White Trim | O12: 12 Watt
A13: 203585 | B13: NRRR12W30T | D13: 0 | E13: 0 | F13: 0 | G13: 0 | H13: 0 | I13: 0 | J13: 0 | K13: Wide - 40° | L13: 3000K | M13: TRIAC Dimming | N13: Round White Trim | O13: 12 Watt
... A43: 203786 | B43: NRRT12W26BTD | D43: 0 | E43: 0 | F43: 0 | G43: 0 | H43: 0 | I43: 0 | J43: 0 | K43: Wide - 40° | L43: 2700K - 6000K Dual Color | M43: Bluetooth + Dual Color (2700K - 6000K) | N43: Round Two Color Trim | O43: 12 Watt
