Workbook

Sheet Stock Item
A1: Name | B1: Group Name | C1: Units | D1: Name of BOM | E1: Unit of manufacture | F1: BOM Component - Item Name | G1: BOM Component - Quantity | H1: BOM Component - Godown | I1: BOM Component - Type of Item | J1: BOM Component - Rate (%) | K1: BOM Component - Location | L1: Unit Price | M1: Cost | N1: USD | O1: INS&FRED | P1: BCD | Q1: Total Cost
A2: =$D$2 -> RDCR18W30 | C2: Nos. | D2: RDCR18W30 | E2: 1 | F2: ='Backend data'!C6 -> TRIM - OD-83.5 ID -65 H-46mmWHITE - EV-1910 RDCR18W | G2: 1 | H2: Mechanical Store | I2: Component | L2: =Q2*87 -> 205.5375 | M2: =L2*G2 -> 205.5375 | N2: 1.575 | O2: 0.5 | Q2: =N2+(N2*(O2+P2)) -> 2.3625
F3: HS 55mm (Zhouhe) Use Samsei - GLWR18W | G3: 1 | H3: Mechanical Store | I3: Component
F4: Primary Refl- OD-45mm, H-12mm , L- 20mm | G4: 1 | H4: Mechanical Store | I4: Component
F5: Diff. 50014-W D-49.5 T-1.2mm Frosted - 8-18W | G5: 1 | H5: Mechanical Store | I5: Component
F6: COB Holder 50014-W OD-35 ID-17 H-3.5mm 8-18W | G6: 1 | H6: Mechanical Store | I6: Component
F7: HS Ring - OD- 50mm , ID -46mm , H-14MM. | G7: 1 | H7: Mechanical Store | I7: Component
F8: Locking Spring-L-45 W-15.5 T-0.2mm-SS | G8: 2 | H8: Mechanical Store | I8: Component
F9: Refl. 50014-W OD-50 LES ID -20.5 H-13.4mm 8-18W | G9: 1 | H9: Mechanical Store | I9: Component | L9: =Q9*87 -> 7.4385 | M9: =L9*G9 -> 7.4385 | N9: 0.057 | O9: 0.5 | Q9: =N9+(N9*(O9+P9)) -> 0.0855
F10: PBX - COB 8-15W | G10: 1 | H10: Mechanical Store | I10: Component | L10: 8.5 | M10: =L10*G10 -> 8.5
F11: SBX - COB 8-18W (12Nos) | G11: 0.08 | H11: Mechanical Store | I11: Component | L11: 27 | M11: =L11*G11 -> 2.16
F12: Sleeve M4mm Fiber Glass White | G12: 0.12 | H12: Mechanical Store | I12: Component | L12: =5.7/1000*120 -> 0.684 | M12: =L12*G12 -> 0.08208
F13: Screw M3x6.5mm Self Csk Head Ss | G13: 2 | H13: Mechanical Store | I13: Component | L13: 0.15 | M13: =L13*G13 -> 0.3
F14: screw-M3X6mm CSK HEAD - SS | G14: 2 | H14: Mechanical Store | I14: Component | L14: 0.48 | M14: =L14*G14 -> 0.96
F15: Conn. 2Pin Ass. Wire Black Male (Small) | G15: 1 | H15: Mechanical Store | I15: Component | L15: =Q15*87 -> 3.915 | M15: =L15*G15 -> 3.915 | N15: =0.06/2 -> 0.03 | O15: 0.5 | Q15: =N15+(N15*(O15+P15)) -> 0.045
L16: =Q16*87 -> 0 | M16: =L16*G16 -> 0
F17: ='Backend data'!G6 -> COB 30-36W 3000K 12LED 34-38V 890mA 19x19mm CRI-90 | G17: 1 | H17: Electronics Store | I17: Component | L17: =Q17*87 -> 84.825 | M17: =L17*G17 -> 84.825 | N17: 0.65 | O17: 0.5 | Q17: =N17+(N17*(O17+P17)) -> 0.975
F18: ='Backend data'!H6 -> PS 18W 440mA 36V Maxic(PCB LT-MX-20W-V2) | G18: 1 | H18: Mechanical Store | I18: Component | L18: =Q18*87 -> 0 | M18: =L18*G18 -> 0 | N18: PS Rate Mention with Total Amt
M19: =SUM(M2:M18) -> 313.71808
K21: RDCR18-CC | M21: =M19+98 -> 411.71808

Sheet Stock Item (Read Me)
A1: List of Fields | B1: Applicable Countries | C1: Applicable Values
A2: General Details
A3: Name | B3: All | E3: Read the following, before you start using the sample file:
A4: Group Name | B4: All | E4: Stock Item worksheet:
A5: B | B5: All | E5: - Use the worksheet without making any changes to the column headers to enter your business data. - The column headers represent field names in TallyPrime. Mandatory fields are marked in bold for easy reference. - Add new columns, if needed. Ensure to enter Column Headers exactly as mentioned under the List of Fields of the Read Me worksheet. - Delete unwanted columns. However, do not delete columns that represent mandatory fields for masters.
A6: Part No. | B6: All
A7: Alias - Part No. | B7: All
A8: Description | B8: All
A9: Notes | B9: All
A10: Category | B10: All
A11: Units | B11: All | E11: Stock Item (Read Me)
A12: Conversion | B12: All | E12: - The Read Me worksheet is only for your reference. It lists all the fields, with related details, applicable for Stock Item.
A13: Denominator | B13: All
A14: Alternate Units | B14: All | E14: For more information on using Sample Excel File for importing data, refer to | M14: TallyHelp
A15: GST Applicability | B15: All | C15: Applicable, Not Applicable
A16: Opening Balance - Quantity | B16: All
A17: Opening Balance - Rate | B17: All
A18: Opening Balance - Rate Per | B18: All
A19: Opening Balance - Value | B19: All
A20: Language for Name (Except English) | B20: All
A21: Is TCS Applicable | B21: All
A22: Item Allocations Details
A23: Item Allocations - Godown | B23: (When Accounting Terminology is set to "India/SAARC")
A24: Item Allocations - Batch | B24: All
A25: Item Allocations - Quantity | B25: All
A26: Item Allocations - Rate | B26: All
A27: Item Allocations - Rate per | B27: All
A28: Item Allocations - Amount | B28: All
A29: Item Allocations - Mfg. Date | B29: All
A30: Item Allocations - Expiry Date | B30: All
A31: Item Allocations - Location | B31: (When Accounting Terminology is set to "International")
A32: Additional Details
A33: Maintain in Batches | B33: All
A34: Track date of manufacturing | B34: All
A35: Use expiry dates | B35: All
A36: Enable Cost Tracking | B36: All
A37: Costing Method | B37: All | C37: At Zero Cost, Avg. Cost, FIFO, FIFO Perpetual, Last Purchase Cost, LIFO Annual, LIFO Perpetual, Monthly Avg. Cost, Std. Cost
A38: Market Valuation Method | B38: All | C38: At Zero Price, Avg. Price, Last Sale Price, Std. Price
A39: Behaviour
A40: Ignore difference due to physical counting | B40: All
...

Sheet Backend data
C2: TRIM | D2: HOUSING/HS | E2: REFLECTOR | F2: BEAM ANGLE | G2: COLOR TEMP | H2: DRIVING SYSTEM | I2: EXTRA
C3: =MID('Stock Item'!$D$2,4,1) -> R | D3: =MID('Stock Item'!$D$2,5,2) -> 18 | E3: =MID('Stock Item'!$D$2,4,1) -> R | F3: =MID('Stock Item'!$D$2,8,1) -> 3 | G3: =MID('Stock Item'!$D$2,8,2) -> 30 | H3: =MID('Stock Item'!$D$2,10,12) | I3: =MID('Stock Item'!$D$2,2,1) -> D
D4: =CONCATENATE($D$3,$F$3) -> 183 | G4: =CONCATENATE(G3,$H$3,"-") -> 30- | H4: =CONCATENATE($D$3,$H$3,"-") -> 18-
B6: Formulae | C6: =VLOOKUP($C$3,$B$23:$E$72,2,0) -> TRIM - OD-83.5 ID -65 H-46mmWHITE - EV-1910 RDCR18W | D6: =VLOOKUP($D$4,G23:$J$100,2,0) -> #N/A | E6: =VLOOKUP($E$3,$L$23:$O$72,2,0) -> #N/A | F6: =VLOOKUP($F$3,$Q$23:$T$72,2,0) -> #N/A | G6: =VLOOKUP($G$4,$V$23:$Y$72,2,0) -> COB 30-36W 3000K 12LED 34-38V 890mA 19x19mm CRI-90 | H6: =VLOOKUP($H$4,$AA$23:$AD$72,2,0) -> PS 18W 440mA 36V Maxic(PCB LT-MX-20W-V2) | I6: =VLOOKUP($I$3,AF23:$AI$100,2,0) -> #N/A
B7: Formulae for COST | C7: =VLOOKUP($C$3,$B$23:$E$72,4,0) -> 0 | D7: =VLOOKUP($D$4,G23:$J$100,4,0) -> #N/A | E7: =VLOOKUP($E$3,$L$23:$O$72,4,0) -> #N/A | F7: =VLOOKUP($F$3,$Q$23:$T$72,4,0) -> #N/A | G7: =VLOOKUP($G$4,$V$23:$Y$72,4,0) -> 0 | H7: =VLOOKUP($H$4,$AA$23:$AD$72,4,0) -> 0 | I7: =VLOOKUP($I$3,$AF$23:$AI$100,4,0) -> #N/A
B8: Formulae for Quantity | C8: =VLOOKUP($C$3,$B$23:$E$72,3,0) -> 0 | D8: =VLOOKUP($D$4,G23:$J$100,3,0) -> #N/A | E8: =VLOOKUP($E$3,$L$23:$O$72,3,0) -> #N/A | F8: =VLOOKUP($F$3,$Q$23:$T$72,3,0) -> #N/A | G8: =VLOOKUP($G$4,$V$23:$Y$72,3,0) -> 0 | H8: =VLOOKUP($H$4,$AA$23:$AD$72,3,0) -> 0 | I8: =VLOOKUP($I$3,$AF$23:$AI$100,3,0) -> #N/A
B21: TRIM | G21: HOUSING/HS | L21: REFLECTOR | Q21: BEAM ANGLE | V21: COLOR TEMPERATURE | AA21: DRIVING SYSTEM | AF21: EXTRA
B22: Code | C22: Item Name | D22: Quantity | E22: Cost | G22: Code | H22: Item Name | I22: Quantity | J22: Cost | L22: Code | M22: Item Name | N22: Quantity | O22: Cost | Q22: Code | R22: Item Name | S22: Quantity | T22: Cost | V22: Code | W22: Item Name | X22: Quantity | Y22: Cost | AA22: Code | AB22: Item Name | AC22: Quantity | AD22: Cost | AF22: Code | AG22: Item Name | AH22: Quantity | AI22: Cost
B23: R | C23: TRIM - OD-83.5 ID -65 H-46mmWHITE - EV-1910 RDCR18W | AA23: 18- | AB23: PS 18W 440mA 36V Maxic(PCB LT-MX-20W-V2) | AF23: 08W- | AG23: PBX-NRRR-08W
V24: 30- | W24: COB 30-36W 3000K 12LED 34-38V 890mA 19x19mm CRI-90 | AA24: 18T- | AB24: PS - 18W, 36V, 440mA-TRIAC
V25: 40- | W25: COB 30-36W 4000K 12LED 34-38V 890mA 19x19mm CRI-90 | AA25: 18I- | AB25: PS - 18W, 36V, 440mA-DALI
V26: 50- | W26: COB 30-36W 5000K 12LED 34-38V 890mA 19x19mm CRI-90 | AA26: 18BT- | AB26: PS - 18W, 36V, 440mA-BT
V27: 60- | W27: COB 30-36W 6000K 12LED 34-38V 890mA 19x19mm CRI-90 | AA27: 18ID- | AB27: PS - 18W, 36V, 440mA-(DALI+DUAL)
AA28: 18BTD- | AB28: PS - 18W, 36V, 440mA-BTD
V30: 30T- | W30: COB 30-36W 3000K 12LED 34-38V 890mA 19x19mm CRI-90
V31: 40T- | W31: COB 30-36W 4000K 12LED 34-38V 890mA 19x19mm CRI-90
V32: 50T- | W32: COB 30-36W 5000K 12LED 34-38V 890mA 19x19mm CRI-90
V33: 60T- | W33: COB 30-36W 6000K 12LED 34-38V 890mA 19x19mm CRI-90
V36: 30I- | W36: COB 30-36W 3000K 12LED 34-38V 890mA 19x19mm CRI-90
V37: 40I- | W37: COB 30-36W 4000K 12LED 34-38V 890mA 19x19mm CRI-90
V38: 50I- | W38: COB 30-36W 5000K 12LED 34-38V 890mA 19x19mm CRI-90
V39: 60I- | W39: COB 30-36W 6000K 12LED 34-38V 890mA 19x19mm CRI-90
V43: 30BT- | W43: COB 30-36W 3000K 12LED 34-38V 890mA 19x19mm CRI-90
V44: 40BT- | W44: COB 30-36W 4000K 12LED 34-38V 890mA 19x19mm CRI-90
V45: 50BT- | W45: COB 30-36W 5000K 12LED 34-38V 890mA 19x19mm CRI-90
V46: 60BT- | W46: COB 30-36W 6000K 12LED 34-38V 890mA 19x19mm CRI-90
