Workbook

Sheet Stock Item
A1: Name | B1: Group Name | C1: Units | D1: Name of BOM | E1: Unit of manufacture | F1: BOM Component - Item Name | G1: BOM Component - Quantity | H1: BOM Component - Godown | I1: BOM Component - Type of Item | J1: BOM Component - Rate (%) | K1: BOM Component - Location | L1: Unit Price | M1: Cost | N1: USD | O1: INS&FRED | P1: BCD | Q1: Total Cost
A2: =$D$2 -> RSDR12F30 | B2: Down light Series | C2: Nos. | D2: RSDR12F30 | E2: 1 | F2: ='Backend data'!C6 -> Fitting RSDR12W- Round White | G2: 1 | H2: Mechanical Store | I2: Component | L2: 40 | M2: =G2*L2 -> 40
F3: Diff OD- 119 ID-116 H-8mm T-1.5mm | G3: 1 | H3: Mechanical Store | I3: Component
F4: Bracket W-25 L-90 H-14mm. | G4: 1 | H4: Mechanical Store | I4: Component
F5: Conn. 2 pin ass. Wire Black male (small) | G5: 1 | H5: Mechanical Store | I5: Component | L5: =Q5*87 -> 3.915 | M5: =G5*L5 -> 3.915 | N5: 0.03 | O5: 0.5 | Q5: =N5+(N5*(O5+P5)) -> 0.045
F6: PBX-FRDR15W & SBDR16W | G6: 1 | H6: Mechanical Store | I6: Component | L6: 8.5 | M6: =G6*L6 -> 8.5
F7: SBX FRDR15-20W (12Nos) | G7: 0.08 | H7: Mechanical Store | I7: Component | L7: 27 | M7: =G7*L7 -> 2.16
F8: Sleeve M4mm Fiber Glass White | G8: 0.12 | H8: Mechanical Store | I8: Component | L8: =5.7/1000*120 -> 0.684 | M8: =G8*L8 -> 0.08208
F9: Screw M3x6mm CSK Head SS | G9: 3 | H9: Mechanical Store | I9: Component | L9: 0.48 | M9: =G9*L9 -> 1.44
F10: =D13 -> RSDR12F30 BOM LED PCB | G10: 1 | H10: Mechanical Store | I10: Component
F11: ='Backend data'!H6 -> PS 8-12W 300mA 36V Power Plazza (RSDR12W) | G11: 1 | H11: Mechanical Store | I11: Component | L11: =Q11*87 -> 0 | M11: =G11*L11 -> 0 | N11: PS Rate Mention with Total Amt
L12: =Q12*87 -> 0 | M12: =G12*L12 -> 0
A13: =A2 -> RSDR12F30 | B13: Down Light Series | D13: =CONCATENATE('Backend data'!$H$5," ",'Backend data'!H10) -> RSDR12F30 BOM LED PCB | E13: 1 | F13: ='Backend data'!G6 -> LED 2835-60mA-3000K (WW) | G13: 108 | H13: Electronics Store | I13: Component | L13: 0.09 | M13: =G13*L13 -> 9.72
F14: PCB BS-12W ( RSDR12W ) | G14: 1 | H14: Electronics Store | I14: Component | L14: 35.68 | M14: =G14*L14 -> 35.68
M15: =SUM(M2:M14) -> 101.49708
K17: RSDR12-CC | M17: =M15+98 -> 199.49708

Sheet Stock Item (Read Me)
A1: List of Fields | B1: Applicable Countries | C1: Applicable Values
A2: General Details
A3: Name | B3: All | E3: Read the following, before you start using the sample file:
A4: Group Name | B4: All | E4: Stock Item worksheet:
A5: B | B5: All | E5: - Use the worksheet without making any changes to the column headers to enter your business data. - The column headers represent field names in TallyPrime. Mandatory fields are marked in bold for easy reference. - Add new columns, if needed. Ensure to enter Column Headers exactly as mentioned under the List of Fields of the Read Me worksheet. - Delete unwanted columns. However, do not delete columns that represent mandatory fields for masters.
A6: Part No. | B6: All
A7: Alias - Part No. | B7: All
A8: Description | B8: All
A9: Notes | B9: All
A10: Category | B10: All
A11: Units | B11: All | E11: Stock Item (Read Me)
A12: Conversion | B12: All | E12: - The Read Me worksheet is only for your reference. It lists all the fields, with related details, applicable for Stock Item.
A13: Denominator | B13: All
A14: Alternate Units | B14: All | E14: For more information on using Sample Excel File for importing data, refer to | M14: TallyHelp
A15: GST Applicability | B15: All | C15: Applicable, Not Applicable
A16: Opening Balance - Quantity | B16: All
A17: Opening Balance - Rate | B17: All
A18: Opening Balance - Rate Per | B18: All
A19: Opening Balance - Value | B19: All
A20: Language for Name (Except English) | B20: All
A21: Is TCS Applicable | B21: All
A22: Item Allocations Details
A23: Item Allocations - Godown | B23: (When Accounting Terminology is set to "India/SAARC")
A24: Item Allocations - Batch | B24: All
A25: Item Allocations - Quantity | B25: All
A26: Item Allocations - Rate | B26: All
A27: Item Allocations - Rate per | B27: All
A28: Item Allocations - Amount | B28: All
A29: Item Allocations - Mfg. Date | B29: All
A30: Item Allocations - Expiry Date | B30: All
A31: Item Allocations - Location | B31: (When Accounting Terminology is set to "International")
A32: Additional Details
A33: Maintain in Batches | B33: All
A34: Track date of manufacturing | B34: All
A35: Use expiry dates | B35: All
A36: Enable Cost Tracking | B36: All
A37: Costing Method | B37: All | C37: At Zero Cost, Avg. Cost, FIFO, FIFO Perpetual, Last Purchase Cost, LIFO Annual, LIFO Perpetual, Monthly Avg. Cost, Std. Cost
A38: Market Valuation Method | B38: All | C38: At Zero Price, Avg. Price, Last Sale Price, Std. Price
A39: Behaviour
A40: Ignore difference due to physical counting | B40: All
...

Sheet Backend data
C2: TRIM | D2: HOUSING/HS | E2: REFLECTOR | F2: BEAM ANGLE | G2: COLOR TEMP | H2: DRIVING SYSTEM | I2: EXTRA
C3: =MID('Stock Item'!$D$2,4,1) -> R | D3: =MID('Stock Item'!$D$2,6,2) -> 2F | E3: =MID('Stock Item'!$D$2,7,1) -> F | F3: =MID('Stock Item'!$D$2,5,2) -> 12 | G3: =MID('Stock Item'!$D$2,8,2) -> 30 | H3: =MID('Stock Item'!$D$2,10,11) | I3: =MID('Stock Item'!$D$2,2,1) -> S
D4: =CONCATENATE(C3) -> R | G4: =CONCATENATE($G$3,"-") -> 30- | H4: =CONCATENATE($F$3,"-") -> 12-
H5: =CONCATENATE('Stock Item'!D2) -> RSDR12F30
B6: Formulae | C6: =VLOOKUP($C$3,$B$23:$E$72,2,0) -> Fitting RSDR12W- Round White | D6: =VLOOKUP($D$4,G23:$J$100,2,0) -> #N/A | E6: =VLOOKUP($E$3,$L$23:$O$72,2,0) -> #N/A | F6: =VLOOKUP($F$3,$Q$23:$T$72,2,0) -> #N/A | G6: =VLOOKUP($G$4,$V$23:$Y$72,2,0) -> LED 2835-60mA-3000K (WW) | H6: =VLOOKUP($H$4,$AA$23:$AD$72,2,0) -> PS 8-12W 300mA 36V Power Plazza (RSDR12W) | I6: =VLOOKUP($I$3,AF23:$AI$100,2,0) -> #N/A
B7: Formulae for COST | C7: =VLOOKUP($C$3,$B$23:$E$72,4,0) -> 0 | D7: =VLOOKUP($D$4,G23:$J$100,4,0) -> #N/A | E7: =VLOOKUP($E$3,$L$23:$O$72,4,0) -> #N/A | F7: =VLOOKUP($F$3,$Q$23:$T$72,4,0) -> #N/A | G7: =VLOOKUP($G$4,$V$23:$Y$72,4,0) -> 0 | H7: =VLOOKUP($H$4,$AA$23:$AD$72,4,0) -> 0 | I7: =VLOOKUP($I$3,$AF$23:$AI$100,4,0) -> #N/A
B8: Formulae for Quantity | C8: =VLOOKUP($C$3,$B$23:$E$72,3,0) -> 0 | D8: =VLOOKUP($D$4,G23:$J$100,3,0) -> #N/A | E8: =VLOOKUP($E$3,$L$23:$O$72,3,0) -> #N/A | F8: =VLOOKUP($F$3,$Q$23:$T$72,3,0) -> #N/A | G8: =VLOOKUP($G$4,$V$23:$Y$72,3,0) -> 0 | H8: =VLOOKUP($H$4,$AA$23:$AD$72,3,0) -> 0 | I8: =VLOOKUP($I$3,$AF$23:$AI$100,3,0) -> #N/A
H10: BOM LED PCB
B21: TRIM | G21: MOUNTING TRIM | L21: REFLECTOR | Q21: BEAM ANGLE | V21: COLOUR TEMPERATURE | AA21: DRIVING SYSTEM | AF21: EXTRA
B22: Code | C22: Item Name | D22: Quantity | E22: Cost | G22: Code | H22: Item Name | I22: Quantity | J22: Cost | L22: Code | M22: Item Name | N22: Quantity | O22: Cost | Q22: Code | R22: Item Name | S22: Quantity | T22: Cost | V22: Code | W22: Item Name | X22: Quantity | Y22: Cost | AA22: Code | AB22: Item Name | AC22: Quantity | AD22: Cost | AF22: Code | AG22: Item Name | AH22: Quantity | AI22: Cost
B23: R | C23: Fitting RSDR12W- Round White | Q23: M | V23: 60- | W23: LED 2835-60mA-6000K (PW) | AA23: 12- | AB23: PS 8-12W 300mA 36V Power Plazza (RSDR12W)
B24: B | C24: Fitting RSDR12W- Round Black | V24: 50- | W24: LED 2835-60mA-5000K (PW)
B25: T | V25: 40- | W25: LED 2835-60mA-4000K (NW)
V26: 30- | W26: LED 2835-60mA-3000K (WW)
V27: 27- | W27: LED SMD 2835 60mA 2700K (WW)
