Workbook

Sheet Stock Item
A1: Name | B1: Group Name | C1: Units | D1: Name of BOM | E1: Unit of manufacture | F1: BOM Component - Item Name | G1: BOM Component - Quantity | H1: BOM Component - Godown | I1: BOM Component - Type of Item | J1: MODEL NAME | K1: Unit Price | L1: Cost | M1: USD | N1: INS&FRED | O1: BCD | P1: Total Cost
A2: =CONCATENATE(D2) -> SBDR07F30 | B2: Down Light Series | C2: Nos. | D2: SBDR07F30 | E2: 1 | F2: =VLOOKUP('SBDR07-16-24W-DATA'!AA12,'SBDR07-16-24W-DATA'!A2:B4,2,0) -> Housing-O-89.5 H-28 L-61.8mm White SBDR7W | G2: 1 | H2: Mechanical Store | I2: Component | K2: =P2*87 -> 60.1605 | L2: =G2*K2 -> 60.1605 | M2: 0.461 | N2: 0.5 | P2: =M2+(M2*(N2+O2)) -> 0.6915
F3: =VLOOKUP('SBDR07-16-24W-DATA'!AA13,'SBDR07-16-24W-DATA'!E2:F4,2,0) -> Diff-O-61.8 H-6 L-57.8mm-PC SBDR7W | G3: 1 | H3: Mechanical Store | I3: Component
F4: Torsion Spring - L-49 W-18mm Coil D-1mm D-8 Black | G4: 2 | H4: Mechanical Store | I4: Component | K4: =P4*87 -> 1.044 | L4: =G4*K4 -> 2.088 | M4: 0.008 | N4: 0.5 | P4: =M4+(M4*(N4+O4)) -> 0.012
F5: Conn. 2 Pin Ass. Wire Black Male (Small) | G5: 1 | H5: Mechanical Store | I5: Component | K5: =P5*87 -> 3.915 | L5: =G5*K5 -> 3.915 | M5: 0.03 | N5: 0.5 | P5: =M5+(M5*(N5+O5)) -> 0.045
F6: Sleeve M4mm Fiber Glass White | G6: 0.12 | H6: Mechanical Store | I6: Component | K6: =5.7/1000*120 -> 0.684 | L6: =G6*K6 -> 0.08208
F7: Wire Clip-M3-MS | G7: 1 | H7: Mechanical Store | I7: Component | K7: 0.6 | L7: =G7*K7 -> 0.6
F8: Screw M2X6.5mm CSK Self Pan + Head MS | G8: 2 | H8: Mechanical Store | I8: Component | K8: 0.15 | L8: =G8*K8 -> 0.3
F9: Screw M3x6 Pan+ Head SS | G9: 2 | H9: Mechanical Store | I9: Component | K9: 0.53 | L9: =G9*K9 -> 1.06
F10: Screw M3X4 Pan + Head SS | G10: 2 | H10: Mechanical Store | I10: Component | K10: 0.58 | L10: =G10*K10 -> 1.16
F11: =CONCATENATE(D15) -> SBDR07F30 BOM LED PCB | G11: 1 | H11: Electronics Store | I11: Component | K11: =P11*87 -> 0 | L11: =G11*K11 -> 0
F12: =VLOOKUP('SBDR07-16-24W-DATA'!AA16,'SBDR07-16-24W-DATA'!I2:J15,2,0) -> PS 7W 270mA 21V LPF | G12: 1 | H12: Mechanical Store | I12: Component | M12: PS Rate Mention with Total Amt
F13: =VLOOKUP('SBDR07-16-24W-DATA'!$AD$7,'SBDR07-16-24W-DATA'!$V$2:$W$4,2,0) -> PBX - SBDR7W | G13: 1 | H13: Mechanical Store | I13: Component | K13: 6 | L13: =G13*K13 -> 6
F14: =VLOOKUP('SBDR07-16-24W-DATA'!$AE$7,'SBDR07-16-24W-DATA'!V7:$W$9,2,0) -> SBX - COB 8-18W (12Nos) | G14: 0.08 | H14: Mechanical Store | I14: Component | K14: 27 | L14: =G14*K14 -> 2.16
A15: =CONCATENATE(D15) -> SBDR07F30 BOM LED PCB | B15: Down Light Series | C15: Nos. | D15: =CONCATENATE(D2," ",'SBDR07-16-24W-DATA'!AC12) -> SBDR07F30 BOM LED PCB | E15: 1
F16: =VLOOKUP('SBDR07-16-24W-DATA'!AA14,'SBDR07-16-24W-DATA'!S2:T4,2,0) -> PCB-2835-5B7C (55X0.8mm) SBDR07W | G16: 1 | H16: Electronics Store | I16: Component | K16: =P16*87 -> 7.6995 | L16: =G16*K16 -> 7.6995 | M16: 0.059 | N16: 0.5 | P16: =M16+(M16*(N16+O16)) -> 0.0885
F17: =VLOOKUP('SBDR07-16-24W-DATA'!AA15,'SBDR07-16-24W-DATA'!M2:N18,2,0) -> LED 2835-60mA-3000K (WW) | G17: =VLOOKUP('SBDR07-16-24W-DATA'!AA15,'SBDR07-16-24W-DATA'!O2:P18,2,0) -> 35 | H17: Electronics Store | I17: Component | K17: 0.09 | L17: =G17*K17 -> 3.15
L18: =SUM(L2:L17) -> 88.37508
J20: SBDR07W -CC | L20: =L18+42 -> 130.37508

Sheet SBDR07-16-24W-DATA
A1: CODE | B1: Housing | C1: COST | E1: CODE | F1: Diffuser | G1: COST | I1: CODE | J1: DRIVER | K1: COST | M1: CODE | N1: Temperature | O1: CODE | P1: QTY | Q1: COST | S1: CODE | T1: PCB | U1: COST | V1: CODE | W1: BOX | X1: COST
A2: R07 | B2: Housing-O-89.5 H-28 L-61.8mm White SBDR7W | C2: =AD19 -> 59.469 | E2: R07 | F2: Diff-O-61.8 H-6 L-57.8mm-PC SBDR7W | G2: =AC19 -> 59.469 | I2: 07- | J2: PS 7W 270mA 21V LPF | K2: 42 | M2: 07F60 | N2: LED 2835-60mA-6000K (PW) | O2: 07F60 | P2: 35 | Q2: 0.1 | S2: R07 | T2: PCB-2835-5B7C (55X0.8mm) SBDR07W | U2: =AC24 -> 7.611 | V2: 07- | W2: PBX - SBDR7W | Z2: Housing | AA2: Watt | AB2: Temperature | AC2: Driver | AD2: PBX | AE2: SBX | AF2: =MID('Stock Item'!D2,1,9) -> SBDR07F30 | AG2: CC
A3: R16 | B3: Housing-O-119.5 H-28 L-95mm White SBDR16W | C3: =AD20 -> 96.492 | E3: R16 | F3: Diff-O-94.5 H-6 L-89mm-PC SBDR16W | G3: =AC20 -> 96.492 | I3: 07-T | J3: PS-7W 21V 300mA-TRIAC | K3: 275 | M3: 07F50 | N3: LED 2835-60mA-5000K (PW) | O3: 07F50 | P3: 35 | Q3: 0.1 | S3: R16 | T3: PCB-2835-5B16C (85.8X0.8mm) SBDR16W | U3: =AC25 -> 19.479 | V3: 16- | W3: PBX-FRDR15W & SBDR16W | Z3: =LEFT('Stock Item'!D2,4) -> SBDR | AA3: =LEFT('Stock Item'!D2,6) -> SBDR07 | AB3: =LEFT('Stock Item'!D2,10) -> SBDR07F30 | AC3: =LEFT('Stock Item'!D2,12) -> SBDR07F30 | AG3: I
A4: R24 | B4: Housing-O-170 H-28 L-143mm White SBDR24W | C4: =AD21 -> 139.578 | E4: R24 | F4: Diff-O-142.5 H-6 L-138.5mm-PC SBDR24W | G4: =AC21 -> 139.578 | I4: 07-I | J4: PS-7W 21V 300mA-DALI | K4: 621 | M4: 07F40 | N4: LED 2835-60mA-4000K (NW) | O4: 07F40 | P4: 35 | Q4: 0.1 | S4: R24 | T4: PCB-2835-5B24C (134X0.8mm) SBDR24W | U4: =AC26 -> 45.15 | V4: 24- | W4: PBX - SBDR24W | AG4: T
I5: 07-BT | J5: PS-7W 21V 300mA-BT | K5: 317 | M5: 07F30 | N5: LED 2835-60mA-3000K (WW) | O5: 07F30 | P5: 35 | Q5: 0.1 | Z5: =MID(Z3,4,1) -> R | AA5: =MID(AA3,5,2) -> 07 | AB5: =MID(AB3,8,2) -> 30 | AC5: =MID(AC3,10,3) | AD5: - | AG5: BT
M6: 07F27 | N6: LED SMD 2835 60mA 2700K (WW) | O6: 07F27 | P6: 35 | Q6: 0.1 | AG6: ID
I7: 16- | J7: PS 16W 48V 270mA MAXIC | K7: 98 | V7: 07- | W7: SBX - COB 8-18W (12Nos) | AB7: =MID(AB3,7,1) -> F | AD7: =CONCATENATE($AA$5,AD5) -> 07- | AE7: =CONCATENATE(AD7) -> 07- | AG7: BTD
I8: 16-T | J8: PS-16W 48V 300mA-TRIAC | K8: 275 | M8: 16F60 | N8: LED 2835-60mA-6000K (PW) | O8: 16F60 | P8: 80 | Q8: 0.1 | V8: 16- | W8: SBX FRDR15-20W (12Nos)
I9: 16-I | J9: PS-16W 48V 300mA-DALI | K9: 621 | M9: 16F50 | N9: LED 2835-60mA-5000K (PW) | O9: 16F50 | P9: 80 | Q9: 0.1 | V9: 24- | W9: SBX - SBDR24W
I10: 16-BT | J10: PS-16W 48V 300mA-BT | K10: 270 | M10: 16F40 | N10: LED 2835-60mA-4000K (NW) | O10: 16F40 | P10: 80 | Q10: 0.1
M11: 16F30 | N11: LED 2835-60mA-3000K (WW) | O11: 16F30 | P11: 80 | Q11: 0.1
I12: 24- | J12: PS 24W 300mA 24LED 72V Maxic (Mx-50W) | K12: 98 | M12: 16F27 | N12: LED SMD 2835 60mA 2700K (WW) | O12: 16F27 | P12: 80 | Q12: 0.1 | Z12: Housing | AA12: =CONCATENATE(Z5,AA5) -> R07 | AC12: BOM LED PCB
I13: 24-T | J13: PS-24W 72V 300mA-TRIAC | Z13: Diffuser | AA13: =CONCATENATE(Z5,AA5) -> R07
I14: 24-I | J14: PS-24W 72V 300mA-DALI | K14: 734 | M14: 24F60 | N14: LED 2835-60mA-6000K (PW) | O14: 24F60 | P14: 120 | Q14: 0.1 | Z14: PCB | AA14: =CONCATENATE(Z5,AA5) -> R07
I15: 24-BT | J15: PS-24W 72V 300mA-BT | K15: 270 | M15: 24F50 | N15: LED 2835-60mA-5000K (PW) | O15: 24F50 | P15: 120 | Q15: 0.1 | Z15: Temperature | AA15: =CONCATENATE(AA5,AB7,AB5) -> 07F30
M16: 24F40 | N16: LED 2835-60mA-4000K (NW) | O16: 24F40 | P16: 120 | Q16: 0.1 | Z16: Driver | AA16: =CONCATENATE(AA5,AD5,AC5) -> 07-
M17: 24F30 | N17: LED 2835-60mA-3000K (WW) | O17: 24F30 | P17: 120 | Q17: 0.1
M18: 24F27 | N18: LED SMD 2835 60mA 2700K (WW) | O18: 24F27 | P18: 120 | Q18: 0.1 | Y18: Part Number | AB18: Qty | AC18: Unit Price | AD18: Cost | AE18: USD | AF18: INS&FRED | AG18: BCD | AH18: Total Cost
Y19: FITTING SBDR07W ALL SET | AB19: 1 | AC19: =86*AH19 -> 59.469 | AD19: =AB19*AC19 -> 59.469 | AE19: 0.461 | AF19: 0.5 | AH19: =AE19+(AE19*(AF19+AG19)) -> 0.6915
Y20: FITTING SBDR16W ALL SET | AB20: 1 | AC20: =86*AH20 -> 96.492 | AD20: =AB20*AC20 -> 96.492 | AE20: 0.748 | AF20: 0.5 | AH20: =AE20+(AE20*(AF20+AG20)) -> 1.122
Y21: FITTING SBDR24W ALL SET | AB21: 1 | AC21: =86*AH21 -> 139.578 | AD21: =AB21*AC21 -> 139.578 | AE21: 1.082 | AF21: 0.5 | AH21: =AE21+(AE21*(AF21+AG21)) -> 1.623
Y22: Conn. 2 Pin Ass. Wire Black Male (Small) | AB22: 1 | AC22: =86*AH22 -> 3.483 | AD22: =AB22*AC22 -> 3.483 | AE22: 0.027 | AF22: 0.5 | AH22: =AE22+(AE22*(AF22+AG22)) -> 0.0405
Y23: Torsion Spring - L-49 W-18mm Coil D-1mm D-8 Black | AB23: 2 | AC23: =86*AH23 -> 0.903 | AD23: =AB23*AC23 -> 1.806 | AE23: 0.007 | AF23: 0.5 | AH23: =AE23+(AE23*(AF23+AG23)) -> 0.0105
Y24: PCB-2835-5B7C (55X0.8mm) SBDR07W | AB24: 1 | AC24: =86*AH24 -> 7.611 | AD24: =AB24*AC24 -> 7.611 | AE24: 0.059 | AF24: 0.5 | AH24: =AE24+(AE24*(AF24+AG24)) -> 0.0885
Y25: PCB-2835-5B16C (85.8X0.8mm) SBDR16W | AB25: 1 | AC25: =86*AH25 -> 19.479 | AD25: =AB25*AC25 -> 19.479 | AE25: 0.151 | AF25: 0.5 | AH25: =AE25+(AE25*(AF25+AG25)) -> 0.2265
Y26: PCB-2835-5B24C (134X0.8mm) SBDR24W | AB26: 1 | AC26: =86*AH26 -> 45.15 | AD26: =AB26*AC26 -> 45.15 | AE26: 0.35 | AF26: 0.5 | AH26: =AE26+(AE26*(AF26+AG26)) -> 0.525

Sheet Stock Item (Read Me)
A1: List of Fields | B1: Applicable Countries | C1: Applicable Values
A2: General Details
A3: Name | B3: All | E3: Read the following, before you start using the sample file:
A4: Group Name | B4: All | E4: Stock Item worksheet:
A5: B | B5: All | E5: - Use the worksheet without making any changes to the column headers to enter your business data. - The column headers represent field names in TallyPrime. Mandatory fields are marked in bold for easy reference. - Add new columns, if needed. Ensure to enter Column Headers exactly as mentioned under the List of Fields of the Read Me worksheet. - Delete unwanted columns. However, do not delete columns that represent mandatory fields for masters.
A6: Part No. | B6: All
A7: Alias - Part No. | B7: All
A8: Description | B8: All
A9: Notes | B9: All
A10: Category | B10: All
A11: Units | B11: All | E11: Stock Item (Read Me)
A12: Conversion | B12: All | E12: - The Read Me worksheet is only for your reference. It lists all the fields, with related details, applicable for Stock Item.
A13: Denominator | B13: All
A14: Alternate Units | B14: All | E14: For more information on using Sample Excel File for importing data, refer to | M14: TallyHelp
A15: GST Applicability | B15: All | C15: Applicable, Not Applicable
A16: Opening Balance - Quantity | B16: All
A17: Opening Balance - Rate | B17: All
A18: Opening Balance - Rate Per | B18: All
A19: Opening Balance - Value | B19: All
A20: Language for Name (Except English) | B20: All
A21: Is TCS Applicable | B21: All
A22: Item Allocations Details
A23: Item Allocations - Godown | B23: (When Accounting Terminology is set to "India/SAARC")
A24: Item Allocations - Batch | B24: All
A25: Item Allocations - Quantity | B25: All
A26: Item Allocations - Rate | B26: All
A27: Item Allocations - Rate per | B27: All
A28: Item Allocations - Amount | B28: All
A29: Item Allocations - Mfg. Date | B29: All
A30: Item Allocations - Expiry Date | B30: All
A31: Item Allocations - Location | B31: (When Accounting Terminology is set to "International")
A32: Additional Details
A33: Maintain in Batches | B33: All
A34: Track date of manufacturing | B34: All
A35: Use expiry dates | B35: All
A36: Enable Cost Tracking | B36: All
A37: Costing Method | B37: All | C37: At Zero Cost, Avg. Cost, FIFO, FIFO Perpetual, Last Purchase Cost, LIFO Annual, LIFO Perpetual, Monthly Avg. Cost, Std. Cost
A38: Market Valuation Method | B38: All | C38: At Zero Price, Avg. Price, Last Sale Price, Std. Price
A39: Behaviour
A40: Ignore difference due to physical counting | B40: All
...

Sheet SBDR07-16-24W-SKU
A1: SKU Id | B1: SKU Code | C1: Product Name | D1: Cost Price | E1: Retail Price | F1: Selling Price | G1: Weight | H1: Width | I1: Height | J1: Depth | K1: Input Power | L1: Trim | M1: Beam Angle | N1: Color Temp | O1: Driving System
A2: 144561 | B2: SBDR07F60- | C2: =CONCATENATE(R2,S2,T2,U2,V2) -> SBDR07F60 | D2: 0 | E2: 0 | F2: 476 | G2: 0 | H2: 0 | I2: 0 | J2: 0 | K2: 07 Watt | L2: Round White Trim | M2: Flood - 100° | N2: 6000K | O2: Constant Current | R2: =MID(B2,1,3) -> SBD | S2: =MID(B2,4,1) -> R | T2: =MID(B2,5,2) -> 07 | U2: =MID(B2,7,1) -> F | V2: =MID(B2,8,2) -> 60
A3: 144562 | B3: SBDR07F40- | C3: =CONCATENATE(R3,S3,T3,U3,V3) -> SBDR07F40 | D3: 0 | E3: 0 | F3: 476 | G3: 0 | H3: 0 | I3: 0 | J3: 0 | K3: 07 Watt | L3: Round White Trim | M3: Flood - 100° | N3: 4000k | O3: Constant Current | R3: =MID(B3,1,3) -> SBD | S3: =MID(B3,4,1) -> R | T3: =MID(B3,5,2) -> 07 | U3: =MID(B3,7,1) -> F | V3: =MID(B3,8,2) -> 40
A4: 144563 | B4: SBDR07F30- | C4: =CONCATENATE(R4,S4,T4,U4,V4) -> SBDR07F30 | D4: 0 | E4: 0 | F4: 476 | G4: 0 | H4: 0 | I4: 0 | J4: 0 | K4: 07 Watt | L4: Round White Trim | M4: Flood - 100° | N4: 3000k | O4: Constant Current | R4: =MID(B4,1,3) -> SBD | S4: =MID(B4,4,1) -> R | T4: =MID(B4,5,2) -> 07 | U4: =MID(B4,7,1) -> F | V4: =MID(B4,8,2) -> 30
A5: 144564 | B5: SBDR07F27- | C5: =CONCATENATE(R5,S5,T5,U5,V5) -> SBDR07F27 | D5: 0 | E5: 0 | F5: 476 | G5: 0 | H5: 0 | I5: 0 | J5: 0 | K5: 07 Watt | L5: Round White Trim | M5: Flood - 100° | N5: 2700K | O5: Constant Current | R5: =MID(B5,1,3) -> SBD | S5: =MID(B5,4,1) -> R | T5: =MID(B5,5,2) -> 07 | U5: =MID(B5,7,1) -> F | V5: =MID(B5,8,2) -> 27
A6: 144565 | B6: SBDR07F50- | C6: =CONCATENATE(R6,S6,T6,U6,V6) -> SBDR07F50 | D6: 0 | E6: 0 | F6: 476 | G6: 0 | H6: 0 | I6: 0 | J6: 0 | K6: 07 Watt | L6: Round White Trim | M6: Flood - 100° | N6: 5000K | O6: Constant Current | R6: =MID(B6,1,3) -> SBD | S6: =MID(B6,4,1) -> R | T6: =MID(B6,5,2) -> 07 | U6: =MID(B6,7,1) -> F | V6: =MID(B6,8,2) -> 50
A7: 144591 | B7: SBDR07F60T | C7: =CONCATENATE(R7,S7,T7,U7,V7) -> SBDR07F60T | D7: 0 | E7: 0 | F7: 932 | G7: 0 | H7: 0 | I7: 0 | J7: 0 | K7: 07 Watt | L7: Round White Trim | M7: Flood - 100° | N7: 6000K | O7: TRIAC Dimming | R7: =MID(B7,1,3) -> SBD | S7: =MID(B7,4,1) -> R | T7: =MID(B7,5,2) -> 07 | U7: =MID(B7,7,1) -> F | V7: =MID(B7,8,6) -> 60T
A8: 144592 | B8: SBDR07F40T | C8: =CONCATENATE(R8,S8,T8,U8,V8) -> SBDR07F40T | D8: 0 | E8: 0 | F8: 932 | G8: 0 | H8: 0 | I8: 0 | J8: 0 | K8: 07 Watt | L8: Round White Trim | M8: Flood - 100° | N8: 4000k | O8: TRIAC Dimming | R8: =MID(B8,1,3) -> SBD | S8: =MID(B8,4,1) -> R | T8: =MID(B8,5,2) -> 07 | U8: =MID(B8,7,1) -> F | V8: =MID(B8,8,6) -> 40T
A9: 144593 | B9: SBDR07F30T | C9: =CONCATENATE(R9,S9,T9,U9,V9) -> SBDR07F30T | D9: 0 | E9: 0 | F9: 932 | G9: 0 | H9: 0 | I9: 0 | J9: 0 | K9: 07 Watt | L9: Round White Trim | M9: Flood - 100° | N9: 3000k | O9: TRIAC Dimming | R9: =MID(B9,1,3) -> SBD | S9: =MID(B9,4,1) -> R | T9: =MID(B9,5,2) -> 07 | U9: =MID(B9,7,1) -> F | V9: =MID(B9,8,6) -> 30T
A10: 144594 | B10: SBDR07F27T | C10: =CONCATENATE(R10,S10,T10,U10,V10) -> SBDR07F27T | D10: 0 | E10: 0 | F10: 932 | G10: 0 | H10: 0 | I10: 0 | J10: 0 | K10: 07 Watt | L10: Round White Trim | M10: Flood - 100° | N10: 2700K | O10: TRIAC Dimming | R10: =MID(B10,1,3) -> SBD | S10: =MID(B10,4,1) -> R | T10: =MID(B10,5,2) -> 07 | U10: =MID(B10,7,1) -> F | V10: =MID(B10,8,6) -> 27T
A11: 144595 | B11: SBDR07F50T | C11: =CONCATENATE(R11,S11,T11,U11,V11) -> SBDR07F50T | D11: 0 | E11: 0 | F11: 932 | G11: 0 | H11: 0 | I11: 0 | J11: 0 | K11: 07 Watt | L11: Round White Trim | M11: Flood - 100° | N11: 5000K | O11: TRIAC Dimming | R11: =MID(B11,1,3) -> SBD | S11: =MID(B11,4,1) -> R | T11: =MID(B11,5,2) -> 07 | U11: =MID(B11,7,1) -> F | V11: =MID(B11,8,6) -> 50T
A12: 144606 | B12: SBDR07F60I | C12: =CONCATENATE(R12,S12,T12,U12,V12) -> SBDR07F60I | D12: 0 | E12: 0 | F12: 2071 | G12: 0 | H12: 0 | I12: 0 | J12: 0 | K12: 07 Watt | L12: Round White Trim | M12: Flood - 100° | N12: 6000K | O12: DALI Dimming | R12: =MID(B12,1,3) -> SBD | S12: =MID(B12,4,1) -> R | T12: =MID(B12,5,2) -> 07 | U12: =MID(B12,7,1) -> F | V12: =MID(B12,8,6) -> 60I
A13: 144607 | B13: SBDR07F40I | C13: =CONCATENATE(R13,S13,T13,U13,V13) -> SBDR07F40I | D13: 0 | E13: 0 | F13: 2071 | G13: 0 | H13: 0 | I13: 0 | J13: 0 | K13: 07 Watt | L13: Round White Trim | M13: Flood - 100° | N13: 4000k | O13: DALI Dimming | R13: =MID(B13,1,3) -> SBD | S13: =MID(B13,4,1) -> R | T13: =MID(B13,5,2) -> 07 | U13: =MID(B13,7,1) -> F | V13: =MID(B13,8,6) -> 40I
A14: 144608 | B14: SBDR07F30I | C14: =CONCATENATE(R14,S14,T14,U14,V14) -> SBDR07F30I | D14: 0 | E14: 0 | F14: 2071 | G14: 0 | H14: 0 | I14: 0 | J14: 0 | K14: 07 Watt | L14: Round White Trim | M14: Flood - 100° | N14: 3000k | O14: DALI Dimming | R14: =MID(B14,1,3) -> SBD | S14: =MID(B14,4,1) -> R | T14: =MID(B14,5,2) -> 07 | U14: =MID(B14,7,1) -> F | V14: =MID(B14,8,6) -> 30I
A15: 144609 | B15: SBDR07F27I | C15: =CONCATENATE(R15,S15,T15,U15,V15) -> SBDR07F27I | D15: 0 | E15: 0 | F15: 2071 | G15: 0 | H15: 0 | I15: 0 | J15: 0 | K15: 07 Watt | L15: Round White Trim | M15: Flood - 100° | N15: 2700K | O15: DALI Dimming | R15: =MID(B15,1,3) -> SBD | S15: =MID(B15,4,1) -> R | T15: =MID(B15,5,2) -> 07 | U15: =MID(B15,7,1) -> F | V15: =MID(B15,8,6) -> 27I
A16: 144610 | B16: SBDR07F50I | C16: =CONCATENATE(R16,S16,T16,U16,V16) -> SBDR07F50I | D16: 0 | E16: 0 | F16: 2071 | G16: 0 | H16: 0 | I16: 0 | J16: 0 | K16: 07 Watt | L16: Round White Trim | M16: Flood - 100° | N16: 5000K | O16: DALI Dimming | R16: =MID(B16,1,3) -> SBD | S16: =MID(B16,4,1) -> R | T16: =MID(B16,5,2) -> 07 | U16: =MID(B16,7,1) -> F | V16: =MID(B16,8,6) -> 50I
A17: 144621 | B17: SBDR07F60BT | C17: =CONCATENATE(R17,S17,T17,U17,V17) -> SBDR07F60BT | D17: 0 | E17: 0 | F17: 1332 | G17: 0 | H17: 0 | I17: 0 | J17: 0 | K17: 07 Watt | L17: Round White Trim | M17: Flood - 100° | N17: 6000K | O17: Bluetooth Dimming | R17: =MID(B17,1,3) -> SBD | S17: =MID(B17,4,1) -> R | T17: =MID(B17,5,2) -> 07 | U17: =MID(B17,7,1) -> F | V17: =MID(B17,8,6) -> 60BT
A18: 144622 | B18: SBDR07F40BT | C18: =CONCATENATE(R18,S18,T18,U18,V18) -> SBDR07F40BT | D18: 0 | E18: 0 | F18: 1332 | G18: 0 | H18: 0 | I18: 0 | J18: 0 | K18: 07 Watt | L18: Round White Trim | M18: Flood - 100° | N18: 4000k | O18: Bluetooth Dimming | R18: =MID(B18,1,3) -> SBD | S18: =MID(B18,4,1) -> R | T18: =MID(B18,5,2) -> 07 | U18: =MID(B18,7,1) -> F | V18: =MID(B18,8,6) -> 40BT
... A21: 144625 | B21: SBDR07F50BT | C21: =CONCATENATE(R21,S21,T21,U21,V21) -> SBDR07F50BT | D21: 0 | E21: 0 | F21: 1332 | G21: 0 | H21: 0 | I21: 0 | J21: 0 | K21: 07 Watt | L21: Round White Trim | M21: Flood - 100° | N21: 5000K | O21: Bluetooth Dimming | R21: =MID(B21,1,3) -> SBD | S21: =MID(B21,4,1) -> R | T21: =MID(B21,5,2) -> 07 | U21: =MID(B21,7,1) -> F | V21: =MID(B21,8,6) -> 50BT
