Workbook

Sheet Stock Item
A1: Name | B1: Group Name | C1: Units | D1: Name of BOM | E1: Unit of manufacture | F1: BOM Component - Item Name | G1: BOM Component - Quantity | H1: BOM Component - Godown | I1: BOM Component - Type of Item | J1: BOM Component - Rate (%) | K1: BOM Component - Location | L1: Unit Price | M1: Cost | N1: USD | O1: INS&FRED | P1: BCD | Q1: Total Cost
A2: =$D$2 -> SRDR20F30 | B2: Down Light Series | C2: Nos. | D2: SRDR20F30 | E2: 1 | F2: ='Backend data'!C6 -> Trim-O-97 I-70.5 H-55mm White SRRR20/30W | G2: 1 | H2: Mechanical Store | I2: Component | L2: =Q2*87 -> 66.555 | M2: =G2*L2 -> 66.555 | N2: 0.51 | O2: 0.5 | Q2: =N2+(N2*(O2+P2)) -> 0.765
F3: ='Backend data'!D6 -> HS 69X42.5mm (Fulai) SRRR20W | G3: 1 | H3: Mechanical Store | I3: Component | L3: =Q3*87 -> 109.62 | M3: =G3*L3 -> 109.62 | N3: 0.84 | O3: 0.5 | Q3: =N3+(N3*(O3+P3)) -> 1.26
F4: Refl-O-69 H-35 L-20mm-PC 69014 SRRR20 & 30W-F | G4: 1 | H4: Mechanical Store | I4: Component | L4: =Q4*87 -> 12.528 | M4: =G4*L4 -> 12.528 | N4: 0.096 | O4: 0.5 | Q4: =N4+(N4*(O4+P4)) -> 0.144
F5: Diff. 69.8x1.5mm Prismatic SRRR20W | G5: 1 | H5: Mechanical Store | I5: Component | L5: =Q5*87 -> 6.9165 | M5: =G5*L5 -> 6.9165 | N5: 0.053 | O5: 0.5 | Q5: =N5+(N5*(O5+P5)) -> 0.0795
F6: Diff Flim-69.5X0.20mm-PC SRRR20W | G6: 1 | H6: Mechanical Store | I6: Component
F7: COB Holder-O-37.5 H-3.5 L-17mm-PC(19X19mm) | G7: 1 | H7: Mechanical Store | I7: Component | L7: =Q7*87 -> 0 | M7: =G7*L7 -> 0 | N7: 0 | O7: 0.5 | Q7: =N7+(N7*(O7+P7)) -> 0
F8: Torsion Spring - L-49 W-18mm Coil D-1mm D-8 Black | G8: 2 | H8: Mechanical Store | I8: Component | L8: =Q8*87 -> 1.044 | M8: =G8*L8 -> 2.088 | N8: 0.008 | O8: 0.5 | Q8: =N8+(N8*(O8+P8)) -> 0.012
F9: Spring Holding Clip L-37 W-25 T-0.70mm MS | G9: 2 | H9: Mechanical Store | I9: Component | L9: 2 | M9: =G9*L9 -> 4 | N9: 0 | O9: 0.5 | Q9: =N9+(N9*(O9+P9)) -> 0
F10: Conn. 2 Pin Ass. Wire Black Male (Small) | G10: 1 | H10: Mechanical Store | I10: Component | L10: =Q10*87 -> 3.915 | M10: =G10*L10 -> 3.915 | N10: 0.03 | O10: 0.5 | Q10: =N10+(N10*(O10+P10)) -> 0.045
F11: PBX - COB 8-15W | G11: 1 | H11: Mechanical Store | I11: Component | L11: 8.5 | M11: =G11*L11 -> 8.5 | N11: 0 | O11: 0.5 | Q11: =N11+(N11*(O11+P11)) -> 0
F12: SBX - COB 8-18W (12Nos) | G12: 0.08 | H12: Mechanical Store | I12: Component | L12: 27 | M12: =G12*L12 -> 2.16 | N12: 0 | O12: 0.5 | Q12: =N12+(N12*(O12+P12)) -> 0
F13: Sleeve M4mm-Fiber Glass White | G13: 0.12 | H13: Mechanical Store | I13: Component | L13: 0.684 | M13: =G13*L13 -> 0.08208 | N13: 0 | O13: 0.5 | Q13: =N13+(N13*(O13+P13)) -> 0
F14: Wire Clip-M3-MS | G14: 1 | H14: Mechanical Store | I14: Component | L14: 0.6 | M14: =G14*L14 -> 0.6 | N14: 0 | O14: 0.5 | Q14: =N14+(N14*(O14+P14)) -> 0
F15: Screw No. 4X6.5mm Self Pan Combi. PH - SS | G15: 1 | H15: Mechanical Store | I15: Component | L15: 0.21 | M15: =G15*L15 -> 0.21 | N15: 0 | O15: 0.5 | Q15: =N15+(N15*(O15+P15)) -> 0
F16: Screw M3X6mm CSK PH - SS | G16: 2 | H16: Mechanical Store | I16: Component | L16: 0.5 | M16: =G16*L16 -> 1 | N16: 0 | O16: 0.5 | Q16: =N16+(N16*(O16+P16)) -> 0
F17: Rivet 1/8"X1/4" MS (Big) | G17: 4 | H17: Mechanical Store | I17: Component | L17: 0.26 | M17: =G17*L17 -> 1.04 | N17: 0 | O17: 0.5 | Q17: =N17+(N17*(O17+P17)) -> 0
F18: Rivet 3/32" X 3/16" MS (Small) | G18: 4 | H18: Mechanical Store | I18: Component | L18: 0.32 | M18: =G18*L18 -> 1.28 | N18: 0 | O18: 0.5 | Q18: =N18+(N18*(O18+P18)) -> 0
L19: =Q19*87 -> 0 | M19: =G19*L19 -> 0 | N19: 0 | O19: 0.5 | Q19: =N19+(N19*(O19+P19)) -> 0
F20: ='Backend data'!G6 -> COB 30-36W 3000K 12LED 34-38V 890mA 19x19mm CRI-90 | G20: 1 | H20: Electronics store | I20: Component | L20: =Q20*87 -> 84.825 | M20: =G20*L20 -> 84.825 | N20: 0.65 | O20: 0.5 | Q20: =N20+(N20*(O20+P20)) -> 0.975
F21: ='Backend data'!H6 -> PS 20W 500mA 36V Maxic(PCB LT-MX-20W-V2) | G21: 1 | H21: Mechanical Store | I21: Component | N21: PS Rate Mention with Total Amt
M22: =SUM(M2:M21) -> 305.31958
K24: SRDR20-CC | M24: =M22+98 -> 403.31958
K25: SRDR20 Track Dimming | M25: =M22 -> 305.31958 | R25: Rate
K26: SRDR20 Dali Single Color | M26: =((M22)+(Q26*87)) -> 305.31958 | N26: 0 | O26: 0.5 | Q26: =N26+(N26*(O26+P26)) -> 0 | R26: =Q26*87 -> 0
K27: SRDR20 BT Single Color | M27: =M22+330 -> 635.31958
K28: SRDR20 Dali Dual Color | M28: =((M22)+(Q28*87)) -> 1107.8946 | N28: 6.15 | O28: 0.5 | Q28: =N28+(N28*(O28+P28)) -> 9.225 | R28: =Q28*87 -> 802.575
K29: SRDR20 BT Dual Color | M29: =M22+330 -> 635.31958

Sheet Stock Item (Read Me)
A1: List of Fields | B1: Applicable Countries | C1: Applicable Values
A2: General Details
A3: Name | B3: All | E3: Read the following, before you start using the sample file:
A4: Group Name | B4: All | E4: Stock Item worksheet:
A5: B | B5: All | E5: - Use the worksheet without making any changes to the column headers to enter your business data. - The column headers represent field names in TallyPrime. Mandatory fields are marked in bold for easy reference. - Add new columns, if needed. Ensure to enter Column Headers exactly as mentioned under the List of Fields of the Read Me worksheet. - Delete unwanted columns. However, do not delete columns that represent mandatory fields for masters.
A6: Part No. | B6: All
A7: Alias - Part No. | B7: All
A8: Description | B8: All
A9: Notes | B9: All
A10: Category | B10: All
A11: Units | B11: All | E11: Stock Item (Read Me)
A12: Conversion | B12: All | E12: - The Read Me worksheet is only for your reference. It lists all the fields, with related details, applicable for Stock Item.
A13: Denominator | B13: All
A14: Alternate Units | B14: All | E14: For more information on using Sample Excel File for importing data, refer to | M14: TallyHelp
A15: GST Applicability | B15: All | C15: Applicable, Not Applicable
A16: Opening Balance - Quantity | B16: All
A17: Opening Balance - Rate | B17: All
A18: Opening Balance - Rate Per | B18: All
A19: Opening Balance - Value | B19: All
A20: Language for Name (Except English) | B20: All
A21: Is TCS Applicable | B21: All
A22: Item Allocations Details
A23: Item Allocations - Godown | B23: (When Accounting Terminology is set to "India/SAARC")
A24: Item Allocations - Batch | B24: All
A25: Item Allocations - Quantity | B25: All
A26: Item Allocations - Rate | B26: All
A27: Item Allocations - Rate per | B27: All
A28: Item Allocations - Amount | B28: All
A29: Item Allocations - Mfg. Date | B29: All
A30: Item Allocations - Expiry Date | B30: All
A31: Item Allocations - Location | B31: (When Accounting Terminology is set to "International")
A32: Additional Details
A33: Maintain in Batches | B33: All
A34: Track date of manufacturing | B34: All
A35: Use expiry dates | B35: All
A36: Enable Cost Tracking | B36: All
A37: Costing Method | B37: All | C37: At Zero Cost, Avg. Cost, FIFO, FIFO Perpetual, Last Purchase Cost, LIFO Annual, LIFO Perpetual, Monthly Avg. Cost, Std. Cost
A38: Market Valuation Method | B38: All | C38: At Zero Price, Avg. Price, Last Sale Price, Std. Price
A39: Behaviour
A40: Ignore difference due to physical counting | B40: All
...

Sheet Backend data
C2: TRIM | D2: HOUSING/HS | E2: REFLECTOR | F2: BEAM ANGLE | G2: COLOR TEMP | H2: DRIVING SYSTEM | I2: EXTRA
C3: =MID('Stock Item'!$D$2,4,3) -> R20 | D3: =MID('Stock Item'!$D$2,5,2) -> 20 | E3: =MID('Stock Item'!$D$2,3,1) -> D | F3: =MID('Stock Item'!$D$2,7,1) -> F | G3: =MID('Stock Item'!$D$2,8,2) -> 30 | H3: =MID('Stock Item'!$D$2,8,11) -> 30 | I3: =MID('Stock Item'!$D$2,2,1) -> R
D4: =CONCATENATE(C3) -> R20 | G4: =CONCATENATE($H$3,"-") -> 30- | H4: =CONCATENATE(D3,"-") -> 20-
B6: Formulae | C6: =VLOOKUP($C$3,$B$23:$E$72,2,0) -> Trim-O-97 I-70.5 H-55mm White SRRR20/30W | D6: =VLOOKUP($D$4,G23:$J$100,2,0) -> HS 69X42.5mm (Fulai) SRRR20W | E6: =VLOOKUP($E$3,$L$23:$O$72,2,0) -> #N/A | F6: =VLOOKUP($F$3,$Q$23:$T$72,2,0) -> #N/A | G6: =VLOOKUP($G$4,$V$23:$Y$72,2,0) -> COB 30-36W 3000K 12LED 34-38V 890mA 19x19mm CRI-90 | H6: =VLOOKUP($H$4,$AA$23:$AD$72,2,0) -> PS 20W 500mA 36V Maxic(PCB LT-MX-20W-V2) | I6: =VLOOKUP($I$3,AF23:$AI$100,2,0) -> #N/A
B7: Formulae for COST | C7: =VLOOKUP($C$3,$B$23:$E$72,4,0) -> 0 | D7: =VLOOKUP($D$4,G23:$J$100,4,0) -> 0 | E7: =VLOOKUP($E$3,$L$23:$O$72,4,0) -> #N/A | F7: =VLOOKUP($F$3,$Q$23:$T$72,4,0) -> #N/A | G7: =VLOOKUP($G$4,$V$23:$Y$72,4,0) -> 0 | H7: =VLOOKUP($H$4,$AA$23:$AD$72,4,0) -> 0 | I7: =VLOOKUP($I$3,$AF$23:$AI$100,4,0) -> #N/A
B8: Formulae for Quantity | C8: =VLOOKUP($C$3,$B$23:$E$72,3,0) -> 0 | D8: =VLOOKUP($D$4,G23:$J$100,3,0) -> 0 | E8: =VLOOKUP($E$3,$L$23:$O$72,3,0) -> #N/A | F8: =VLOOKUP($F$3,$Q$23:$T$72,3,0) -> #N/A | G8: =VLOOKUP($G$4,$V$23:$Y$72,3,0) -> 0 | H8: =VLOOKUP($H$4,$AA$23:$AD$72,3,0) -> 0 | I8: =VLOOKUP($I$3,$AF$23:$AI$100,3,0) -> #N/A
H10: BOM LED PCB
B21: TRIM | G21: HOUSING/HS | L21: REFLECTOR | Q21: BEAM ANGLE | V21: COLOUR TEMPERATURE | AA21: DRIVING SYSTEM | AF21: EXTRA
B22: Code | C22: Item Name | D22: Quantity | E22: Cost | G22: Code | H22: Item Name | I22: Quantity | J22: Cost | L22: Code | M22: Item Name | N22: Quantity | O22: Cost | Q22: Code | R22: Item Name | S22: Quantity | T22: Cost | V22: Code | W22: Item Name | X22: Quantity | Y22: Cost | AA22: Code | AB22: Item Name | AC22: Quantity | AD22: Cost | AF22: Code | AG22: Item Name | AH22: Quantity | AI22: Cost
B23: R20 | C23: Trim-O-97 I-70.5 H-55mm White SRRR20/30W | G23: R20 | H23: HS 69X42.5mm (Fulai) SRRR20W | V23: 27- | W23: COB 30W 2700K 12LED 34-38V 890mA 19x19mm CRI-90 | AA23: 20- | AB23: PS 20W 500mA 36V Maxic(PCB LT-MX-20W-V2)
B24: B20 | C24: Trim O-97 I-70.5 H-55mm Black SRRR20/30W | G24: R30 | H24: HS 69X54.5mm (Fulai) SRRR20W | V24: 30- | W24: COB 30-36W 3000K 12LED 34-38V 890mA 19x19mm CRI-90 | AA24: 20T- | AB24: PS 20W-500mA 36V Track Dimming
B25: R30 | C25: Trim-O-97 I-70.5 H-55mm White SRRR20/30W | V25: 40- | W25: COB 30-36W 4000K 12LED 34-38V 890mA 19x19mm CRI-90 | AA25: 20I- | AB25: Dali Driver SC-21W PE-L20DA40 (AI-Dimming)-(9-42V)
B26: B30 | C26: Trim O-97 I-70.5 H-55mm Black SRRR20/30W | G26: B20 | H26: HS 69X42.5mm (Fulai) SRRR20W | V26: 50- | W26: COB 30-36W 5000K 12LED 34-38V 890mA 19x19mm CRI-90 | AA26: 20BT- | AB26: PS CCT 20W 420MA 36V BT-SC (PCB LT 7-20W-CCT-V 1.1 REV-1)
G27: B30 | H27: HS 69X54.5mm (Fulai) SRRR20W | V27: 60- | W27: COB 30-36W 6000K 12LED 34-38V 890mA 19x19mm CRI-90 | AA27: 20ID- | AB27: Dali Driver DC-20W PE69R4240 (AI-Dimming)-25-40V
AA28: 20BTD- | AB28: PS CCT 20W 420MA 36V BT-DC (PCB LT 7-20W-CCT-V 1.1 REV-1)
V29: 27T- | W29: COB 30W 2700K 12LED 34-38V 890mA 19x19mm CRI-90
V30: 30T- | W30: COB 30-36W 3000K 12LED 34-38V 890mA 19x19mm CRI-90 | AA30: 30- | AB30: PS 30W 730mA 36V Maxic (MX-50W)
V31: 40T- | W31: COB 30-36W 4000K 12LED 34-38V 890mA 19x19mm CRI-90 | AA31: 30T- | AB31: PS-30W 730mA 36V-TRIAC
V32: 50T- | W32: COB 30-36W 5000K 12LED 34-38V 890mA 19x19mm CRI-90 | AA32: 30I- | AB32: PS 30W 730MA 36V DALI DIMMING SINGLE COLOUR
V33: 60T- | W33: COB 30-36W 6000K 12LED 34-38V 890mA 19x19mm CRI-90 | AA33: 30BT- | AB33: PS-30W 650mA 36V-BT
AA34: 30ID- | AB34: PS-30W 730mA 36V-DALI DC
V35: 27I- | W35: COB 30W 2700K 12LED 34-38V 890mA 19x19mm CRI-90 | AA35: 30BTD- | AB35: PS-30W 650mA 36V-BT DC
V36: 30I- | W36: COB 30-36W 3000K 12LED 34-38V 890mA 19x19mm CRI-90
V37: 40I- | W37: COB 30-36W 4000K 12LED 34-38V 890mA 19x19mm CRI-90
V38: 50I- | W38: COB 30-36W 5000K 12LED 34-38V 890mA 19x19mm CRI-90
V39: 60I- | W39: COB 30-36W 6000K 12LED 34-38V 890mA 19x19mm CRI-90
V40: 25ID- | W40: LED COB Dual Colour 30W 2700K-5000k
V42: 27BT- | W42: COB 30W 2700K 12LED 34-38V 890mA 19x19mm CRI-90
V43: 30BT- | W43: COB 30-36W 3000K 12LED 34-38V 890mA 19x19mm CRI-90
V44: 40BT- | W44: COB 30-36W 4000K 12LED 34-38V 890mA 19x19mm CRI-90
V45: 50BT- | W45: COB 30-36W 5000K 12LED 34-38V 890mA 19x19mm CRI-90
V46: 60BT- | W46: COB 30-36W 6000K 12LED 34-38V 890mA 19x19mm CRI-90
V47: 25BTD- | W47: LED COB Dual Colour 30W 2700K-5000k

Sheet SRD20-30W-SKU
A1: SKU Id | B1: SKU Code | C1: Product Name | D1: Cost Price | E1: Retail Price | F1: Selling Price | G1: Weight | H1: Width | I1: Height | J1: Depth | K1: Beam Angle | L1: Color Temp | M1: Trim | N1: Driving System | O1: Watt
A2: 141615 | B2: SRDR20F60- | C2: =CONCATENATE(Q2,R2,S2,T2,U2) -> SRDR20F60 | D2: 0 | E2: 0 | F2: 1159 | G2: 0 | H2: 0 | I2: 0 | J2: 0 | K2: Flood - 68° | L2: 6000K | M2: Round White Trim | N2: Constant Current | O2: 20 Watt | Q2: =MID(B2,1,3) -> SRD | R2: =MID(B2,4,1) -> R | S2: =MID(B2,5,2) -> 20 | T2: =MID(B2,7,1) -> F | U2: =MID(B2,8,2) -> 60
A3: 141616 | B3: SRDR20F50- | C3: =CONCATENATE(Q3,R3,S3,T3,U3) -> SRDR20F50 | D3: 0 | E3: 0 | F3: 1159 | G3: 0 | H3: 0 | I3: 0 | J3: 0 | K3: Flood - 68° | L3: 5000K | M3: Round White Trim | N3: Constant Current | O3: 20 Watt | Q3: =MID(B3,1,3) -> SRD | R3: =MID(B3,4,1) -> R | S3: =MID(B3,5,2) -> 20 | T3: =MID(B3,7,1) -> F | U3: =MID(B3,8,2) -> 50
A4: 141617 | B4: SRDR20F40- | C4: =CONCATENATE(Q4,R4,S4,T4,U4) -> SRDR20F40 | D4: 0 | E4: 0 | F4: 1159 | G4: 0 | H4: 0 | I4: 0 | J4: 0 | K4: Flood - 68° | L4: 4000K | M4: Round White Trim | N4: Constant Current | O4: 20 Watt | Q4: =MID(B4,1,3) -> SRD | R4: =MID(B4,4,1) -> R | S4: =MID(B4,5,2) -> 20 | T4: =MID(B4,7,1) -> F | U4: =MID(B4,8,2) -> 40
A5: 141618 | B5: SRDR20F30- | C5: =CONCATENATE(Q5,R5,S5,T5,U5) -> SRDR20F30 | D5: 0 | E5: 0 | F5: 1159 | G5: 0 | H5: 0 | I5: 0 | J5: 0 | K5: Flood - 68° | L5: 3000K | M5: Round White Trim | N5: Constant Current | O5: 20 Watt | Q5: =MID(B5,1,3) -> SRD | R5: =MID(B5,4,1) -> R | S5: =MID(B5,5,2) -> 20 | T5: =MID(B5,7,1) -> F | U5: =MID(B5,8,2) -> 30
A6: 141622 | B6: SRDB20F60- | C6: =CONCATENATE(Q6,R6,S6,T6,U6) -> SRDB20F60 | D6: 0 | E6: 0 | F6: 1326 | G6: 0 | H6: 0 | I6: 0 | J6: 0 | K6: Flood - 68° | L6: 6000K | M6: Round Black Trim | N6: Constant Current | O6: 20 Watt | Q6: =MID(B6,1,3) -> SRD | R6: =MID(B6,4,1) -> B | S6: =MID(B6,5,2) -> 20 | T6: =MID(B6,7,1) -> F | U6: =MID(B6,8,2) -> 60
A7: 141623 | B7: SRDB20F50- | C7: =CONCATENATE(Q7,R7,S7,T7,U7) -> SRDB20F50 | D7: 0 | E7: 0 | F7: 1326 | G7: 0 | H7: 0 | I7: 0 | J7: 0 | K7: Flood - 68° | L7: 5000K | M7: Round Black Trim | N7: Constant Current | O7: 20 Watt | Q7: =MID(B7,1,3) -> SRD | R7: =MID(B7,4,1) -> B | S7: =MID(B7,5,2) -> 20 | T7: =MID(B7,7,1) -> F | U7: =MID(B7,8,2) -> 50
A8: 141624 | B8: SRDB20F40- | C8: =CONCATENATE(Q8,R8,S8,T8,U8) -> SRDB20F40 | D8: 0 | E8: 0 | F8: 1326 | G8: 0 | H8: 0 | I8: 0 | J8: 0 | K8: Flood - 68° | L8: 4000K | M8: Round Black Trim | N8: Constant Current | O8: 20 Watt | Q8: =MID(B8,1,3) -> SRD | R8: =MID(B8,4,1) -> B | S8: =MID(B8,5,2) -> 20 | T8: =MID(B8,7,1) -> F | U8: =MID(B8,8,2) -> 40
A9: 141625 | B9: SRDB20F30- | C9: =CONCATENATE(Q9,R9,S9,T9,U9) -> SRDB20F30 | D9: 0 | E9: 0 | F9: 1326 | G9: 0 | H9: 0 | I9: 0 | J9: 0 | K9: Flood - 68° | L9: 3000K | M9: Round Black Trim | N9: Constant Current | O9: 20 Watt | Q9: =MID(B9,1,3) -> SRD | R9: =MID(B9,4,1) -> B | S9: =MID(B9,5,2) -> 20 | T9: =MID(B9,7,1) -> F | U9: =MID(B9,8,2) -> 30
A10: 141629 | B10: SRDR30F60- | C10: =CONCATENATE(Q10,R10,S10,T10,U10) -> SRDR30F60 | D10: 0 | E10: 0 | F10: 1596 | G10: 0 | H10: 0 | I10: 0 | J10: 0 | K10: Flood - 68° | L10: 6000K | M10: Round White Trim | N10: Constant Current | O10: 30 Watt | Q10: =MID(B10,1,3) -> SRD | R10: =MID(B10,4,1) -> R | S10: =MID(B10,5,2) -> 30 | T10: =MID(B10,7,1) -> F | U10: =MID(B10,8,2) -> 60
A11: 141630 | B11: SRDR30F50- | C11: =CONCATENATE(Q11,R11,S11,T11,U11) -> SRDR30F50 | D11: 0 | E11: 0 | F11: 1596 | G11: 0 | H11: 0 | I11: 0 | J11: 0 | K11: Flood - 68° | L11: 5000K | M11: Round White Trim | N11: Constant Current | O11: 30 Watt | Q11: =MID(B11,1,3) -> SRD | R11: =MID(B11,4,1) -> R | S11: =MID(B11,5,2) -> 30 | T11: =MID(B11,7,1) -> F | U11: =MID(B11,8,2) -> 50
A12: 141631 | B12: SRDR30F40- | C12: =CONCATENATE(Q12,R12,S12,T12,U12) -> SRDR30F40 | D12: 0 | E12: 0 | F12: 1596 | G12: 0 | H12: 0 | I12: 0 | J12: 0 | K12: Flood - 68° | L12: 4000K | M12: Round White Trim | N12: Constant Current | O12: 30 Watt | Q12: =MID(B12,1,3) -> SRD | R12: =MID(B12,4,1) -> R | S12: =MID(B12,5,2) -> 30 | T12: =MID(B12,7,1) -> F | U12: =MID(B12,8,2) -> 40
A13: 141632 | B13: SRDR30F30- | C13: =CONCATENATE(Q13,R13,S13,T13,U13) -> SRDR30F30 | D13: 0 | E13: 0 | F13: 1596 | G13: 0 | H13: 0 | I13: 0 | J13: 0 | K13: Flood - 68° | L13: 3000K | M13: Round White Trim | N13: Constant Current | O13: 30 Watt | Q13: =MID(B13,1,3) -> SRD | R13: =MID(B13,4,1) -> R | S13: =MID(B13,5,2) -> 30 | T13: =MID(B13,7,1) -> F | U13: =MID(B13,8,2) -> 30
... A17: 141639 | B17: SRDB30F30- | C17: =CONCATENATE(Q17,R17,S17,T17,U17) -> SRDB30F30 | D17: 0 | E17: 0 | F17: 1821 | G17: 0 | H17: 0 | I17: 0 | J17: 0 | K17: Flood - 68° | L17: 3000K | M17: Round Black Trim | N17: Constant Current | O17: 30 Watt | Q17: =MID(B17,1,3) -> SRD | R17: =MID(B17,4,1) -> B | S17: =MID(B17,5,2) -> 30 | T17: =MID(B17,7,1) -> F | U17: =MID(B17,8,2) -> 30
A18: 141643 | B18: SRDR20F60T | C18: =CONCATENATE(Q18,R18,S18,T18,U18) -> SRDR20F60T | D18: 0 | E18: 0 | F18: 1384 | G18: 0 | H18: 0 | I18: 0 | J18: 0 | K18: Flood - 68° | L18: 6000K | M18: Round White Trim | N18: TRIAC Dimming | O18: 20 Watt | Q18: =MID(B18,1,3) -> SRD | R18: =MID(B18,4,1) -> R | S18: =MID(B18,5,2) -> 20 | T18: =MID(B18,7,1) -> F | U18: =MID(B18,8,6) -> 60T
A19: 141644 | B19: SRDR20F50T | C19: =CONCATENATE(Q19,R19,S19,T19,U19) -> SRDR20F50T | D19: 0 | E19: 0 | F19: 1384 | G19: 0 | H19: 0 | I19: 0 | J19: 0 | K19: Flood - 68° | L19: 5000K | M19: Round White Trim | N19: TRIAC Dimming | O19: 20 Watt | Q19: =MID(B19,1,3) -> SRD | R19: =MID(B19,4,1) -> R | S19: =MID(B19,5,2) -> 20 | T19: =MID(B19,7,1) -> F | U19: =MID(B19,8,6) -> 50T
A20: 141645 | B20: SRDR20F40T | C20: =CONCATENATE(Q20,R20,S20,T20,U20) -> SRDR20F40T | D20: 0 | E20: 0 | F20: 1384 | G20: 0 | H20: 0 | I20: 0 | J20: 0 | K20: Flood - 68° | L20: 4000K | M20: Round White Trim | N20: TRIAC Dimming | O20: 20 Watt | Q20: =MID(B20,1,3) -> SRD | R20: =MID(B20,4,1) -> R | S20: =MID(B20,5,2) -> 20 | T20: =MID(B20,7,1) -> F | U20: =MID(B20,8,6) -> 40T
A21: 141646 | B21: SRDR20F30T | C21: =CONCATENATE(Q21,R21,S21,T21,U21) -> SRDR20F30T | D21: 0 | E21: 0 | F21: 1384 | G21: 0 | H21: 0 | I21: 0 | J21: 0 | K21: Flood - 68° | L21: 3000K | M21: Round White Trim | N21: TRIAC Dimming | O21: 20 Watt | Q21: =MID(B21,1,3) -> SRD | R21: =MID(B21,4,1) -> R | S21: =MID(B21,5,2) -> 20 | T21: =MID(B21,7,1) -> F | U21: =MID(B21,8,6) -> 30T
A22: 141650 | B22: SRDB20F60T | C22: =CONCATENATE(Q22,R22,S22,T22,U22) -> SRDB20F60T | D22: 0 | E22: 0 | F22: 1387 | G22: 0 | H22: 0 | I22: 0 | J22: 0 | K22: Flood - 68° | L22: 6000K | M22: Round Black Trim | N22: TRIAC Dimming | O22: 20 Watt | Q22: =MID(B22,1,3) -> SRD | R22: =MID(B22,4,1) -> B | S22: =MID(B22,5,2) -> 20 | T22: =MID(B22,7,1) -> F | U22: =MID(B22,8,6) -> 60T
A23: 141651 | B23: SRDB20F50T | C23: =CONCATENATE(Q23,R23,S23,T23,U23) -> SRDB20F50T | D23: 0 | E23: 0 | F23: 1387 | G23: 0 | H23: 0 | I23: 0 | J23: 0 | K23: Flood - 68° | L23: 5000K | M23: Round Black Trim | N23: TRIAC Dimming | O23: 20 Watt | Q23: =MID(B23,1,3) -> SRD | R23: =MID(B23,4,1) -> B | S23: =MID(B23,5,2) -> 20 | T23: =MID(B23,7,1) -> F | U23: =MID(B23,8,6) -> 50T
A24: 141652 | B24: SRDB20F40T | C24: =CONCATENATE(Q24,R24,S24,T24,U24) -> SRDB20F40T | D24: 0 | E24: 0 | F24: 1387 | G24: 0 | H24: 0 | I24: 0 | J24: 0 | K24: Flood - 68° | L24: 4000K | M24: Round Black Trim | N24: TRIAC Dimming | O24: 20 Watt | Q24: =MID(B24,1,3) -> SRD | R24: =MID(B24,4,1) -> B | S24: =MID(B24,5,2) -> 20 | T24: =MID(B24,7,1) -> F | U24: =MID(B24,8,6) -> 40T
A25: 141653 | B25: SRDB20F30T | C25: =CONCATENATE(Q25,R25,S25,T25,U25) -> SRDB20F30T | D25: 0 | E25: 0 | F25: 1387 | G25: 0 | H25: 0 | I25: 0 | J25: 0 | K25: Flood - 68° | L25: 3000K | M25: Round Black Trim | N25: TRIAC Dimming | O25: 20 Watt | Q25: =MID(B25,1,3) -> SRD | R25: =MID(B25,4,1) -> B | S25: =MID(B25,5,2) -> 20 | T25: =MID(B25,7,1) -> F | U25: =MID(B25,8,6) -> 30T
A26: 141657 | B26: SRDR30F60T | C26: =CONCATENATE(Q26,R26,S26,T26,U26) -> SRDR30F60T | D26: 0 | E26: 0 | F26: 0 | G26: 0 | H26: 0 | I26: 0 | J26: 0 | K26: Flood - 68° | L26: 6000K | M26: Round White Trim | N26: TRIAC Dimming | O26: 30 Watt | Q26: =MID(B26,1,3) -> SRD | R26: =MID(B26,4,1) -> R | S26: =MID(B26,5,2) -> 30 | T26: =MID(B26,7,1) -> F | U26: =MID(B26,8,6) -> 60T
A27: 141658 | B27: SRDR30F50T | C27: =CONCATENATE(Q27,R27,S27,T27,U27) -> SRDR30F50T | D27: 0 | E27: 0 | F27: 0 | G27: 0 | H27: 0 | I27: 0 | J27: 0 | K27: Flood - 68° | L27: 5000K | M27: Round White Trim | N27: TRIAC Dimming | O27: 30 Watt | Q27: =MID(B27,1,3) -> SRD | R27: =MID(B27,4,1) -> R | S27: =MID(B27,5,2) -> 30 | T27: =MID(B27,7,1) -> F | U27: =MID(B27,8,6) -> 50T
A28: 141659 | B28: SRDR30F40T | C28: =CONCATENATE(Q28,R28,S28,T28,U28) -> SRDR30F40T | D28: 0 | E28: 0 | F28: 0 | G28: 0 | H28: 0 | I28: 0 | J28: 0 | K28: Flood - 68° | L28: 4000K | M28: Round White Trim | N28: TRIAC Dimming | O28: 30 Watt | Q28: =MID(B28,1,3) -> SRD | R28: =MID(B28,4,1) -> R | S28: =MID(B28,5,2) -> 30 | T28: =MID(B28,7,1) -> F | U28: =MID(B28,8,6) -> 40T
A29: 141660 | B29: SRDR30F30T | C29: =CONCATENATE(Q29,R29,S29,T29,U29) -> SRDR30F30T | D29: 0 | E29: 0 | F29: 0 | G29: 0 | H29: 0 | I29: 0 | J29: 0 | K29: Flood - 68° | L29: 3000K | M29: Round White Trim | N29: TRIAC Dimming | O29: 30 Watt | Q29: =MID(B29,1,3) -> SRD | R29: =MID(B29,4,1) -> R | S29: =MID(B29,5,2) -> 30 | T29: =MID(B29,7,1) -> F | U29: =MID(B29,8,6) -> 30T
... A73: 141836 | B73: SRDB30F25BTD | C73: =CONCATENATE(Q73,R73,S73,T73,U73) -> SRDB30F25BTD | D73: 0 | E73: 0 | F73: 0 | G73: 0 | H73: 0 | I73: 0 | J73: 0 | K73: Flood - 68° | L73: 2700k - 5000k Bluetooth + Dual Color (Driving System) Only for 20W | M73: Round Black Trim | N73: Bluetooth + Dual Color (2700K - 5000K) Only for 20W | O73: 30 Watt | Q73: =MID(B73,1,3) -> SRD | R73: =MID(B73,4,1) -> B | S73: =MID(B73,5,2) -> 30 | T73: =MID(B73,7,1) -> F | U73: =MID(B73,8,6) -> 25BTD
