Workbook

Sheet Stock Item
A1: Name | B1: Group Name | C1: Units | D1: Name of BOM | E1: Unit of manufacture | F1: BOM Component - Item Name | G1: BOM Component - Quantity | H1: BOM Component - Godown | I1: BOM Component - Type of Item | J1: BOM Component - Rate (%) | K1: BOM Component - Location | L1: Unit Price | M1: Cost | N1: USD | O1: INS&FRED | P1: BCD | Q1: Total Cost
A2: =$D$2 -> SRDR18F30T | B2: Down Light Series | C2: Nos. | D2: SRDR18F30T | E2: 1 | F2: ='Backend data'!C6 -> Trim-O-85 I-51 H-50mm White SRD-12/15/18W | G2: 1 | H2: Mechanical Store | I2: Component | L2: 7 | M2: =G2*L2 -> 7
F3: ='Backend data'!D6 -> HS-50X50.5mm (SR-DR-NR-18W) | G3: 1 | H3: Mechanical Store | I3: Component | L3: =Q3*87 -> 77.3865 | M3: =G3*L3 -> 77.3865 | N3: 0.593 | O3: 0.5 | Q3: =N3+(N3*(O3+P3)) -> 0.8895
F4: Refl. 50014-W OD-50 LES ID -20.5 H-13.4mm 8-18W | G4: 1 | H4: Mechanical Store | I4: Component | L4: =Q4*87 -> 7.4385 | M4: =G4*L4 -> 7.4385 | N4: 0.057 | O4: 0.5 | Q4: =N4+(N4*(O4+P4)) -> 0.0855
F5: COB Holder 50014-W OD-35 ID-17 H-3.5mm 8-18W | G5: 1 | H5: Mechanical Store | I5: Component | Q5: =N5+(N5*(O5+P5)) -> 0
F6: Diff. Film 48.4mm DRDR8-12W Paper | G6: 1 | H6: Mechanical Store | I6: Component | L6: =Q6*87 -> 5.481 | M6: =G6*L6 -> 5.481 | N6: 0.042 | O6: 0.5 | Q6: =N6+(N6*(O6+P6)) -> 0.063
F7: Diff. 48.5x1.5mm Prismatic DRDR8-12W | G7: 1 | H7: Mechanical Store | I7: Component | Q7: =N7+(N7*(O7+P7)) -> 0
F8: Torsion Spring - L-49 W-18mm Coil D-1mm D-8 Black | G8: 2 | H8: Mechanical Store | I8: Component | L8: =Q8*87 -> 1.044 | M8: =G8*L8 -> 2.088 | N8: 0.008 | O8: 0.5 | Q8: =N8+(N8*(O8+P8)) -> 0.012
F9: Spring Holding Clip L-37 W-25 T-0.70mm MS | G9: 2 | H9: Mechanical Store | I9: Component | L9: 2 | M9: =G9*L9 -> 4
F10: PBX - COB 8-15W | G10: 1 | H10: Mechanical Store | I10: Component | L10: 8.5 | M10: =G10*L10 -> 8.5
F11: SBX - COB 8-18W (12Nos) | G11: 0.08 | H11: Mechanical Store | I11: Component | L11: 27 | M11: =G11*L11 -> 2.16
F12: Conn. 2Pin Ass. Wire Black Male (Small) | G12: 1 | H12: Mechanical Store | I12: Component | L12: =Q12*87 -> 3.915 | M12: =G12*L12 -> 3.915 | N12: 0.03 | O12: 0.5 | Q12: =N12+(N12*(O12+P12)) -> 0.045
F13: Sleeve M4mm Fiber Glass White | G13: 0.12 | H13: Mechanical Store | I13: Component | L13: =5.7/1000*120 -> 0.684 | M13: =G13*L13 -> 0.08208
F14: Wire Clip-M3-MS | G14: 1 | H14: Mechanical Store | I14: Component | L14: 0.6 | M14: =G14*L14 -> 0.6
F15: Screw No. 4X6.5mm Self Pan Combi. PH - SS | G15: 1 | H15: Mechanical Store | I15: Component | L15: 0.21 | M15: =G15*L15 -> 0.21
F16: Screw M3X6mm CSK PH - SS | G16: 2 | H16: Mechanical Store | I16: Component | L16: 0.5 | M16: =G16*L16 -> 1
F17: Rivet 1/8" x 1/4" MS (Big) | G17: 2 | H17: Mechanical Store | I17: Component | L17: 0.26 | M17: =G17*L17 -> 0.52
F18: Rivet 3/32" X 3/16" MS (Small) | G18: 4 | H18: Mechanical Store | I18: Component | L18: 0.32 | M18: =G18*L18 -> 1.28
F20: ='Backend data'!G6 -> COB 30-36W 3000K 12LED 34-38V 890mA 19x19mm CRI-90 | G20: 1 | H20: Electronics Store | I20: Component | L20: =Q20*87 -> 84.825 | M20: =G20*L20 -> 84.825 | N20: 0.65 | O20: 0.5 | Q20: =N20+(N20*(O20+P20)) -> 0.975
F21: ='Backend data'!H6 -> PS 18W 440mA 36V Maxic(PCB LT-MX-20W-V2) | G21: 1 | H21: Mechanical Store | I21: Component | L21: =Q21*87 -> 0 | M21: =G21*L21 -> 0 | N21: PS Rate Mention with Total Amt
M22: =SUM(M2:M21) -> 206.48608
K24: SRDR18W-CC | M24: =M22+98 -> 304.48608
K25: SRDR18 Track Dimming | M25: =M22 -> 206.48608 | R25: Rate
K26: SRDR18 Dali Single Color | M26: =((M22)+(Q26*87)) -> 950.33608 | N26: 5.7 | O26: 0.5 | Q26: =N26+(N26*(O26+P26)) -> 8.55 | R26: =Q26*87 -> 743.85
K27: SRDR18 BT Single Color | M27: =M22+330 -> 536.48608
K28: SRDR18 Dali Dual Color | M28: =((M22)+(Q28*87)) -> 1009.0611 | N28: 6.15 | O28: 0.5 | Q28: =N28+(N28*(O28+P28)) -> 9.225 | R28: =Q28*87 -> 802.575
K29: SRDR18 BT Dual Color | M29: =M22+330 -> 536.48608

Sheet Stock Item (Read Me)
A1: List of Fields | B1: Applicable Countries | C1: Applicable Values
A2: General Details
A3: Name | B3: All | E3: Read the following, before you start using the sample file:
A4: Group Name | B4: All | E4: Stock Item worksheet:
A5: B | B5: All | E5: - Use the worksheet without making any changes to the column headers to enter your business data. - The column headers represent field names in TallyPrime. Mandatory fields are marked in bold for easy reference. - Add new columns, if needed. Ensure to enter Column Headers exactly as mentioned under the List of Fields of the Read Me worksheet. - Delete unwanted columns. However, do not delete columns that represent mandatory fields for masters.
A6: Part No. | B6: All
A7: Alias - Part No. | B7: All
A8: Description | B8: All
A9: Notes | B9: All
A10: Category | B10: All
A11: Units | B11: All | E11: Stock Item (Read Me)
A12: Conversion | B12: All | E12: - The Read Me worksheet is only for your reference. It lists all the fields, with related details, applicable for Stock Item.
A13: Denominator | B13: All
A14: Alternate Units | B14: All | E14: For more information on using Sample Excel File for importing data, refer to | M14: TallyHelp
A15: GST Applicability | B15: All | C15: Applicable, Not Applicable
A16: Opening Balance - Quantity | B16: All
A17: Opening Balance - Rate | B17: All
A18: Opening Balance - Rate Per | B18: All
A19: Opening Balance - Value | B19: All
A20: Language for Name (Except English) | B20: All
A21: Is TCS Applicable | B21: All
A22: Item Allocations Details
A23: Item Allocations - Godown | B23: (When Accounting Terminology is set to "India/SAARC")
A24: Item Allocations - Batch | B24: All
A25: Item Allocations - Quantity | B25: All
A26: Item Allocations - Rate | B26: All
A27: Item Allocations - Rate per | B27: All
A28: Item Allocations - Amount | B28: All
A29: Item Allocations - Mfg. Date | B29: All
A30: Item Allocations - Expiry Date | B30: All
A31: Item Allocations - Location | B31: (When Accounting Terminology is set to "International")
A32: Additional Details
A33: Maintain in Batches | B33: All
A34: Track date of manufacturing | B34: All
A35: Use expiry dates | B35: All
A36: Enable Cost Tracking | B36: All
A37: Costing Method | B37: All | C37: At Zero Cost, Avg. Cost, FIFO, FIFO Perpetual, Last Purchase Cost, LIFO Annual, LIFO Perpetual, Monthly Avg. Cost, Std. Cost
A38: Market Valuation Method | B38: All | C38: At Zero Price, Avg. Price, Last Sale Price, Std. Price
A39: Behaviour
A40: Ignore difference due to physical counting | B40: All
...

Sheet Backend data
C2: TRIM | D2: HOUSING/HS | E2: REFLECTOR | F2: BEAM ANGLE | G2: COLOR TEMP | H2: DRIVING SYSTEM | I2: PCB
C3: =MID('Stock Item'!$D$2,4,1) -> R | D3: =MID('Stock Item'!$D$2,5,2) -> 18 | E3: =MID('Stock Item'!$D$2,3,1) -> D | F3: =MID('Stock Item'!$D$2,7,1) -> F | G3: =MID('Stock Item'!$D$2,8,2) -> 30 | H3: =MID('Stock Item'!$D$2,10,11) -> T | I3: =MID('Stock Item'!$D$2,2,1) -> R
D4: =CONCATENATE($D$3,$F$3) -> 18F | G4: =CONCATENATE('Backend data'!$G$3,'Backend data'!$H$3,"-") -> 30T- | H4: =CONCATENATE($D$3,$H$3,"-") -> 18T- | I4: =CONCATENATE(C3,D3) -> R18
H5: =CONCATENATE('Stock Item'!D2) -> SRDR18F30T
B6: Formulae | C6: =VLOOKUP($C$3,$B$23:$E$72,2,0) -> Trim-O-85 I-51 H-50mm White SRD-12/15/18W | D6: =VLOOKUP($D$4,G23:$J$100,2,0) -> HS-50X50.5mm (SR-DR-NR-18W) | E6: =VLOOKUP($E$3,$L$23:$O$72,2,0) -> #N/A | F6: =VLOOKUP($F$3,$Q$23:$T$72,2,0) -> #N/A | G6: =VLOOKUP($G$4,$V$23:$Y$72,2,0) -> COB 30-36W 3000K 12LED 34-38V 890mA 19x19mm CRI-90 | H6: =VLOOKUP($H$4,$AA$23:$AD$72,2,0) -> PS 18W 440mA 36V Maxic(PCB LT-MX-20W-V2) | I6: =VLOOKUP($I$3,AF23:$AI$100,2,0) -> #N/A
B7: Formulae for COST | C7: =VLOOKUP($C$3,$B$23:$E$72,4,0) -> 0 | D7: =VLOOKUP($D$4,G23:$J$100,4,0) -> 0 | E7: =VLOOKUP($E$3,$L$23:$O$72,4,0) -> #N/A | F7: =VLOOKUP($F$3,$Q$23:$T$72,4,0) -> #N/A | G7: =VLOOKUP($G$4,$V$23:$Y$72,4,0) -> 0 | H7: =VLOOKUP($H$4,$AA$23:$AD$72,4,0) -> 0 | I7: =VLOOKUP($I$3,$AF$23:$AI$100,4,0) -> #N/A
B8: Formulae for Quantity | C8: =VLOOKUP($C$3,$B$23:$E$72,3,0) -> 0 | D8: =VLOOKUP($D$4,G23:$J$100,3,0) -> 0 | E8: =VLOOKUP($E$3,$L$23:$O$72,3,0) -> #N/A | F8: =VLOOKUP($F$3,$Q$23:$T$72,3,0) -> #N/A | G8: =VLOOKUP($G$4,$V$23:$Y$72,3,0) -> 0 | H8: =VLOOKUP($H$4,$AA$23:$AD$72,3,0) -> 0 | I8: =VLOOKUP($I$3,$AF$23:$AI$100,3,0) -> #N/A
H10: BOM LED PCB
B21: TRIM | G21: HOUSING/HS | L21: REFLECTOR | Q21: BEAM ANGLE | V21: COLOUR TEMPERATURE | AA21: DRIVING SYSTEM | AF21: PCB
B22: Code | C22: Item Name | D22: Quantity | E22: Cost | G22: Code | H22: Item Name | I22: Quantity | J22: Cost | L22: Code | M22: Item Name | N22: Quantity | O22: Cost | Q22: Code | R22: Item Name | S22: Quantity | T22: Cost | V22: Code | W22: Item Name | X22: Quantity | Y22: Cost | AA22: Code | AB22: Item Name | AC22: Quantity | AD22: Cost | AF22: Code | AG22: Item Name | AH22: Quantity | AI22: Cost
B23: R | C23: Trim-O-85 I-51 H-50mm White SRD-12/15/18W | G23: 12F | H23: HS 50x34.5mm (SR-DR-NR-12W) | V23: 27T- | W23: COB 30W 2700K 12LED 34-38V 890mA 19x19mm CRI-90
B24: B | C24: Trim-O-85 I-51 H-50mm Black SRD-12/15/18W | G24: 15F | H24: HS-50X40.5mm (SR-DR-NR-15W) | V24: 30T- | W24: COB 30-36W 3000K 12LED 34-38V 890mA 19x19mm CRI-90 | AA24: 18T- | AB24: PS 18W 440mA 36V Maxic(PCB LT-MX-20W-V2)
B25: T | C25: Trim-O-85 I-51 H-50mm Two Color SRD-12/15/18W | G25: 18F | H25: HS-50X50.5mm (SR-DR-NR-18W) | V25: 40T- | W25: COB 30-36W 4000K 12LED 34-38V 890mA 19x19mm CRI-90 | AA25: 18I- | AB25: PS 18W 450mA 36V Track Dimming
V26: 50T- | W26: COB 30-36W 5000K 12LED 34-38V 890mA 19x19mm CRI-90 | AA26: 18BT- | AB26: Dali Driver SC-15-20W PE19DA4240 (AI-Dimming)9-42V
V27: 60T- | W27: COB 30-36W 6000K 12LED 34-38V 890mA 19x19mm CRI-90 | AA27: 18ID- | AB27: PS CCT 18W 375MA 36V BT-SC (PCB LT 7-20W-CCT-V 1.1 REV-1)
AA28: 18BTD- | AB28: Dali Driver DC-20W PE69R4240 (AI-Dimming)-25-40V
V29: 27I- | W29: COB 30W 2700K 12LED 34-38V 890mA 19x19mm CRI-90 | AB29: PS CCT 18W 375MA 36V BT-DC (PCB LT 7-20W-CCT-V 1.1 REV-1)
V30: 30I- | W30: COB 30-36W 3000K 12LED 34-38V 890mA 19x19mm CRI-90
V31: 40I- | W31: COB 30-36W 4000K 12LED 34-38V 890mA 19x19mm CRI-90
V32: 50I- | W32: COB 30-36W 5000K 12LED 34-38V 890mA 19x19mm CRI-90
V33: 60I- | W33: COB 30-36W 6000K 12LED 34-38V 890mA 19x19mm CRI-90
V34: 25ID- | W34: LED COB Dual Colour 30W 2700K-5000k
V36: 27BT- | W36: COB 30W 2700K 12LED 34-38V 890mA 19x19mm CRI-90
V37: 30BT- | W37: COB 30-36W 3000K 12LED 34-38V 890mA 19x19mm CRI-90
V38: 40BT- | W38: COB 30-36W 4000K 12LED 34-38V 890mA 19x19mm CRI-90
V39: 50BT- | W39: COB 30-36W 5000K 12LED 34-38V 890mA 19x19mm CRI-90
V40: 60BT- | W40: COB 30-36W 6000K 12LED 34-38V 890mA 19x19mm CRI-90
V41: 25BTD- | W41: LED COB Dual Colour 30W 2700K-5000k

Sheet SRDR12-15-18W-SKU
A1: SKU Id | B1: SKU Code | C1: Product Name | D1: Cost Price | E1: Retail Price | F1: Selling Price | G1: Weight | H1: Width | I1: Height | J1: Depth | K1: Trim | L1: Beam Angle | M1: Color Temp | N1: Driving System | O1: Watt
A2: 134875 | B2: SRDR18F60T | C2: =CONCATENATE(Q2,R2,S2,T2,U2) -> SRDR18F60T | D2: 0 | E2: 0 | F2: 1782 | G2: 0 | H2: 0 | I2: 0 | J2: 0 | K2: Round White Trim | L2: Flood - 77° | M2: 6000K | N2: TRIAC Dimming | O2: 18 Watt | Q2: =MID(B2,1,3) -> SRD | R2: =MID(B2,4,1) -> R | S2: =MID(B2,5,2) -> 18 | T2: =MID(B2,7,1) -> F | U2: =MID(B2,8,5) -> 60T
A3: 134876 | B3: SRDR18F50T | C3: =CONCATENATE(Q3,R3,S3,T3,U3) -> SRDR18F50T | D3: 0 | E3: 0 | F3: 1782 | G3: 0 | H3: 0 | I3: 0 | J3: 0 | K3: Round White Trim | L3: Flood - 77° | M3: 5000K | N3: TRIAC Dimming | O3: 18 Watt | Q3: =MID(B3,1,3) -> SRD | R3: =MID(B3,4,1) -> R | S3: =MID(B3,5,2) -> 18 | T3: =MID(B3,7,1) -> F | U3: =MID(B3,8,5) -> 50T
A4: 134877 | B4: SRDR18F40T | C4: =CONCATENATE(Q4,R4,S4,T4,U4) -> SRDR18F40T | D4: 0 | E4: 0 | F4: 1782 | G4: 0 | H4: 0 | I4: 0 | J4: 0 | K4: Round White Trim | L4: Flood - 77° | M4: 4000K | N4: TRIAC Dimming | O4: 18 Watt | Q4: =MID(B4,1,3) -> SRD | R4: =MID(B4,4,1) -> R | S4: =MID(B4,5,2) -> 18 | T4: =MID(B4,7,1) -> F | U4: =MID(B4,8,5) -> 40T
A5: 134878 | B5: SRDR18F30T | C5: =CONCATENATE(Q5,R5,S5,T5,U5) -> SRDR18F30T | D5: 0 | E5: 0 | F5: 1782 | G5: 0 | H5: 0 | I5: 0 | J5: 0 | K5: Round White Trim | L5: Flood - 77° | M5: 3000K | N5: TRIAC Dimming | O5: 18 Watt | Q5: =MID(B5,1,3) -> SRD | R5: =MID(B5,4,1) -> R | S5: =MID(B5,5,2) -> 18 | T5: =MID(B5,7,1) -> F | U5: =MID(B5,8,5) -> 30T
A6: 134879 | B6: SRDR18F27T | C6: =CONCATENATE(Q6,R6,S6,T6,U6) -> SRDR18F27T | D6: 0 | E6: 0 | F6: 1782 | G6: 0 | H6: 0 | I6: 0 | J6: 0 | K6: Round White Trim | L6: Flood - 77° | M6: 2700K | N6: TRIAC Dimming | O6: 18 Watt | Q6: =MID(B6,1,3) -> SRD | R6: =MID(B6,4,1) -> R | S6: =MID(B6,5,2) -> 18 | T6: =MID(B6,7,1) -> F | U6: =MID(B6,8,5) -> 27T
A7: 134883 | B7: SRDB18F60T | C7: =CONCATENATE(Q7,R7,S7,T7,U7) -> SRDB18F60T | D7: 0 | E7: 0 | F7: 1844 | G7: 0 | H7: 0 | I7: 0 | J7: 0 | K7: Round Black Trim | L7: Flood - 77° | M7: 6000K | N7: TRIAC Dimming | O7: 18 Watt | Q7: =MID(B7,1,3) -> SRD | R7: =MID(B7,4,1) -> B | S7: =MID(B7,5,2) -> 18 | T7: =MID(B7,7,1) -> F | U7: =MID(B7,8,5) -> 60T
A8: 134884 | B8: SRDB18F50T | C8: =CONCATENATE(Q8,R8,S8,T8,U8) -> SRDB18F50T | D8: 0 | E8: 0 | F8: 1844 | G8: 0 | H8: 0 | I8: 0 | J8: 0 | K8: Round Black Trim | L8: Flood - 77° | M8: 5000K | N8: TRIAC Dimming | O8: 18 Watt | Q8: =MID(B8,1,3) -> SRD | R8: =MID(B8,4,1) -> B | S8: =MID(B8,5,2) -> 18 | T8: =MID(B8,7,1) -> F | U8: =MID(B8,8,5) -> 50T
A9: 134885 | B9: SRDB18F40T | C9: =CONCATENATE(Q9,R9,S9,T9,U9) -> SRDB18F40T | D9: 0 | E9: 0 | F9: 1844 | G9: 0 | H9: 0 | I9: 0 | J9: 0 | K9: Round Black Trim | L9: Flood - 77° | M9: 4000K | N9: TRIAC Dimming | O9: 18 Watt | Q9: =MID(B9,1,3) -> SRD | R9: =MID(B9,4,1) -> B | S9: =MID(B9,5,2) -> 18 | T9: =MID(B9,7,1) -> F | U9: =MID(B9,8,5) -> 40T
A10: 134886 | B10: SRDB18F30T | C10: =CONCATENATE(Q10,R10,S10,T10,U10) -> SRDB18F30T | D10: 0 | E10: 0 | F10: 1844 | G10: 0 | H10: 0 | I10: 0 | J10: 0 | K10: Round Black Trim | L10: Flood - 77° | M10: 3000K | N10: TRIAC Dimming | O10: 18 Watt | Q10: =MID(B10,1,3) -> SRD | R10: =MID(B10,4,1) -> B | S10: =MID(B10,5,2) -> 18 | T10: =MID(B10,7,1) -> F | U10: =MID(B10,8,5) -> 30T
A11: 134887 | B11: SRDB18F27T | C11: =CONCATENATE(Q11,R11,S11,T11,U11) -> SRDB18F27T | D11: 0 | E11: 0 | F11: 1844 | G11: 0 | H11: 0 | I11: 0 | J11: 0 | K11: Round Black Trim | L11: Flood - 77° | M11: 2700K | N11: TRIAC Dimming | O11: 18 Watt | Q11: =MID(B11,1,3) -> SRD | R11: =MID(B11,4,1) -> B | S11: =MID(B11,5,2) -> 18 | T11: =MID(B11,7,1) -> F | U11: =MID(B11,8,5) -> 27T
A12: 134891 | B12: SRDT18F60T | C12: =CONCATENATE(Q12,R12,S12,T12,U12) -> SRDT18F60T | D12: 0 | E12: 0 | F12: 1914 | G12: 0 | H12: 0 | I12: 0 | J12: 0 | K12: Round Two Color Trim | L12: Flood - 77° | M12: 6000K | N12: TRIAC Dimming | O12: 18 Watt | Q12: =MID(B12,1,3) -> SRD | R12: =MID(B12,4,1) -> T | S12: =MID(B12,5,2) -> 18 | T12: =MID(B12,7,1) -> F | U12: =MID(B12,8,5) -> 60T
A13: 134892 | B13: SRDT18F50T | C13: =CONCATENATE(Q13,R13,S13,T13,U13) -> SRDT18F50T | D13: 0 | E13: 0 | F13: 1914 | G13: 0 | H13: 0 | I13: 0 | J13: 0 | K13: Round Two Color Trim | L13: Flood - 77° | M13: 5000K | N13: TRIAC Dimming | O13: 18 Watt | Q13: =MID(B13,1,3) -> SRD | R13: =MID(B13,4,1) -> T | S13: =MID(B13,5,2) -> 18 | T13: =MID(B13,7,1) -> F | U13: =MID(B13,8,5) -> 50T
... A52: 135330 | B52: SRDT18F25BTD | C52: =CONCATENATE(Q52,R52,S52,T52,U52) -> SRDT18F25BTD | D52: 0 | E52: 0 | F52: 2949 | G52: 0 | H52: 0 | I52: 0 | J52: 0 | K52: Round Two Color Trim | L52: Flood - 77° | M52: 2700k - 5000k Bluetooth + Dual Color (Driving System) | N52: Bluetooth + Dual Color (2700K - 5000K) | O52: 18 Watt | Q52: =MID(B52,1,3) -> SRD | R52: =MID(B52,4,1) -> T | S52: =MID(B52,5,2) -> 18 | T52: =MID(B52,7,1) -> F | U52: =MID(B52,8,5) -> 25BTD
