Workbook

Sheet Stock Item
A1: Name | B1: Group Name | C1: Units | D1: Name of BOM | E1: Unit of manufacture | F1: BOM Component - Item Name | G1: BOM Component - Quantity | H1: BOM Component - Godown | I1: BOM Component - Type of Item | J1: BOM Component - Rate (%) | K1: BOM Component - Location | L1: Unit Price | M1: Cost | N1: USD | O1: INS&FRED | P1: BCD | Q1: Total Cost
A2: =$D$2 -> SRRR12F30 | B2: Down Light Series | C2: Nos. | D2: SRRR12F30 | E2: 1 | F2: ='Backend data'!C6 -> Trim-O-85 I-51 H-50mm White SRRR-8-18W | G2: 1 | H2: Mechanical Store | I2: Component | L2: 7 | M2: =G2*L2 -> 7 | N2: 0 | O2: 0.5 | Q2: =N2+(N2*(O2+P2)) -> 0
F3: ='Backend data'!D6 -> HS 50x34.5mm (SR-DR-NR-12W) | G3: 1 | H3: Mechanical Store | I3: Component | L3: =Q3*87 -> 60.291 | M3: =G3*L3 -> 60.291 | N3: 0.462 | O3: 0.5 | Q3: =N3+(N3*(O3+P3)) -> 0.693
F4: Refl. 50014-W OD-50 LES ID -20.5 H-13.4mm 8-18W | G4: 1 | H4: Mechanical Store | I4: Component | L4: =Q4*87 -> 7.4385 | M4: =G4*L4 -> 7.4385 | N4: 0.057 | O4: 0.5 | Q4: =N4+(N4*(O4+P4)) -> 0.0855
F5: Diff. 50014-W D-49.5 T-1.2mm Frosted - 8-18W | G5: 1 | H5: Mechanical Store | I5: Component
F6: COB Holder 50014-W OD-35 ID-17 H-3.5mm 8-18W | G6: 1 | H6: Mechanical Store | I6: Component
F7: Torsion Spring - L-49 W-18mm Coil D-1mm D-8 Black | G7: 2 | H7: Mechanical Store | I7: Component | L7: =Q7*87 -> 1.044 | M7: =G7*L7 -> 2.088 | N7: 0.008 | O7: 0.5 | Q7: =N7+(N7*(O7+P7)) -> 0.012
F8: Spring Holding Clip L-37 W-25 T-0.70mm MS | G8: 2 | H8: Mechanical Store | I8: Component | L8: 2 | M8: =G8*L8 -> 4 | N8: 0 | O8: 0.5 | Q8: =N8+(N8*(O8+P8)) -> 0
F9: PBX-COB 8-15W | G9: 1 | H9: Mechanical Store | I9: Component | L9: 8.5 | M9: =G9*L9 -> 8.5 | N9: 0 | O9: 0.5 | Q9: =N9+(N9*(O9+P9)) -> 0
F10: SBX-COB 8-18W (12Nos) | G10: 0.08 | H10: Mechanical Store | I10: Component | L10: 27 | M10: =G10*L10 -> 2.16 | N10: 0 | O10: 0.5 | Q10: =N10+(N10*(O10+P10)) -> 0
F11: Conn. 2 Pin Ass. Wire Black Male(small) | G11: 1 | H11: Mechanical Store | I11: Component | L11: =Q11*87 -> 3.915 | M11: =G11*L11 -> 3.915 | N11: 0.03 | O11: 0.5 | Q11: =N11+(N11*(O11+P11)) -> 0.045
F12: Sleeve M4mm Fiber Glass White | G12: 0.12 | H12: Mechanical Store | I12: Component | L12: =5.7/1000*120 -> 0.684 | M12: =G12*L12 -> 0.08208 | N12: 0 | O12: 0.5 | Q12: =N12+(N12*(O12+P12)) -> 0
F13: Wire Clip-M3-MS | G13: 1 | H13: Mechanical Store | I13: Component | L13: 0.6 | M13: =G13*L13 -> 0.6 | N13: 0 | O13: 0.5 | Q13: =N13+(N13*(O13+P13)) -> 0
F14: Screw No. 4X6.5mm Self Pan Combi. PH - SS | G14: 1 | H14: Mechanical Store | I14: Component | L14: 0.21 | M14: =G14*L14 -> 0.21 | N14: 0 | O14: 0.5 | Q14: =N14+(N14*(O14+P14)) -> 0
F15: Screw M3X6mm CSK PH-SS | G15: 2 | H15: Mechanical Store | I15: Component | L15: 0.5 | M15: =G15*L15 -> 1 | N15: 0 | O15: 0.5 | Q15: =N15+(N15*(O15+P15)) -> 0
F16: Rivet 1/8" x 1/4" MS (Big) | G16: 2 | H16: Mechanical Store | I16: Component | L16: 0.26 | M16: =G16*L16 -> 0.52 | N16: 0 | O16: 0.5 | Q16: =N16+(N16*(O16+P16)) -> 0
F17: Rivet 3/32x1/4 (Small) | G17: 4 | H17: Mechanical Store | I17: Component | L17: 0.4 | M17: =G17*L17 -> 1.6 | N17: 0 | O17: 0.5 | Q17: =N17+(N17*(O17+P17)) -> 0
F19: ='Backend data'!G6 -> COB 30-36W 3000K 12LED 34-38V 890mA 19x19mm CRI-90 | G19: 1 | H19: Electronics Store | I19: Component | L19: =Q19*87 -> 84.825 | M19: =G19*L19 -> 84.825 | N19: 0.65 | O19: 0.5 | Q19: =N19+(N19*(O19+P19)) -> 0.975
F20: ='Backend data'!H6 -> PS 12-20W 300mA 36-72V Maxic (PCB LT-MX-20W-V2) | G20: 1 | H20: Mechanical Store | I20: Component | L20: =Q20*87 -> 0 | M20: =G20*L20 -> 0 | N20: PS Rate Mention with Total Amt
M21: =SUM(M2:M20) -> 184.22958
K23: SRRR12-CC | M23: =M21+98 -> 282.22958
K24: SRRR12 Track Dimming | M24: =M21+275 -> 459.22958 | R24: Rate
K25: SRRR12 Dali Single Color | M25: =((M21)+(Q25*87)) -> 841.94958 | N25: 5.04 | O25: 0.5 | Q25: =N25+(N25*(O25+P25)) -> 7.56 | R25: =Q25*87 -> 657.72
K26: SRRR12 BT Single Color | M26: =M21+330 -> 514.22958
K27: SRRR12 Dali Dual Color | M27: =((M21)+(Q27*87)) -> 898.71708 | N27: 5.475 | O27: 0.5 | Q27: =N27+(N27*(O27+P27)) -> 8.2125 | R27: =Q27*87 -> 714.4875
K28: SRRR12 BT Dual Color | M28: =M21+330 -> 514.22958

Sheet Stock Item (Read Me)
A1: List of Fields | B1: Applicable Countries | C1: Applicable Values
A2: General Details
A3: Name | B3: All | E3: Read the following, before you start using the sample file:
A4: Group Name | B4: All | E4: Stock Item worksheet:
A5: B | B5: All | E5: - Use the worksheet without making any changes to the column headers to enter your business data. - The column headers represent field names in TallyPrime. Mandatory fields are marked in bold for easy reference. - Add new columns, if needed. Ensure to enter Column Headers exactly as mentioned under the List of Fields of the Read Me worksheet. - Delete unwanted columns. However, do not delete columns that represent mandatory fields for masters.
A6: Part No. | B6: All
A7: Alias - Part No. | B7: All
A8: Description | B8: All
A9: Notes | B9: All
A10: Category | B10: All
A11: Units | B11: All | E11: Stock Item (Read Me)
A12: Conversion | B12: All | E12: - The Read Me worksheet is only for your reference. It lists all the fields, with related details, applicable for Stock Item.
A13: Denominator | B13: All
A14: Alternate Units | B14: All | E14: For more information on using Sample Excel File for importing data, refer to | M14: TallyHelp
A15: GST Applicability | B15: All | C15: Applicable, Not Applicable
A16: Opening Balance - Quantity | B16: All
A17: Opening Balance - Rate | B17: All
A18: Opening Balance - Rate Per | B18: All
A19: Opening Balance - Value | B19: All
A20: Language for Name (Except English) | B20: All
A21: Is TCS Applicable | B21: All
A22: Item Allocations Details
A23: Item Allocations - Godown | B23: (When Accounting Terminology is set to "India/SAARC")
A24: Item Allocations - Batch | B24: All
A25: Item Allocations - Quantity | B25: All
A26: Item Allocations - Rate | B26: All
A27: Item Allocations - Rate per | B27: All
A28: Item Allocations - Amount | B28: All
A29: Item Allocations - Mfg. Date | B29: All
A30: Item Allocations - Expiry Date | B30: All
A31: Item Allocations - Location | B31: (When Accounting Terminology is set to "International")
A32: Additional Details
A33: Maintain in Batches | B33: All
A34: Track date of manufacturing | B34: All
A35: Use expiry dates | B35: All
A36: Enable Cost Tracking | B36: All
A37: Costing Method | B37: All | C37: At Zero Cost, Avg. Cost, FIFO, FIFO Perpetual, Last Purchase Cost, LIFO Annual, LIFO Perpetual, Monthly Avg. Cost, Std. Cost
A38: Market Valuation Method | B38: All | C38: At Zero Price, Avg. Price, Last Sale Price, Std. Price
A39: Behaviour
A40: Ignore difference due to physical counting | B40: All
...

Sheet Backend data
C2: TRIM | D2: HOUSING/HS | E2: REFLECTOR | F2: BEAM ANGLE | G2: COLOR TEMP | H2: DRIVING SYSTEM | I2: EXTRA
C3: =MID('Stock Item'!$D$2,4,3) -> R12 | D3: =MID('Stock Item'!$D$2,5,2) -> 12 | E3: =MID('Stock Item'!$D$2,3,1) -> R | F3: =MID('Stock Item'!$D$2,7,1) -> F | G3: =MID('Stock Item'!$D$2,8,2) -> 30 | H3: =MID('Stock Item'!$D$2,10,11) | I3: =MID('Stock Item'!$D$2,2,1) -> R
D4: =CONCATENATE(C3) -> R12 | G4: =CONCATENATE($G$3,H3,"-") -> 30- | H4: =CONCATENATE(D3,$H$3,"-") -> 12-
H5: =CONCATENATE('Stock Item'!D2) -> SRRR12F30
B6: Formulae | C6: =VLOOKUP($C$3,$B$23:$E$73,2,0) -> Trim-O-85 I-51 H-50mm White SRRR-8-18W | D6: =VLOOKUP($D$4,G23:$J$101,2,0) -> HS 50x34.5mm (SR-DR-NR-12W) | E6: =VLOOKUP($E$3,$L$23:$O$73,2,0) -> #N/A | F6: =VLOOKUP($F$3,$Q$23:$T$73,2,0) -> #N/A | G6: =VLOOKUP($G$4,$V$23:$Y$73,2,0) -> COB 30-36W 3000K 12LED 34-38V 890mA 19x19mm CRI-90 | H6: =VLOOKUP($H$4,$AA$23:$AD$73,2,0) -> PS 12-20W 300mA 36-72V Maxic (PCB LT-MX-20W-V2) | I6: =VLOOKUP($I$3,AF23:$AI$101,2,0) -> #N/A
B7: Formulae for COST | C7: =VLOOKUP($C$3,$B$23:$E$73,4,0) -> 0 | D7: =VLOOKUP($D$4,G23:$J$101,4,0) -> 0 | E7: =VLOOKUP($E$3,$L$23:$O$73,4,0) -> #N/A | F7: =VLOOKUP($F$3,$Q$23:$T$73,4,0) -> #N/A | G7: =VLOOKUP($G$4,$V$23:$Y$73,4,0) -> 0 | H7: =VLOOKUP($H$4,$AA$23:$AD$73,4,0) -> 0 | I7: =VLOOKUP($I$3,$AF$23:$AI$101,4,0) -> #N/A
B8: Formulae for Quantity | C8: =VLOOKUP($C$3,$B$23:$E$73,3,0) -> 0 | D8: =VLOOKUP($D$4,G23:$J$101,3,0) -> 0 | E8: =VLOOKUP($E$3,$L$23:$O$73,3,0) -> #N/A | F8: =VLOOKUP($F$3,$Q$23:$T$73,3,0) -> #N/A | G8: =VLOOKUP($G$4,$V$23:$Y$73,3,0) -> 0 | H8: =VLOOKUP($H$4,$AA$23:$AD$73,3,0) -> 0 | I8: =VLOOKUP($I$3,$AF$23:$AI$101,3,0) -> #N/A
C10: SRRB12F25BTD | H10: BOM LED PCB
B21: TRIM | G21: HOUSING/HS | L21: REFLECTOR | Q21: BEAM ANGLE | V21: COLOR TEMPERATURE | AA21: DRIVING SYSTEM | AF21: EXTRA
B22: Code | C22: Item Name | D22: Quantity | E22: Cost | G22: Code | H22: Item Name | I22: Quantity | J22: Cost | L22: Code | M22: Item Name | N22: Quantity | O22: Cost | Q22: Code | R22: Item Name | S22: Quantity | T22: Cost | V22: Code | W22: Item Name | X22: Quantity | Y22: Cost | AA22: Code | AB22: Item Name | AC22: Quantity | AD22: Cost | AF22: Code | AG22: Item Name | AH22: Quantity | AI22: Cost
B23: R12 | C23: Trim-O-85 I-51 H-50mm White SRRR-8-18W | G23: R12 | H23: HS 50x34.5mm (SR-DR-NR-12W) | V23: 27- | W23: COB 30W 2700K 12LED 34-38V 890mA 19x19mm CRI-90 | AA23: 12- | AB23: PS 12-20W 300mA 36-72V Maxic (PCB LT-MX-20W-V2)
B24: B12 | C24: Trim-O-85 I-51 H-50mm Black SRRR-8-18W | G24: B12 | H24: HS 50x34.5mm (SR-DR-NR-12W) | V24: 30- | W24: COB 30-36W 3000K 12LED 34-38V 890mA 19x19mm CRI-90 | AA24: 12T- | AB24: PS 12W 300mA 36V Triac Dimming
B25: T12 | C25: Trim-O-85 I-51 H-50mm Two Color SRRR-8-18W | G25: T12 | H25: HS 50x34.5mm (SR-DR-NR-12W) | V25: 40- | W25: COB 30-36W 4000K 12LED 34-38V 890mA 19x19mm CRI-90 | AA25: 12I- | AB25: Dali Driver SC-10W PE19DA4240 (AI-Dimming)-25-40V
V26: 50- | W26: COB 30-36W 5000K 12LED 34-38V 890mA 19x19mm CRI-90 | AA26: 12BT- | AB26: PS CCT 12W 250MA 36V BT-SC (PCB LT 7-20W-CCT-V 1.1 REV-1)
B27: R15 | C27: Trim-O-85 I-51 H-50mm White SRRR-8-18W | G27: R15 | H27: HS-50X40.5mm (SR-DR-NR-15W) | AA27: 12ID- | AB27: Dali Driver DC-10W PE694R4230(AI-Dimming)-25-40V
B28: B15 | C28: Trim-O-85 I-51 H-50mm Black SRRR-8-18W | G28: B15 | H28: HS-50X40.5mm (SR-DR-NR-15W) | AA28: 12BTD- | AB28: PS CCT 12W 250MA 36V BT-DC (PCB LT 7-20W-CCT-V 1.1 REV-1)
B29: T15 | C29: Trim-O-85 I-51 H-50mm Two Color SRRR-8-18W | G29: T15 | H29: HS-50X40.5mm (SR-DR-NR-15W) | V29: 27T- | W29: COB 30W 2700K 12LED 34-38V 890mA 19x19mm CRI-90
V30: 30T- | W30: COB 30-36W 3000K 12LED 34-38V 890mA 19x19mm CRI-90 | AA30: 15- | AB30: PS-15W 360mA 36V
B31: R18 | C31: Trim-O-85 I-51 H-50mm White SRRR-8-18W | G31: R18 | H31: HS-50X50.5mm (SR-DR-NR-12W) | V31: 40T- | W31: COB 30-36W 4000K 12LED 34-38V 890mA 19x19mm CRI-90 | AA31: 15T- | AB31: PS-15W 360mA 36V-TRIAC
B32: B18 | C32: Trim-O-85 I-51 H-50mm Black SRRR-8-18W | G32: B18 | H32: HS-50X50.5mm (SR-DR-NR-12W) | V32: 50T- | W32: COB 30-36W 5000K 12LED 34-38V 890mA 19x19mm CRI-90 | AA32: 15I- | AB32: PS-15W 360mA 36V-DALI
B33: T18 | C33: Trim-O-85 I-51 H-50mm Two Color SRRR-8-18W | G33: T18 | H33: HS-50X50.5mm (SR-DR-NR-12W) | AA33: 15BT- | AB33: PS-15W 360mA 36V-BT
AA34: 15ID- | AB34: PS-15W 360mA 36V-(DALI+DC)
V35: 27I- | W35: COB 30W 2700K 12LED 34-38V 890mA 19x19mm CRI-90 | AA35: 15BTD- | AB35: PS-15W 360mA 36V-(BT+DC)
V36: 30I- | W36: COB 30-36W 3000K 12LED 34-38V 890mA 19x19mm CRI-90
V37: 40I- | W37: COB 30-36W 4000K 12LED 34-38V 890mA 19x19mm CRI-90 | AA37: 18- | AB37: PS-18W 440mA 36V
V38: 50I- | W38: COB 30-36W 5000K 12LED 34-38V 890mA 19x19mm CRI-90 | AA38: 18T- | AB38: PS-18W 440mA 36V-TRIAC
V39: 26ID- | W39: LED COB Dual Colour 30W 2700K-5000k | AA39: 18I- | AB39: PS-18W 440mA 36V-DALI
AA40: 18BT- | AB40: PS-18W 440mA 36V-BT
AA41: 18ID- | AB41: PS-18W 440mA 36V-(DALI+DC)
V42: 27BT- | W42: COB 30W 2700K 12LED 34-38V 890mA 19x19mm CRI-90 | AA42: 18BTD- | AB42: PS-18W 440mA 36V-(BT+DC)
V43: 30BT- | W43: COB 30-36W 3000K 12LED 34-38V 890mA 19x19mm CRI-90
V44: 40BT- | W44: COB 30-36W 4000K 12LED 34-38V 890mA 19x19mm CRI-90
V45: 50BT- | W45: COB 30-36W 5000K 12LED 34-38V 890mA 19x19mm CRI-90
V46: 26BTD- | W46: LED COB Dual Colour 30W 2700K-5000k

Sheet Result
A1: SKU Id | B1: SKU Code | C1: Product Name | D1: Cost Price | E1: Retail Price | F1: Selling Price | G1: Weight | H1: Width | I1: Height | J1: Depth | K1: Trim | L1: Beam Angle | M1: Color Temperature | N1: Driving System | O1: Watt
A2: 202660 | B2: SRRR12F30 | D2: 0 | E2: 0 | F2: 0 | G2: 0 | H2: 0 | I2: 0 | J2: 0 | K2: White | L2: Wide | M2: 3000K | N2: Constant Current | O2: 12W
A3: 202661 | B3: SRRR12F40 | D3: 0 | E3: 0 | F3: 0 | G3: 0 | H3: 0 | I3: 0 | J3: 0 | K3: White | L3: Wide | M3: 4000K | N3: Constant Current | O3: 12W
A4: 202662 | B4: SRRR12F50 | D4: 0 | E4: 0 | F4: 0 | G4: 0 | H4: 0 | I4: 0 | J4: 0 | K4: White | L4: Wide | M4: 5000K | N4: Constant Current | O4: 12W
A5: 202672 | B5: SRRB12F30 | D5: 0 | E5: 0 | F5: 0 | G5: 0 | H5: 0 | I5: 0 | J5: 0 | K5: Black | L5: Wide | M5: 3000K | N5: Constant Current | O5: 12W
A6: 202673 | B6: SRRB12F40 | D6: 0 | E6: 0 | F6: 0 | G6: 0 | H6: 0 | I6: 0 | J6: 0 | K6: Black | L6: Wide | M6: 4000K | N6: Constant Current | O6: 12W
A7: 202674 | B7: SRRB12F50 | D7: 0 | E7: 0 | F7: 0 | G7: 0 | H7: 0 | I7: 0 | J7: 0 | K7: Black | L7: Wide | M7: 5000K | N7: Constant Current | O7: 12W
A8: 202684 | B8: SRRT12F30 | D8: 0 | E8: 0 | F8: 0 | G8: 0 | H8: 0 | I8: 0 | J8: 0 | K8: Two Color | L8: Wide | M8: 3000K | N8: Constant Current | O8: 12W
A9: 202685 | B9: SRRT12F40 | D9: 0 | E9: 0 | F9: 0 | G9: 0 | H9: 0 | I9: 0 | J9: 0 | K9: Two Color | L9: Wide | M9: 4000K | N9: Constant Current | O9: 12W
A10: 202686 | B10: SRRT12F50 | D10: 0 | E10: 0 | F10: 0 | G10: 0 | H10: 0 | I10: 0 | J10: 0 | K10: Two Color | L10: Wide | M10: 5000K | N10: Constant Current | O10: 12W
A11: 202696 | B11: SRRR12F30T | D11: 0 | E11: 0 | F11: 0 | G11: 0 | H11: 0 | I11: 0 | J11: 0 | K11: White | L11: Wide | M11: 3000K | N11: TRIAC Dimming | O11: 12W
A12: 202697 | B12: SRRR12F40T | D12: 0 | E12: 0 | F12: 0 | G12: 0 | H12: 0 | I12: 0 | J12: 0 | K12: White | L12: Wide | M12: 4000K | N12: TRIAC Dimming | O12: 12W
A13: 202698 | B13: SRRR12F50T | D13: 0 | E13: 0 | F13: 0 | G13: 0 | H13: 0 | I13: 0 | J13: 0 | K13: White | L13: Wide | M13: 5000K | N13: TRIAC Dimming | O13: 12W
... A43: 202867 | B43: SRRT12F26BTD | D43: 0 | E43: 0 | F43: 0 | G43: 0 | H43: 0 | I43: 0 | J43: 0 | K43: Two Color | L43: Wide | M43: 2700K - 6000K | N43: Bluetooth Dual | O43: 12W
